Workbook
Name HHD_MC: 'Tổng hợp'!$B$33

Sheet Dữ liệu nguồn
C4: CÔNG TY TNHH NEPO
A5: Số 26/63/36 đường Vạn Mỹ, Phường Vạn Mỹ, Quận Ngô Quyền, TP. Hải Phòng
A6: MST: 0201588208 | C6: ĐT: 031.6.260956 / Fax: 0313753956
A7: CÔNG NỢ PHẢI THU KHÁCH HÀNG T6.2019
A8: STT | B8: KHÁCH HÀNG | C8: NỢ CŨ | D8: PHÁT SINH TRONG THÁNG | F8: THANH TOÁN | H8: SỐ TIỀN CÒN NỢ | I8: GHI CHÚ
D9: SỐ TIỀN | E9: GBN | F9: SỐ TIỀN | G9: NGÀY THÁNG
A11: 1 | B11: MỘC SƯƠNG | C11: 950 | H11: =C11+SUM(D11:D13)-SUM(F11:F13) -> 950
A14: 2 | B14: LIGARDEN | C14: 0 | D14: 30308850 | E14: LG19003 | F14: 30308850 | G14: 43612 | H14: =C14+SUM(D14:D16)-SUM(F14:F16) -> 0
A17: 3 | B17: ĐẠI LỘC | C17: 0 | H17: =C17+SUM(D17:D19)-SUM(F17:F19) -> 0
A20: 4 | B20: TÂN LẬP MC | C20: 15446000 | D20: 46338000 | E20: TLMC1905001 | F20: 15446000 | G20: 43605 | H20: =C20+D20-F20-F21-F22 -> 0
F21: 36338000 | G21: 43629
F22: 10000000 | G22: 43629
A23: 5 | B23: VISTA | C23: 45867037 | D23: 7903000 | E23: BKT5 | F23: 45867037 | G23: 43605 | H23: =C23+SUM(D23:D28)-SUM(F23:F28) -> 7903000
A29: 6 | B29: VINATEA MỘC CHÂU | C29: 104524650 | F29: 100000000 | G29: 43601 | H29: =C29+SUM(D29:D36)-SUM(F29:F36) -> 4524650 | I29: nợ t4
L35: 1375000
L36: 783000
A37: 7 | B37: VIỆT PHÁT | L37: 1100000
L38: =SUM(L35:L37) -> 3258000
A40: 8 | B40: TRÀ THU ĐAN | C40: 35553 | H40: =C40+SUM(D40:D41)-SUM(F40:F41) -> 35553
A42: 9 | B42: SATOEN | C42: 0 | H42: =C42+SUM(D42:D43)-SUM(F42:F43) -> 0
A44: 10 | B44: KHÍ VINA | C44: 2888300 | D44: 2958200 | E44: VNG1905001 | F44: 2888900 | G44: 43602 | H44: =C44+SUM(D44:D45)-SUM(F44:F45) -> -600
F45: 2958200 | G45: 43634
A46: 11 | B46: CỜ ĐỎ MỘC CHÂU | C46: 26586000 | F46: 26586000 | G46: 43626 | H46: =C46+SUM(D46:D50)-SUM(F46:F50) -> 0
L49: =250000+31461+176300 -> 457761
L50: =25*250000 -> 6250000
A51: 12 | B51: QUỐC CƯỜNG | C51: 0 | H51: =C51+SUM(D51:D57)-SUM(F51:F57) -> 0 | L51: =+L50*0.1 -> 625000
L52: =+L50+L51 -> 6875000
A58: 13 | B58: EIDAI | C58: -20000 | H58: =C58+SUM(D58:D68)-SUM(F58:F68) -> -20000
A69: 14 | B69: NGÔ PHÚ THỌ | C69: 0 | H69: =C69+SUM(D69:D73)-SUM(F69:F73) -> 0
A74: 15 | B74: SAO VÀNG | C74: 0 | H74: =C74+D74-F74 -> 0
A75: 16 | B75: VIETSUN | C75: 71330000 | D75: 21970000 | E75: BKT5 | F75: 25380000 | G75: 43595 | H75: =C75+SUM(D75:D77)-SUM(F75:F77) -> 21970000
F76: 45950000 | G76: 43630
A78: 17 | B78: TÂN VIỆT HƯNG | C78: 256280000 | D78: 197600000 | E78: BKT5 | F78: 70040000 | G78: 43595 | H78: =C78+SUM(D78:D83)-SUM(F78:F83) -> 233840000 | I78: NỢ PHẦN T4
F80: 50000000 | G80: 43621
F81: 100000000 | G81: 43631 | J81: =+C78+D78-F78 -> 383840000
A84: 18 | B84: TOÀN CẦU | C84: 0 | H84: =C84+D84-F84 -> 0
A85: 19 | B85: TRƯỜNG PHÁT | C85: 0 | H85: =C85+D85+D86-F85-F86 -> 0
A87: 20 | B87: LỢI SƠN ĐIỀN | C87: 0 | H87: =C87+D87-F87 -> 0
A88: 21 | B88: SAO Á | C88: 0 | H88: =C88+D88-F88 -> 0
A89: 22 | B89: DŨNG DMC | C89: 0 | H89: =C89+D89-F89 -> 0
...

Sheet Tổng hợp
A1: CÔNG NỢ PHẢI THU, PHẢI TRẢ 2024-2025
F2: Ngày tháng | G2: =TODAY() -> 45784
A3: STT | B3: Tên đơn vị | C3: Phải thu | D3: Phải trả | E3: Ghi chú
A4: 1 | B4: ='Mộc Sương'!D3 -> Mộc Sương | C4: ='Mộc Sương'!F7 -> 0
A5: 2 | B5: =Ligarden!D3 -> Ligarden | C5: =Ligarden!F7 -> 0
A6: 3 | B6: ='Tan Lap MC'!D3 -> Tân Lập MC | C6: ='Tan Lap MC'!F7 -> 27330030 | E6: Nợ T4
A7: 4 | B7: =Vista!D3 -> Vista | C7: =Vista!F7 -> 25988000 | E7: Nợ T4
A8: 5 | B8: ='Vinatea MC'!D3 -> Vinatea MC | C8: ='Vinatea MC'!F7 -> 76640050 | E8: Nợ T3,4
A9: 6 | B9: ='Tra Thu Dan'!D3 -> Trà Thu Đan | C9: ='Tra Thu Dan'!F7 -> 240291120 | E9: Nợ T1,2,3,4
A10: 7 | B10: ='Khi Vina'!D3 -> Khí Vina | C10: ='Khi Vina'!F7 -> 800
A11: 8 | B11: ='Codo MC'!D3 -> Cờ đỏ Mộc Châu | C11: ='Codo MC'!F7 -> 0
A12: 9 | B12: ='Hải Nam'!D3 -> Hải Nam | C12: ='Hải Nam'!F7 -> 0
A13: 10 | B13: =Vietsun!D3 -> Vietsun | C13: =Vietsun!F7 -> 1.750924e+08 | E13: Nợ T3,4
A14: 11 | B14: ='Tan Viet Hung'!D3 -> Tân Việt Hưng | C14: ='Tan Viet Hung'!F7 -> 256338000 | E14: Nợ T2, T3,4
A15: 12 | B15: ='Che My Lam'!D3 -> Chè Mỹ Lâm | C15: ='Che My Lam'!F7 -> 107972800 | E15: Nợ T3,4
A16: 13 | B16: ='Phu Tai'!D3 -> Phú Tài | C16: ='Phu Tai'!F7 -> 43740800 | E16: Nợ T3,4
A17: 14 | B17: ='Hai Dang'!D3 -> Hải Đăng | C17: ='Hai Dang'!F7 -> 79308000 | E17: Nợ T1,2,3,4
A18: 15 | B18: An Khánh | D18: ='An Khanh'!F7 -> -6696000 | E18: Trả T4
A19: 16 | B19: ='Hong Anh Phat'!D3 -> Anh Đoàn (Hồng Anh Phát) | C19: ='Hong Anh Phat'!F7 -> 41151200 | E19: Nợ T2,T3 Trả T4
A20: 17 | B20: ='Anh Phương VS'!D3 -> Anh Phương Vietsun | C20: ='Anh Phương VS'!F7 -> 1700000 | E20: Nợ T2
A21: 18 | B21: =Vietimex!D3 -> Vietimex | C21: =Vietimex!F7 -> 0
A22: 19 | B22: ='Hùng Thuận'!D3 -> Hùng Thuận | C22: ='Hùng Thuận'!F7 -> 14862400 | E22: Nợ T12,2,4
A23: 20 | B23: =Satoen!D3 -> Fire Phoenix | C23: =Satoen!F7 -> 0
A24: 21 | B24: ='KHÁCH LẺ'!D3 -> Khách lẻ | D24: ='KHÁCH LẺ'!F7 -> 0
A25: 22 | B25: ='Vượng Phát'!D3 -> Vượng Phát | D25: ='Vượng Phát'!F7 -> -42660000 | E25: Trả T4
A26: 23 | B26: ='Anh Hiệp'!D3 -> Anh Hiệp | C26: ='Anh Hiệp'!F7 -> 0
A27: 24 | B27: CTY Hân Trang | D27: ='Hân Trang'!F7 -> 0
A28: 25 | B28: Chè Mường Hoa' | D28: ='Chè Mường Hoa'!F7 -> 0
A29: 26 | B29: Chè Tô Múa | C29: ='Chè Tô Múa'!F7 -> 0
A30: 27 | B30: TUÂN THÀNH PHÁT | D30: ='TUÂN THÀNH PHÁT'!F7 -> 0
A31: 28 | B31: ='VIỆT VƯƠNG'!D3 -> VIỆT VƯƠNG | C31: ='VIỆT VƯƠNG'!F7 -> 23400000 | E31: Nợ T7.20
A32: 29 | B32: CTY AT-AT | C32: ='CTY AT-AT'!F7 -> 0
A33: 30 | B33: HHD MC | C33: ='HHD MC'!F7 -> 0
A34: 31 | B34: TỔNG CTY CHÈ' | C34: ='TỔNG CTY CHÈ'!F7 -> 0
A35: 32 | B35: LÊ MINH | C35: ='LÊ MINH'!F7 -> 0
A36: 33 | B36: Mr Huy VS | C36: ='Mr Huy VS'!F7 -> 0
A37: 34 | B37: Mr Huấn VS | C37: ='Mr Huấn VS'!F7 -> 0
A38: 35 | B38: Chè Nà Tân | C38: ='Chè Nà Tân'!F7 -> 0
A39: 36 | B39: Cty Thuận Vũ | C39: ='Cty Thuận Vũ'!F7 -> 4428000 | E39: Nợ T2
A40: 37 | B40: Nam Tùng' | D40: ='Nam Tùng'!F7 -> -5832000 | E40: Trả T4
...

Sheet Mộc Sương
G1: TH
A2: BẢNG KÊ CHI TIẾT CÔNG NỢ
A3: Khách hàng | D3: Mộc Sương
E4: Số dư đầu kỳ | F4: 950
A5: Ngày tháng | D5: =+'Tổng hợp'!$G$2 -> 45784 | E5: Phát sinh Nợ | F5: =SUM(D10:D68) -> 490979150
E6: Phát sinh Có | F6: =SUM(E10:E68) -> 490980100
E7: Số dư cuối kỳ | F7: =+F4+F5-F6 -> 0
A8: STT | B8: Ngày tháng | C8: Diễn giải | D8: Phát sinh | F8: Lũy kế | G8: Ghi chú
D9: Nợ | E9: Có
A10: 1 | B10: 43622 | C10: Giấy báo nợ số MS19001 | D10: 26567900 | F10: =D10+F4 -> 26568850
A11: 2 | B11: 43654 | C11: Công ty chè Mộc Sương thanh toán tiền MS19001 | E11: 26567000 | F11: =F10+D11-E11 -> 1850
A12: 3 | B12: 43677 | C12: Giấy báo nợ số MS19002 | D12: 26819450 | F12: =F11+D12-E12 -> 26821300
A13: 4 | B13: 43704 | C13: Công ty chè Mộc Sương thanh toán tiền MS19002 | E13: 26819450 | F13: =F12+D13-E13 -> 1850
A14: 5 | B14: 26/9/2019 | C14: GBN MS19003 | D14: 26819450 | F14: =F13+D14-E14 -> 26821300
A15: 6 | B15: 21/10/2019 | C15: GBN MS19004 | D15: 22069750 | F15: =F14+D15-E15 -> 48891050
A16: 7 | B16: 43776 | C16: MS thanh toán | E16: =48890100+950 -> 48891050 | F16: =F15+D16-E16 -> 0
A17: 8 | B17: 28/4/2020 | C17: GBN MS20001 | D17: 26687400 | F17: =F16+D17-E17 -> 26687400
A18: 9 | B18: 43983 | C18: MS thanh toán | E18: 26687400 | F18: =F17+D18-E18 -> 0
A19: 10 | B19: 43991 | C19: GBN MS20002 | D19: 24650550 | F19: =F18+D19-E19 -> 24650550
A20: 11 | B20: 44028 | C20: GBN MS20003 | D20: 23813950 | F20: =F19+D20-E20 -> 48464500
A21: 12 | B21: 44035 | C21: MS thanh toán | E21: 48464950 | F21: =F20+D21-E21 -> -450
A22: 13 | B22: 44321 | C22: GBN MS21001 | D22: 40225450 | F22: =F21+D22-E22 -> 40225000
A23: 14 | B23: 44336 | C23: MS thanh toán | E23: 40225450 | F23: =F22+D23-E23 -> -450
A24: 15 | B24: 44398 | C24: GBN MS21002 | D24: 40442950 | F24: =F23+D24-E24 -> 40442500
A25: 16 | B25: 44428 | C25: GBN MS21003 | D25: 46254400 | F25: =F24+D25-E25 -> 86696900
A26: 17 | B26: 44447 | C26: MS thanh toán | E26: =86697350-450 -> 86696900 | H26: xử lý 450 chênh lệch
A27: 18 | B27: 44803 | C27: GBN MS22001 | D27: 57276950
A28: 19 | B28: 44827 | C28: MS thanh toán | E28: 57276950
A29: 20 | B29: 45182 | C29: GBN MS23001 | D29: 43241200
A30: 21 | B30: 45229 | C30: GBN MS23002 | D30: 34352550
A31: 22 | B31: 45245 | C31: GBN MS23003 | D31: 28352800
A32: 23 | B32: 45257 | C32: MS thanh toán | E32: 105946550
A33: 24 | B33: 45541 | C33: GBN MS24001 | D33: 23404400
B34: 45560 | C34: MS thanh toán | E34: 23404400

Sheet Ligarden
G1: TH
A2: BẢNG KÊ CHI TIẾT CÔNG NỢ
A3: Khách hàng | D3: Ligarden
E4: Số dư đầu kỳ | F4: 0
A5: Ngày tháng | D5: =+'Tổng hợp'!$G$2 -> 45784 | E5: Phát sinh Nợ | F5: =SUM(D10:D68) -> 601493208
E6: Phát sinh Có | F6: =SUM(E10:E68) -> 601493208
E7: Số dư cuối kỳ | F7: =+F4+F5-F6 -> 0
A8: STT | B8: Ngày tháng | C8: Diễn giải | D8: Phát sinh | F8: Ghi chú
D9: Nợ | E9: Có
A10: 1 | B10: 43778 | C10: GBN LG19004 | D10: 31282450
A11: 2 | B11: 43656 | C11: Ligarden thanh toán | E11: 31282450
A12: 3 | B12: 26/12/2019 | C12: GBN LG19005 | D12: 34553550
A13: 4 | B13: 44044 | C13: GBN LG19006 | D13: 31258150
A14: 5 | B14: 16/1/2019 | C14: Ligarden thanh toán | E14: 65811700
A15: 6 | B15: 14/3/2020 | C15: LG20001NK | D15: 38734500
A16: 7 | B16: 25/3/2020 | C16: Ligarden thanh toán | E16: 38734500
A17: 8 | B17: 44124 | C17: LG20002 | D17: 25569950
A18: 9 | B18: 44140 | C18: Ligarden thanh toán | E18: 25569950
A19: 10 | B19: 44352 | C19: LG21001NK | D19: 5021006
A20: 11 | B20: 44354 | C20: Tiền thuế HĐ | D20: 200000
A21: 12 | B21: 44354 | C21: Ligarden thanh toán | E21: 5221006
A22: 13 | B22: 44615 | C22: LG22001 | D22: 66037200
A23: 14 | B23: 44650 | C23: Ligarden thanh toán | E23: 66037200
A24: 15 | B24: 44705 | C24: LG22003 | D24: 43148450
A25: 16 | B25: 44714 | C25: GBN LG22001NK | D25: 23174604
A26: 17 | B26: 44718 | C26: Ligarden thanh toán | E26: 66323054
A27: 18 | B27: 44747 | C27: LG22004 | D27: 62029950
A28: 19 | B28: 44761 | C28: Ligarden thanh toán | E28: 62029950
A29: 20 | B29: 44848 | C29: LG22005 | D29: 41442383
A30: 21 | B30: 44872 | C30: Ligarden thanh toán | E30: 41442383
A31: 22 | B31: 45022 | C31: LG23001NK | D31: 42730460
A32: 23 | C32: Ligarden thanh toán | E32: 42730460
A33: 24 | B33: 45068 | C33: LG23002 | D33: 43448895
A34: 25 | B34: 45072 | C34: Ligarden thanh toán | E34: 43448895
A35: 26 | B35: 45377 | C35: LG24001 | D35: 37182300
A36: 27 | B36: 45387 | C36: Ligarden thanh toán | E36: 37182300
A37: 28 | B37: 45405 | C37: LG24002 | D37: 31460160
A38: 29 | B38: 45414 | C38: Ligarden thanh toán | E38: 31460160
A39: 30 | B39: 45553 | C39: LG24003 | D39: 44219200
A40: 31 | B40: 45573 | C40: Ligarden thanh toán | E40: 44219200
...

Sheet Tan Lap MC
G1: TH
A2: BẢNG KÊ CHI TIẾT CÔNG NỢ
A3: Khách hàng | D3: Tân Lập MC
E4: Số dư đầu kỳ | F4: 46338000
A5: Ngày tháng | D5: =+'Tổng hợp'!$G$2 -> 45784 | E5: Phát sinh Nợ | F5: =SUM(D10:D200) -> 1489489210
E6: Phát sinh Có | F6: =SUM(E10:E200) -> 1508497180
E7: Số dư cuối kỳ | F7: =+F4+F5-F6 -> 27330030
A8: STT | B8: Ngày tháng | C8: Diễn giải | D8: Phát sinh | F8: Lũy kế | G8: Ghi chú
D9: Nợ | E9: Có
A10: 1 | B10: 43629 | C10: Tân Lập MC thanh toán tiền | E10: 36338000 | F10: =F4-E10 -> 10000000
A11: 2 | B11: 43629 | C11: Tân Lập MC thanh toán tiền | E11: 10000000 | F11: =F10+D11-E11 -> 0
A12: 3 | B12: 43645 | C12: Công nợ phát sinh trong T6/2019 | D12: 30932000 | F12: =F11+D12-E12 -> 30932000
A13: 4 | B13: 43656 | C13: Tân Lập MC thanh toán tiền | E13: 30932000 | F13: =F12+D13-E13 -> 0
A14: 5 | B14: 43677 | C14: Công nợ phát sinh trong T7/2019 | D14: 32270000 | F14: =F13+D14-E14 -> 32270000
A15: 6 | B15: 30/8/2019 | C15: Tân Lập MC thanh toán tiền | E15: 32270000 | F15: =F14+D15-E15 -> 0
A16: 7 | B16: 31/10/2019 | C16: Công nợ phát sinh T10 | D16: 10722000 | F16: =F15+D16-E16 -> 10722000
A17: 8 | B17: 24/11/2019 | C17: GBN TLMC1911001 | D17: 32270000 | F17: =F16+D17-E17 -> 42992000
A18: 9 | B18: 13/12/2019 | C18: TLMC thanh toán | E18: 42992000 | F18: =F17+D18-E18 -> 0
A19: 10 | B19: 31/3/2020 | C19: GBN TLMC2003001 | D19: 16916000 | F19: =F18+D19-E19 -> 16916000
A20: 11 | B20: 14/4/2020 | C20: TLMC thanh toán | E20: 16916000 | F20: =F19+D20-E20 -> 0
A21: 12 | B21: 29/4/2020 | C21: GBN TLMC2004001 | D21: 44988000 | F21: =F20+D21-E21 -> 44988000
A22: 13 | B22: 44048 | C22: TLMC thanh toán | E22: 44988000 | F22: =F21+D22-E22 -> 0
A23: 14 | B23: 30/5/2020 | C23: GBN TLC2005001 | D23: 46368000 | F23: =F22+D23-E23 -> 46368000
A24: 15 | B24: 17/6/2020 | C24: TLMC thanh toán | E24: 46368000 | F24: =F23+D24-E24 -> 0
A25: 16 | B25: 30/6/2020 | C25: GBN TLMC2006001 | D25: 23822000 | F25: =F24+D25-E25 -> 23822000
A26: 17 | B26: 44021 | C26: TLMC thanh toán | E26: 23822000 | F26: =F25+D26-E26 -> 0
A27: 18 | B27: 44043 | C27: GBN TLMC2007001 | D27: 29072000 | F27: =F26+D27-E27 -> 29072000
A28: 19 | B28: 44064 | C28: TLMC thanh toán | E28: 29072000 | F28: =F27+D28-E28 -> 0
A29: 20 | B29: 44074 | C29: GBN TLMC2008001 | D29: 25202000 | F29: =F28+D29-E29 -> 25202000
A30: 21 | B30: 44092 | C30: TLMC thanh toán | E30: 25202000 | F30: =F29+D30-E30 -> 0
A31: 22 | B31: 44104 | C31: GBN TLMC 2009001 | D31: 43728000 | F31: =F30+D31-E31 -> 43728000
A32: 23 | B32: 44135 | C32: GBN TLMC 2010001 | D32: 29172000 | F32: =F31+D32-E32 -> 72900000
A33: 24 | B33: 44137 | C33: TLMC thanh toán | E33: 43728000 | F33: =F32+D33-E33 -> 29172000
A34: 25 | B34: 44167 | C34: TLMC thanh toán | E34: 29172000 | F34: =F33+D34-E34 -> 0
A35: 26 | B35: 44165 | C35: GBN TLMC 20110001 | D35: 14580000 | F35: =F34+D35-E35 -> 14580000
A36: 27 | B36: 44229 | C36: TLMC thanh toán | E36: 14580000 | F36: =F35+D36-E36 -> 0
A37: 28 | B37: 44284 | C37: GBN CTL21001 | D37: 11968950 | F37: =F36+D37-E37 -> 11968950
A38: 29 | B38: 44284 | C38: TLMC thanh toán | E38: 11968950 | F38: =F37+D38-E38 -> 0 | G38: TM
A39: 30 | B39: 44286 | C39: GBN TLMC2103001 | D39: 29338000 | F39: =F38+D39-E39 -> 29338000
A40: 31 | B40: 44309 | C40: TLMC thanh toán | E40: 29338000 | F40: =F39+D40-E40 -> 0
...

Sheet Vista
G1: TH
A2: BẢNG KÊ CHI TIẾT CÔNG NỢ
A3: Khách hàng | D3: Vista
E4: Số dư đầu kỳ | F4: 7903000 | K4: Đã gửi lại HĐ nguyên tắc, sau đó sẽ email đề nghị thanh toán nốt T5/2019
A5: Ngày tháng | D5: =+'Tổng hợp'!$G$2 -> 45784 | E5: Phát sinh Nợ | F5: =SUM(D10:D200) -> 1778700998
E6: Phát sinh Có | F6: =SUM(E10:E200) -> 1760615998
E7: Số dư cuối kỳ | F7: =+F4+F5-F6 -> 25988000
A8: STT | B8: Ngày tháng | C8: Diễn giải | D8: Phát sinh | F8: Ghi chú
D9: Nợ | E9: Có
A10: 1 | B10: 43645 | C10: Công nợ T6/2019 | D10: 21061200 | H10: =F4+D10-E10 -> 28964200
A11: 2 | B11: 43663 | C11: Vista thanh toán công nợ T6/2019 | E11: 21061200 | H11: =H10+D11-E11 -> 7903000
A12: 3 | B12: 43693 | C12: Vista thanh toán công nợ T5/2019 | E12: 7903000 | H12: =H11+D12-E12 -> 0
A13: 4 | B13: 30/9/2019 | C13: GBN VTA1909001 | D13: 12017700 | H13: =H12+D13-E13 -> 12017700
A14: 5 | B14: 43745 | C14: Vista thanh toán công nợ T9 | E14: 12017700 | H14: =H13+D14-E14 -> 0
A15: 6 | B15: 29/10/2019 | C15: VTA19002NK | D15: 1988892 | H15: =H14+D15-E15 -> 1988892
A16: 7 | B16: 31/10/2019 | C16: Công nợ phát sinh T10 | D16: 9800000 | H16: =H15+D16-E16 -> 11788892
A17: 8 | B17: 19/11/2019 | C17: Vista thanh toán công nợ T10 | E17: 11788892 | H17: =H16+D17-E17 -> 0
A18: 9 | B18: 30/11/2019 | C18: Phát sinh công nợ T11 | D18: =25421000+5775610 -> 31196610 | H18: =H17+D18-E18 -> 31196610
A19: 10 | B19: 16/12/2019 | C19: Vista thanh toán | E19: 31196610 | H19: =H18+D19-E19 -> 0
A20: 11 | B20: 31/12/2019 | C20: Phát sinh công nợ T12 | D20: 35109000 | H20: =H19+D20-E20 -> 35109000
A21: 12 | B21: 15/1/2019 | C21: Vista thanh toán | E21: 35109000 | H21: =H20+D21-E21 -> 0
A22: 13 | B22: 31/1/2020 | C22: VTA2001001 | D22: 35853000 | H22: =H21+D22-E22 -> 35853000
A23: 14 | B23: 29/2/2020 | C23: VTA2002001 | D23: 6492000 | H23: =H22+D23-E23 -> 42345000
A24: 15 | B24: 44138 | C24: Vista thanh toán | E24: 35853000 | H24: =H23+D24-E24 -> 6492000
A25: 16 | B25: 15/4/2020 | C25: Vista thanh toán | E25: 6492000 | H25: =H24+D25-E25 -> 0
A26: 17 | B26: 43927 | C26: VTA20001NK | D26: 5221060 | H26: =H25+D26-E26 -> 5221060
A27: 18 | B27: 30/6/2020 | C27: Phát sinh công nợ T6 | D27: 39602000 | H27: =H26+D27-E27 -> 44823060
A28: 19 | B28: 44021 | C28: Vista thanh toán | E28: 44823060 | H28: =H27+D28-E28 -> 0
A29: 20 | B29: 44043 | C29: Phát sinh công nợ T7 | D29: 25392000 | H29: =H28+D29-E29 -> 25392000
A30: 21 | B30: 44057 | C30: Vista thanh toán | E30: 25392000 | H30: =H29+D30-E30 -> 0
A31: 22 | B31: 44074 | C31: Phát sinh công nợ T8 | D31: 20039000 | H31: =H30+D31-E31 -> 20039000
A32: 23 | B32: 44083 | C32: Vista thanh toán | E32: 20039000 | H32: =H31+D32-E32 -> 0
A33: 24 | B33: 44104 | C33: Phát sinh công nợ T9 | D33: 19063000 | H33: =H32+D33-E33 -> 19063000
A34: 25 | B34: 44116 | C34: Vista thanh toán | E34: 19063000 | H34: =H33+D34-E34 -> 0
A35: 26 | B35: 44135 | C35: Phát sinh công nợ T10 | D35: 12738000 | H35: =H34+D35-E35 -> 12738000
A36: 27 | B36: 44155 | C36: Vista thanh toán | E36: 12738000 | H36: =H35+D36-E36 -> 0
A37: 28 | B37: 44165 | C37: Phát sinh công nợ T11 | D37: 6163000 | H37: =H36+D37-E37 -> 6163000
A38: 29 | B38: 44172 | C38: Vista thanh toán | E38: 6163000 | H38: =H37+D38-E38 -> 0
A39: 30 | B39: 44196 | C39: Phát sinh công nợ T12.20 | D39: 18695000 | H39: =H38+D39-E39 -> 18695000
A40: 31 | B40: 44209 | C40: Vista thanh toán | E40: 18695000 | H40: =H39+D40-E40 -> 0
...

Sheet Vinatea MC
G1: TH
A2: BẢNG KÊ CHI TIẾT CÔNG NỢ
A3: Khách hàng | D3: Vinatea MC
E4: Số dư đầu kỳ | F4: 4524650
A5: Ngày tháng | D5: =+'Tổng hợp'!$G$2 -> 45784 | E5: Phát sinh Nợ | F5: =SUM(D10:D500) -> 5486142741
E6: Phát sinh Có | F6: =SUM(E10:E500) -> 5414027341
E7: Số dư cuối kỳ | F7: =+F4+F5-F6 -> 76640050
A8: STT | B8: Ngày tháng | C8: Diễn giải | D8: Phát sinh | F8: Ghi chú
D9: Nợ | E9: Có
A10: 1 | B10: 43629 | C10: Giấy báo nợ số MCT19005 | D10: 37251250 | F10: =F4+D10-E10 -> 41775900
A11: 2 | B11: 43640 | C11: Giấy báo nợ số MCT19006 | D11: 28163450 | F11: =F10+D11-E11 -> 69939350
A12: 3 | B12: 43677 | C12: Giấy báo nợ số MCT19007 | D12: 128682564 | F12: =F11+D12-E12 -> 198621914
A13: 4 | B13: 43677 | C13: Giấy báo nợ số MCT19008 | D13: 45895233 | F13: =F12+D13-E13 -> 244517147
A14: 5 | B14: 43683 | C14: Vinatea MC thanh toán | E14: 100000000 | F14: =F13+D14-E14 -> 144517147
A15: 6 | B15: 43696 | C15: Vinatea MC thanh toán | E15: 100000000 | F15: =F14+D15-E15 -> 44517147
A16: 7 | B16: 43717 | C16: Vinatea MC thanh toán | E16: 40000000 | F16: =F15+D16-E16 -> 4517147
A17: 8 | B17: 18/9/2019 | C17: Giấy báo nợ số MCT19009 | D17: 42915864 | F17: =F16+D17-E17 -> 47433011
A18: 9 | B18: 18/9/2019 | C18: Giấy báo nợ số MCT19010 | D18: 28160850 | F18: =F17+D18-E18 -> 75593861
A19: 10 | B19: 19/9/2019 | C19: Vinatea MC thanh toán | E19: 50000000 | F19: =F18+D19-E19 -> 25593861
A20: 11 | B20: 43506 | C20: Giấy báo nợ số MCT19011 | D20: 85788376 | F20: =F19+D20-E20 -> 111382237
A21: 12 | B21: 16/10/2019 | C21: Vinatea MC thanh toán | E21: 25593861 | F21: =F20+D21-E21 -> 85788376
A22: 13 | B22: 18/10/2019 | C22: Vinatea MC thanh toán | E22: 50000000 | F22: =F21+D22-E22 -> 35788376
A23: 14 | B23: 43596 | C23: GBN MCT19012 | D23: 82110376 | F23: =F22+D23-E23 -> 117898752
A24: 15 | B24: 43781 | C24: GBN MCT19013 | D24: 28649550 | F24: =F23+D24-E24 -> 146548302
A25: 16 | B25: 43720 | C25: Vinatea MC thanh toán | E25: 120000000 | F25: =F24+D25-E25 -> 26548302
A26: 17 | B26: 30/12/2019 | C26: MCT 19014 | D26: 93522400 | F26: =F25+D26-E26 -> 120070702
A27: 18 | B27: 13/1/2020 | C27: Vinatea MC thanh toán | E27: 120070702 | F27: =F26+D27-E27 -> 0
A28: 19 | B28: 21/4/2020 | C28: GBN MCT20001 | D28: 52269000 | F28: =F27+D28-E28 -> 52269000
A29: 20 | B29: 21/4/2020 | C29: GBN MCT20002 | D29: 96787000 | F29: =F28+D29-E29 -> 149056000
A30: 21 | B30: 21/4/2020 | C30: GBN MCT20003 | D30: 96632000 | F30: =F29+D30-E30 -> 245688000
A31: 22 | B31: 28/4/2020 | C31: GBN MCT20004 | D31: 30366200 | F31: =F30+D31-E31 -> 276054200
A32: 23 | B32: 44017 | C32: Vinatea MC thanh toán | E32: 150000000 | F32: =F31+D32-E32 -> 126054200
A33: 24 | B33: 43895 | C33: Vinatea MC thanh toán | E33: 50000000 | F33: =F32+D33-E33 -> 76054200
A34: 25 | B34: 27/5/2020 | C34: BS phí gia hạn freetime cho 2 lô MCT20002+003 | D34: 9420000 | F34: =F33+D34-E34 -> 85474200
A35: 26 | B35: 15/6/2020 | C35: GBN MCT20006 | D35: 25067450 | F35: =F34+D35-E35 -> 110541650
A36: 27 | B36: 17/6/2020 | C36: Vinatea MC thanh toán | E36: 85474200 | F36: =F35+D36-E36 -> 25067450
A37: 28 | B37: 18/6/2020 | C37: GBN MCT20005 | D37: 90184000 | F37: =F36+D37-E37 -> 115251450
A38: 29 | B38: 24/06/2020 | C38: GBN MCT20005-1 | D38: 6993000 | F38: =F37+D38-E38 -> 122244450
A39: 30 | B39: 29/6/2020 | C39: Vinatea MC thanh toán | E39: 100000000 | F39: =F38+D39-E39 -> 22244450
A40: 31 | B40: 44019 | C40: GBN MCT20007 | D40: 97148000 | F40: =F39+D40-E40 -> 119392450
...

Sheet Tra Thu Dan
G1: TH
A2: BẢNG KÊ CHI TIẾT CÔNG NỢ
A3: Khách hàng | D3: Trà Thu Đan
E4: Số dư đầu kỳ | F4: 35553
A5: Ngày tháng | D5: =+'Tổng hợp'!$G$2 -> 45784 | E5: Phát sinh Nợ | F5: =SUM(D10:D500) -> 3402431793
E6: Phát sinh Có | F6: =SUM(E10:E500) -> 3162176226
E7: Số dư cuối kỳ | F7: =+F4+F5-F6 -> 240291120
A8: STT | B8: Ngày tháng | C8: Diễn giải | D8: Phát sinh | F8: Ghi chú
D9: Nợ | E9: Có
A10: 1 | B10: 43629 | C10: Giay báo nợ số TD19004 | D10: 36747315 | I10: =F4+D10-E10 -> 36782868
A11: 2 | B11: 43630 | C11: Giay báo nợ số TD19005 | D11: 32957050 | I11: =I10+D11-E11 -> 69739918
A12: 3 | B12: 43643 | C12: Thu Đan thanh toán tiền GBN TD19004 | E12: 36747315 | I12: =I11+D12-E12 -> 32992603
A13: 4 | B13: 43670 | C13: Thu Đan thanh toán tiền GBN TD19005 | E13: 32957050 | I13: =I12+D13-E13 -> 35553
A14: 5 | B14: 43779 | C14: GBN TD19006 | D14: 36356650 | I14: =I13+D14-E14 -> 36392203
A15: 6 | B15: 21/10/2019 | C15: GBN TD19007 | D15: 36123150 | I15: =I14+D15-E15 -> 72515353
A16: 7 | B16: 43536 | C16: Thu Đan thanh toán | E16: =72479800+35553 -> 72515353 | I16: =I15+D16-E16 -> 0
A17: 8 | B17: 19/2/2020 | C17: GBN TD20001 | D17: 37930050 | I17: =I16+D17-E17 -> 37930050
A18: 9 | B18: 24/3/2020 | C18: GBN TD20002NK | D18: 36808240 | I18: =I17+D18-E18 -> 74738290
A19: 10 | B19: 15/4/2020 | C19: Thu Đan thanh toán tiền | E19: 74738290 | I19: =I18+D19-E19 -> 0
A20: 11 | B20: 21/4/2020 | C20: GBN TD20003 | D20: 64277600 | I20: =I19+D20-E20 -> 64277600
A21: 12 | B21: 43963 | C21: GBN TD20004 | D21: 36001250 | I21: =I20+D21-E21 -> 100278850
A22: 13 | B22: 29/5/2020 | C22: Thu Đan thanh toán tiền | E22: 100278850 | I22: =I21+D22-E22 -> 0
A23: 14 | B23: 43991 | C23: GBN TD20005 | D23: 30500550 | I23: =I22+D23-E23 -> 30500550
A24: 15 | B24: 29/06/2020 | C24: GBN TD20006TT | D24: 15463950 | F24: Theo TD 20006: 29.463.950 đ | I24: =I23+29463950-E24 -> 59964500
A25: 16 | B25: 44049 | C25: GBN TD20007NK | D25: 36065880 | I25: =I24+D25-E25 -> 96030380
A26: 17 | B26: 44054 | C26: GBN TD20008 | D26: 14479150 | I26: =I25+D26-E26 -> 110509530
A27: 18 | B27: 44068 | C27: GBN TD20009 | D27: 31515350 | I27: =I26+D27-E27 -> 142024880
A28: 19 | B28: 44078 | C28: Thu Đan thanh toán tiền NK | E28: 36065880 | I28: =I27+D28-E28 -> 105959000
A29: 20 | B29: 44081 | C29: GBN TD20010 | D29: 14089150 | I29: =I28+D29-E29 -> 120048150
A30: 21 | B30: 44089 | C30: GBN TD20011 | D30: 14529150 | I30: =I29+D30-E30 -> 134577300
A31: 22 | B31: 44095 | C31: GBN TD20012 | D31: 31515350 | I31: =I30+D31-E31 -> 166092650
A32: 23 | B32: 44102 | C32: Thu Đan thanh toán tiền | E32: 59964500 | I32: =I31+D32-E32 -> 106128150
A33: 24 | B33: 44124 | C33: GBN TD20013 | D33: 40978300 | I33: =I32+D33-E33 -> 147106450
A34: 25 | B34: 44130 | C34: GBN TD20015 | D34: 14089150 | I34: =I33+D34-E34 -> 161195600
A35: 26 | B35: 44141 | C35: GBN TD20014TNK | D35: 10072950 | I35: =I34+D35-E35 -> 171268550
A36: 27 | B36: 44148 | C36: GBN TD20016 | D36: 32678850 | I36: =I35+D36-E36 -> 203947400
A37: 28 | B37: 44176 | C37: Thu Đan thanh toán tiền | E37: 106128150 | I37: =I36+D37-E37 -> 97819250
A38: 29 | B38: 44179 | C38: GBN TD20017 | D38: 38608100 | F38: Chưa TT | I38: =I37+D38-E38 -> 136427350 | J38: =132252150 -> 132252150
A39: 30 | B39: 44221 | C39: Thu Đan thanh toán tiền | E39: 80000000 | I39: =I38+D39-E39 -> 56427350 | J39: =I38-J38 -> 4175200
A40: 31 | B40: 44222 | C40: GBN TD21001 | D40: 44000300 | I40: =I39+D40-E40 -> 100427650
...

Sheet Khi Vina
G1: TH
A2: BẢNG KÊ CHI TIẾT CÔNG NỢ
A3: Khách hàng | D3: Khí Vina
E4: Số dư đầu kỳ | F4: 2958200 | K4: Điều chỉnh lại số dư đầu kỳ cho khớp với GBN gửi khách
A5: Ngày tháng | D5: =+'Tổng hợp'!$G$2 -> 45784 | E5: Phát sinh Nợ | F5: =SUM(D10:D200) -> 1228709441
E6: Phát sinh Có | F6: =SUM(E10:E200) -> 1231666841
E7: Số dư cuối kỳ | F7: =+F4+F5-F6 -> 800
A8: STT | B8: Ngày tháng | C8: Diễn giải | D8: Phát sinh | F8: Ghi chú
D9: Nợ | E9: Có
A10: 1 | B10: 43634 | C10: Công ty Khí Vina thanh toán tiền | E10: 2958200
A11: 2 | B11: 43645 | C11: Công nợ Khí VINA T6/2019 | D11: 7377000 | H11: =D11-E11 -> 7377000
A12: 3 | B12: 43656 | C12: Công ty Khí Vina thanh toán tiền | E12: 7377000 | H12: =H11+D12-E12 -> 0
A13: 4 | B13: 43677 | C13: Công nợ Khí VINA T7/2019 | D13: 3940000 | H13: =H12+D13-E13 -> 3940000
A14: 5 | B14: 43689 | C14: Công ty Khí Vina thanh toán tiền | E14: 3940000 | H14: =H13+D14-E14 -> 0
A15: 6 | B15: 43701 | C15: GBN VNG1908001 | D15: 15705278 | H15: =H14+D15-E15 -> 15705278
A16: 7 | B16: 43708 | C16: GBN VNG1908002 | D16: 1800000 | H16: =H15+D16-E16 -> 17505278
A17: 8 | B17: 43625 | C17: Công ty Khí Vina thanh toán tiền | E17: 15705278 | H17: =H16+D17-E17 -> 1800000
A18: 9 | B18: 43778 | C18: Công ty Khí Vina thanh toán tiền | E18: 1800000 | H18: =H17+D18-E18 -> 0
A19: 10 | B19: 19/9/2019 | C19: GBN VNG1909001 | D19: 23226820 | H19: =H18+D19-E19 -> 23226820
A20: 11 | B20: 25/9/2019 | C20: Công ty Khí Vina thanh toán tiền | E20: 23226820 | H20: =H19+D20-E20 -> 0
A21: 12 | B21: 30/9/2019 | C21: GBN VNG1909002 | D21: 10160000 | H21: =H20+D21-E21 -> 10160000
A22: 13 | B22: 14/10/2019 | C22: Công ty Khí Vina thanh toán tiền | E22: 10160000 | H22: =H21+D22-E22 -> 0
A23: 14 | B23: 31/10/2019 | C23: GBN VNG1910001 | D23: 18720000 | H23: =H22+D23-E23 -> 18720000
A24: 15 | B24: 43780 | C24: Công ty Khí Vina thanh toán tiền | E24: 18720000 | H24: =H23+D24-E24 -> 0
A25: 16 | B25: 30/11/2019 | C25: GBN VNG1911001 | D25: 5750000 | H25: =H24+D25-E25 -> 5750000
A26: 17 | B26: 43750 | C26: Công ty Khí Vina thanh toán tiền | E26: 5750000 | H26: =H25+D26-E26 -> 0
A27: 18 | B27: 31/12/2019 | C27: GBN VNG1912001 | D27: 57980000 | H27: =H26+D27-E27 -> 57980000
A28: 19 | B28: 44044 | C28: Công ty Khí Vina thanh toán tiền | E28: 57980000 | H28: =H27+D28-E28 -> 0
A29: 20 | B29: 31/1/2020 | C29: GBN VNG2001001 | D29: 2815000 | H29: =H28+D29-E29 -> 2815000
A30: 21 | B30: 43984 | C30: Công ty Khí Vina thanh toán tiền | E30: 2815000 | H30: =H29+D30-E30 -> 0
A31: 22 | B31: 29/2/2020 | C31: VNG2002001 | D31: 5510000 | H31: =H30+D31-E31 -> 5510000
A32: 23 | B32: 43954 | C32: Công ty Khí Vina thanh toán tiền | E32: 5510000 | H32: =H31+D32-E32 -> 0
A33: 24 | B33: 31/3/2020 | C33: GBN VNG2003001 | D33: 24990000 | H33: =H32+D33-E33 -> 24990000
A34: 25 | B34: 31/3/2020 | C34: GBN VNG2003002 | D34: 750000 | H34: =H33+D34-E34 -> 25740000
A35: 26 | B35: 44016 | C35: VNG thanh toán | E35: 24990000 | H35: =H34+D35-E35 -> 750000
A36: 27 | B36: 21/4/2020 | C36: VNG thanh toán | E36: 750000 | H36: =H35+D36-E36 -> 0
A37: 28 | B37: 29/4/2020 | C37: VNG2004001 | D37: 16800000 | H37: =H36+D37-E37 -> 16800000
A38: 29 | B38: 29/4/2020 | C38: VNG2004002 | D38: 2150000 | H38: =H37+D38-E38 -> 18950000
A39: 30 | B39: 44140 | C39: VNG thanh toán | E39: 18950000 | H39: =H38+D39-E39 -> 0
A40: 31 | B40: 30/5/2020 | C40: VNG2005001 | D40: 5710000 | H40: =H39+D40-E40 -> 5710000
...

Sheet Codo MC
G1: TH
A2: BẢNG KÊ CHI TIẾT CÔNG NỢ
A3: Khách hàng | D3: Cờ đỏ Mộc Châu | L3: 0982112120
E4: Số dư đầu kỳ | F4: 26586000
A5: Ngày tháng | D5: =+'Tổng hợp'!$G$2 -> 45784 | E5: Phát sinh Nợ | F5: =SUM(D10:D69) -> 580039130
E6: Phát sinh Có | F6: =SUM(E10:E69) -> 606625130
E7: Số dư cuối kỳ | F7: =+F4+F5-F6 -> 0
A8: STT | B8: Ngày tháng | C8: Diễn giải | D8: Phát sinh | F8: Lũy kế | G8: Ghi chú
D9: Nợ | E9: Có
A10: 1 | B10: 43626 | C10: Cờ Đỏ Mộc Châu thanh toán tiền | E10: 26586000 | F10: =F4+D10-E10 -> 0
A11: 2 | B11: 43645 | C11: Công nợ T6/2019 | D11: 15309000 | F11: =F10+D11-E11 -> 15309000
A12: 3 | B12: 43677 | C12: Công nợ T7/2019 | D12: 14461000 | F12: =F11+D12-E12 -> 29770000
A13: 4 | B13: 43708 | C13: Công nợ T8/2019 | D13: 15309000 | F13: =F12+D13-E13 -> 45079000
A14: 5 | B14: 43747 | C14: Cờ Đỏ Mộc Châu thanh toán hết công nợ T7/2019 | E14: 29770000 | F14: =F13+D14-E14 -> 15309000
A15: 6 | B15: 30/9/2019 | C15: Công nợ T9/2019 | D15: 15309000 | F15: =F14+D15-E15 -> 30618000
A16: 7 | B16: 31/10/2019 | C16: Công nợ T10/2019 | D16: 15309000 | F16: =F15+D16-E16 -> 45927000
A17: 8 | B17: 43628 | C17: Cờ đỏ mộc châu thanh toán | E17: 23927000 | F17: =F16+D17-E17 -> 22000000
A18: 9 | B18: 43808 | C18: GBN CDMC1912001 | D18: 6159000 | F18: =F17+D18-E18 -> 28159000
A19: 10 | B19: 26/12/2019 | C19: CĐMC thanh toán | E19: 28159000 | F19: =F18+D19-E19 -> 0
A20: 11 | B20: 31/1/2020 | C20: CĐMC2001001 | D20: 15386000 | F20: =F19+D20-E20 -> 15386000
A21: 12 | B21: 30/5/2020 | C21: CĐMC2005001 | D21: 28832000 | F21: =F20+D21-E21 -> 44218000
A22: 13 | B22: 43957 | C22: CĐMC thanh toán | E22: 15386000 | F22: =F21+D22-E22 -> 28832000
A23: 14 | B23: 44025 | C23: CĐMC thanh toán | E23: 28832000 | F23: =F22+D23-E23 -> 0
A24: 15 | B24: 44043 | C24: CDMC2007001 | D24: 14416000 | F24: =F23+D24-E24 -> 14416000
A25: 16 | B25: 44074 | C25: CDMC2008001 | D25: 14416000 | F25: =F24+D25-E25 -> 28832000
A26: 17 | B26: 44104 | C26: CDMC2009001 | D26: 14464400 | F26: =F25+D26-E26 -> 43296400
A27: 18 | B27: 44134 | C27: CĐMC thanh toán | E27: 14464400 | F27: =F26+D27-E27 -> 28832000
A28: 19 | B28: 44135 | C28: CDMC2010001 | D28: 14484400 | F28: =F27+D28-E28 -> 43316400
A29: 20 | B29: 44165 | C29: CDMC2011001 | D29: 14484400 | F29: =F28+D29-E29 -> 57800800
A30: 21 | B30: 44190 | C30: CĐMC thanh toán | E30: 28968800 | F30: =F29+D30-E30 -> 28832000
A31: 22 | B31: 44196 | C31: CDMC2012001 | D31: 14484400 | F31: =F30+D31-E31 -> 43316400
A32: 23 | B32: 44230 | C32: CĐMC thanh toán | E32: 43316400 | F32: =F31+D32-E32 -> 0
A33: 24 | B33: 44255 | C33: CDMC2102001 | D33: 14900000 | F33: =F32+D33-E33 -> 14900000
A34: 25 | B34: 44313 | C34: CDMC thanh toán | E34: 14900000 | F34: =F33+D34-E34 -> 0
A35: 26 | B35: 44315 | C35: CDMC2104001 | D35: 15140000 | F35: =F34+D35-E35 -> 15140000
A36: 27 | B36: 44377 | C36: CDMC2106001 | D36: 45672000 | F36: =F35+D36-E36 -> 60812000
A37: 28 | B37: 44354 | C37: CDMC thanh toán | E37: 15140000 | F37: =F36+D37-E37 -> 45672000
A38: 29 | B38: 44410 | C38: CDMC thanh toán | E38: 45672000 | F38: =F37+D38-E38 -> 0
A39: 30 | B39: 44439 | C39: CDMC2108001 | D39: 30864000 | F39: =F38+D39-E39 -> 30864000
A40: 31 | B40: 44456 | C40: CDMC thanh toán | E40: 30864000 | F40: =F39+D40-E40 -> 0
...

Sheet Hải Nam
G1: TH
A2: BẢNG KÊ CHI TIẾT CÔNG NỢ
A3: Khách hàng | D3: Hải Nam
E4: Số dư đầu kỳ
A5: Ngày tháng | D5: =+'Tổng hợp'!$G$2 -> 45784 | E5: Phát sinh Nợ | F5: =SUM(D10:D68) -> 42200000
E6: Phát sinh Có | F6: =SUM(E10:E68) -> 42200000
E7: Số dư cuối kỳ | F7: =+F4+F5-F6 -> 0
A8: STT | B8: Ngày tháng | C8: Diễn giải | D8: Phát sinh | F8: Ghi chú
D9: Nợ | E9: Có
A10: 1 | B10: 44803 | C10: Phát sinh công nợ phải thu | D10: 4400000 | G10: =D10-E10 -> 4400000
A11: 2 | B11: 44895 | C11: Phát sinh công nợ phải thu tháng 11 | D11: 8700000 | G11: =G10+D11-E11 -> 13100000
A12: 3 | B12: 44944 | C12: Hải Nam thanh toán tiền cước tháng 8 | E12: 4400000 | G12: =G11+D12-E12 -> 8700000
A13: 4 | B13: 44985 | C13: Phát sinh công nợ phải trả tháng 2 | E13: 12600000 | G13: =G12+D13-E13 -> -3900000
A14: 5 | B14: 45015 | C14: Phát sinh công nợ phải thu tháng 3 | D14: 24950000 | G14: =G13+D14-E14 -> 21050000
A15: 6 | B15: 45035 | C15: Hải Nam thanh toán tiền cước tháng 11 | E15: 8700000 | G15: =G14+D15-E15 -> 12350000
A16: 7 | B16: 45046 | C16: Phát sinh công nợ phải thu tháng 4 | D16: 4150000 | G16: =G15+D16-E16 -> 16500000
A17: 8 | B17: 45150 | C17: Hải Nam thanh toán tiền cước tháng 3 đói trừ tháng 2 | E17: =D14-E13 -> 12350000
A18: 9 | B18: 45202 | C18: Hải Nam thanh toán tiền | E18: 4150000
A19: 10
A20: 11
A21: 12
A22: 13
A23: 14
A24: 15
A25: 16
A26: 17
A27: 18
A28: 19
A29: 20
A30: 21
... A34: 25

Sheet Vietsun
G1: TH
A2: BẢNG KÊ CHI TIẾT CÔNG NỢ
A3: Khách hàng | D3: Vietsun
E4: Số dư đầu kỳ | F4: 67920000
A5: Ngày tháng | D5: =+'Tổng hợp'!$G$2 -> 45784 | E5: Phát sinh Nợ | F5: =SUM(D10:D201) -> 5.2656716e+09
E6: Phát sinh Có | F6: =SUM(E10:E201) -> 5158499198
E7: Số dư cuối kỳ | F7: =+F4+F5-F6 -> 1.750924e+08
A8: STT | B8: Ngày tháng | C8: Diễn giải | D8: Phát sinh | F8: Ghi chú
D9: Nợ | E9: Có
A10: 1 | B10: 43630 | C10: Vietsun thanh toán CN T4/2019 | E10: 45950000 | F10: =F4+D10-E10 -> 21970000
A11: 2 | B11: 43645 | C11: Phát sinh công nợ T6 | D11: 23880000 | F11: =F10+D11-E11 -> 45850000
A12: 3 | B12: 43658 | C12: Vietsun thanh toán CN T5/2019 | E12: 21970000 | F12: =F11+D12-E12 -> 23880000
A13: 4 | B13: 43677 | C13: Phát sinh công nợ T7 | D13: 70380000 | F13: =F12+D13-E13 -> 94260000 | H13: Vietsun chốt số T7 theo số Nepo, thừa thiếu sẽ chuyển sang T8
A14: 5 | B14: 43686 | C14: Vietsun thanh toán tiền công nợ T6 | E14: 23880000 | F14: =F13+D14-E14 -> 70380000
A15: 6 | B15: 31/8/2019 | C15: Phát sinh công nợ T8 | D15: 46949000 | F15: =F14+D15-E15 -> 117329000 | H15: 460k thiếu của T8 sẽ chuyển sang BK T9
A16: 7 | B16: 43625 | C16: Vietsun thanh toán tiền công nợ T7 | E16: 70380000 | F16: =F15+D16-E16 -> 46949000
A17: 8 | B17: 30/9/2019 | C17: Phát sinh công nợ T9 | D17: 32730000 | F17: =F16+D17-E17 -> 79679000
A18: 9 | B18: 43742 | C18: Vietsun thanh toán cước T8 | E18: 46949000 | F18: =F17+D18-E18 -> 32730000
A19: 10 | B19: 31/10/2019 | C19: Phát sinh công nợ T10 | D19: 74220000 | F19: =F18+D19-E19 -> 106950000
A20: 11 | B20: 43775 | C20: Vietsun thanh toán cước T9 | E20: 32730000 | F20: =F19+D20-E20 -> 74220000
A21: 12 | B21: 30/11/2019 | C21: Phát sinh công nợ T11 | D21: 55840000 | F21: =F20+D21-E21 -> 130060000
A22: 13 | B22: 30/11/2019 | C22: Phát sinh công nợ T11 không lấy hóa đơn | D22: 1300000 | F22: =F21+D22-E22 -> 131360000
A23: 14 | B23: 43628 | C23: Vietsun thanh toán cước T10 | E23: 74220000 | F23: =F22+D23-E23 -> 57140000
A24: 15 | B24: 31/12/2019 | C24: Phát sinh công nợ T12 | D24: 48680000 | F24: =F23+D24-E24 -> 105820000
A25: 16 | B25: 43891 | C25: Vietsun thanh toán | E25: 55840000 | F25: =F24+D25-E25 -> 49980000
A26: 17 | B26: 15/1/2020 | C26: Viet sun thanh toán công nợ T11 không lấy hóa đơn (cont DRYU9590030 ngày 28/10) | E26: 1300000 | F26: =F25+D26-E26 -> 48680000
A27: 18 | B27: 44014 | C27: Vietsun thanh toán | E27: 48680000 | F27: =F26+D27-E27 -> 0
A28: 19 | B28: 31/1/2020 | C28: Phát sinh công nợ T1/2020 | D28: =43006000+3450000 -> 46456000 | F28: =F27+D28-E28 -> 46456000
A29: 20 | B29: 43985 | C29: Vietsun thanh toán | E29: 46456000 | F29: =F28+D29-E29 -> 0
A30: 21 | B30: 29/2/2020 | C30: Phát sinh công nợ T2/2020 | D30: 47420000 | F30: =F29+D30-E30 -> 47420000
A31: 22 | B31: 31/3/2020 | C31: Phát sinh công nợ T3/2020 | D31: 70280000 | F31: =F30+D31-E31 -> 117700000
A32: 23 | B32: 43894 | C32: Vietsun thanh toán cước T2/2020 | E32: 47420000 | F32: =F31+D32-E32 -> 70280000
A33: 24 | B33: 29/4/2020 | C33: Phát sinh công nợ T4/2020 | D33: 42720000 | F33: =F32+D33-E33 -> 113000000
A34: 25 | B34: 44048 | C34: Vietsun thanh toán | E34: 70280000 | F34: =F33+D34-E34 -> 42720000
A35: 26 | B35: 30/5/2020 | C35: Phát sinh công nợ T5/2020 xuất hóa đơn | D35: 30300000 | F35: =F34+D35-E35 -> 73020000
A36: 27 | B36: 30/5/2020 | C36: Phát sinh công nợ T5/2020 TT tiền mặt | D36: 2100000 | F36: =F35+D36-E36 -> 75120000
A37: 28 | B37: 30/5/2020 | C37: Phát sinh công nợ T5/2020 anh Huy TT ngoài cont TCNU4973297, TCNU4834861 | D37: =6400000/1.1 -> 5818181.8 | F37: =F36+D37-E37 -> 80938182
A38: 29 | B38: 43957 | C38: Vietsun thanh toán | E38: 42720000 | F38: =F37+D38-E38 -> 38218182
A39: 30 | B39: 43897 | C39: Vietsun thanh toán | E39: 30300000 | F39: =F38+D39-E39 -> 7918181.8
A40: 31 | B40: 44012 | C40: Phát sinh công nợ T6/2020 | D40: 72250000 | F40: =F39+D40-E40 -> 80168182
...

Sheet Tan Viet Hung
G1: TH
A2: BẢNG KÊ CHI TIẾT CÔNG NỢ
A3: Khách hàng | D3: Tân Việt Hưng
E4: Số dư đầu kỳ | F4: 383840000
A5: Ngày tháng | D5: =+'Tổng hợp'!$G$2 -> 45784 | E5: Phát sinh Nợ | F5: =SUM(D10:D200) -> 2988670333
E6: Phát sinh Có | F6: =SUM(E10:E200) -> 3116172333
E7: Số dư cuối kỳ | F7: =+F4+F5-F6 -> 256338000
A8: STT | B8: Ngày tháng | C8: Diễn giải | D8: Phát sinh | F8: Ghi chú
D9: Nợ | E9: Có
A10: 1 | B10: 43621 | C10: Tân Việt Hưng thanh toán tiền | E10: 50000000 | H10: =F4+D10-E10 -> 333840000
A11: 2 | B11: 43631 | C11: Tân Việt Hưng thanh toán tiền | E11: 100000000 | H11: =H10+D11-E11 -> 233840000
A12: 3 | B12: 43646 | C12: Công nợ Tân Việt Hưng T6/2019 | D12: 191700000 | H12: =H11+D12-E12 -> 425540000
A13: 4 | B13: 08/07/209 | C13: Tân Việt Hưng thanh toán tiền | E13: 36240000 | H13: =H12+D13-E13 -> 389300000
A14: 5 | B14: 43662 | C14: Tân Việt Hưng thanh toán tiền | E14: 100000000 | H14: =H13+D14-E14 -> 289300000
A15: 6 | B15: 43668 | C15: Tân Việt Hưng thanh toán tiền | E15: 97600000 | H15: =H14+D15-E15 -> 191700000
A16: 7 | B16: 43679 | C16: Tân Việt Hưng thanh toán tiền | E16: 50000000 | H16: =H15+D16-E16 -> 141700000
A17: 8 | B17: 43677 | C17: Công nợ Tân Việt Hưng T7/2019 | D17: 185940000 | H17: =H16+D17-E17 -> 327640000
A18: 9 | B18: 43690 | C18: Tân Việt Hưng thanh toán tiền | E18: 100000000 | H18: =H17+D18-E18 -> 227640000
A19: 10 | B19: 43693 | C19: Tân Việt Hưng thanh toán tiền | E19: 41700000 | H19: =H18+D19-E19 -> 185940000
A20: 11 | B20: 31/8/2019 | C20: Công nợ Tân Việt Hưng T8/2019 | D20: 182960000 | H20: =H19+D20-E20 -> 368900000
A21: 12 | B21: 14/9/2019 | C21: Tân Việt Hưng thanh toán cước T7/19 | E21: 185940000 | H21: =H20+D21-E21 -> 182960000
A22: 13 | B22: 30/9/2019 | C22: Công nợ Tân Việt Hưng T9/2019 | D22: 179740000 | H22: =H21+D22-E22 -> 362700000
A23: 14 | B23: 15/10/2019 | C23: Tân Việt Hưng thanh toán cước T8/19 lần 1 | E23: 100000000 | H23: =H22+D23-E23 -> 262700000
A24: 15 | B24: 21/10/2019 | C24: Tân Việt Hưng thanh toán cước T8/19 lần | E24: =82000000+960000 -> 82960000 | H24: =H23+D24-E24 -> 179740000
A25: 16 | B25: 31/10/2019 | C25: Công nợ Tân Việt Hưng T10/2019 | D25: 126660000 | H25: =H24+D25-E25 -> 306400000
A26: 17 | B26: 18/11/2019 | C26: Tân Việt Hưng thanh toán | E26: 100000000 | H26: =H25+D26-E26 -> 206400000
A27: 18 | B27: 19/11/2019 | C27: Tân Việt Hưng thanh toán | E27: 79740000 | H27: =H26+D27-E27 -> 126660000
A28: 19 | B28: 30/11/2019 | C28: Công nợ Tân Việt Hưng T11/2019 | D28: 127820000 | H28: =H27+D28-E28 -> 254480000
A29: 20 | B29: 16/12/2019 | C29: Tân Việt Hưng thanh toán | E29: 100000000 | H29: =H28+D29-E29 -> 154480000
A30: 21 | B30: 19/12/2019 | C30: Tân Việt Hưng thanh toán | E30: 26660000 | H30: =H29+D30-E30 -> 127820000
A31: 22 | B31: 31/12/2019 | C31: Công nợ Tân Việt Hưng T12/2019 | D31: 177900000 | H31: =H30+D31-E31 -> 305720000
A32: 23 | B32: 14/1/2019 | C32: Tân Việt Hưng thanh toán cước vận chuyển T11/19 | E32: 127820000 | H32: =H31+D32-E32 -> 177900000
A33: 24 | B33: 31/1/2020 | C33: Công nợ Tân Việt Hưng T1/2020 | D33: 11400000 | H33: =H32+D33-E33 -> 189300000
A34: 25 | B34: 17/2/2020 | C34: Tân Việt Hưng thanh toán cước vận chuyển T12/19 lần 1 | E34: 100000000 | H34: =H33+D34-E34 -> 89300000
A35: 26 | B35: 20/2/2020 | C35: Tân Việt Hưng thanh toán nốt cước vận chuyển T12/19 | E35: 77900000 | H35: =H34+D35-E35 -> 11400000
A36: 27 | B36: 18/3/20 | C36: Tân Việt Hưng thanh toán cước vận chuyển T1/2020 | E36: 11400000 | H36: =H35+D36-E36 -> 0
A37: 28 | B37: 44074 | C37: Phát sinh cước vận chuyển T8 | D37: 13000000 | H37: =H36+D37-E37 -> 13000000
A38: 29 | B38: 44130 | C38: Tân Việt hưng tháng toán tiền cước vận chuyển T8/2020 | E38: 13000000 | H38: =H37+D38-E38 -> 0
A39: 30 | B39: 44165 | C39: Phát sinh cước vận chuyển T11 | D39: 7700000 | H39: =H38+D39-E39 -> 7700000
A40: 31 | B40: 44235 | C40: Tân Việt Hưng thanh toán | E40: 7700000 | H40: =H39+D40-E40 -> 0
...

Sheet Che My Lam
G1: TH
A2: BẢNG KÊ CHI TIẾT CÔNG NỢ | J2: 0983223404 | K2: Chị Tươi
A3: Khách hàng | D3: Chè Mỹ Lâm | J3: 02073875110 | K3: Phòng KT
E4: Số dư đầu kỳ | F4: 88654000 | J4: 0911275686 | K4: Chị Tuyết | L4: KTT
A5: Ngày tháng | D5: =+'Tổng hợp'!$G$2 -> 45784 | E5: Phát sinh Nợ | F5: =SUM(D10:D500) -> 5562332279
E6: Phát sinh Có | F6: =SUM(E10:E1500) -> 5543013479
E7: Số dư cuối kỳ | F7: =+F4+F5-F6 -> 107972800
A8: STT | B8: Ngày tháng | C8: Diễn giải | D8: Phát sinh | F8: Ghi chú
D9: Nợ | E9: Có
A10: 1 | B10: 43630 | C10: Mỹ Lâm thanh toán công nợ T4 | E10: 32058000 | H10: =F4+D10-E10 -> 56596000
A11: 2 | B11: 43645 | C11: Công nợ tháng 6 Mỹ Lâm | D11: 44935000 | H11: =H10+D11-E11 -> 101531000
A12: 3 | B12: 43654 | C12: Chè Mỹ Lâm thanh toán công nợ T5/2019 | E12: 56596000 | H12: =H11+D12-E12 -> 44935000
A13: 4 | B13: 43677 | C13: Chè Mỹ Lâm thanh toán công nợ T6/2019 | E13: 44935000 | H13: =H12+D13-E13 -> 0
A14: 5 | B14: 43677 | C14: Công nợ tháng 7 Mỹ Lâm | D14: 89430000 | H14: =H13+D14-E14 -> 89430000
A15: 6 | B15: 43708 | C15: Công nợ tháng 8 Mỹ Lâm | D15: 145929000 | H15: =H14+D15-E15 -> 235359000
A16: 7 | B16: 43625 | C16: Chè Mỹ Lâm thanh toán công nợ T7/2019 | E16: 89430000 | H16: =H15+D16-E16 -> 145929000
A17: 8 | B17: 27/9/2019 | C17: Chè Mỹ Lâm thanh toán công nợ T8/2019 | E17: 145929000 | H17: =H16+D17-E17 -> 0
A18: 9 | B18: 30/9/2019 | C18: Công nợ tháng 9 Mỹ Lâm | D18: 100714000 | H18: =H17+D18-E18 -> 100714000
A19: 10 | B19: 29/10/2019 | C19: Chè Mỹ Lâm thanh toán công nợ T9 | E19: 100714000 | H19: =H18+D19-E19 -> 0
A20: 11 | B20: 31/10/2019 | C20: Công nợ T10 | D20: 101721000 | H20: =H19+D20-E20 -> 101721000
A21: 12 | B21: 30/11/2019 | C21: Công nợ T11 | D21: 100477000 | H21: =H20+D21-E21 -> 202198000
A22: 13 | B22: 43720 | C22: Chè Mỹ Lâm thanh toán công nợ T10 | E22: 101721000 | H22: =H21+D22-E22 -> 100477000
A23: 14 | B23: 31/12/2019 | C23: Công nợ T12 | D23: 101181000 | H23: =H22+D23-E23 -> 201658000
A24: 15 | B24: 15/1/2019 | C24: Chè Mỹ Lâm thanh toán công nợ T11+12 | E24: 210474091 | H24: =H23+D24-E24 -> -8816091
A25: 16 | B25: 31/1/2020 | C25: Công nợ T1/2020 | D25: 68311000 | H25: =H24+D25-E25 -> 59494909
A26: 17 | B26: 29/2/2020 | C26: Công nợ T2/2020 | D26: 45832000 | H26: =H25+D26-E26 -> 105326909
A27: 18 | B27: 25/3/2020 | C27: Mỹ Lâm thanh toán công nợ T1+2 | E27: 105326909 | H27: =H26+D27-E27 -> 0
A28: 19 | B28: 43865 | C28: Cước vận chuyển+phí dịch vụ cont MRKU6098599 | D28: 10735000 | H28: =H27+D28-E28 -> 10735000
A29: 20 | B29: 15/4/2020 | C29: Mỹ Lâm thanh toán cước vận chuyển cont MRKU6098599 | E29: 10235000 | H29: =H28+D29-E29 -> 500000
A30: 21 | B30: 27/4/2020 | C30: Mỹ lâm thanh toán phí cơ sở hạ tầng cont MRKU6098599 | E30: 500000 | H30: =H29+D30-E30 -> 0
A31: 22 | B31: 30/5/2020 | C31: Công nợ T5/2020 | D31: 57301890 | H31: =H30+D31-E31 -> 57301890
A32: 23 | B32: 30/06/2020 | C32: Công nợ T6/2020 | D32: 84950000 | H32: =H31+D32-E32 -> 142251890
A33: 24 | B33: 44020 | C33: Mỹ Lâm thanh toán công nợ T5,T6 | E33: 132251890 | H33: =H32+D33-E33 -> 10000000
A34: 25 | B34: 44043 | C34: Công nợ T7/2020 | D34: 148443000 | F34: DNTT HD 140.043.000 đ | H34: =H33+D34-E34 -> 158443000
A35: 26 | B35: 44075 | C35: Mỹ Lâm thanh toán công nợ T7 -HĐ | E35: 140043000 | H35: =H34+D35-E35 -> 18400000
A36: 27 | B36: 44074 | C36: Công nợ T8/2020 | D36: 53228000 | H36: =H35+D36-E36 -> 71628000
A37: 28 | B37: 44103 | C37: Mỹ Lâm thanh toán công nợ T8-HĐ | E37: 63628000 | H37: =H36+D37-E37 -> 8000000
A38: 29 | B38: 44104 | C38: Công nợ T9/2020 | D38: 116602000 | H38: =H37+D38-E38 -> 124602000
A39: 30 | B39: 44130 | C39: Mỹ Lâm thanh toán công nợ T9-HĐ | E39: 124602000 | H39: =H38+D39-E39 -> 0
A40: 31 | B40: 44135 | C40: Công nợ T10/2020 | D40: 98775000 | H40: =H39+D40-E40 -> 98775000
...

Sheet Phu Tai
G1: TH
A2: BẢNG KÊ CHI TIẾT CÔNG NỢ
A3: Khách hàng | D3: Phú Tài
E4: Số dư đầu kỳ | F4: 23056450
A5: Ngày tháng | D5: =+'Tổng hợp'!$G$2 -> 45784 | E5: Phát sinh Nợ | F5: =SUM(D10:D500) -> 2274867269
E6: Phát sinh Có | F6: =SUM(E10:E500) -> 2254182919
E7: Số dư cuối kỳ | F7: =+F4+F5-F6 -> 43740800
A8: STT | B8: Ngày tháng | C8: Diễn giải | D8: Phát sinh | F8: Ghi chú
D9: Nợ | E9: Có
A10: 1 | B10: 43619 | C10: Phú Tài thanh toán tiền tháng 5 | E10: 23056450 | J10: =F4+D10-E10 -> 0
A11: 2 | B11: 43622 | C11: Giay báo nợ số PTF19009 | D11: 23060650 | J11: =J10+D11-E11 -> 23060650
A12: 3 | B12: 43642 | C12: Giay báo nợ số PTF19010 | D12: 25973150 | J12: =J11+D12-E12 -> 49033800
A13: 4 | B13: 43655 | C13: Phú Tài thanh toán GBN PTF19009 | E13: 23060650 | J13: =J12+D13-E13 -> 25973150
A14: 5 | B14: 43655 | C14: Giay báo nợ số PTF19011 | D14: 23052650 | J14: =J13+D14-E14 -> 49025800
A15: 6 | B15: 43675 | C15: Phú Tài thanh toán trước vào TKCN A Phụng | F15: 25000000 | H15: Đã xử lý chuyển trả lại | J15: =J14+D15-E15 -> 49025800
A16: 7 | B16: 43686 | C16: Phú Tài thanh toán tiền GBN PTF19010 | E16: 25961150 | H16: TT thiếu 12k do sử dụng GBN cũ | J16: =J15+D16-E16 -> 23064650
A17: 8 | B17: 16/8/2019 | C17: GBN PTF19012 | D17: 23064450 | J17: =J16+D17-E17 -> 46129100
A18: 9 | B18: 27/8/2019 | C18: GBN PTF19013 | D18: 27052050 | E18: 23052650 | J18: =J17+D18-E18 -> 50128500
A19: 10 | B19: 43625 | C19: Phú Tài thanh toán GBN PTF19012 | E19: 23064450 | J19: =J18+D19-E19 -> 27064050
A20: 11 | B20: 43808 | C20: PTF thanh toán quan TK Anh Phụng | E20: 4000000 | J20: =J19+D20-E20 -> 23064050
A21: 12 | B21: 18/9/2019 | C21: GBN PTF19014 | D21: 25969650 | J21: =J20+D21-E21 -> 49033700
A22: 13 | B22: 43740 | C22: GBN PTF19015 | D22: 23052050 | J22: =J21+D22-E22 -> 72085750
A23: 14 | B23: 43742 | C23: PTF thanh toán | E23: 46116500 | J23: =J22+D23-E23 -> 25969250
A24: 15 | B24: 43746 | C24: PTF thanh toán | E24: 2917200 | J24: =J23+D24-E24 -> 23052050
A25: 16 | B25: 21/10/2019 | C25: GBN PTF19016 | D25: 27052450 | J25: =J24+D25-E25 -> 50104500
A26: 17 | B26: 43627 | C26: GBN PTF19017 | D26: 23576650 | J26: =J25+D26-E26 -> 73681150
A27: 18 | B27: 7/11/209 | C27: PTF thanh toán | E27: 23052050 | J27: =J26+D27-E27 -> 50629100
A28: 19 | B28: 43780 | C28: PTF thanh toán | E28: 23052450 | J28: =J27+D28-E28 -> 27576650
A29: 20 | B29: 19/11/2019 | C29: GBN PTF19018 | D29: 28333200 | J29: =J28+D29-E29 -> 55909850
A30: 21 | B30: 20/11/2019 | C30: PTF thanh toán tiền chênh lệch lô PTF19016 | E30: 4000000 | J30: =J29+D30-E30 -> 51909850
A31: 22 | B31: 43567 | C31: PTF thanh toán GBN PTF19017 | E31: 23576650 | J31: =J30+D31-E31 -> 28333200
A32: 23 | B32: 43536 | C32: GBN PTF19019 | D32: 23319950 | J32: =J31+D32-E32 -> 51653150
A33: 24 | B33: 23/12/2019 | C33: PTF thanh toán PTF19018+PTF19019 | E33: 47653150 | J33: =J32+D33-E33 -> 4000000
A34: 25 | B34: 26/12/2019 | C34: GBN PTF19020 | D34: =23049450+4000000 -> 27049450 | J34: =J33+D34-E34 -> 31049450
A35: 26 | B35: 31/12/2019 | C35: Phú tài thanh toán GBN PTF19020 | E35: 23049450 | J35: =J34+D35-E35 -> 8000000
A36: 27 | B36: 43617 | C36: PTF thanh toán tiền chênh lệch lô PTF19018/020 | E36: 8000000 | J36: =J35+D36-E36 -> 0
A37: 28 | B37: 43900 | C37: GBN PTF20001NK | D37: 26745620 | J37: =J36+D37-E37 -> 26745620
A38: 29 | B38: 43900 | C38: Chênh lệch GBN PTF20001NK so với thực tế | D38: 4500000 | J38: =J37+D38-E38 -> 31245620
A39: 30 | B39: 43928 | C39: PTF thanh toán | E39: 26745620 | J39: =J38+D39-E39 -> 4500000
A40: 31 | B40: 43923 | C40: GBN PTF20002 | D40: 27068550 | J40: =J39+D40-E40 -> 31568550
...

Sheet Hai Dang
G1: TH
A2: BẢNG KÊ CHI TIẾT CÔNG NỢ
A3: Khách hàng | D3: Hải Đăng
E4: Số dư đầu kỳ | F4: 46800000 | L4: 13/05/2019 Hải Đăng đã quyết toán và thanh toán hết công nợ T4/2019
A5: Ngày tháng | D5: =+'Tổng hợp'!$G$2 -> 45784 | E5: Phát sinh Nợ | F5: =SUM(D10:D200) -> 1465376996
E6: Phát sinh Có | F6: =SUM(E10:E200) -> 1432868996 | L6: 9/8/2019 Hải Đăng đã quyết toán và thanh toán hết công nợ T7/2019
E7: Số dư cuối kỳ | F7: =+F4+F5-F6 -> 79308000
A8: STT | B8: Ngày tháng | C8: Diễn giải | D8: Phát sinh | F8: Lũy kế | G8: Ghi chú
D9: Nợ | E9: Có
A10: 1 | B10: 43645 | C10: Phát sinh công nợ T6/2019 | D10: 40000 | F10: =F4+D10-E10 -> 46840000
A11: 2 | B11: 43677 | C11: Đối trừ công nợ T7/2019 | E11: 8700000 | F11: =F10+D11-E11 -> 38140000
A12: 3 | B12: 43686 | C12: Công ty Hải Đăng thanh toán hết tiền cước sau khi tất toán công nợ đến hết 31/07/2019 | E12: 38140000 | F12: =F11+D12-E12 -> 0
A13: 4 | B13: 31/8/2019 | C13: Phát sinh công nợ T8/2019 | D13: 290909 | F13: =F12+D13-E13 -> 290909
A14: 5 | B14: 15/11/2019 | C14: Đối trừ cước T8 phải thu với 1 phần công nợ phải trả T9 | E14: 290909 | F14: =F13+D14-E14 -> 0
A15: 6 | B15: 31/1/2020 | C15: Phát sinh công nợ T1/2020 | D15: 22300000 | F15: =F14+D15-E15 -> 22300000
A16: 7 | B16: 29/2/2020 | C16: Phát sinh công nợ T2/2020 | D16: 5480909 | F16: =F15+D16-E16 -> 27780909
A17: 8 | B17: 29/2/2020 | C17: Đối trừ cước bổ sung T9+cước T12/19 với công nợ phải thu | E17: 26021817 | F17: =F16+D17-E17 -> 1759092
A18: 9 | B18: 19/3/2020 | C18: Hải Đăng quyết toán nốt cước đến thời điểm 29.2.20 | E18: 1759092 | F18: =F17+D18-E18 -> 0 | L18: 19/3/2020 Hải đăng đã quyết toán và thanh toán hết công nợ T2/2020
A19: 10 | B19: 31/3/2020 | C19: Phát sinh công nợ T3/2020 | D19: 41506364 | F19: =F18+D19-E19 -> 41506364
A20: 11 | B20: 29/4/2020 | C20: Phát sinh công nợ T4/2020 | D20: 10513636 | F20: =F19+D20-E20 -> 52020000
A21: 12 | B21: 44346 | C21: Phát sinh công nợ phải trả tháng 5/20 | E21: 29950000 | F21: =F20+D21-E21 -> 22070000
A22: 13 | B22: 30/6/2020 | C22: Hải Đăng thanh toán cước vận chuyển T3/20 | E22: 41506364 | F22: =F21+D22-E22 -> -19436364
A23: 14 | B23: 44012 | C23: Phát sinh công nợ phải trả tháng 6/20 | E23: 6674546 | F23: =F22+D23-E23 -> -26110910
A24: 15 | B24: 44043 | C24: Phát sinh công nợ phải trả tháng 7/20 | E24: =25900000+1200000 -> 27100000 | F24: =F23+D24-E24 -> -53210910
A25: 16 | B25: 44073 | C25: Phát sinh công nợ phải trả tháng 8/20 | E25: =8800000+4935000 -> 13735000 | F25: =F24+D25-E25 -> -66945910
A26: 17 | B26: 44462 | C26: NePo thanh toán cước tháng 5/20 | D26: 19436364 | F26: =F25+D26-E26 -> -47509546
A27: 18 | B27: 44097 | C27: NEPO thanh toán tiền phí hải quan tháng 8/20 | D27: 4935000 | F27: =F26+D27-E27 -> -42574546
A28: 19 | B28: 44104 | C28: Phát sinh công nợ tháng 9/20 | D28: 26900000 | F28: =F27+D28-E28 -> -15674546
A29: 20 | B29: 44112 | C29: NePo thanh toán tiền cước tháng 6/20 | D29: 6674546 | F29: =F28+D29-E29 -> -9000000
A30: 21 | B30: 44135 | C30: Phát sinh công nợ T10/2020 | D30: 13800000 | F30: =F29+D30-E30 -> 4800000
A31: 22 | B31: 44151 | C31: NEPO thanh toán tiền cước T7.20 | D31: 25900000 | F31: =F30+D31-E31 -> 30700000
A32: 23 | B32: 44151 | C32: NEPO thanh toán tiền dịch vụ hải quan T7 | D32: 1200000 | F32: =F31+D32-E32 -> 31900000
A33: 24 | B33: 44165 | C33: Phát sinh công nợ T11/2020 | D33: 11336364 | F33: =F32+D33-E33 -> 43236364
A34: 25 | B34: 44196 | C34: Phát sinh công nợ T12/2020 | D34: 25200000 | F34: =F33+D34-E34 -> 68436364
A35: 26 | B35: 44196 | C35: Thu tiền cước cont FSCU5107074 tháng 12 | E35: 3800000 | F35: =F34+D35-E35 -> 64636364
A36: 27 | B36: 44225 | C36: Hải Đăng thanh toán tiền cước T9,10,11 bù trừ tháng 8 | E36: 43236364 | F36: =F35+D36-E36 -> 21400000
A37: 28 | B37: 44227 | C37: Phát sinh công nợ T01/21 | D37: 71900000 | F37: =F36+D37-E37 -> 93300000
A38: 29 | B38: 44255 | C38: Phát sinh công nợ T02/21 | D38: 32700000 | F38: =F37+D38-E38 -> 126000000
A39: 30 | B39: 44286 | C39: Phát sinh công nợ phải trả tháng 3/21 | E39: 1600000 | F39: =F38+D39-E39 -> 124400000
A40: 31 | B40: 44301 | C40: Hải Đăng thanh toán tiền cước T12 | E40: 21400000 | F40: =F39+D40-E40 -> 103000000
...

Sheet An Khanh
G1: TH
A2: BẢNG KÊ CHI TIẾT CÔNG NỢ
A3: Khách hàng | D3: An Khánh
E4: Số dư đầu kỳ | F4: 60600000
A5: Ngày tháng | D5: =+'Tổng hợp'!$G$2 -> 45784 | E5: Phát sinh Nợ | F5: =SUM(D10:D298) -> 1007920400
E6: Phát sinh Có | F6: =SUM(E10:E298) -> 1075216400
E7: Số dư cuối kỳ | F7: =+F4+F5-F6 -> -6696000
A8: STT | B8: Ngày tháng | C8: Diễn giải | D8: Phát sinh | F8: Lũy kế | G8: Ghi chú
D9: Nợ | E9: Có
A10: 1 | B10: 43645 | C10: Công nợ An Khánh T6/2019 | D10: 12100000 | F10: =F4+D10-E10 -> 72700000
A11: 2 | B11: 43677 | C11: Công nợ An Khánh T7/2019 | D11: 15500000 | F11: =F10+D11-E11 -> 88200000
A12: 3 | B12: 43694 | C12: An Khánh thanh toán 1 phần công nợ T5/2019 | E12: 30600000 | F12: =F11+D12-E12 -> 57600000
A13: 4 | B13: 30/08/2019 | C13: An Khánh thanh toán 1 phần công nợ T5/2019 | E13: 15000000 | F13: =F12+D13-E13 -> 42600000
A14: 5 | B14: 31/8/2019 | C14: Công nợ An Khánh T8/19 | D14: 11600000 | F14: =F13+D14-E14 -> 54200000
A15: 6 | B15: 43594 | C15: An Khánh thanh toán nốt công nợ T5/2019 | E15: 15000000 | F15: =F14+D15-E15 -> 39200000
A16: 7 | B16: 43565 | C16: An Khánh thanh toán nốt công nợ T6/2019 | E16: 12100000 | F16: =F15+D16-E16 -> 27100000
A17: 8 | B17: 30/11/2019 | C17: Công nợ An Khánh T11/19 | D17: 15200000 | F17: =F16+D17-E17 -> 42300000
A18: 9 | B18: 43750 | C18: An khánh thanh toán cước T7+8/19 | E18: 27100000 | F18: =F17+D18-E18 -> 15200000
A19: 10 | B19: 31/1/2020 | C19: Công nợ An Khánh T1/20 | D19: 3900000 | F19: =F18+D19-E19 -> 19100000
A20: 11 | B20: 30/3/2020 | C20: Đối trừ cước vận chuyển T12/2019 với cước vận chuyển T11/19 phải thu | E20: 4000000 | F20: =F19+D20-E20 -> 15100000
A21: 12 | B21: 30/3/2020 | C21: Anh Khánh thanh toán hết công nợ năm 2019 | E21: 11200000 | F21: =F20+D21-E21 -> 3900000
A22: 13 | B22: 31/3/2020 | C22: Công nợ An Khánh T3/20 | D22: 14600000 | F22: =F21+D22-E22 -> 18500000
A23: 14 | B23: 15/5/2020 | C23: An Khánh thanh toán cước T1/20 | E23: 3900000 | F23: =F22+D23-E23 -> 14600000
A24: 15 | B24: 30/6/2020 | C24: Đối trừ công nợ cước vận chuyển T3 với T4/20 | E24: 14600000 | F24: =F23+D24-E24 -> 0
A25: 16 | B25: 30/06/2020 | C25: Công nợ An Khánh T6/2020 | D25: 1400000 | F25: =F24+D25-E25 -> 1400000
A26: 17 | B26: 44074 | C26: Công nợ An Khánh T8/2020 | D26: 2500000 | F26: =F25+D26-E26 -> 3900000
A27: 18 | B27: 44084 | C27: Đối trừ công nợ T6 với tháng 5 | E27: 1400000 | F27: =F26+D27-E27 -> 2500000
A28: 19 | B28: 44104 | C28: Công nợ An Khánh T9/20 | D28: 19650000 | F28: =F27+D28-E28 -> 22150000
A29: 20 | B29: 44165 | C29: Công nợ An Khánh T11/20 | D29: 581818 | F29: =F28+D29-E29 -> 22731818
A30: 21 | B30: 44151 | C30: Đối trừ công nợ T8/20 | E30: 2500000 | F30: =F29+D30-E30 -> 20231818
A31: 22 | B31: 44214 | C31: An Khánh thanh toán tiền cước | E31: 10331818 | F31: =F30+D31-E31 -> 9900000
A32: 23 | B32: 44214 | C32: Đối trừ tiền tháng 10,12 | E32: 9900000 | F32: =F31+D32-E32 -> 0
A33: 24 | B33: 44226 | C33: Công nợ phải trả | E33: 14000000 | F33: =F32+D33-E33 -> -14000000
A34: 25 | B34: 44286 | C34: Công nợ phải trả | E34: 27500000 | F34: =F33+D34-E34 -> -41500000
A35: 26 | B35: 44315 | C35: Công nợ phải trả | E35: 14300000 | F35: =F34+D35-E35 -> -55800000
A36: 27 | B36: 44323 | C36: NePo thanh toán tiền | D36: 14000000 | F36: =F35+D36-E36 -> -41800000
A37: 28 | B37: 44347 | C37: Công nợ phải thu | D37: 200000 | F37: =F36+D37-E37 -> -41600000
A38: 29 | B38: 44377 | C38: Công nợ phải trả | E38: 11018182 | F38: =F37+D38-E38 -> -52618182
A39: 30 | B39: 44386 | C39: NePo thanh toán tiền | D39: 27500000 | F39: =F38+D39-E39 -> -25118182
A40: 31 | B40: 44408 | C40: Công nợ phải thu | D40: 17900000 | F40: =F39+D40-E40 -> -7218182
...

Sheet Hong Anh Phat
G1: TH
A2: BẢNG KÊ CHI TIẾT CÔNG NỢ
A3: Khách hàng | D3: Anh Đoàn (Hồng Anh Phát)
E4: Số dư đầu kỳ | F4: 6540000
A5: Ngày tháng | D5: =+'Tổng hợp'!$G$2 -> 45784 | E5: Phát sinh Nợ | F5: =SUM(D10:D500) -> 774080706
E6: Phát sinh Có | F6: =SUM(E10:E500) -> 7.3946951e+08
E7: Số dư cuối kỳ | F7: =+F4+F5-F6 -> 41151200
A8: STT | B8: Ngày tháng | C8: Diễn giải | D8: Phát sinh | F8: Lũy kế | G8: Ghi chú
D9: Nợ | E9: Có
A10: 1 | B10: 43646 | C10: Công nợ T6/2019 phát sinh | D10: 18560000 | F10: =F4+D10-E10 -> 25100000
A11: 2 | B11: 31/8/2019 | C11: Công nợ T8/2019 phát sinh | D11: 25554545 | F11: =F10+D11-E11 -> 50654545
A12: 3 | B12: 31/10/2019 | C12: Công nợ T10/2019 phát sinh | D12: 31380000 | F12: =F11+D12-E12 -> 82034545
A13: 4 | B13: 15/11/2019 | C13: Đối trừ công nợ phải trả T7/T9 với công nợ phải thu T5/T6 | E13: 22081818 | F13: =F12+D13-E13 -> 59952727
A14: 5 | B14: 16/11/2019 | C14: Đối trừ công nợ phải thu với VAT T10 | E14: 5300000 | F14: =F13+D14-E14 -> 54652727
A15: 6 | B15: 20/11/2019 | C15: Đối trừ công nợ phải thu với VAT T11 | E15: 18500000 | F15: =F14+D15-E15 -> 36152727
A16: 7 | B16: 30/11/2019 | C16: Công nợ T11/2019 phát sinh | D16: 7960000 | F16: =F15+D16-E16 -> 44112727
A17: 8 | B17: 31/12/2019 | C17: Công nợ T12/2019 phát sinh | D17: 23740000 | F17: =F16+D17-E17 -> 67852727
A18: 9 | B18: 43847 | C18: Tiền VAT T12/19 (HĐ 0000367) | E18: 10000000 | F18: =F17+D18-E18 -> 57852727
A19: 10 | B19: 31/1/2020 | C19: Công nợ T1/2020 phát sinh | D19: 46430909 | F19: =F18+D19-E19 -> 104283636
A20: 11 | B20: 29/2/2020 | C20: Công nợ T2/2020 phát sinh | D20: 24290909 | F20: =F19+D20-E20 -> 128574545
A21: 12 | B21: 31/3/2020 | C21: Hồng Anh Phát thanh toán cước vận chuyển | E21: 20000000 | F21: =F20+D21-E21 -> 108574545
A22: 13 | B22: 31/3/2020 | C22: Công nợ T3/2020 phát sinh | D22: 16450000 | F22: =F21+D22-E22 -> 125024545
A23: 14 | B23: 29/4/2020 | C23: Hồng Anh Phát thanh toán cước vận chuyển | E23: 20000000 | F23: =F22+D23-E23 -> 105024545
A24: 15 | B24: 29/4/2020 | C24: Công nợ T4/2020 phát sinh | D24: 3600000 | F24: =F23+D24-E24 -> 108624545
A25: 16 | B25: 43956 | C25: Tiền VAT T5/20 (HĐ 0000416) | E25: 25000000 | F25: =F24+D25-E25 -> 83624545
A26: 17 | B26: 30/5/2020 | C26: Hồng Anh Phát thanh toán hết cước vận chuyển 2019 | E26: 17850000 | F26: =F25+D26-E26 -> 65774545
A27: 18 | B27: 30/5/2020 | C27: Công nợ T5/2020 phát sinh | D27: 2827273 | F27: =F26+D27-E27 -> 68601818
A28: 19 | B28: 31/5/2020 | C28: Tiền VAT T5/20 (HĐ 0000425) | E28: 5500000 | F28: =F27+D28-E28 -> 63101818
A29: 20 | B29: 31/5/2020 | C29: Giảm 50% cước vận chuyển cont NYKU4394787 do lái xe kéo nhầm ngày 21/12/2019 | E29: =4300000/2 -> 2150000 | F29: =F28+D29-E29 -> 60951818
A30: 21 | B30: 44012 | C30: Tiền VAT T6/2020(HĐ0000430) | E30: 16200000 | F30: =F29+D30-E30 -> 44751818
A31: 22 | B31: 44043 | C31: Tiền VAT hóa đơn 446 tháng 7/2020 | E31: 19000000 | F31: =F30+D31-E31 -> 25751818
A32: 23 | B32: 44012 | C32: Công nợ phải trả tháng 6.20 | E32: 21296364 | F32: =F31+D32-E32 -> 4455454
A33: 24 | B33: 44043 | C33: Ps công nợ T7.20 | D33: 37200000 | F33: =F32+D33-E33 -> 41655454
A34: 25 | B34: 44074 | C34: Ps công nợ T8.20 | D34: 4400000 | F34: =F33+D34-E34 -> 46055454
A35: 26 | B35: 44074 | C35: Tiền VAT T8/2020 (HD 0000456) | E35: =59980000/1.1*0.1 -> 5452727.3 | F35: =F34+D35-E35 -> 40602727
A36: 27 | B36: 44104 | C36: PS công nợ T9.20 | D36: 9100000 | F36: =F35+D36-E36 -> 49702727
A37: 28 | B37: 44117 | C37: Tiền VAT T9/2020 ( HĐ 0000467) | E37: 11507273 | F37: =F36+D37-E37 -> 38195454
A38: 29 | B38: 44135 | C38: Ps công nợ T10.20 | D38: 15736364 | F38: =F37+D38-E38 -> 53931818
A39: 30 | B39: 44135 | C39: Tiền VAT T10/20 ( HĐ 474) | E39: 12082727 | F39: =F38+D39-E39 -> 41849091
A40: 31 | B40: 44165 | C40: Tiền VAT T11/20 ( HĐ 477) | E40: 10974545 | F40: =F39+D40-E40 -> 30874546
...

Sheet Anh Phương VS
G1: TH
A2: BẢNG KÊ CHI TIẾT CÔNG NỢ
A3: Khách hàng | D3: Anh Phương Vietsun
E4: Số dư đầu kỳ
A5: Ngày tháng | D5: =+'Tổng hợp'!$G$2 -> 45784 | E5: Phát sinh Nợ | F5: =SUM(D10:D70) -> 212000000
E6: Phát sinh Có | F6: =SUM(E10:E70) -> 210300000
E7: Số dư cuối kỳ | F7: =+F4+F5-F6 -> 1700000
A8: STT | B8: Ngày tháng | C8: Diễn giải | D8: Phát sinh | F8: Lũy kế | G8: Ghi chú
D9: Nợ | E9: Có
A10: 1 | B10: 45015 | C10: Phát sinh công nợ tháng 3 | D10: 3700000 | F10: =D10-E10 -> 3700000
A11: 2 | B11: 45046 | C11: Phát sinh công nợ tháng 4 | D11: 128900000 | F11: =F10+D11-E11 -> 132600000
A12: 3 | B12: 45077 | C12: Phát sinh công nợ tháng 5 | D12: 4000000 | F12: =F11+D12-E12 -> 136600000
A13: 4 | B13: 45107 | C13: Phát sinh công nợ phải thu T6 | E13: 8400000 | F13: =F12+D13-E13 -> 128200000
A14: 5 | B14: 45117 | C14: Anh Phương thanh toán tiền | E14: 128200000 | F14: =F13+D14-E14 -> 0 | I14: CK vào TKCN Anh Phụng, nộp vào TK ACB
