Workbook

Sheet CHI PHI BAN DAU
A1: Bảng tổng hợp chi phí xe 15C-070.63
A3: STT | B3: Nội dung | C3: Thành tiền | D3: Phí ngân hàng
A4: 1 | B4: Thanh toán nốt tiền mua xe đầu kéo biển số 15C- 070.63 | C4: =249100000+70000000 -> 319100000
A5: 2 | B5: Làm đăng ký xe 15C- 070.63 | C5: 7200000
A6: 3 | B6: Cào số khung, số máy xe 15C- 070.63 | C6: 100000
A7: 4 | B7: Thanh toán tiền bảo hiểm xe 15C-070.63 | C7: 9120000
A8: 5 | B8: Bơm mỡ xe 15C-070.63 | C8: 70000
A9: 6 | B9: Bơm mỡ đầu kéo xe 15C-070.63 | C9: 100000
A10: 7 | B10: Kiểm tra điện hộp đèn xe 15C-070.63 | C10: 200000
A11: 8 | B11: Thanh toán tiền sửa chữa xe 15C-070.63 (tháo lốp trong bãi, thay lốp, đảo 1 cầu) | C11: 430000
A12: 9 | B12: Thanh toán tiền lọc nhớt, lọc thả xe 15C-070.63 | C12: 540000
A13: 10 | B13: Công chứng đăng ký+đăng kiểm xe 15C-070.63 | C13: 50000
A14: 11 | B14: Trả tiền công đăng ký xe 15C-070.63 | C14: 500000
A15: 12 | B15: Cắt chữ xe 15C-070.63 | C15: 350000
A16: 13 | B16: Dọn nội thất xe 15C-070.63 | C16: 500000
... A24: 21 | B24: Thay lốp xe 15C-070.63 | C24: 120000
B31: Tổng cộng | C31: =SUM(C4:C30) -> 343630000 | D31: =SUM(D4:D30) -> 0

Sheet 07-2018
A1: Bảng theo dõi doanh thu/ chi phí theo phương tiện vận chuyển
A2: Biển số xe: 15C - 070.63
B3: THÁNG 07.2018
A5: STT | B5: Ngày tháng | C5: Diễn giải | D5: Số cont | E5: Tuyến đường vận chuyển | F5: Khoảng cách (km) | G5: Chi phí | O5: Tổng chi phí | P5: Cước vận chuyển | Q5: Lợi nhuận gộp
G6: Dầu (l) | H6: Dầu (đồng) | I6: Mức TTBQ | J6: Đi đường | K6: Lương lx | L6: Sửa chữa | M6: Lốp | N6: Dầu máy
A8: 1 | B8: 43306 | C8: Trả hàng NK sáng 26/07 | D8: HJCU1491703 | E8: KCN Đình Bảng, Bắc Ninh | G8: 200 | H8: 3448000 | J8: 790000 | O8: =H8+J8+K8+L8+M8+N8 -> 4238000 | P8: 3300000 | Q8: =P8-O8 -> -938000
A9: 2 | B9: 43307 | C9: Trả hàng NK sáng 27/07 | D9: EITU1735591 | E9: Ngọc Hồi, Hà Nội | J9: 970000 | O9: =H9+J9+K9+L9+M9+N9 -> 970000 | P9: 3700000 | Q9: =P9-O9 -> 2730000
A10: 3 | B10: 43311 | C10: Đóng hàng chè sáng 30/07 | D10: EITU0061102 | E10: Mỹ Bằng, Yên Sơn, Tuyên Quang | G10: 200 | H10: 3448000 | J10: 1600000 | O10: =H10+J10+K10+L10+M10+N10 -> 5048000 | P10: 7227273 | Q10: =P10-O10 -> 2179273
A11: 4 | B11: 43311 | C11: Trả hàng + đóng hàng KH 31/07 | D11: TRHU1630894 | E11: Lý Nhân, Hà Nam - Hà Nam | G11: 199 | H11: 3430760 | J11: 750000 | O11: =H11+J11+K11+L11+M11+N11 -> 4180760 | P11: 4700000 | Q11: =P11-O11 -> 519240
O12: =H12+J12+K12+L12+M12+N12 -> 0 | Q12: =P12-O12 -> 0
C13: Thay nhớt + nhớt dự phòng phân bổ | N13: =11500000/4 -> 2875000 | O13: =H13+J13+K13+L13+M13+N13 -> 2875000 | Q13: =P13-O13 -> -2875000
A19: TỔNG CỘNG | G19: =SUM(G7:G18) -> 599 | H19: =SUM(H7:H18) -> 10326760 | I19: =SUM(I7:I18) -> 0 | J19: =SUM(J7:J18) -> 4110000 | K19: =SUM(K7:K18) -> 0 | L19: =SUM(L7:L18) -> 0 | M19: =SUM(M7:M18) -> 0 | N19: =SUM(N7:N18) -> 2875000 | ... Q19: =SUM(Q7:Q18) -> 1615513
P21: LK = | Q21: =Q19 -> 1615513

Sheet 08-2018
A1: Bảng theo dõi doanh thu/ chi phí theo phương tiện vận chuyển
A2: Biển số xe: 15C - 070.63
B3: THÁNG 08.2018
A5: STT | B5: Ngày tháng | C5: Diễn giải | D5: Số cont | E5: Tuyến đường vận chuyển | F5: Khoảng cách (km) | G5: Chi phí | O5: Tổng chi phí | P5: Cước vận chuyển | Q5: Lợi nhuận gộp
G6: Dầu (l) | H6: Dầu (đồng) | I6: Mức TTBQ | J6: Đi đường | K6: Lương lx | L6: Sửa chữa | M6: Lốp | N6: Dầu máy
A8: 1 | B8: 43312 | C8: Đóng hàng chè sáng 01/08 | D8: EITU0059390 | E8: Mỹ Bằng, Yên Sơn, Tuyên Quang | J8: 1600000 | O8: =H8+J8+K8+L8+M8+N8 -> 1600000 | P8: 7227273 | Q8: =P8-O8 -> 5627273
A9: 2 | B9: 43314 | C9: Trả hàng + đóng hàng KH 03/08 | D9: GMDU2152961 | E9: Vĩnh Yên , Vĩnh Phúc - Hà Nam | J9: 1260000 | O9: =H9+J9+K9+L9+M9+N9 -> 1260000 | P9: 6100000 | Q9: =P9-O9 -> 4840000
A10: 3 | B10: 43315 | C10: Đóng hàng bột đá 04/08 | D10: VNLU3090145 | E10: Phủ Lý, Hà Nam | G10: 247 | H10: 4258280 | J10: 430000 | O10: =H10+J10+K10+L10+M10+N10 -> 4688280 | P10: 3200000 | Q10: =P10-O10 -> -1488280
A11: 4 | B11: 43318 | C11: Trả hàng + đóng hàng KH 06/08 | D11: GMDU2412735 | E11: Vĩnh Yên, Vĩnh Phúc - Đông Anh, Hà Nội | G11: 142 | H11: 2448080 | J11: 1260000 | O11: =H11+J11+K11+L11+M11+N11 -> 3708080 | P11: 6100000 | Q11: =P11-O11 -> 2391920
A12: 5 | B12: 43318 | C12: Trả hàng NK sáng 07/08 | D12: CRXU3139214 | E12: Đan Phượng, Hà Nội | G12: 243 | H12: 4189320 | J12: 820000 | O12: =H12+J12+K12+L12+M12+N12 -> 5009320 | P12: 3700000 | Q12: =P12-O12 -> -1309320
A13: 6 | B13: 43319 | C13: Đóng hàng sáng 08/08 | D13: UTCU4148970 | E13: TP Vinh, Nghệ An | G13: 91 | H13: 1595230 | J13: 1360000 | O13: =H13+J13+K13+L13+M13+N13 -> 2955230 | P13: 8909091 | Q13: =P13-O13 -> 5953861
A14: 7 | B14: 43322 | C14: Đóng hàng bột đá chiều 10/08 | D14: BISU2828861 | E14: Phủ Lý, Hà Nam | G14: 201 | H14: 3523530 | J14: 430000 | O14: =H14+J14+K14+L14+M14+N14 -> 3953530 | P14: 3200000 | Q14: =P14-O14 -> -753530
A15: 8 | B15: 43322 | C15: Đóng hàng bột đá chiều 11/08 | D15: CAXU3299049 | E15: Phủ Lý, Hà Nam | J15: 430000 | O15: =H15+J15+K15+L15+M15+N15 -> 430000 | P15: 3200000 | Q15: =P15-O15 -> 2770000
A16: 9 | B16: 43323 | C16: Đóng hàng chè sáng 13/08 | D16: WHLU0654717 | E16: Tân Lập, Mộc Châu, Sơn La | J16: 2440000 | O16: =H16+J16+K16+L16+M16+N16 -> 2440000 | P16: 13181818 | Q16: =P16-O16 -> 10741818
A17: 10 | B17: 43325 | C17: Trả hàng + đóng hàng KH 14/08 | D17: CRSU1526660 | E17: Vĩnh Tường, Vĩnh Phúc - Hà Nam | G17: 191 | H17: 3348230 | J17: 1260000 | O17: =H17+J17+K17+L17+M17+N17 -> 4608230 | P17: 6100000 | Q17: =P17-O17 -> 1491770
A18: 11 | B18: 43327 | C18: Trả hàng NK sáng 16/08 | D18: NYKU3559136 | E18: Bát Tràng, Gia Lâm, Hà Nội | G18: 217 | H18: 3804010 | J18: 680000 | O18: =H18+J18+K18+L18+M18+N18 -> 4484010 | P18: 3100000 | Q18: =P18-O18 -> -1384010
A19: 12 | B19: 43328 | C19: Trả hàng + đóng hàng KH 17/08 | D19: DRYU2901910 | E19: Gia Lâm, Hà Nội - Hà Nam | J19: 1200000 | O19: =H19+J19+K19+L19+M19+N19 -> 1200000 | P19: 5100000 | Q19: =P19-O19 -> 3900000
A20: 13 | B20: 43329 | C20: Trả hàng sáng 18/08 | D20: XINU1273295 | E20: Long Biên, Hà Nội | G20: 225 | H20: 3944250 | J20: 820000 | O20: =H20+J20+K20+L20+M20+N20 -> 4764250 | P20: 3600000 | Q20: =P20-O20 -> -1164250
A21: 14 | B21: 43332 | C21: Trả hàng + đóng hàng KH 20/08 | D21: BISU2836070 | E21: Thường Tín, Hà Nội - Hà Nam | G21: 182 | H21: 3190460 | J21: 1200000 | O21: =H21+J21+K21+L21+M21+N21 -> 4390460 | P21: 5300000 | Q21: =P21-O21 -> 909540
A22: 15 | B22: 43332 | C22: Đóng hàng sáng 21/08 | D22: HCVT0010 | E22: TP. Việt Trì, Phú Thọ | J22: 1130000 | O22: =H22+J22+K22+L22+M22+N22 -> 1130000 | P22: 5200000 | Q22: =P22-O22 -> 4070000
A23: 16 | B23: 43333 | C23: Trả hàng sáng 22/08 | D23: TCLU7558219 | E23: Bát Tràng, Hà Nội | J23: 680000 | O23: =H23+J23+K23+L23+M23+N23 -> 680000 | P23: 3100000 | Q23: =P23-O23 -> 2420000
A24: 17 | B24: 43334 | C24: Trả hàng + đóng hàng KH 23/08 | D24: GMDU2151570 | E24: Đông Hưng, Thái Bình - Hà Nam | G24: 237 | H24: 4154610 | J24: 750000 | O24: =H24+J24+K24+L24+M24+N24 -> 4904610 | P24: 4700000 | Q24: =P24-O24 -> -204610
A25: 18 | B25: 43335 | C25: Đóng hàng chè sáng 24/08 | D25: WBPU2021413 | E25: Mỹ Bằng, Yên Sơn, Tuyên Quang | G25: 164 | H25: 2899520 | J25: 1600000 | O25: =H25+J25+K25+L25+M25+N25 -> 4499520 | P25: 7227273 | Q25: =P25-O25 -> 2727753
A26: 19 | B26: 43336 | C26: Đóng hàng chiều 25/08 | D26: HCVT0017 | E26: TP. Việt Trì, Phú Thọ | G26: 153 | H26: 2705040 | J26: 1130000 | O26: =H26+J26+K26+L26+M26+N26 -> 3835040 | P26: 5200000 | Q26: =P26-O26 -> 1364960
A27: 20 | B27: 43339 | C27: Đóng hàng chiều 27/08 | D27: HCVT0013 | E27: TP. Việt Trì, Phú Thọ | J27: 1130000 | O27: =H27+J27+K27+L27+M27+N27 -> 1130000 | P27: 5200000 | Q27: =P27-O27 -> 4070000
A28: 21 | B28: 43340 | C28: Trả hàng NK sáng 29/08 | D28: DRYU2736020 | E28: Mộc Châu, Sơn La | G28: 250 | H28: 4420000 | J28: 2440000 | O28: =H28+J28+K28+L28+M28+N28 -> 6860000 | P28: 12000000 | Q28: =P28-O28 -> 5140000
A29: 22 | B29: 43341 | C29: Trả hàng sáng 30/08 | D29: 0613001 | E29: KCN Đại Đồng, Bắc Ninh | J29: 680000 | O29: =H29+J29+K29+L29+M29+N29 -> 680000 | P29: 3400000 | Q29: =P29-O29 -> 2720000
A30: 23 | B30: 43342 | C30: Trả hàng + đóng hàng KH 31/08 | D30: VSLU3040110 | E30: Từ Liêm, Hà Nội - Hà Nam | G30: 205 | H30: 3624400 | J30: 1260000 | O30: =H30+J30+K30+L30+M30+N30 -> 4884400 | P30: 5300000 | Q30: =P30-O30 -> 415600
G31: 214 | H31: =G31*17680 -> 3783520 | O31: =H31+J31+K31+L31+M31+N31 -> 3783520 | Q31: =P31-O31 -> -3783520
C32: Anh Phụng thanh toán tiền cứu hộ, sửa lốp xe 15C-070.63 | L32: 3800000 | O32: =H32+J32+K32+L32+M32+N32 -> 3800000 | Q32: =P32-O32 -> -3800000
C33: Thanh toán tiền sửa xe 15C-070.63 (đèn vàng 8 mắt, bộ dây điện đèn vàng, đèn hành trình mooc, pha đèn tròn, tắc đèn pha 3 chân, công thợ làm điện) | L33: 1330000 | O33: =H33+J33+K33+L33+M33+N33 -> 1330000 | Q33: =P33-O33 -> -1330000
C34: Thanh toán tiền sửa xe 15C-070.63 cho Thái Tân Phát (nắn thanh bảo hiểm sau, nắn hàn táp chắn bùn, thay xương đỡ chắn bún) | L34: 700000 | O34: =H34+J34+K34+L34+M34+N34 -> 700000 | Q34: =P34-O34 -> -700000
C35: Thanh toán tiền sửa xe 15C-070.63 cho Thái Tân Phát (đắp dán co pô sít xương ca bô, hàn dán+bắt chỉnh mi đèn, hàn chế xương đầu BĐS, bả sau ca bô+mi đèn) | L35: 2000000 | O35: =H35+J35+K35+L35+M35+N35 -> 2000000 | Q35: =P35-O35 -> -2000000
C36: Đưa Anh Háu thanh toán tiền sửa xe 15C-070.63 cho Trí điện (chỉnh gió, cúp bo) | L36: 700000 | O36: =H36+J36+K36+L36+M36+N36 -> 700000 | Q36: =P36-O36 -> -700000
C37: Thanh toán tiền sửa xe 15C-070.63 (tán phanh, công thợ tháo lắp, mua lò xo , vỏ tắc kê, tiện con lăn) | L37: 1800000 | O37: =H37+J37+K37+L37+M37+N37 -> 1800000 | Q37: =P37-O37 -> -1800000
C38: Thanh toán tiền sửa xe 15C-070.63 (mua cúc hơi+công) ngày 26/8 | L38: 100000 | O38: =H38+J38+K38+L38+M38+N38 -> 100000 | Q38: =P38-O38 -> -100000
C39: Phí gửi xe | L39: =1200000*1.1 -> 1320000 | O39: =H39+J39+K39+L39+M39+N39 -> 1320000 | Q39: =P39-O39 -> -1320000
C40: Lương lái xe | M40: 8353846 | O40: =H40+J40+K40+L40+M40+N40 -> 8353846 | Q40: =P40-O40 -> -8353846
A41: TỔNG CỘNG | G41: =SUM(G7:G40) -> 2962 | H41: =SUM(H7:H40) -> 51888480 | I41: =SUM(I7:I40) -> 0 | J41: =SUM(J7:J40) -> 25990000 | K41: =SUM(K7:K40) -> 0 | L41: =SUM(L7:L40) -> 11750000 | M41: =SUM(M7:M40) -> 8353846 | N41: =SUM(N7:N40) -> 0 | ... Q41: =SUM(Q7:Q40) -> 31363129
P43: LK = | Q43: ='07-2018'!Q21+'08-2018'!Q41 -> 32978642

Sheet 09-2018
A1: Bảng theo dõi doanh thu/ chi phí theo phương tiện vận chuyển
A2: Biển số xe: 15C - 070.63
B3: THÁNG 09.2018
A5: STT | B5: Ngày tháng | C5: Diễn giải | D5: Số cont | E5: Tuyến đường vận chuyển | F5: Khoảng cách (km) | G5: Chi phí | O5: Tổng chi phí | P5: Cước vận chuyển | Q5: Lợi nhuận gộp
G6: Dầu (l) | H6: Dầu (đồng) | I6: Mức TTBQ | J6: Đi đường | K6: Lương lx | L6: Sửa chữa | M6: Lốp | N6: Dầu máy
A8: 1 | B8: 43343 | C8: Trả hàng + đóng hàng KH 01/09 | D8: BISU2828265 | E8: Phủ Lý, Hà Nam | J8: 430000 | O8: =H8+J8+K8+L8+M8+N8 -> 430000 | P8: 3200000 | Q8: =P8-O8 -> 2770000
A9: 2 | B9: 43347 | C9: Trả hàng + đóng hàng KH 04/09 | D9: VSLU4499973 | E9: Vĩnh Yên, Vĩnh Phúc - Hà Nam | J9: 1200000 | O9: =H9+J9+K9+L9+M9+N9 -> 1200000 | P9: 6100000 | Q9: =P9-O9 -> 4900000
A10: 3 | B10: 43347 | C10: Trả hàng + đóng hàng KH 05/09 | D10: VSLU1049381 | E10: Yên Mỹ, Hưng Yên - Hà Nam | J10: 1050000 | O10: =H10+J10+K10+L10+M10+N10 -> 1050000 | P10: 4700000 | Q10: =P10-O10 -> 3650000
A11: 4 | B11: 43348 | C11: Trả hàng + đóng hàng KH 06/09 | D11: DRYU2851760 | E11: Yên Mỹ, Hưng Yên - Hà Nam | G11: 230 | H11: 4066400 | J11: 1050000 | O11: =H11+J11+K11+L11+M11+N11 -> 5116400 | P11: 4700000 | Q11: =P11-O11 -> -416400
A12: 5 | B12: 43349 | C12: Trả hàng + đóng hàng KH 07/09 | D12: WFHU1356588 | E12: Tân Quang, Văn Lâm, Hưng Yên - Hà Nam | J12: 1260000 | O12: =H12+J12+K12+L12+M12+N12 -> 1260000 | P12: 5000000 | Q12: =P12-O12 -> 3740000
A13: 6 | B13: 43350 | C13: Trả hàng + đóng hàng KH 08/09 | D13: DRYU3094686 | E13: Vĩnh Yên, Vĩnh Phúc - Hà Nam | G13: 237 | H13: 4280220 | J13: 1200000 | O13: =H13+J13+K13+L13+M13+N13 -> 5480220 | P13: 6100000 | Q13: =P13-O13 -> 619780
A14: 7 | B14: 43352 | C14: Trả hàng + đóng hàng KH 10/09 | D14: BISU2825287 | E14: Thường Tín, Hà Nội - Hà Nam | G14: 270 | H14: 4876200 | J14: 1200000 | O14: =H14+J14+K14+L14+M14+N14 -> 6076200 | P14: 5300000 | Q14: =P14-O14 -> -776200
A15: 8 | B15: 43353 | C15: Đóng hàng chè sáng 11/09 | D15: FBIU0480084 | E15: Tân Lập, Mộc Châu, Sơn La | G15: 118 | H15: 2131080 | J15: 2440000 | O15: =H15+J15+K15+L15+M15+N15 -> 4571080 | P15: 13181818 | Q15: =P15-O15 -> 8610738
A16: 9 | B16: 43354 | C16: Đóng hàng bột đá 12/09 | D16: VNLU3099435 | E16: Phủ Lý, Hà Nam | J16: 430000 | O16: =H16+J16+K16+L16+M16+N16 -> 430000 | P16: 3200000 | Q16: =P16-O16 -> 2770000
A17: 10 | B17: 43355 | C17: Đóng hàng XK sáng 13/09 | D17: HCVT0002 | E17: TP. Việt Trì, Phú Thọ | G17: 225 | H17: 4063500 | J17: 1130000 | O17: =H17+J17+K17+L17+M17+N17 -> 5193500 | P17: 5200000 | Q17: =P17-O17 -> 6500
A18: 11 | B18: 43356 | C18: Đóng hàng chè sáng 14/09 | D18: TEMU1656046 | E18: Mỹ Bằng, Yên Sơn, Tuyên Quang | J18: 1600000 | O18: =H18+J18+K18+L18+M18+N18 -> 1600000 | P18: 7227273 | Q18: =P18-O18 -> 5627273
A19: 12 | B19: 43357 | C19: Trả hàng sáng 15/09 | D19: WHLU0547133 | E19: KCN Đại Đồng, Bắc Ninh | G19: 220 | H19: 3973200 | J19: 680000 | O19: =H19+J19+K19+L19+M19+N19 -> 4653200 | P19: 3400000 | Q19: =P19-O19 -> -1253200
A20: 13 | B20: 43359 | C20: Trả hàng + đóng hàng KH 17/09 | D20: TCKU3112237 | E20: Thường Tín, Hà Nội - Hà Nam | G20: 158 | H20: 2853480 | J20: 1200000 | O20: =H20+J20+K20+L20+M20+N20 -> 4053480 | P20: 5400000 | Q20: =P20-O20 -> 1346520
A21: 14 | B21: 43360 | C21: Trả hàng + đóng hàng KH 18/09 | D21: DRYU2899177 | E21: Tiền Hải, Thái Bình - Hà Nam | J21: =750000+280000 -> 1030000 | O21: =H21+J21+K21+L21+M21+N21 -> 1030000 | P21: 4800000 | Q21: =P21-O21 -> 3770000
A22: 15 | B22: 43361 | C22: Đóng hàng sáng 19/09 | D22: HCVT0015 | E22: TP. Việt Trì, Phú Thọ | G22: 207 | H22: 3738420 | J22: 1130000 | O22: =H22+J22+K22+L22+M22+N22 -> 4868420 | P22: 5200000 | Q22: =P22-O22 -> 331580
A23: 16 | B23: 43362 | C23: Trả hàng + đóng hàng KH 20/09 | D23: FSCU7790251 | E23: TP Nam Định - Hà Nam | J23: 750000 | O23: =H23+J23+K23+L23+M23+N23 -> 750000 | P23: 4700000 | Q23: =P23-O23 -> 3950000
A24: 17 | B24: 43363 | C24: Trả hàng NK sáng 21/09 | D24: FCIU2866150 | E24: Bát Tràng, Hà Nội | G24: 258 | H24: 4659480 | J24: 680000 | O24: =H24+J24+K24+L24+M24+N24 -> 5339480 | P24: 3200000 | Q24: =P24-O24 -> -2139480
A25: 18 | B25: 43364 | C25: Trả hàng NK sáng 22/09 | D25: HCVT0017 | E25: TP. Việt Trì, Phú Thọ | J25: 1130000 | O25: =H25+J25+K25+L25+M25+N25 -> 1130000 | P25: 5200000 | Q25: =P25-O25 -> 4070000
A26: 19 | B26: 43365 | C26: Trả hàng + đóng hàng KH 24/09 | D26: GMDU2150722 | E26: Khai Quang, Vĩnh Phúc - Hà Nam | G26: 188 | H26: 3406560 | J26: 1200000 | O26: =H26+J26+K26+L26+M26+N26 -> 4606560 | P26: 6100000 | Q26: =P26-O26 -> 1493440
A27: 20 | B27: 43367 | C27: Trả hàng + đóng hàng KH 25/09 | D27: GMDU2152263 | E27: Khuyến Lương, Hà Nội - Hà Nam | J27: 1200000 | O27: =H27+J27+K27+L27+M27+N27 -> 1200000 | P27: 5400000 | Q27: =P27-O27 -> 4200000
A28: 21 | B28: 43368 | C28: Đóng hàng chè sáng 26/09 | D28: EITU0016783 | E28: Mỹ Bằng, Yên Sơn, Tuyên Quang | G28: 272 | H28: 4928640 | J28: 1600000 | O28: =H28+J28+K28+L28+M28+N28 -> 6528640 | P28: 7227273 | Q28: =P28-O28 -> 698633
A29: 22 | B29: 43368 | C29: Đóng hàng chè sáng 27/09 | D29: WHLU0583064 | E29: Tân Lập, Mộc Châu, Sơn La | G29: 123 | H29: 2228760 | J29: 2440000 | O29: =H29+J29+K29+L29+M29+N29 -> 4668760 | P29: 13181818 | Q29: =P29-O29 -> 8513058
A30: 23 | B30: 43370 | C30: Trả hàng + đóng hàng KH 28/09 | D30: GMDU2151185 | E30: Cẩm Giàng, Hải Dương - Hà Nam | G30: 160 | H30: 2899200 | J30: 1050000 | O30: =H30+J30+K30+L30+M30+N30 -> 3949200 | P30: 4800000 | Q30: =P30-O30 -> 850800
A31: 24 | B31: 43371 | C31: Trả hàng + đóng hàng KH 29/09 | D31: WFHU1365110 | E31: Đại An, Hải Dương- Hà Nam | G31: 240 | H31: 4348800 | J31: 1050000 | O31: =H31+J31+K31+L31+M31+N31 -> 5398800 | P31: 4800000 | Q31: =P31-O31 -> -598800
G32: 215 | H32: =G32*18120 -> 3895800 | O32: =H32+J32+K32+L32+M32+N32 -> 3895800 | Q32: =P32-O32 -> -3895800
O33: =H33+J33+K33+L33+M33+N33 -> 0 | Q33: =P33-O33 -> 0
C34: Thanh toán tiền sửa chữa xe 15C-070.63 (công thợ căn chỉnh, mua dầu rửa, rẻ, keo) | L34: 9300000 | O34: =H34+J34+K34+L34+M34+N34 -> 9300000 | Q34: =P34-O34 -> -9300000
C35: Thanh toán tiền sửa xe 15C-070.63 | L35: 150000 | O35: =H35+J35+K35+L35+M35+N35 -> 150000 | Q35: =P35-O35 -> -150000
C36: Thanh toán phí sử dụng đường bộ xe 15C-070.63 | L36: 8628000 | O36: =H36+J36+K36+L36+M36+N36 -> 8628000 | Q36: =P36-O36 -> -8628000
C37: Thanh toán phí đăng kiểm xe 15C-070.63 | L37: 610000 | O37: =H37+J37+K37+L37+M37+N37 -> 610000 | Q37: =P37-O37 -> -610000
C38: Thanh toán tiền mua dầu cầu Total | N38: =2760000 -> 2760000 | O38: =H38+J38+K38+L38+M38+N38 -> 2760000 | Q38: =P38-O38 -> -2760000
C39: Bơm mỡ đầu kéo+mooc xe 15C-070.63 ngày 22/9 | L39: 170000 | O39: =H39+J39+K39+L39+M39+N39 -> 170000 | Q39: =P39-O39 -> -170000
C40: Phí gửi xe | L40: =1200000*1.1 -> 1320000 | O40: =H40+J40+K40+L40+M40+N40 -> 1320000 | Q40: =P40-O40 -> -1320000
C41: Lương lái xe | M41: 5975000 | O41: =H41+J41+K41+L41+M41+N41 -> 5975000 | Q41: =P41-O41 -> -5975000
A42: TỔNG CỘNG | G42: =SUM(G7:G41) -> 3121 | H42: =SUM(H7:H41) -> 56349740 | I42: =SUM(I7:I41) -> 0 | J42: =SUM(J7:J41) -> 28130000 | K42: =SUM(K7:K41) -> 0 | L42: =SUM(L7:L41) -> 20178000 | M42: =SUM(M7:M41) -> 5975000 | N42: =SUM(N7:N41) -> 2760000 | ... Q42: =SUM(Q7:Q41) -> 23925442
...

Sheet 10-2018
A1: Bảng theo dõi doanh thu/ chi phí theo phương tiện vận chuyển
A2: Biển số xe: 15C - 070.63
B3: THÁNG 10.2018
A5: STT | B5: Ngày tháng | C5: Diễn giải | D5: Số cont | E5: Tuyến đường vận chuyển | F5: Khoảng cách (km) | G5: Chi phí | O5: Tổng chi phí | P5: Cước vận chuyển | Q5: Lợi nhuận gộp
G6: Dầu (l) | H6: Dầu (đồng) | I6: Mức TTBQ | J6: Đi đường | K6: Lương lx | L6: Sửa chữa | M6: Lốp | N6: Dầu máy
A8: 1 | B8: 43374 | C8: Trả hàng + đóng hàng KH 01/10 | D8: WHLU2307701 | E8: Yên Mỹ, Hưng Yên - Hà Nam | J8: 1050000 | O8: =H8+J8+K8+L8+M8+N8 -> 1050000 | P8: 4800000 | Q8: =P8-O8 -> 3750000
A9: 2 | B9: 43374 | C9: Đóng hàng Vietsun sáng 02/10 | D9: TRHU1344273 | E9: Chí Linh, Hải Dương | J9: 540000 | O9: =H9+J9+K9+L9+M9+N9 -> 540000 | P9: 2600000 | Q9: =P9-O9 -> 2060000
A10: 3 | B10: 43374 | C10: Đóng hàng Vietsun chiều 02/10 | D10: DRYU2924069 | E10: Chí Linh, Hải Dương | J10: 540000 | O10: =H10+J10+K10+L10+M10+N10 -> 540000 | P10: 2600000 | Q10: =P10-O10 -> 2060000
A11: 4 | B11: 43375 | C11: Trả hàng + đóng hàng KH 03/10 | D11: VSLU4487062 | E11: Thường Tín, Hà Nội - Hà Nam | G11: 220 | H11: 3986400 | J11: 1200000 | O11: =H11+J11+K11+L11+M11+N11 -> 5186400 | P11: 5400000 | Q11: =P11-O11 -> 213600
A12: 5 | B12: 43376 | C12: Trả hàng + đóng hàng KH 04/10 | D12: TRHU1344925 | E12: Yên Mỹ, Hưng Yên - Hà Nam | J12: 1050000 | O12: =H12+J12+K12+L12+M12+N12 -> 1050000 | P12: 4800000 | Q12: =P12-O12 -> 3750000
A13: 6 | B13: 43377 | C13: Đóng hàng Vietsun sáng 05/10 | D13: VSLU4489527 | E13: Chí Linh, Hải Dương | J13: 450000 | O13: =H13+J13+K13+L13+M13+N13 -> 450000 | P13: 2600000 | Q13: =P13-O13 -> 2150000
A14: 7 | B14: 43377 | C14: Đóng hàng Vietsun chiều 05/10 | D14: DRYU2851609 | E14: Chí Linh, Hải Dương | J14: 450000 | O14: =H14+J14+K14+L14+M14+N14 -> 450000 | P14: 2600000 | Q14: =P14-O14 -> 2150000
A15: 8 | B15: 43378 | C15: Trả hàng Nk sáng 06/10 | D15: BMOU1123110 | E15: Thường Tín, Hà Nội | G15: 237 | H15: 4294440 | J15: 820000 | O15: =H15+J15+K15+L15+M15+N15 -> 5114440 | P15: 6300000 | Q15: =P15-O15 -> 1185560
A16: 9 | B16: 43381 | C16: Trả hàng + đóng hàng KH 09/10 | D16: BISU2820433 | E16: Trôi, Hà Nội - Hà Nam | J16: 1200000 | O16: =H16+J16+K16+L16+M16+N16 -> 1200000 | P16: 5400000 | Q16: =P16-O16 -> 4200000
A17: 10 | B17: 43382 | C17: Đóng hàng chè sáng 11/10 | D17: WHSU2377556 | E17: Tân Lập, Mộc Châu, Sơn La | G17: =185+125 -> 310 | H17: =3442850+125*18610 -> 5769100 | J17: =2440000-120000 -> 2320000 | O17: =H17+J17+K17+L17+M17+N17 -> 8089100 | P17: 13181818 | Q17: =P17-O17 -> 5092718
A18: 11 | B18: 43384 | C18: Trả hàng + đóng hàng KH 12/10 | D18: DRYU3025371 | E18: Yên Mỹ, Hưng Yên - Hà Nam | G18: 214 | H18: =G18*18610 -> 3982540 | J18: 1050000 | O18: =H18+J18+K18+L18+M18+N18 -> 5032540 | P18: 4900000 | Q18: =P18-O18 -> -132540
A19: 12 | B19: 43385 | C19: Đóng hàng bột đá 13/10 | D19: BISU2834972 | E19: Phủ Lý, Hà Nam | J19: 430000 | O19: =H19+J19+K19+L19+M19+N19 -> 430000 | P19: 3200000 | Q19: =P19-O19 -> 2770000
A20: 13 | B20: 43388 | C20: Đóng hàng chè sáng 15/10 | D20: TEMU3994119 | E20: Mỹ Bằng, Yên Sơn, Tuyên Quang | G20: 220 | H20: =G20*18610 -> 4094200 | J20: 1600000 | O20: =H20+J20+K20+L20+M20+N20 -> 5694200 | P20: 7227273 | Q20: =P20-O20 -> 1533073
A21: 14 | B21: 43388 | C21: Trả hàng + đóng hàng chè 16/10 | D21: WHLU0606637 | E21: Phủ Lỗ, Sóc Sơn, Hà Nội | G21: 140 | H21: =G21*18610 -> 2605400 | J21: =700000+300000 -> 1000000 | O21: =H21+J21+K21+L21+M21+N21 -> 3605400 | P21: 6300000 | Q21: =P21-O21 -> 2694600
A22: 15 | B22: 43389 | C22: Đóng hàng bột đá chiều 17/10 | D22: VNLU2093279 | E22: Phủ Lý, Hà Nam | J22: 430000 | O22: =H22+J22+K22+L22+M22+N22 -> 430000 | P22: 3200000 | Q22: =P22-O22 -> 2770000
A23: 16 | B23: 43390 | C23: Trả hàng NK sáng 18/10 | D23: TRHU2869477 | E23: Bát Tràng, Hà Nội | J23: 680000 | O23: =H23+J23+K23+L23+M23+N23 -> 680000 | P23: 3200000 | Q23: =P23-O23 -> 2520000
A24: 17 | B24: 43391 | C24: Trả hàng sáng 19/10 | D24: CSNU1659311 | E24: Thường Tín, Hà Nội | G24: 178 | H24: =G24*18610 -> 3312580 | J24: 810000 | O24: =H24+J24+K24+L24+M24+N24 -> 4122580 | P24: 4100000 | Q24: =P24-O24 -> -22580
A25: 18 | B25: 43392 | C25: Trả hàng + đóng hàng KH 20/10 | D25: GAOU2108166 | E25: Vĩnh Tường, Vĩnh Phúc - Hà Nam | J25: 1200000 | O25: =H25+J25+K25+L25+M25+N25 -> 1200000 | P25: 6100000 | Q25: =P25-O25 -> 4900000
A26: 19 | B26: 43393 | C26: Trả hàng sáng 22/10 | D26: CSNU1403274 | E26: Thường Tín, Hà Nội | G26: 158 | H26: =G26*18610 -> 2940380 | J26: 810000 | O26: =H26+J26+K26+L26+M26+N26 -> 3750380 | P26: 4100000 | Q26: =P26-O26 -> 349620
A27: 20 | B27: 43395 | C27: Trả hàng NK sáng 23/10 | D27: CAIU6097179 | E27: KCN Đồng Văn, Hà Nam - Long Biên, Hà Nội | G27: 173 | H27: =G27*18610 -> 3219530 | J27: =430000+400000 -> 830000 | O27: =H27+J27+K27+L27+M27+N27 -> 4049530 | P27: 5100000 | Q27: =P27-O27 -> 1050470
A28: 21 | B28: 43396 | C28: Đóng hàng chè sáng 24/10 | D28: BSIU3178668 | E28: TT Trần Phú, Văn Chấn, Yên Bái | G28: 191 | H28: =G28*18610 -> 3554510 | J28: 1970000 | O28: =H28+J28+K28+L28+M28+N28 -> 5524510 | P28: 9545455 | Q28: =P28-O28 -> 4020945
A29: 22 | B29: 43397 | C29: Trả hàng + đóng hàng KH 25/10 | D29: GMDU2181240 | E29: KCN Vân Trung, Bắc Giang - Hà Nam | J29: 1260000 | O29: =H29+J29+K29+L29+M29+N29 -> 1260000 | P29: 5400000 | Q29: =P29-O29 -> 4140000
A30: 23 | B30: 43398 | C30: Trả hàng NK sáng 26/10 | D30: TGBU2376040 | E30: Thường Tín, Hà Nội | G30: 180 | H30: =G30*18610 -> 3349800 | J30: 810000 | O30: =H30+J30+K30+L30+M30+N30 -> 4159800 | P30: 4100000 | Q30: =P30-O30 -> -59800
A31: 24 | B31: 43399 | C31: Trả hàng + đóng hàng KH 27/10 | D31: DRYU2873402 | E31: Long Biên, Hà Nội - Hà Nam | G31: 225 | H31: =G31*18610 -> 4187250 | J31: 1200000 | O31: =H31+J31+K31+L31+M31+N31 -> 5387250 | P31: 5400000 | Q31: =P31-O31 -> 12750
A32: 25 | B32: 43402 | C32: Trả hàng + đóng hàng KH 29/10 | D32: VSLU3035941 | E32: Thường Tín, Hà Nội - Hà Nam | J32: 1200000 | O32: =H32+J32+K32+L32+M32+N32 -> 1200000 | P32: 5500000 | Q32: =P32-O32 -> 4300000
A33: 26 | B33: 43402 | C33: Trả hàng + đóng hàng KH 30/10 | D33: TRHU3295440 | E33: Bát Tràng, Gia Lâm, Hà Nội - Hà Nam | G33: 245 | H33: =G33*18610 -> 4559450 | J33: 1050000 | O33: =H33+J33+K33+L33+M33+N33 -> 5609450 | P33: 5400000 | Q33: =P33-O33 -> -209450
A34: 27 | B34: 43403 | C34: Trả hàng Vietsun sáng 31/10 | D34: DRYU3093490 | E34: KCN Tràng Duệ, An Dương, Hải Phòng | G34: 145 | H34: =G34*18610 -> 2698450 | J34: 200000 | O34: =H34+J34+K34+L34+M34+N34 -> 2898450 | P34: 1372727 | Q34: =P34-O34 -> -1525723
O35: =H35+J35+K35+L35+M35+N35 -> 0 | Q35: =P35-O35 -> 0
O36: =H36+J36+K36+L36+M36+N36 -> 0 | Q36: =P36-O36 -> 0
C37: Thanh toán tiền sửa xe 15C-070.63 (sửa máy phát, thay dàn Diot) | L37: 750000 | O37: =H37+J37+K37+L37+M37+N37 -> 750000 | Q37: =P37-O37 -> -750000
C38: Mua củ đề xe 15C-070.63 | L38: 2500000 | O38: =H38+J38+K38+L38+M38+N38 -> 2500000 | Q38: =P38-O38 -> -2500000
C39: Công chứng 15C-128.07 xe 15C-070.63 | L39: 25000 | O39: =H39+J39+K39+L39+M39+N39 -> 25000 | Q39: =P39-O39 -> -25000
C40: Mua bóng hơi ca bin xe 15C-070.63 | L40: 500000 | O40: =H40+J40+K40+L40+M40+N40 -> 500000 | Q40: =P40-O40 -> -500000
C41: Thanh toán tiền thay bóng hơi+cút hơi xe 15C-070.63 ngày 31/10 | L41: 100000 | O41: =H41+J41+K41+L41+M41+N41 -> 100000 | Q41: =P41-O41 -> -100000
C42: Thanh toán tiền thay dầu máy+bơm mỡ, thay lọc nhớt xe 15C-070.63 ngày 31/10 | L42: 170000 | O42: =H42+J42+K42+L42+M42+N42 -> 170000 | Q42: =P42-O42 -> -170000
...

Sheet 11.2018
A1: Bảng theo dõi doanh thu/ chi phí theo phương tiện vận chuyển
A2: Biển số xe: 15C - 070.63
B3: THÁNG 11.2018
A5: STT | B5: Ngày tháng | C5: Diễn giải | D5: Số cont | E5: Tuyến đường vận chuyển | F5: Khoảng cách (km) | G5: Chi phí | O5: Tổng chi phí | P5: Cước vận chuyển | Q5: Lợi nhuận gộp
G6: Dầu (l) | H6: Dầu (đồng) | I6: Mức TTBQ | J6: Đi đường | K6: Lương lx | L6: Sửa chữa | M6: Lốp | N6: Dầu máy
A8: 1 | B8: 43405 | C8: Đóng hàng chè sáng 01/11 | D8: FCIU6425276 | E8: Tân Lập, Mộc Châu, Sơn La | J8: 2200000 | O8: =H8+J8+K8+L8+M8+N8 -> 2200000 | P8: 13181818 | Q8: =P8-O8 -> 10981818
A9: 2 | B9: 43406 | C9: Trả hàng + đóng hàng KH 02/11 | D9: DRYU3021859 | E9: Văn Giang, HY- Đồng Văn, HN - Hà Nam | G9: 233 | H9: =G9*18610 -> 4336130 | J9: 1050000 | O9: =H9+J9+K9+L9+M9+N9 -> 5386130 | P9: 5100000 | Q9: =P9-O9 -> -286130
A10: 3 | B10: 43407 | C10: Trả hàng + đóng hàng KH 03/11 | D10: VSLU4495290 | E10: Yên Mỹ, Hưng Yên - Hà Nam | J10: 1050000 | O10: =H10+J10+K10+L10+M10+N10 -> 1050000 | P10: 4900000 | Q10: =P10-O10 -> 3850000
A11: 4 | B11: 43409 | C11: Trả hàng + đóng hàng KH 05/11 | D11: VSLU3031099 | E11: Từ Liêm, Hà Nội - Hà Nam | G11: 235 | H11: =G11*18610 -> 4373350 | J11: 1200000 | O11: =H11+J11+K11+L11+M11+N11 -> 5573350 | P11: 5500000 | Q11: =P11-O11 -> -73350
A12: 5 | B12: 43410 | C12: Trả hàng + đóng hàng KH 06/11 | D12: GAOU2112398 | E12: Văn Giang, HY- Đồng Văn, HN - Hà Nam | G12: 239 | H12: =G12*18540 -> 4431060 | J12: 1050000 | O12: =H12+J12+K12+L12+M12+N12 -> 5481060 | P12: 5100000 | Q12: =P12-O12 -> -381060
A13: 6 | B13: 43411 | C13: Trả hàng + đóng hàng KH 07/11 | D13: VSLU1042469 | E13: Yên Mỹ, Hưng Yên - Hà Nam | J13: 1050000 | O13: =H13+J13+K13+L13+M13+N13 -> 1050000 | P13: 4900000 | Q13: =P13-O13 -> 3850000
A14: 7 | B14: 43412 | C14: Trả hàng NK sáng 08/11 | D14: TGBU2267938 | E14: Hoài Đức, Hà Nội | J14: 810000 | O14: =H14+J14+K14+L14+M14+N14 -> 810000 | P14: 4200000 | Q14: =P14-O14 -> 3390000
A15: 8 | B15: 43413 | C15: Trả hàng + đóng hàng KH 09/11 | D15: DRYU2851337 | E15: Yên Mỹ, Hưng Yên - Hà Nam | G15: 204 | H15: =G15*18540 -> 3782160 | J15: 1050000 | O15: =H15+J15+K15+L15+M15+N15 -> 4832160 | P15: 4900000 | Q15: =P15-O15 -> 67840
A16: 9 | B16: 43414 | C16: Trả hàng sáng 10/11 | D16: CSNU1341362 | E16: Thường Tín, Hà Nội | J16: 810000 | O16: =H16+J16+K16+L16+M16+N16 -> 810000 | P16: 4100000 | Q16: =P16-O16 -> 3290000
A17: 10 | B17: 43415 | C17: Đóng hàng chè sáng 11/11 | D17: OOLU9758215 | E17: Mộc Châu, Sơn La | G17: 193 | H17: =G17*18540 -> 3578220 | J17: 2380000 | O17: =H17+J17+K17+L17+M17+N17 -> 5958220 | P17: 12090909 | Q17: =P17-O17 -> 6132689
A18: 11 | B18: 43416 | C18: Trả hàng NK sáng 12/11 | D18: MAGU5686515 | E18: Ngọc Hồi, Hà Nội | G18: 250 | H18: =G18*18540 -> 4635000 | J18: 970000 | O18: =H18+J18+K18+L18+M18+N18 -> 5605000 | P18: 4000000 | Q18: =P18-O18 -> -1605000
A19: 12 | B19: 43417 | C19: Trả hàng + đóng hàng KH 13/11 | D19: DRYU3024734 | E19: Tân Quang, Văn Lâm, Hưng Yên - Hà Nam | J19: =1050000+210000 -> 1260000 | O19: =H19+J19+K19+L19+M19+N19 -> 1260000 | P19: 5100000 | Q19: =P19-O19 -> 3840000
A20: 13 | B20: 43418 | C20: Trả hàng + đóng hàng KH 14/11 | D20: DRYU3093360 | E20: Cẩm Giàng, HD - Chương Mỹ, HN - Hà Nam | G20: 222 | H20: =G20*18540 -> 4115880 | J20: 1200000 | O20: =H20+J20+K20+L20+M20+N20 -> 5315880 | P20: 5800000 | Q20: =P20-O20 -> 484120
A21: 14 | B21: 43419 | C21: Trả hàng + đóng hàng KH 15/11 | D21: DRYU2923203 | E21: TP. Hải Dương - Hà Nam | J21: 1050000 | O21: =H21+J21+K21+L21+M21+N21 -> 1050000 | P21: 4900000 | Q21: =P21-O21 -> 3850000
A22: 15 | B22: 43420 | C22: Đóng hàng sáng 16/11 | D22: NSDU2000762 | E22: An Lão, Hải Phòng | G22: 266 | H22: =G22*18540 -> 4931640 | J22: 200000 | O22: =H22+J22+K22+L22+M22+N22 -> 5131640 | P22: 2000000 | Q22: =P22-O22 -> -3131640
A23: 16 | B23: 43421 | C23: Trả hàng NK sáng 17/11 | D23: EGSU3081065 | E23: KCN Đại Đồng, Bắc Ninh | J23: 680000 | O23: =H23+J23+K23+L23+M23+N23 -> 680000 | P23: 3500000 | Q23: =P23-O23 -> 2820000
A24: 17 | B24: 43423 | C24: Trả hàng + đóng hàng KH 19/11 | D24: WFHU1358533 | E24: Yên Mỹ, Hưng Yên - Hà Nam | J24: 1050000 | O24: =H24+J24+K24+L24+M24+N24 -> 1050000 | P24: 5100000 | Q24: =P24-O24 -> 4050000
A25: 18 | B25: 43424 | C25: Đóng hàng sáng 20/11 | D25: GMDU2141398 | E25: Phủ Lý, Hà Nam | G25: 200 | H25: =G25*18540 -> 3708000 | J25: 430000 | O25: =H25+J25+K25+L25+M25+N25 -> 4138000 | P25: 3200000 | Q25: =P25-O25 -> -938000
A26: 19 | B26: 43425 | C26: Trả hàng sáng 21/11 | D26: VHPU170305 | E26: KCN Đại Đồng, Bắc Ninh | J26: 680000 | O26: =H26+J26+K26+L26+M26+N26 -> 680000 | P26: 3500000 | Q26: =P26-O26 -> 2820000
A27: 20 | B27: 43426 | C27: Trả hàng NK sáng 22/11 | D27: WHLU2513908 | E27: KCN Khai Quang, Vĩnh Phúc - Hà Nam | G27: 185 | H27: =G27*17630 -> 3261550 | J27: 1200000 | O27: =H27+J27+K27+L27+M27+N27 -> 4461550 | P27: 6100000 | Q27: =P27-O27 -> 1638450
A28: 21 | B28: 43427 | C28: Đóng hàng phân sáng 23/11 | D28: MSKU7713863 | E28: Hoa Lư, Ninh Bình | G28: 265 | H28: =G28*17630 -> 4671950 | J28: 430000 | O28: =H28+J28+K28+L28+M28+N28 -> 5101950 | P28: 3800000 | Q28: =P28-O28 -> -1301950
A29: 22 | B29: 43428 | C29: Đóng hàng phân sáng 24/11 | D29: MSKU2203867 | E29: Hoa Lư, Ninh Bình | J29: 430000 | O29: =H29+J29+K29+L29+M29+N29 -> 430000 | P29: 3800000 | Q29: =P29-O29 -> 3370000
A30: 23 | B30: 43430 | C30: Trả hàng NK sáng 26/11 | D30: GMDU2181507 | E30: Gia Lâm, Hà Nội - Hà Nam | J30: 1200000 | O30: =H30+J30+K30+L30+M30+N30 -> 1200000 | P30: 5400000 | Q30: =P30-O30 -> 4200000
A31: 24 | B31: 43431 | C31: Trả hàng + đóng hàng KH 27/11 | D31: AKLU6004413 | E31: KCN Khai Quang, Vĩnh Phúc - Hà Nam | G31: 223 | H31: =G31*17630 -> 3931490 | J31: 1200000 | O31: =H31+J31+K31+L31+M31+N31 -> 5131490 | P31: 6100000 | Q31: =P31-O31 -> 968510
A32: 25 | B32: 43432 | C32: Trả hàng NK sáng 28/11 | D32: DFSU1459596 | E32: KCN VSIP Bắc Ninh | J32: 680000 | O32: =H32+J32+K32+L32+M32+N32 -> 680000 | P32: 3300000 | Q32: =P32-O32 -> 2620000
A33: 26 | B33: 43433 | C33: Trả hàng + đóng hàng KH 29/11 | D33: DRYU2902331 | E33: Yên Mỹ, Hưng Yên - Hà Nam | G33: 236 | H33: =G33*17630 -> 4160680 | J33: 1050000 | O33: =H33+J33+K33+L33+M33+N33 -> 5210680 | P33: 4900000 | Q33: =P33-O33 -> -310680
A34: 27 | B34: 43434 | C34: Trả hàng NK sáng 30/11 | D34: OCGU2013117 | E34: Yên Viên - Mỹ Đình, Hà Nội | G34: 206 | H34: =G34*17630 -> 3631780 | J34: 810000 | O34: =H34+J34+K34+L34+M34+N34 -> 4441780 | P34: 4500000 | Q34: =P34-O34 -> 58220
O35: =H35+J35+K35+L35+M35+N35 -> 0 | Q35: =P35-O35 -> 0
O36: =H36+J36+K36+L36+M36+N36 -> 0 | Q36: =P36-O36 -> 0
C37: Thanh toán tiền lọc nhớt, lọc diesel xe 15C-070.63 | L37: 520000 | O37: =H37+J37+K37+L37+M37+N37 -> 520000 | Q37: =P37-O37 -> -520000
C38: Thanh toán tiền mua dầu total rubia tir 7400 | N38: =11700000/4 -> 2925000 | O38: =H38+J38+K38+L38+M38+N38 -> 2925000 | Q38: =P38-O38 -> -2925000
C39: Phí gửi xe | L39: =1200000*1.1 -> 1320000 | O39: =H39+J39+K39+L39+M39+N39 -> 1320000 | Q39: =P39-O39 -> -1320000
C40: Lương lái xe | K40: 10538462 | O40: =H40+J40+K40+L40+M40+N40 -> 10538462 | Q40: =P40-O40 -> -10538462
A41: TỔNG CỘNG | G41: =SUM(G7:G40) -> 3157 | H41: =SUM(H7:H40) -> 57548890 | I41: =SUM(I7:I40) -> 0 | J41: =SUM(J7:J40) -> 27170000 | K41: =SUM(K7:K40) -> 10538462 | L41: =SUM(L7:L40) -> 1840000 | M41: =SUM(M7:M40) -> 0 | N41: =SUM(N7:N40) -> 2925000 | ... Q41: =SUM(Q7:Q40) -> 38950375
P43: LK = | Q43: ='10-2018'!Q47+'11.2018'!Q41 -> 136866548

Sheet 12.2018
A1: Bảng theo dõi doanh thu/ chi phí theo phương tiện vận chuyển
A2: Biển số xe: 15C - 070.63
B3: THÁNG 12.2018
A5: STT | B5: Ngày tháng | C5: Diễn giải | D5: Số cont | E5: Tuyến đường vận chuyển | F5: Khoảng cách (km) | G5: Chi phí | O5: Tổng chi phí | P5: Cước vận chuyển | Q5: Lợi nhuận gộp
G6: Dầu (l) | H6: Dầu (đồng) | I6: Mức TTBQ | J6: Đi đường | K6: Lương lx | L6: Sửa chữa | M6: Lốp | N6: Dầu máy
A8: 1 | B8: 43435 | C8: Trả hàng + đóng hàng KH 01/12 | D8: CAXU6913778 | E8: KCN Khai Quang, Vĩnh Phúc - Hà Nam | J8: 1260000 | O8: =H8+J8+K8+L8+M8+N8 -> 1260000 | P8: 6100000 | Q8: =P8-O8 -> 4840000
A9: 2 | B9: 43437 | C9: Trả hàng + đóng hàng KH 03/12 | D9: DRYU2848101 | E9: Đông Anh, Hà Nội - Hà Nam | G9: 176 | H9: =G9*17630 -> 3102880 | J9: 1260000 | O9: =H9+J9+K9+L9+M9+N9 -> 4362880 | P9: 5500000 | Q9: =P9-O9 -> 1137120
A10: 3 | B10: 43438 | C10: Trả hàng + đóng hàng KH 04/12 | D10: DRYU2851701 | E10: KCN Khai Quang, Vĩnh Phúc - Hà Nam | J10: 1200000 | O10: =H10+J10+K10+L10+M10+N10 -> 1200000 | P10: 6100000 | Q10: =P10-O10 -> 4900000
A11: 4 | B11: 43439 | C11: Trả hàng Vietsun sáng 05/12 | D11: WFHU1352690 | E11: KCN Tân Quang, Văn Lâm, Hưng Yên | G11: 276 | H11: =G11*17630 -> 4865880 | J11: 930000 | O11: =H11+J11+K11+L11+M11+N11 -> 5795880 | P11: 2918182 | Q11: =P11-O11 -> -2877698
A12: 5 | B12: 43440 | C12: Đóng hàng chè sáng 06/12 | D12: GCXU2132776 | E12: Hương Canh, Vĩnh Phúc | J12: 850000 | O12: =H12+J12+K12+L12+M12+N12 -> 850000 | P12: 4545455 | Q12: =P12-O12 -> 3695455
A13: 6 | B13: 43441 | C13: Trả hàng + đóng hàng KH 07/12 | D13: GAOU2113141 | E13: Phố Nối A, Hưng Yên - Hà Nam | J13: 1050000 | O13: =H13+J13+K13+L13+M13+N13 -> 1050000 | P13: 4900000 | Q13: =P13-O13 -> 3850000
A14: 7 | B14: 43442 | C14: Đóng hàng XK 08/12 | D14: PONU2989248 | E14: Hoa Lư, Ninh Bình | G14: 262 | H14: =G14*16250 -> 4257500 | J14: 430000 | O14: =H14+J14+K14+L14+M14+N14 -> 4687500 | P14: 3800000 | Q14: =P14-O14 -> -887500
A15: 8 | B15: 43445 | C15: Trả hàng NK sáng 11/12 | D15: GCXU2108321 | E15: KCN VSIP Bắc Ninh | G15: 186 | H15: =G15*16250 -> 3022500 | J15: 680000 | O15: =H15+J15+K15+L15+M15+N15 -> 3702500 | P15: 3300000 | Q15: =P15-O15 -> -402500
A16: 9 | B16: 43446 | C16: Trả hàng + đóng hàng KH 12/12 | D16: BISU2836379 | E16: Vạn Phúc, Hà Đông - Hà Nam | J16: 1260000 | O16: =H16+J16+K16+L16+M16+N16 -> 1260000 | P16: 5500000 | Q16: =P16-O16 -> 4240000
A17: 10 | B17: 43447 | C17: Trả hàng + đóng hàng KH 13/12 | D17: GMDU2185919 | E17: KCN Khai Quang, Vĩnh Phúc - Hà Nam | G17: 155 | H17: =G17*16250 -> 2518750 | J17: =1200000+60000 -> 1260000 | O17: =H17+J17+K17+L17+M17+N17 -> 3778750 | P17: 6100000 | Q17: =P17-O17 -> 2321250
A18: 11 | B18: 43448 | C18: Trả hàng + đóng hàng KH 14/12 | D18: GMDU2182904 | E18: TP. Hải Dương - Hà Nam | G18: 158 | H18: =G18*16250 -> 2567500 | J18: 1050000 | O18: =H18+J18+K18+L18+M18+N18 -> 3617500 | P18: 4900000 | Q18: =P18-O18 -> 1282500
A19: 12 | B19: 43451 | C19: Trả hàng NK sáng 17/12 | D19: CSNU1053999 | E19: Thường Tín, Hà Nội | G19: 110 | H19: =G19*16250 -> 1787500 | J19: =810000+60000 -> 870000 | O19: =H19+J19+K19+L19+M19+N19 -> 2657500 | P19: 4100000 | Q19: =P19-O19 -> 1442500
A20: 13 | B20: 43451 | C20: Trả hàng + đóng hàng KH 17/12 | D20: GAOU2110625 | E20: Từ Liêm, Hà Nội - Hà Nam | J20: 1200000 | O20: =H20+J20+K20+L20+M20+N20 -> 1200000 | P20: 5500000 | Q20: =P20-O20 -> 4300000
A21: 14 | B21: 43453 | C21: Trả hàng + đóng hàng KH 19/12 | D21: GAOU2114699 | E21: Mỹ Hào, Hưng Yên - Hà Nam | G21: 208 | H21: =G21*16250 -> 3380000 | J21: 1050000 | O21: =H21+J21+K21+L21+M21+N21 -> 4430000 | P21: 4900000 | Q21: =P21-O21 -> 470000
A22: 15 | B22: 43454 | C22: Trả hàng + đóng hàng KH 20/12 | D22: GAOU2108633 | E22: Dị Sử, Mỹ Hào, Hưng Yên - Hà Nam | J22: 1050000 | O22: =H22+J22+K22+L22+M22+N22 -> 1050000 | P22: 4900000 | Q22: =P22-O22 -> 3850000
A23: 16 | B23: 43455 | C23: Trả hàng + đóng hàng KH 21/12 | D23: DRYU2852415 | E23: Dị Sử, Mỹ Hào, Hưng Yên - Hà Nam | G23: 216 | H23: =G23*16250 -> 3510000 | J23: 1050000 | O23: =H23+J23+K23+L23+M23+N23 -> 4560000 | P23: 4900000 | Q23: =P23-O23 -> 340000
A24: 17 | B24: 43456 | C24: Trả hàng + đóng hàng KH 22/12 | D24: TRHU3295497 | E24: KCN Đại Đồng, Bắc Ninh - Hà Nam | G24: 218 | H24: =G24*16000 -> 3488000 | J24: 1260000 | O24: =H24+J24+K24+L24+M24+N24 -> 4748000 | P24: 5400000 | Q24: =P24-O24 -> 652000
A25: 18 | B25: 43823 | C25: Trả hàng + đóng hàng KH 24/12 | D25: GMDU2180162 | E25: Khai Quang, Vĩnh Phúc - Hà Nam | J25: 1260000 | O25: =H25+J25+K25+L25+M25+N25 -> 1260000 | P25: 6100000 | Q25: =P25-O25 -> 4840000
A26: 19 | B26: 43459 | C26: Trả hàng + đóng hàng KH 25/12 | D26: GMDU2185673 | E26: Thạch Thất, Hà Nội - Hà Nam | G26: 152 | H26: =G26*16000 -> 2432000 | J26: 1260000 | O26: =H26+J26+K26+L26+M26+N26 -> 3692000 | P26: 5600000 | Q26: =P26-O26 -> 1908000
A27: 20 | B27: 43460 | C27: Đóng hàng phân sáng 26/12 | D27: MAEU6963746 | E27: Hoa Lư, Ninh Bình | J27: 450000 | O27: =H27+J27+K27+L27+M27+N27 -> 450000 | P27: 3800000 | Q27: =P27-O27 -> 3350000
A28: 21 | B28: 43461 | C28: Trả hàng + đóng hàng KH 27/12 | D28: DRYU2852652 | E28: Cẩm Giàng, HD - Chương Mỹ, HN - Hà Nam | G28: 228 | H28: =G28*16000 -> 3648000 | J28: 1260000 | O28: =H28+J28+K28+L28+M28+N28 -> 4908000 | P28: 5800000 | Q28: =P28-O28 -> 892000
A29: 22 | B29: 43462 | C29: Trả hàng + đóng hàng KH 28/12 | D29: KKTU7938300 | E29: Khai Quang, Vĩnh Phúc - Hà Nam | G29: 146 | H29: =G29*16000 -> 2336000 | J29: 1260000 | O29: =H29+J29+K29+L29+M29+N29 -> 3596000 | P29: 6100000 | Q29: =P29-O29 -> 2504000
A30: 23 | B30: 43463 | C30: Trả hàng + đóng hàng KH 29/12 | D30: KKTU7910833 | E30: Khai Quang, Vĩnh Phúc - Hà Nam | G30: 154 | H30: =G30*16000 -> 2464000 | J30: 1260000 | O30: =H30+J30+K30+L30+M30+N30 -> 3724000 | P30: 6100000 | Q30: =P30-O30 -> 2376000
O31: =H31+J31+K31+L31+M31+N31 -> 0 | Q31: =P31-O31 -> 0
O32: =H32+J32+K32+L32+M32+N32 -> 0 | Q32: =P32-O32 -> 0
C33: Mua cầu chì | L33: =150000/4 -> 37500 | O33: =H33+J33+K33+L33+M33+N33 -> 37500 | Q33: =P33-O33 -> -37500
C34: Mua nước lọc đổ | L34: =80000/4 -> 20000 | O34: =H34+J34+K34+L34+M34+N34 -> 20000 | Q34: =P34-O34 -> -20000
C35: Lắp camera hành trình | L35: =2200000/4 -> 550000 | O35: =H35+J35+K35+L35+M35+N35 -> 550000 | Q35: =P35-O35 -> -550000
C36: Mua bạc tay giằng ngao xe 15C-070.63 | L36: 600000 | O36: =H36+J36+K36+L36+M36+N36 -> 600000 | Q36: =P36-O36 -> -600000
C37: Thanh toán tiền sửa xe 15C-070.63 (vỉ quạt gió mới) | L37: 1650000 | O37: =H37+J37+K37+L37+M37+N37 -> 1650000 | Q37: =P37-O37 -> -1650000
C38: Thanh toán tiền lọc gió xe 15C-070.63 | L38: 850000 | O38: =H38+J38+K38+L38+M38+N38 -> 850000 | Q38: =P38-O38 -> -850000
C39: Thanh toán tiền sửa xe 15C-070.63 (gia công bạc giảm sóc, công tháo lắp, bạc tay giằng...) | L39: 310000 | O39: =H39+J39+K39+L39+M39+N39 -> 310000 | Q39: =P39-O39 -> -310000
C40: Thanh toán nước làm mát | L40: 2000000 | O40: =H40+J40+K40+L40+M40+N40 -> 2000000 | Q40: =P40-O40 -> -2000000
C41: Thưởng tết dương lịch cho lái xe | K41: 500000 | O41: =H41+J41+K41+L41+M41+N41 -> 500000 | Q41: =P41-O41 -> -500000
C42: Phí gửi xe | L42: =1200000*1.1 -> 1320000 | O42: =H42+J42+K42+L42+M42+N42 -> 1320000 | Q42: =P42-O42 -> -1320000
...

Sheet 1.2019
A1: Bảng theo dõi doanh thu/ chi phí theo phương tiện vận chuyển
A2: Biển số xe: 15C - 070.63
B3: THÁNG 1.2019
A5: STT | B5: Ngày tháng | C5: Diễn giải | D5: Số cont | E5: Tuyến đường vận chuyển | F5: Khoảng cách (km) | G5: Chi phí | O5: Tổng chi phí | P5: Cước vận chuyển | Q5: Lợi nhuận gộp
G6: Dầu (l) | H6: Dầu (đồng) | I6: Mức TTBQ | J6: Đi đường | K6: Lương lx | L6: Sửa chữa | M6: Lốp | N6: Dầu máy
A8: 1 | B8: 43467 | C8: Đóng hàng phân sáng 02/01 | D8: EITU0362370 | E8: Hoa Lư, Ninh Bình | G8: 262 | H8: =G8*14900 -> 3903800 | J8: 450000 | O8: =H8+J8+K8+L8+M8+N8 -> 4353800 | P8: 3800000 | Q8: =P8-O8 -> -553800
A9: 2 | B9: 43468 | C9: Đóng hàng chè sáng 03/01 | D9: FBIU0119322 | E9: Mộc Châu, Sơn La | J9: 2230000 | O9: =H9+J9+K9+L9+M9+N9 -> 2230000 | P9: 12090909 | Q9: =P9-O9 -> 9860909
A10: 3 | B10: 43469 | C10: Trả hàng NK sáng 04/01 | D10: TRHU3832030 | E10: Thường Tín, Hà Nội | G10: 222 | H10: =G10*14900 -> 3307800 | J10: 810000 | O10: =H10+J10+K10+L10+M10+N10 -> 4117800 | P10: 4100000 | Q10: =P10-O10 -> -17800
A11: 4 | B11: 43470 | C11: Trả hàng + đóng hàng KH 05/01 | D11: GMDU2185349 | E11: Khai Quang, Vĩnh Phúc - Hà Nam | G11: 243 | H11: =G11*14900 -> 3620700 | J11: 1380000 | O11: =H11+J11+K11+L11+M11+N11 -> 5000700 | P11: 6100000 | Q11: =P11-O11 -> 1099300
A12: 5 | B12: 43472 | C12: Trả hàng + đóng hàng KH 07/01 | D12: DRYU2924310 | E12: Khai Quang, Vĩnh Phúc - Hà Nam | J12: 1380000 | O12: =H12+J12+K12+L12+M12+N12 -> 1380000 | P12: 6100000 | Q12: =P12-O12 -> 4720000
A13: 6 | B13: 43473 | C13: Trả hàng + đóng hàng KH 08/01 | D13: TCLU2361417 | E13: Khai Quang, Vĩnh Phúc - Hà Nam | G13: 142 | H13: =G13*14900 -> 2115800 | J13: 1380000 | O13: =H13+J13+K13+L13+M13+N13 -> 3495800 | P13: 6100000 | Q13: =P13-O13 -> 2604200
A14: 7 | B14: 43474 | C14: Đóng hàng phân sáng 09/01 | D14: TCLU2524350 | E14: Hoa Lư, Ninh Bình | J14: =450000+410000 -> 860000 | O14: =H14+J14+K14+L14+M14+N14 -> 860000 | P14: 4000000 | Q14: =P14-O14 -> 3140000
A15: 8 | B15: 43475 | C15: Trả hàng NK sáng 10/01 | D15: CSNU1398497 | E15: Thường Tín, Hà Nội | G15: 263 | H15: =G15*14900 -> 3918700 | J15: 810000 | O15: =H15+J15+K15+L15+M15+N15 -> 4728700 | P15: 4100000 | Q15: =P15-O15 -> -628700
A16: 9 | B16: 43476 | C16: Trả hàng + đóng hàng KH 11/01 | D16: GAOU2110498 | E16: Tân Quang, Văn Lâm, Hưng Yên - Hà Nam | J16: 1380000 | O16: =H16+J16+K16+L16+M16+N16 -> 1380000 | P16: 5100000 | Q16: =P16-O16 -> 3720000
A17: 10 | B17: 43477 | C17: Trả hàng NK sáng 12/01 | D17: TRHU1511576 | E17: Phố Nối A, Hưng Yên | G17: 191 | H17: =G17*14900 -> 2845900 | J17: 680000 | O17: =H17+J17+K17+L17+M17+N17 -> 3525900 | P17: 3100000 | Q17: =P17-O17 -> -425900
A18: 11 | B18: 43479 | C18: Trả hàng + đóng hàng KH 14/01 | D18: DRYU2923329 | E18: Mỹ Hào, Hưng Yên - Hà Nam | J18: 1170000 | O18: =H18+J18+K18+L18+M18+N18 -> 1170000 | P18: 4900000 | Q18: =P18-O18 -> 3730000
A19: 12 | B19: 43480 | C19: Trả hàng NK sáng 15/01 | D19: UETU2669912 | E19: Hoài Đức, Hà Nội | G19: 166 | H19: =G19*14900 -> 2473400 | J19: =810000+60000 -> 870000 | O19: =H19+J19+K19+L19+M19+N19 -> 3343400 | P19: 4200000 | Q19: =P19-O19 -> 856600
A20: 13 | B20: 43481 | C20: Trả hàng + đóng hàng KH 16/01 | D20: TRHU1344714 | E20: Đồng Văn, Hà Nam - Hà Nam | J20: 990000 | O20: =H20+J20+K20+L20+M20+N20 -> 990000 | P20: 4900000 | Q20: =P20-O20 -> 3910000
A21: 14 | B21: 43482 | C21: Đóng hàng phân sáng 17/01 | D21: PONU0635711 | E21: Hoa Lư, Ninh Bình | G21: 222 | H21: =G21*14900 -> 3307800 | J21: 680000 | O21: =H21+J21+K21+L21+M21+N21 -> 3987800 | P21: 4000000 | Q21: =P21-O21 -> 12200
A22: 15 | B22: 43483 | C22: Trả hàng + đóng hàng KH 18/01 | D22: TRHU1344890 | E22: Trôi, Hà Nội - Hà Nam | J22: =1320000+60000 -> 1380000 | O22: =H22+J22+K22+L22+M22+N22 -> 1380000 | P22: 5600000 | Q22: =P22-O22 -> 4220000
A23: 16 | B23: 43484 | C23: Trả hàng + đóng hàng KH 19/01 | D23: WHLU2530124 | E23: Sơn Dương, Tuyên Quang - Hà Nam | G23: 216 | H23: =G23*14900 -> 3218400 | J23: 1900000 | O23: =H23+J23+K23+L23+M23+N23 -> 5118400 | P23: 8900000 | Q23: =P23-O23 -> 3781600
A24: 17 | B24: 43486 | C24: Trả hàng + đóng hàng KH 21/01 | D24: WFHU1365229 | E24: Mỹ Hào, Hưng Yên - Hà Nam | G24: 188 | H24: =G24*14900 -> 2801200 | J24: 1170000 | O24: =H24+J24+K24+L24+M24+N24 -> 3971200 | P24: 4900000 | Q24: =P24-O24 -> 928800
A25: 18 | B25: 43487 | C25: Trả hàng + đóng hàng KH 22/01 | D25: DRYU2901720 | E25: Từ Liêm, Hà Nội - Hà Nam | J25: 1320000 | O25: =H25+J25+K25+L25+M25+N25 -> 1320000 | P25: 5500000 | Q25: =P25-O25 -> 4180000
A26: 19 | B26: 43488 | C26: Trả hàng + đóng hàng KH 23/01 | D26: GAOU2114493 | E26: KCN Phong Khê, Bắc Ninh - Hà Nam | G26: 228 | H26: =G26*14900 -> 3397200 | J26: 1500000 | O26: =H26+J26+K26+L26+M26+N26 -> 4897200 | P26: 5580000 | Q26: =P26-O26 -> 682800
A27: 20 | B27: 43489 | C27: Đóng hàng phân sáng 24/01 | D27: TGCU2026678 | E27: Hoa Lư, Ninh Bình | G27: 200 | H27: =G27*14900 -> 2980000 | J27: 790000 | O27: =H27+J27+K27+L27+M27+N27 -> 3770000 | P27: 4000000 | Q27: =P27-O27 -> 230000
A28: 21 | B28: 43490 | C28: Đóng hàng chè sáng 25/01 | D28: FBIU0119873 | E28: Mộc Châu, Sơn La | J28: =2200000+500000 -> 2700000 | O28: =H28+J28+K28+L28+M28+N28 -> 2700000 | P28: 13181818 | Q28: =P28-O28 -> 10481818
A29: 22 | B29: 43491 | C29: Trả hàng + đóng hàng KH 26/01 | D29: GAOU2112844 | E29: Yên Mỹ, Hưng Yên - Hà Nam | G29: 210 | H29: =G29*14900 -> 3129000 | J29: 1170000 | O29: =H29+J29+K29+L29+M29+N29 -> 4299000 | P29: 4900000 | Q29: =P29-O29 -> 601000
A30: 23 | B30: 43493 | C30: Trả hàng + đóng hàng KH 28/01 | D30: KKTU7884415 | E30: Sơn Dương, Tuyên Quang - Việt Trì - HP | G30: 118 | H30: =G30*14900 -> 1758200 | J30: =1900000+80000 -> 1980000 | O30: =H30+J30+K30+L30+M30+N30 -> 3738200 | P30: 8900000 | Q30: =P30-O30 -> 5161800
A31: 24 | B31: 43495 | C31: Trả hàng NK sáng 30/01 | D31: CSNU1541165 | E31: Thường Tín, Hà Nội | G31: 174 | H31: =G31*14900 -> 2592600 | J31: 810000 | O31: =H31+J31+K31+L31+M31+N31 -> 3402600 | P31: 4100000 | Q31: =P31-O31 -> 697400
A32: 25 | B32: 43496 | C32: Trả hàng + đóng hàng KH 31/01 | D32: GAOU2108470 | E32: Yên Mỹ, Hưng Yên - Hà Nam | G32: 180 | H32: =G32*14900 -> 2682000 | J32: 1170000 | O32: =H32+J32+K32+L32+M32+N32 -> 3852000 | P32: 4900000 | Q32: =P32-O32 -> 1048000
C33: Thanh toán tiền sửa xe 15C-070.63 (thay ống cao su, ống đai nước, công thợ) | L33: 360000 | O33: =H33+J33+K33+L33+M33+N33 -> 360000 | Q33: =P33-O33 -> -360000
C34: Thanh toán tiền sửa xe 15C-070.63 (mua giảm sóc tải, cầu trì lái+thay) ngày 6/1 | L34: 1300000 | O34: =H34+J34+K34+L34+M34+N34 -> 1300000 | Q34: =P34-O34 -> -1300000
C35: Thanh toán tiền sửa xe 15C-070.63 ngày 6/1 (rơ le, đế cầu trì, cầu trì, thay pha nhỏ, dây điện, công làm) | L35: 480000 | O35: =H35+J35+K35+L35+M35+N35 -> 480000 | Q35: =P35-O35 -> -480000
C36: Thanh toán tiền thay lốp xe 15C-070.63 ngày 14/1 (lốp 1100R20 goodede T 987) | M36: 11600000 | O36: =H36+J36+K36+L36+M36+N36 -> 11600000 | Q36: =P36-O36 -> -11600000
C37: Thanh toán tiền sửa xe 15C-070.63 (bơm mỡ đầu kéo, mooc, kiểm tra ba ngang+ba dọc) | L37: 170000 | O37: =H37+J37+K37+L37+M37+N37 -> 170000 | Q37: =P37-O37 -> -170000
C38: Trả tiền sửa xe 15C-070.63 (dù gió) | L38: 2000000 | O38: =H38+J38+K38+L38+M38+N38 -> 2000000 | Q38: =P38-O38 -> -2000000
C39: Thưởng tết cho lái xe | K39: 4000000 | O39: =H39+J39+K39+L39+M39+N39 -> 4000000 | Q39: =P39-O39 -> -4000000
C40: Phí gửi xe | L40: =1200000*1.1 -> 1320000 | O40: =H40+J40+K40+L40+M40+N40 -> 1320000 | Q40: =P40-O40 -> -1320000
C41: Lương lái xe | K41: 9692308 | O41: =H41+J41+K41+L41+M41+N41 -> 9692308 | Q41: =P41-O41 -> -9692308
A42: TỔNG CỘNG | G42: =SUM(G7:G41) -> 3225 | H42: =SUM(H7:H41) -> 48052500 | I42: =SUM(I7:I41) -> 0 | J42: =SUM(J7:J41) -> 30960000 | K42: =SUM(K7:K41) -> 13692308 | L42: =SUM(L7:L41) -> 5630000 | M42: =SUM(M7:M41) -> 11600000 | N42: =SUM(N7:N41) -> 0 | ... Q42: =SUM(Q7:Q41) -> 33117919
...

Sheet 2.2019
A1: Bảng theo dõi doanh thu/ chi phí theo phương tiện vận chuyển
A2: Biển số xe: 15C - 070.63
B3: THÁNG 2.2019
A5: STT | B5: Ngày tháng | C5: Diễn giải | D5: Số cont | E5: Tuyến đường vận chuyển | F5: Khoảng cách (km) | G5: Chi phí | O5: Tổng chi phí | P5: Cước vận chuyển | Q5: Lợi nhuận gộp
G6: Dầu (l) | H6: Dầu (đồng) | I6: Mức TTBQ | J6: Đi đường | K6: Lương lx | L6: Sửa chữa | M6: Lốp | N6: Dầu máy
A8: 1 | B8: 43508 | C8: Trả hàng + đóng hàng KH 12/02 | D8: GMDU2152577 | E8: KCN Khai Quang, Vĩnh Phúc - Hà Nam | J8: 1380000 | O8: =H8+J8+K8+L8+M8+N8 -> 1380000 | P8: 6100000 | Q8: =P8-O8 -> 4720000
A9: 2 | B9: 43509 | C9: Đóng hàng phân sáng 13/02 | D9: TCLU3552681 | E9: Hoa Lư, Ninh Bình | J9: 680000 | O9: =H9+J9+K9+L9+M9+N9 -> 680000 | P9: 4000000 | Q9: =P9-O9 -> 3320000
A10: 3 | B10: 43510 | C10: Trả hàng + đóng hàng KH 14/02 | D10: BISU2828368 | E10: Trôi, Hà Nội - Hà Nam | G10: 248 | H10: =G10*14900 -> 3695200 | J10: =1320000-60000 -> 1260000 | O10: =H10+J10+K10+L10+M10+N10 -> 4955200 | P10: 5600000 | Q10: =P10-O10 -> 644800
A11: 4 | B11: 43511 | C11: Trả hàng + đóng hàng KH 15/02 | D11: VNLU3093247 | E11: Trôi, Hà Nội - Hà Nam | G11: 128 | H11: =G11*14900 -> 1907200 | J11: 1320000 | O11: =H11+J11+K11+L11+M11+N11 -> 3227200 | P11: 5600000 | Q11: =P11-O11 -> 2372800
A12: 5 | B12: 43512 | C12: Trả hàng NK sáng 16/02 | D12: MAGU2362111 | E12: Thạch Thất, Hà Nội | J12: 810000 | O12: =H12+J12+K12+L12+M12+N12 -> 810000 | P12: 3900000 | Q12: =P12-O12 -> 3090000
A13: 6 | B13: 43515 | C13: Trả hàng NK sáng 19/02 | D13: DFSU1194115 | E13: Hoài Đức, Hà Nội | G13: 242 | H13: =G13*14900 -> 3605800 | J13: 810000 | O13: =H13+J13+K13+L13+M13+N13 -> 4415800 | P13: 4200000 | Q13: =P13-O13 -> -215800
A14: 7 | B14: 43516 | C14: Trả hàng + đóng hàng KH 20/02 | D14: DRYU2901905 | E14: Đông Anh, Hà Nội - Hà Nam | J14: 1320000 | O14: =H14+J14+K14+L14+M14+N14 -> 1320000 | P14: 5500000 | Q14: =P14-O14 -> 4180000
A15: 8 | B15: 43517 | C15: Đóng hàng chè sáng 21/02 | D15: WHSU2140522 | E15: TT Trần Phú, Văn Chấn, Yên Bái | G15: 222 | H15: =G15*14900 -> 3307800 | J15: 1970000 | O15: =H15+J15+K15+L15+M15+N15 -> 5277800 | P15: 9545455 | Q15: =P15-O15 -> 4267655
A16: 9 | B16: 43518 | C16: Trả hàng + đóng hàng KH 22/02 | D16: GMDU2180100 | E16: Đông Anh, Hà Nội - Hà Nam | G16: 166 | H16: =G16*14900 -> 2473400 | J16: 1320000 | O16: =H16+J16+K16+L16+M16+N16 -> 3793400 | P16: 5500000 | Q16: =P16-O16 -> 1706600
A17: 10 | B17: 43519 | C17: Trả hàng NK sáng 23/02 | D17: MRKU8972790 | E17: Thường Tín, Hà Nội | J17: 810000 | O17: =H17+J17+K17+L17+M17+N17 -> 810000 | P17: 4000000 | Q17: =P17-O17 -> 3190000
A18: 11 | B18: 43521 | C18: Trả hàng + đóng hàng KH 25/02 | D18: GAOU2107025 | E18: Yên Mỹ, Hưng Yên - Hà Nam | G18: 233 | H18: =G18*14900 -> 3471700 | J18: 1170000 | O18: =H18+J18+K18+L18+M18+N18 -> 4641700 | P18: 4900000 | Q18: =P18-O18 -> 258300
A19: 12 | B19: 43522 | C19: Trả hàng + đóng hàng KH 26/02 | D19: GAOU2107920 | E19: Yên Mỹ, Hưng Yên - Hà Nam | J19: 1170000 | O19: =H19+J19+K19+L19+M19+N19 -> 1170000 | P19: 4900000 | Q19: =P19-O19 -> 3730000
A20: 13 | B20: 43523 | C20: Trả hàng NK sáng 27/02 | D20: GLDU9916551 | E20: Thạch Thất, Hà Nội | G20: 210 | H20: =G20*14900 -> 3129000 | J20: 810000 | O20: =H20+J20+K20+L20+M20+N20 -> 3939000 | P20: 3900000 | Q20: =P20-O20 -> -39000
A21: 14 | B21: 43524 | C21: Trả hàng + đóng hàng KH 28/02 | D21: VNLU3092699 | E21: Đông Hương, Thanh Hóa, Hà Nam | G21: 246 | H21: =G21*14900 -> 3665400 | J21: 990000 | O21: =H21+J21+K21+L21+M21+N21 -> 4655400 | P21: 6400000 | Q21: =P21-O21 -> 1744600
C24: Lì xì đầu năm cho lái xe | K24: 100000 | O24: =H24+J24+K24+L24+M24+N24 -> 100000 | Q24: =P24-O24 -> -100000
C25: Phí gửi xe | L25: =1200000*1.1 -> 1320000 | O25: =H25+J25+K25+L25+M25+N25 -> 1320000 | Q25: =P25-O25 -> -1320000
C26: Lương lái xe | K26: 5250000 | O26: =H26+J26+K26+L26+M26+N26 -> 5250000 | Q26: =P26-O26 -> -5250000
A27: TỔNG CỘNG | G27: =SUM(G7:G26) -> 1695 | H27: =SUM(H7:H26) -> 25255500 | I27: =SUM(I7:I26) -> 0 | J27: =SUM(J7:J26) -> 15820000 | K27: =SUM(K7:K26) -> 5350000 | L27: =SUM(L7:L26) -> 1320000 | M27: =SUM(M7:M26) -> 0 | N27: =SUM(N7:N26) -> 0 | O27: =SUM(O7:O26) -> 47745500 | P27: =SUM(P8:P26) -> 74045455 | Q27: =SUM(Q7:Q26) -> 26299955
P29: LK = | Q29: ='1.2019'!Q44+'2.2019'!Q27 -> 59417874

Sheet 3.2019
A1: Bảng theo dõi doanh thu/ chi phí theo phương tiện vận chuyển
A2: Biển số xe: 15C - 070.63
B3: THÁNG 3.2019
A5: STT | B5: Ngày tháng | C5: Diễn giải | D5: Số cont | E5: Tuyến đường vận chuyển | F5: Khoảng cách (km) | G5: Chi phí | O5: Tổng chi phí | P5: Cước vận chuyển | Q5: Lợi nhuận gộp
G6: Dầu (l) | H6: Dầu (đồng) | I6: Mức TTBQ | J6: Đi đường | K6: Lương lx | L6: Sửa chữa | M6: Lốp | N6: Dầu máy
A8: 1 | B8: 43525 | C8: Trả hàng + đóng hàng KH 01/03 | D8: GAOU2111621 | E8: Trôi, Hà Nội - Hà Nam | J8: =1320000+60000 -> 1380000 | O8: =H8+J8+K8+L8+M8+N8 -> 1380000 | P8: 5600000 | Q8: =P8-O8 -> 4220000
A9: 2 | B9: 43526 | C9: Đóng hàng phân sáng 02/03 | D9: EITU0093460 | E9: Hoa Lư, Ninh Bình | J9: 680000 | O9: =H9+J9+K9+L9+M9+N9 -> 680000 | P9: 4000000 | Q9: =P9-O9 -> 3320000
A10: 3 | B10: 43527 | C10: Đóng hàng phân sáng 03/03 | D10: EITU0161035 | E10: Hoa Lư, Ninh Bình | G10: 218 | H10: =G10*15860 -> 3457480 | J10: 680000 | O10: =H10+J10+K10+L10+M10+N10 -> 4137480 | P10: 4000000 | Q10: =P10-O10 -> -137480
A11: 4 | B11: 43528 | C11: Trả hàng + đóng hàng KH 04/03 | D11: GMDU2180239 | E11: Quốc Oai, Hà Nội - Hà Nam | J11: 1320000 | O11: =H11+J11+K11+L11+M11+N11 -> 1320000 | P11: 5600000 | Q11: =P11-O11 -> 4280000
A12: 5 | B12: 43529 | C12: Trả hàng + đóng hàng KH 05/03 | D12: VNLU3090314 | E12: Trôi, Hà Nội - Hà Nam | G12: 230 | H12: =G12*15860 -> 3647800 | J12: =1320000+60000 -> 1380000 | O12: =H12+J12+K12+L12+M12+N12 -> 5027800 | P12: 5600000 | Q12: =P12-O12 -> 572200
A13: 6 | B13: 43530 | C13: Trả hàng NK sáng 06/03 | D13: UETU2475394 | E13: Thường Tín, Hà Nội | J13: 810000 | O13: =H13+J13+K13+L13+M13+N13 -> 810000 | P13: 4100000 | Q13: =P13-O13 -> 3290000
A14: 7 | B14: 43531 | C14: Trả hàng NK chiều 07/03 | D14: TRLU3884879 | E14: Phố Nối A, Hưng Yên | G14: 220 | H14: =G14*15860 -> 3489200 | J14: 680000 | O14: =H14+J14+K14+L14+M14+N14 -> 4169200 | P14: 3100000 | Q14: =P14-O14 -> -1069200
A15: 8 | B15: 43532 | C15: Trả hàng NK sáng 08/03 | D15: DRYU2430600 | E15: Đông Anh, Hà Nội | G15: 168 | H15: =G15*15860 -> 2664480 | J15: 810000 | O15: =H15+J15+K15+L15+M15+N15 -> 3474480 | P15: 3860000 | Q15: =P15-O15 -> 385520
A16: 9 | B16: 43533 | C16: Trả hàng + đóng hàng KH 09/03 | D16: GMDU2183650 | E16: Hà Trung, Thanh Hóa, Hà Nam | J16: 990000 | O16: =H16+J16+K16+L16+M16+N16 -> 990000 | P16: 6400000 | Q16: =P16-O16 -> 5410000
A17: 10 | B17: 43535 | C17: Trả hàng + đóng hàng KH 11/03 | D17: BISU2827572 | E17: Trôi, Hà Nội - Hà Nam | G17: 260 | H17: =G17*15860 -> 4123600 | J17: 1320000 | O17: =H17+J17+K17+L17+M17+N17 -> 5443600 | P17: 5600000 | Q17: =P17-O17 -> 156400
A18: 11 | B18: 43536 | C18: Trả hàng + đóng hàng KH 12/03 | D18: DRYU3023018 | E18: Kim Sơn , Ninh Bình - Hà Nam | J18: 990000 | O18: =H18+J18+K18+L18+M18+N18 -> 990000 | P18: 4454545 | Q18: =P18-O18 -> 3464545
A19: 12 | B19: 43537 | C19: Trả hàng + đóng hàng KH 13/03 | D19: GMDU2185502 | E19: Mỹ Hào, Hưng Yên - Hà Nam | G19: 218 | H19: =G19*15860 -> 3457480 | J19: 1050000 | O19: =H19+J19+K19+L19+M19+N19 -> 4507480 | P19: 4900000 | Q19: =P19-O19 -> 392520
A20: 13 | B20: 43538 | C20: Đóng hàng chè sáng 14/03 | D20: WHSU2424576 | E20: Tân Lập, Mộc Châu, Sơn La | J20: 2230000 | O20: =H20+J20+K20+L20+M20+N20 -> 2230000 | P20: 13181818 | Q20: =P20-O20 -> 10951818
A21: 14 | B21: 43539 | C21: Đóng hàng phân sáng 15/03 | D21: TLLU2045401 | E21: Hoa Lư, Ninh Bình | G21: 218 | H21: =G21*15860 -> 3457480 | J21: 680000 | O21: =H21+J21+K21+L21+M21+N21 -> 4137480 | P21: 4000000 | Q21: =P21-O21 -> -137480
A22: 15 | B22: 43540 | C22: Đóng hàng phân sáng 16/03 | D22: TCLU7695973 | E22: Hoa Lư, Ninh Bình | J22: 680000 | O22: =H22+J22+K22+L22+M22+N22 -> 680000 | P22: 4000000 | Q22: =P22-O22 -> 3320000
A23: 16 | B23: 43542 | C23: Trả hàng + đóng hàng KH 18/03 | D23: BISU2836810 | E23: Trôi, Hà Nội - Hà Nam | G23: 196 | H23: =G23*15860 -> 3108560 | J23: 1380000 | O23: =H23+J23+K23+L23+M23+N23 -> 4488560 | P23: 5600000 | Q23: =P23-O23 -> 1111440
A24: 17 | B24: 43543 | C24: Trả hàng + đóng hàng KH 19/03 | D24: GAOU2115416 | E24: Trôi, Hà Nội - Hà Nam | G24: 128 | H24: =G24*15860 -> 2030080 | J24: 1320000 | O24: =H24+J24+K24+L24+M24+N24 -> 3350080 | P24: 5600000 | Q24: =P24-O24 -> 2249920
A25: 18 | B25: 43544 | C25: Đóng hàng phân sáng 20/03 | D25: IMTU3047179 | E25: Hoa Lư, Ninh Bình | G25: 208 | H25: =G25*15860 -> 3298880 | J25: 680000 | O25: =H25+J25+K25+L25+M25+N25 -> 3978880 | P25: 4000000 | Q25: =P25-O25 -> 21120
A26: 19 | B26: 43545 | C26: Đóng hàng chè sáng 21/03 | D26: WHSU2537079 | E26: Tân Lập, Mộc Châu, Sơn La | J26: 2230000 | O26: =H26+J26+K26+L26+M26+N26 -> 2230000 | P26: 13181818 | Q26: =P26-O26 -> 10951818
A27: 20 | B27: 43546 | C27: Trả hàng NK sáng 22/03 | D27: PONU0603951 | E27: Máy soi Tasa - Thường Tín, Hà Nội | G27: 220 | H27: =G27*15860 -> 3489200 | J27: 810000 | O27: =H27+J27+K27+L27+M27+N27 -> 4299200 | P27: 4100000 | Q27: =P27-O27 -> -199200
A28: 21 | B28: 43549 | C28: Trả hàng + đóng hàng KH 25/03 | D28: GMDU2153629 | E28: Bình Đà, Thanh Oai, Hà Nội - Hà Nam | J28: 1320000 | O28: =H28+J28+K28+L28+M28+N28 -> 1320000 | P28: 5600000 | Q28: =P28-O28 -> 4280000
A29: 22 | B29: 43550 | C29: Đóng hàng phân sáng 26/03 | D29: TTNU1288121 | E29: Hoa Lư, Ninh Bình | G29: 236 | H29: =G29*15860 -> 3742960 | J29: 680000 | O29: =H29+J29+K29+L29+M29+N29 -> 4422960 | P29: 4000000 | Q29: =P29-O29 -> -422960
A30: 23 | B30: 43551 | C30: Đóng hàng phân sáng 27/03 | D30: TCLU2206684 | E30: Hoa Lư, Ninh Bình | J30: 680000 | O30: =H30+J30+K30+L30+M30+N30 -> 680000 | P30: 4000000 | Q30: =P30-O30 -> 3320000
A31: 24 | B31: 43552 | C31: Đóng hàng chè sáng 28/03 | D31: WHSU2579388 | E31: Tân Lập, Mộc Châu, Sơn La | G31: 175 | H31: =G31*15860 -> 2775500 | J31: =2230000+380000 -> 2610000 | O31: =H31+J31+K31+L31+M31+N31 -> 5385500 | P31: 13181818 | Q31: =P31-O31 -> 7796318
A32: 25 | B32: 43554 | C32: Trả hàng NK sáng 30/03 | D32: HLBU1388600 | E32: NM Giấy An Hòa, Sơn Dương, Tuyên Quang | G32: 212 | H32: =G32*15860 -> 3362320 | J32: 1720000 | O32: =H32+J32+K32+L32+M32+N32 -> 5082320 | P32: 6900000 | Q32: =P32-O32 -> 1817680
G33: 168 | H33: =G33*15860 -> 2664480 | O33: =H33+J33+K33+L33+M33+N33 -> 2664480 | Q33: =P33-O33 -> -2664480
O34: =H34+J34+K34+L34+M34+N34 -> 0 | Q34: =P34-O34 -> 0
C35: Phí sử dụng đường bộ xe 15C-070.63 | K35: 8580000 | O35: =H35+J35+K35+L35+M35+N35 -> 8580000 | Q35: =P35-O35 -> -8580000
C36: Phí kiểm định xe 15C-070.63 | K36: 610000 | O36: =H36+J36+K36+L36+M36+N36 -> 610000 | Q36: =P36-O36 -> -610000
C37: Bồi dưỡng đăng kiểm xe 15C-070.63 | K37: 400000 | O37: =H37+J37+K37+L37+M37+N37 -> 400000 | Q37: =P37-O37 -> -400000
C38: Thanh toán tiền lọc nhớt detroit xe 15C-070.63 | K38: 400000 | O38: =H38+J38+K38+L38+M38+N38 -> 400000 | Q38: =P38-O38 -> -400000
C39: Thanh toán tiền lọc thả xe 15C-070.63 | K39: 130000 | O39: =H39+J39+K39+L39+M39+N39 -> 130000 | Q39: =P39-O39 -> -130000
C40: Thanh toán tiền dầu rubia tir | N40: =11700000/4 -> 2925000 | O40: =H40+J40+K40+L40+M40+N40 -> 2925000 | Q40: =P40-O40 -> -2925000
C41: Thanh toán tiền sửa xe 15C-070.63 (tán má phanh cầu sau, mua lò xo má phanh, công thợ) | K41: 370000 | O41: =H41+J41+K41+L41+M41+N41 -> 370000 | Q41: =P41-O41 -> -370000
C42: Anh Phụng đi cứu hộ xe+mua dây curoa xe 15C-070.63 | K42: 750000 | O42: =H42+J42+K42+L42+M42+N42 -> 750000 | Q42: =P42-O42 -> -750000
...

Sheet 4.2019
A1: Bảng theo dõi doanh thu/ chi phí theo phương tiện vận chuyển
A2: Biển số xe: 15C - 070.63
B3: THÁNG 4.2019
A5: STT | B5: Ngày tháng | C5: Diễn giải | D5: Số cont | E5: Tuyến đường vận chuyển | F5: Khoảng cách (km) | G5: Chi phí | O5: Tổng chi phí | P5: Cước vận chuyển | Q5: Lợi nhuận gộp
G6: Dầu (l) | H6: Dầu (đồng) | I6: Mức TTBQ | J6: Đi đường | K6: Lương lx | L6: Sửa chữa | M6: Lốp | N6: Dầu máy
A8: 1 | B8: 43556 | C8: Trả hàng + đóng hàng KH 01/04 | D8: HJMU2154245 | E8: Khai Quang, Vĩnh Phúc - Hà Nam | J8: =1440000-120000 -> 1320000 | O8: =H8+J8+K8+L8+M8+N8 -> 1320000 | P8: 6100000 | Q8: =P8-O8 -> 4780000
