Workbook

Sheet CHI PHI BAN DAU
A1: Bảng tổng hợp chi phí xe 15C-180.99
A3: STT | B3: Nội dung | C3: Thành tiền
A4: 1 | B4: Chi phí mua đầu kéo | C4: 740000000
A5: 2 | B5: Định giá rơ mooc 15R-050.37 | C5: 140000000
B6: Tổng cộng | C6: =SUM(C4:C5) -> 880000000
B8: Định giá xe cũ 15C-119.57 | C8: 650000000 | D8: Tỷ lệ
B9: Tiền góp của Mr. Thưởng (không bao gồm phần vốn lưu động) 40.01% | C9: =C8*40.01% -> 2.60065e+08 | D9: =C9/C8 -> 0.4001
B10: Tiền góp của Mr. Phụng (không bao gồm phần vốn lưu động) 59.99% | C10: =C8*59.99% -> 389935000 | D10: =C10/C8 -> 0.5999
B12: Định giá xe mới 15C-180.99 | C12: =C6 -> 880000000 | D12: Tỷ lệ
B13: Tiền góp của Mr. Thưởng | C13: =C9 -> 2.60065e+08 | D13: =C13/C12 -> 0.29552841
B14: Tiền góp của Mr. Phụng | C14: =C12-C13 -> 619935000 | D14: =C14/C12 -> 0.70447159

Sheet 03.2022
A1: Bảng theo dõi doanh thu/ chi phí theo phương tiện vận chuyển
A2: Biển số xe: 15C - 180.99
A3: THÁNG 03.2022
A5: STT | B5: Ngày tháng | C5: Diễn giải | D5: Số cont | E5: Tuyến đường vận chuyển | F5: Khoảng cách (km) | G5: Chi phí | I5: Mức TTBQ | J5: Đi đường | K5: Lương lx | L5: Sửa chữa | M5: Lốp | N5: Dầu máy | O5: Tổng chi phí | P5: Cước vận chuyển | Q5: Lợi nhuận gộp
G6: Dầu (l) | H6: Dầu (đồng)
A8: 1 | B8: 44641 | C8: Đóng hàng XK sáng 21/03 | D8: FSCU5973084 | E8: Bãi 1 Lê Thánh Tông, Hải Phòng | G8: 19 | H8: =G8*23630 -> 448970 | J8: 300000 | O8: =H8+J8+K8+L8+M8+N8 -> 748970 | P8: 2000000 | Q8: =P8-O8 -> 1251030
A9: 2 | B9: 44641 | C9: Đóng hàng XK chiều 21/03 | D9: AXIU6139031 | E9: Bãi 1 Lê Thánh Tông, Hải Phòng | H9: =G9*23630 -> 0 | J9: 300000 | O9: =H9+J9+K9+L9+M9+N9 -> 300000 | P9: 2000000 | Q9: =P9-O9 -> 1700000
A10: 3 | B10: 44641 | C10: Đóng hàng XK sáng 22/03 | D10: GESU9183653 | E10: Bãi 1 Lê Thánh Tông, Hải Phòng | G10: 15 | H10: =G10*23630 -> 354450 | J10: 300000 | O10: =H10+J10+K10+L10+M10+N10 -> 654450 | P10: 2000000 | Q10: =P10-O10 -> 1345550
A11: 4 | B11: 44641 | C11: Đóng hàng XK sáng 22/03 | D11: GESU9268869 | E11: Bãi 1 Lê Thánh Tông, Hải Phòng | G11: 4 | H11: =G11*23630 -> 94520 | J11: 300000 | O11: =H11+J11+K11+L11+M11+N11 -> 394520 | P11: 2000000 | Q11: =P11-O11 -> 1605480
A12: 5 | B12: 44644 | C12: Đóng hàng chè sáng 24/03 | D12: SEGU5815582 | E12: TT. Phong Hải, Bảo Thắng, Lào Cai | G12: 280 | H12: =G12*23630 -> 6616400 | J12: 4200000 | O12: =H12+J12+K12+L12+M12+N12 -> 10816400 | P12: 15650000 | Q12: =P12-O12 -> 4833600
A13: 6 | B13: 44644 | C13: Đóng hàng chè chiều 25/03 | D13: CAXU9055369 | E13: Bình Xuyên, Vĩnh Phúc | G13: 111 | H13: =G13*23630 -> 2622930 | J13: 1150000 | O13: =H13+J13+K13+L13+M13+N13 -> 3772930 | P13: 5650000 | Q13: =P13-O13 -> 1877070
A14: 7 | B14: 44645 | C14: Đóng hàng chè chiều 26/03 | D14: BMOU5757339 | E14: Cty chè Thành Đạt, Thanh Chương, Nghệ An | G14: 264 | H14: =G14*23630 -> 6238320 | J14: 1720000 | O14: =H14+J14+K14+L14+M14+N14 -> 7958320 | P14: 10650000 | Q14: =P14-O14 -> 2691680
A15: 8 | B15: 44648 | C15: Trả hàng NK sáng 28/03 | D15: SEGU4775818 | E15: Đình Bảng, Bắc Ninh | G15: 164 | H15: =G15*23630 -> 3875320 | J15: 1990000 | O15: =H15+J15+K15+L15+M15+N15 -> 5865320 | P15: 4600000 | Q15: =P15-O15 -> -1265320
A16: 9 | B16: 44648 | C16: Đóng hàng KH chiều 28/03 | D16: SEGU4775818 | E16: KCN Mông Hóa, Kỳ Sơn, Hòa Bình | H16: =G16*23630 -> 0 | J16: 0 | O16: =H16+J16+K16+L16+M16+N16 -> 0 | P16: 3800000 | Q16: =P16-O16 -> 3800000
A17: 10 | B17: 44648 | C17: Đóng hàng XK 29/03 | D17: SEGU9515454 | E17: Bãi 1 Lê Thánh Tông, Hải Phòng | G17: 10 | H17: =G17*23630 -> 236300 | J17: 300000 | O17: =H17+J17+K17+L17+M17+N17 -> 536300 | P17: 2000000 | Q17: =P17-O17 -> 1463700
A18: 11 | B18: 44649 | C18: Đóng hàng XK 30/03 | D18: SZLU9520752 | E18: Bãi 1 Lê Thánh Tông, Hải Phòng | G18: 17 | H18: =G18*23630 -> 401710 | J18: 300000 | O18: =H18+J18+K18+L18+M18+N18 -> 701710 | P18: 2200000 | Q18: =P18-O18 -> 1498290
A19: 12 | B19: 44649 | C19: Đóng hàng XK 30/03 | D19: TLLU1132219 | E19: Bãi 1 Lê Thánh Tông, Hải Phòng | H19: =G19*23630 -> 0 | J19: 300000 | O19: =H19+J19+K19+L19+M19+N19 -> 300000 | P19: 2200000 | Q19: =P19-O19 -> 1900000
A20: 13 | B20: 44650 | C20: Đóng hàng chè sáng 31/03 | D20: GCXU5357098 | E20: Thuận Châu, Sơn La | G20: 340 | H20: =G20*25080 -> 8527200 | J20: 3820000 | O20: =H20+J20+K20+L20+M20+N20 -> 12347200 | P20: 20032407 | Q20: =P20-O20 -> 7685207
Q21: =P21-O21 -> 0
C22: Nộp lệ phí trước bạ xe 15C-180.99 | L22: 9900000 | O22: =H22+J22+K22+L22+M22+N22 -> 9900000 | Q22: =P22-O22 -> -9900000
C23: Phí dịch vụ nộp lệ phí trước bạ xe 15C-180.99 | L23: 150000 | O23: =H23+J23+K23+L23+M23+N23 -> 150000 | Q23: =P23-O23 -> -150000
C24: Thanh toán tiền làm phù hiệu xe 15C-180.99 | L24: 300000 | O24: =H24+J24+K24+L24+M24+N24 -> 300000 | Q24: =P24-O24 -> -300000
C25: Thanh toán tiền mua dầu nhớt | N25: 2900000 | O25: =H25+J25+K25+L25+M25+N25 -> 2900000 | Q25: =P25-O25 -> -2900000
C26: Mua 2 chụp cốc lọc nhớt, cốc lọc ly tâm xe 15C-180.99 | L26: 2500000 | O26: =H26+J26+K26+L26+M26+N26 -> 2500000 | Q26: =P26-O26 -> -2500000
C27: Thanh toán mua đôi đèn vàng led, công đấu chuyển xe 15C-180.99 | L27: 800000 | O27: =H27+J27+K27+L27+M27+N27 -> 800000 | Q27: =P27-O27 -> -800000
C28: Mua cờ lê, kìm điện, mỏ lết, hoa thị, súng dây, zắc co xe 15C-180.99 | L28: 740000 | O28: =H28+J28+K28+L28+M28+N28 -> 740000 | Q28: =P28-O28 -> -740000
C29: Mua đèn hậu, 2 bóng pha, 1 rắc pha, chế công tắc xe 15C-180.99 | L29: 580000 | O29: =H29+J29+K29+L29+M29+N29 -> 580000 | Q29: =P29-O29 -> -580000
C30: Thanh toán tiền sửa tổng phanh chân, nhổ 2ốc gãy, thay 1 phớt, công thợ xe 15C-180.99 ngày 23/3 | L30: 550000 | O30: =H30+J30+K30+L30+M30+N30 -> 550000 | Q30: =P30-O30 -> -550000
C31: Lắp 1 bộ cút đồng phi 16-20, 1 cút đồng ống phi 6, 1 quả lóc kê mới, 1 bát phanh xe 15C-180.99 ngày 27/3 | L31: 1050000 | O31: =H31+J31+K31+L31+M31+N31 -> 1050000 | Q31: =P31-O31 -> -1050000
C32: Dán decal xe 15C-180.99 + biển phụ inox rơ mooc | L32: 1200000 | O32: =H32+J32+K32+L32+M32+N32 -> 1200000 | Q32: =P32-O32 -> -1200000
C33: Thanh toán tiền mua lốp 1100R20 xe 15C-180.99 ngày 1/4 | M33: 11540000 | O33: =H33+J33+K33+L33+M33+N33 -> 11540000 | Q33: =P33-O33 -> -11540000
C34: mua khóa bình dầu 15C-180.99 | L34: 250000 | O34: =H34+J34+K34+L34+M34+N34 -> 250000 | Q34: =P34-O34 -> -250000
C35: Thanh toán tiền tháo vè xe 15C-180.99 (lắp cảm biến dầu) | L35: 150000 | O35: =H35+J35+K35+L35+M35+N35 -> 150000 | Q35: =P35-O35 -> -150000
C36: Thanh toán tiền điện bãi xe lấp cảm biến dầu xe 15C-180.99 | L36: 50000 | O36: =H36+J36+K36+L36+M36+N36 -> 50000 | Q36: =P36-O36 -> -50000
C37: Thanh toán mua nắp may ơ, đóng bạc tay giằng 4 đầu, giảm sóc 2 đầu, công tháo xe 15C-180.99 | L37: 1230000 | O37: =H37+J37+K37+L37+M37+N37 -> 1230000 | Q37: =P37-O37 -> -1230000
C38: Thanh toán tiền đổ bổ sung dầu cầu xe 15C-180.99 ngày 23/3 | L38: 475000 | O38: =H38+J38+K38+L38+M38+N38 -> 475000 | Q38: =P38-O38 -> -475000
C39: Thanh toán tiền làm chân moóc thay bi , xiết lắp quang nhíp moóc xe 15C-180.99 ngày 4/4 | L39: 1300000 | O39: =H39+J39+K39+L39+M39+N39 -> 1300000 | Q39: =P39-O39 -> -1300000
C40: Mua kìm cắt chì cộng lực cho xe 15C-180.99 | L40: 300000 | O40: =H40+J40+K40+L40+M40+N40 -> 300000 | Q40: =P40-O40 -> -300000
C41: Thanh toán tiền thay van la răng xe 15C-180.99 ngày 6/5 | L41: 200000 | O41: =H41+J41+K41+L41+M41+N41 -> 200000 | Q41: =P41-O41 -> -200000
C42: Thanh toán tiền sửa tổng phanh chia hơi xuống moóc, thay 1 bộ phớt, chế cút đồng ép táo pi 10, 16, 20 xe 15C-180.99 ngày 4/4" | L42: 950000 | O42: =H42+J42+K42+L42+M42+N42 -> 950000 | Q42: =P42-O42 -> -950000
...

Sheet 04.2022
A1: Bảng theo dõi doanh thu/ chi phí theo phương tiện vận chuyển
A2: Biển số xe: 15C - 180.99
A3: THÁNG 04.2022
A5: STT | B5: Ngày tháng | C5: Diễn giải | D5: Số cont | E5: Tuyến đường vận chuyển | F5: Khoảng cách (km) | G5: Chi phí | I5: Mức TTBQ | J5: Đi đường | K5: Lương lx | L5: Sửa chữa | M5: Lốp | N5: Dầu máy | O5: Tổng chi phí | P5: Cước vận chuyển | Q5: Lợi nhuận gộp
G6: Dầu (l) | H6: Dầu (đồng)
A8: 1 | B8: 44652 | C8: Đóng hàng XK 02/04 | D8: SZLU6002852 | E8: Bãi 1 Lê Thánh Tông, Hải Phòng | G8: 17 | H8: =G8*25080 -> 426360 | J8: 300000 | O8: =H8+J8+K8+L8+M8+N8 -> 726360 | P8: 2000000 | Q8: =P8-O8 -> 1273640
A9: 2 | B9: 44652 | C9: Đóng hàng XK 02/04 | D9: SZLU6000757 | E9: Bãi 1 Lê Thánh Tông, Hải Phòng | H9: =G9*25080 -> 0 | J9: 300000 | O9: =H9+J9+K9+L9+M9+N9 -> 300000 | P9: 2000000 | Q9: =P9-O9 -> 1700000
A10: 3 | B10: 44655 | C10: Trả hàng NK sáng 05/04 | D10: TRHU5021978 | E10: KCN Vân Trung, Việt Yên, Bắc Giang | G10: 87 | H10: =G10*25080 -> 2181960 | J10: 1150000 | O10: =H10+J10+K10+L10+M10+N10 -> 3331960 | P10: 4600000 | Q10: =P10-O10 -> 1268040
A11: 4 | B11: 44656 | C11: Trả hàng Vietsun sáng 06/04 | D11: DRYU9592428 | E11: KCN Tiên Sơn, Bắc Ninh | G11: 79 | H11: =G11*25080 -> 1981320 | J11: 1150000 | O11: =H11+J11+K11+L11+M11+N11 -> 3131320 | P11: 4907778 | Q11: =P11-O11 -> 1776458
A12: 5 | B12: 44658 | C12: Đóng hàng XK 07/04 | D12: BMOU9319285 | E12: Bãi 1 Lê Thánh Tông, Hải Phòng | G12: 17 | H12: =G12*25080 -> 426360 | J12: 300000 | O12: =H12+J12+K12+L12+M12+N12 -> 726360 | P12: 2000000 | Q12: =P12-O12 -> 1273640
A13: 6 | B13: 44658 | C13: Đóng hàng XK 07/04 | D13: FSCU5870595 | E13: Bãi 1 Lê Thánh Tông, Hải Phòng | H13: =G13*25080 -> 0 | J13: 300000 | O13: =H13+J13+K13+L13+M13+N13 -> 300000 | P13: 2000000 | Q13: =P13-O13 -> 1700000
A14: 7 | B14: 44658 | C14: Đóng hàng XK sáng 08/04 | D14: OTPU6142507 | E14: Bãi 1 Lê Thánh Tông, Hải Phòng | G14: 65 | H14: =G14*24380 -> 1584700 | J14: 300000 | O14: =H14+J14+K14+L14+M14+N14 -> 1884700 | P14: 2000000 | Q14: =P14-O14 -> 115300
A15: 8 | B15: 44658 | C15: Trả hàng Vietsun chiều 08/04 | D15: GAOU6143740 | E15: Kho Masan Dị Sử, Hưng Yên | H15: =G15*24380 -> 0 | J15: 790000 | O15: =H15+J15+K15+L15+M15+N15 -> 790000 | P15: 3260000 | Q15: =P15-O15 -> 2470000
A16: 9 | B16: 44659 | C16: Trả hàng NK sáng 09/04 | D16: AXEU6005758 | E16: KCN Vân Trung, Việt Yên, Bắc Giang | G16: 84 | H16: =G16*24380 -> 2047920 | J16: 1150000 | O16: =H16+J16+K16+L16+M16+N16 -> 3197920 | P16: 4600000 | Q16: =P16-O16 -> 1402080
A17: 10 | B17: 44663 | C17: Trả hàng Vietsun sáng 12/04 | D17: GAOU6143165 | E17: Văn Môn, Yên Phong, Bắc Ninh | G17: 99 | H17: =G17*24380 -> 2413620 | J17: 1150000 | O17: =H17+J17+K17+L17+M17+N17 -> 3563620 | P17: 4517778 | Q17: =P17-O17 -> 954158
A18: 11 | B18: 44663 | C18: Đóng hàng KH 12/04 trả 13/04 | D18: GAOU6143165 | E18: Cẩm Giàng, Hải Dương | J18: 600000 | O18: =H18+J18+K18+L18+M18+N18 -> 600000 | P18: 3000000 | Q18: =P18-O18 -> 2400000
A19: 12 | B19: 44664 | C19: Trả hàng NK sáng 14/04 | D19: SMCU1176464 | E19: Lai Cách, Hải Dương | G19: 50 | H19: =G19*24380 -> 1219000 | J19: 700000 | O19: =H19+J19+K19+L19+M19+N19 -> 1919000 | P19: 3200000 | Q19: =P19-O19 -> 1281000
A20: 13 | B20: 44665 | C20: Trả hàng NK sáng 15/04 | D20: ZCSU6729113 | E20: KCN Tây Bắc Ga, Thanh Hóa | G20: 148 | H20: =G20*24380 -> 3608240 | J20: 1000000 | O20: =H20+J20+K20+L20+M20+N20 -> 4608240 | P20: 7000000 | Q20: =P20-O20 -> 2391760
A21: 14 | B21: 44667 | C21: Trả hàng NK sáng 16/04 | D21: ZSCU7536058 | E21: Từ Sơn, Bắc Ninh | G21: 92 | H21: =G21*24380 -> 2242960 | J21: 1150000 | O21: =H21+J21+K21+L21+M21+N21 -> 3392960 | P21: 4800000 | Q21: =P21-O21 -> 1407040
A22: 15 | B22: 44670 | C22: Đóng hàng XK sáng 19/04 | D22: RXTU4508830 | E22: Như Quỳnh, Văn Lâm, Hưng Yên | G22: 70 | H22: =G22*24380 -> 1706600 | J22: 1150000 | O22: =H22+J22+K22+L22+M22+N22 -> 2856600 | P22: 4000000 | Q22: =P22-O22 -> 1143400
A23: 16 | B23: 44670 | C23: Đóng hàng chè sáng 20/04 | D23: TRHU6590407 | E23: Bình Xuyên, Vĩnh Phúc | G23: 113 | H23: =G23*25350 -> 2864550 | J23: 1150000 | O23: =H23+J23+K23+L23+M23+N23 -> 4014550 | P23: 5750000 | Q23: =P23-O23 -> 1735450
A24: 17 | B24: 44671 | C24: Đóng hàng chè sáng 21/04 | D24: BEAU5895729 | E24: Tân Lập, Mộc Châu, Sơn La | G24: 253 | H24: =G24*25350 -> 6413550 | J24: 2740000 | O24: =H24+J24+K24+L24+M24+N24 -> 9153550 | P24: 14636364 | Q24: =P24-O24 -> 5482814
A25: 18 | B25: 44673 | C25: Đóng hàng XK sáng 22/04 | D25: KMTU9323018 | E25: Phong Khê, Bắc Ninh | G25: 79 | H25: =G25*25350 -> 2002650 | J25: 1150000 | O25: =H25+J25+K25+L25+M25+N25 -> 3152650 | P25: 4700000 | Q25: =P25-O25 -> 1547350
A26: 19 | B26: 44673 | C26: Trả hàng NK sáng 23/04 | D26: TCNU8846860 | E26: Ngũ Hiệp, Thanh Trì, Hà Nội | G26: 124 | H26: =G26*25350 -> 3143400 | J26: 1150000 | O26: =H26+J26+K26+L26+M26+N26 -> 4293400 | P26: 6200000 | Q26: =P26-O26 -> 1906600
A27: 20 | B27: 44674 | C27: Đóng hàng KH chiều 23/04 | D27: TCNU8846860 | E27: Phúc Yên, Vĩnh Phúc | H27: =G27*25350 -> 0 | J27: 380000 | O27: =H27+J27+K27+L27+M27+N27 -> 380000 | P27: 0 | Q27: =P27-O27 -> -380000
A28: 21 | B28: 44676 | C28: Trả hàng Vietsun sáng 25/04 | D28: TCNU6672862 | E28: KCN Quế Võ, Bắc Ninh | G28: 72 | H28: =G28*25350 -> 1825200 | J28: 1150000 | O28: =H28+J28+K28+L28+M28+N28 -> 2975200 | P28: 4420000 | Q28: =P28-O28 -> 1444800
A29: 22 | B29: 44676 | C29: Trả hàng NK sáng 26/04 | D29: APZU4839050 | E29: KCN VSIP Bắc Ninh | G29: 86 | H29: =G29*25350 -> 2180100 | J29: 1150000 | O29: =H29+J29+K29+L29+M29+N29 -> 3330100 | P29: 4600000 | Q29: =P29-O29 -> 1269900
A30: 23 | B30: 44678 | C30: Trả hàng NK sáng 27/04 | D30: BMOU6854591 | E30: Yên Mỹ, Hưng Yên | G30: 66 | H30: =G30*25350 -> 1673100 | J30: 790000 | O30: =H30+J30+K30+L30+M30+N30 -> 2463100 | P30: 3500000 | Q30: =P30-O30 -> 1036900
A31: 24 | B31: 44678 | C31: Đóng hàng chè sáng 28/04 | D31: DFSU3050673 | E31: Tân Lập, Mộc Châu, Sơn La | G31: 258 | H31: =G31*25350 -> 6540300 | J31: 2740000 | O31: =H31+J31+K31+L31+M31+N31 -> 9280300 | P31: 8842593 | Q31: =P31-O31 -> -437707
A32: 25 | B32: 44678 | C32: Đóng hàng chè sáng 28/04 | D32: WHSU2383013 | E32: Tân Lập, Mộc Châu, Sơn La | H32: =G32*25350 -> 0 | J32: 300000 | O32: =H32+J32+K32+L32+M32+N32 -> 300000 | P32: 8842593 | Q32: =P32-O32 -> 8542593
A33: 26 | B33: 44679 | C33: Trả hàng Vietsun sáng 29/04 | D33: TCNU4595767 | E33: Bỉm Sơn, Thanh Hóa + KCN Nam Xá, TP. Nam Định | G33: 126 | H33: =G33*25350 -> 3194100 | J33: 1200000 | O33: =H33+J33+K33+L33+M33+N33 -> 4394100 | P33: 7676296 | Q33: =P33-O33 -> 3282196
O34: =H34+J34+K34+L34+M34+N34 -> 0
C35: Lương lx | K35: 8000000 | O35: =H35+J35+K35+L35+M35+N35 -> 8000000
C36: Phí gửi xe | L36: 1200000 | O36: =H36+J36+K36+L36+M36+N36 -> 1200000
A37: TỔNG CỘNG | G37: =SUM(G8:G36) -> 1985 | H37: =SUM(H7:H36) -> 49675990 | I37: =SUM(I7:I36) -> 0 | J37: =SUM(J7:J36) -> 25390000 | K37: =SUM(K7:K36) -> 8000000 | L37: =SUM(L7:L36) -> 1200000 | M37: =SUM(M7:M36) -> 0 | N37: =SUM(N7:N36) -> 0 | O37: =SUM(O8:O36) -> 84265990 | P37: =SUM(P8:P36) -> 123053402 | Q37: =P37-O37 -> 38787412
P39: LK = | Q39: ='03.2022'!Q50+'04.2022'!Q37 -> 20982161

Sheet 05.2022
A1: Bảng theo dõi doanh thu/ chi phí theo phương tiện vận chuyển
A2: Biển số xe: 15C - 180.99
A3: THÁNG 05.2022
A5: STT | B5: Ngày tháng | C5: Diễn giải | D5: Số cont | E5: Tuyến đường vận chuyển | F5: Khoảng cách (km) | G5: Chi phí | I5: Mức TTBQ | J5: Đi đường | K5: Lương lx | L5: Sửa chữa | M5: Lốp | N5: Dầu máy | O5: Tổng chi phí | P5: Cước vận chuyển | Q5: Lợi nhuận gộp
G6: Dầu (l) | H6: Dầu (đồng)
A8: 1 | B8: 44684 | C8: Trả hàng Vietsun sáng 04/05 | D8: DRYU9592921 | E8: Kho DHL - Samsung, KCN VSIP Bắc Ninh | G8: 80 | H8: =G8*25530 -> 2042400 | J8: 1150000 | O8: =H8+J8+K8+L8+M8+N8 -> 3192400 | P8: 4517778 | Q8: =P8-O8 -> 1325378
A9: 2 | B9: 44685 | C9: Trả hàng NK sáng 05/05 | D9: FCIU7233940 | E9: Hải Bối, Đông Anh, Hà Nội | G9: 87 | H9: =G9*25530 -> 2221110 | J9: 1150000 | O9: =H9+J9+K9+L9+M9+N9 -> 3371110 | P9: 4700000 | Q9: =P9-O9 -> 1328890
A10: 3 | B10: 44686 | C10: Trả hàng NK sáng 06/05 | D10: CAIU4415516 | E10: Trưng Trắc, Văn Lâm, Hưng Yên | G10: 71 | H10: =G10*25530 -> 1812630 | J10: 790000 | O10: =H10+J10+K10+L10+M10+N10 -> 2602630 | P10: 3700000 | Q10: =P10-O10 -> 1097370
A11: 4 | B11: 44688 | C11: Trả hàng NK sáng 07/05 | D11: HLXU5342380 | E11: Nguyên Khê, Đông Anh, Hà Nội | G11: 91 | H11: =G11*25530 -> 2323230 | J11: 1150000 | O11: =H11+J11+K11+L11+M11+N11 -> 3473230 | P11: 4700000 | Q11: =P11-O11 -> 1226770
A12: 5 | B12: 44690 | C12: Trả hàng NK sáng 09/05 | D12: JXLU7840570 | E12: KCN Tiên Sơn, Bắc Ninh | G12: 93 | H12: =G12*25530 -> 2374290 | J12: 1150000 | O12: =H12+J12+K12+L12+M12+N12 -> 3524290 | P12: 4800000 | Q12: =P12-O12 -> 1275710
A13: 6 | B13: 44690 | C13: Trả hàng NK sáng 10/05 | D13: ZCSU7195861 | E13: KCN Tây Bắc Ga, Thanh Hóa | G13: 149 | H13: =G13*25530 -> 3803970 | J13: 1000000 | O13: =H13+J13+K13+L13+M13+N13 -> 4803970 | P13: 6900000 | Q13: =P13-O13 -> 2096030
A14: 7 | B14: 44691 | C14: Trả hàng NK sáng 11/05 | D14: ZCSU7562680 | E14: KCN Tây Bắc Ga, Thanh Hóa | G14: 149 | H14: =G14*26650 -> 3970850 | J14: 1000000 | O14: =H14+J14+K14+L14+M14+N14 -> 4970850 | P14: 6900000 | Q14: =P14-O14 -> 1929150
A15: 8 | B15: 44692 | C15: Đóng hàng chè sáng 12/05 | D15: SEGU5303930 | E15: Bình Xuyên, Vĩnh Phúc | G15: 111 | H15: =G15*26650 -> 2958150 | J15: 1150000 | O15: =H15+J15+K15+L15+M15+N15 -> 4108150 | P15: 5850000 | Q15: =P15-O15 -> 1741850
A16: 9 | B16: 44693 | C16: Trả hàng NK sáng 13/05 | D16: BMOU5229497 | E16: Sài Đồng, Long Biên, Hà Nội | G16: 76 | H16: =G16*26650 -> 2025400 | J16: 1150000 | O16: =H16+J16+K16+L16+M16+N16 -> 3175400 | P16: 4400000 | Q16: =P16-O16 -> 1224600
A17: 10 | B17: 44695 | C17: Trả hàng NK đêm 13/05 | D17: TGBU4844849 | E17: cầu Thanh Trì, Hà Nội | G17: 80 | H17: =G17*26650 -> 2132000 | J17: 1150000 | O17: =H17+J17+K17+L17+M17+N17 -> 3282000 | P17: 4600000 | Q17: =P17-O17 -> 1318000
A18: 11 | B18: 44698 | C18: Trả hàng NK chiều 17/05 | D18: SUDU7756642 | E18: Nam Sách, Hải Dương | G18: 51 | H18: =G18*26650 -> 1359150 | J18: 700000 | O18: =H18+J18+K18+L18+M18+N18 -> 2059150 | P18: 3300000 | Q18: =P18-O18 -> 1240850
A19: 12 | B19: 44698 | C19: Trả hàng NK sáng 18/05 | D19: TGBU2068509 | E19: KCN Phú Nghĩa, Chương Mỹ, Hà Nội | G19: 102 | H19: =G19*26650 -> 2718300 | J19: 1150000 | O19: =H19+J19+K19+L19+M19+N19 -> 3868300 | P19: 4700000 | Q19: =P19-O19 -> 831700
A20: 13 | B20: 44700 | C20: Đóng hàng chè sáng 19/05 | D20: TGBU4911931 | E20: Mỹ Bằng, Yên Sơn, Tuyên Quang | G20: 180 | H20: =G20*26650 -> 4797000 | J20: 1890000 | O20: =H20+J20+K20+L20+M20+N20 -> 6687000 | P20: 9716667 | Q20: =P20-O20 -> 3029667
A21: 14 | B21: 44700 | C21: Đóng hàng chè sáng 20/05 | D21: TGCU5032801 | E21: Bình Xuyên, Vĩnh Phúc | G21: 111 | H21: =G21*26650 -> 2958150 | J21: 1150000 | O21: =H21+J21+K21+L21+M21+N21 -> 4108150 | P21: 5980000 | Q21: =P21-O21 -> 1871850
A22: 15 | B22: 44701 | C22: Trả hàng NK sáng 21/05 | D22: TCNU5577557 | E22: Ngọc Long, Yên Mỹ, Hưng Yên | G22: 83 | H22: =G22*26650 -> 2211950 | J22: 790000 | O22: =H22+J22+K22+L22+M22+N22 -> 3001950 | P22: 3800000 | Q22: =P22-O22 -> 798050
A23: 16 | B23: 44704 | C23: Trả hàng Vietsun sáng 23/05 | D23: DRYU6672270 | E23: KCN Quang Minh 2, Mê Linh, Hà Nội | G23: 98 | H23: =G23*25550 -> 2503900 | J23: 1150000 | O23: =H23+J23+K23+L23+M23+N23 -> 3653900 | P23: 4180000 | Q23: =P23-O23 -> 526100
A24: 17 | B24: 44704 | C24: Đóng hàng chè sáng 24/05 | D24: TCNU4070104 | E24: Bình Xuyên, Vĩnh Phúc | G24: 111 | H24: =G24*25550 -> 2836050 | J24: 1150000 | O24: =H24+J24+K24+L24+M24+N24 -> 3986050 | P24: 5980000 | Q24: =P24-O24 -> 1993950
A25: 18 | B25: 44706 | C25: Trả hàng NK sáng 25/05 | D25: TRHU8584039 | E25: KCN VSIP Bắc Ninh | G25: 100 | H25: =G25*25550 -> 2555000 | J25: 1150000 | O25: =H25+J25+K25+L25+M25+N25 -> 3705000 | P25: 4900000 | Q25: =P25-O25 -> 1195000
A26: 19 | B26: 44706 | C26: Trả hàng Vietsun sáng 26/05 | D26: HMMU6459580 | E26: KCN Phú Thụy, Gia Lâm, Hà Nội | G26: 73 | H26: =G26*25550 -> 1865150 | J26: 1150000 | O26: =H26+J26+K26+L26+M26+N26 -> 3015150 | P26: 4110000 | Q26: =P26-O26 -> 1094850
A27: 20 | B27: 44707 | C27: Trả hàng NK sáng 27/05 | D27: KMTU9353326 | E27: Dân Hòa, Kỳ Sơn, Hòa Bình | G27: 129 | H27: =G27*25550 -> 3295950 | J27: 1610000 | O27: =H27+J27+K27+L27+M27+N27 -> 4905950 | P27: 6250000 | Q27: =P27-O27 -> 1344050
A28: 21 | B28: 44708 | C28: Trả hàng Vietsun sáng 28/05 | D28: TCNU4785896 | E28: Kho DHL - Samsung, KCN VSIP Bắc Ninh | G28: 80 | H28: =G28*25550 -> 2044000 | J28: 1150000 | O28: =H28+J28+K28+L28+M28+N28 -> 3194000 | P28: 4517778 | Q28: =P28-O28 -> 1323778
O29: =H29+J29+K29+L29+M29+N29 -> 0
C30: Mua kìm cắt chì cộng lực cho xe 15C-180.99 | L30: 300000 | O30: =H30+J30+K30+L30+M30+N30 -> 300000
C31: Thanh toán tiền thay van la răng xe 15C-180.99 ngày 6/5 | L31: 200000 | O31: =H31+J31+K31+L31+M31+N31 -> 200000
C32: Thanh toán tiền làm lốp đầu kéo xe 15C-180.99 ngày 12/5 | L32: 300000 | O32: =H32+J32+K32+L32+M32+N32 -> 300000
C33: Thanh toán tiền đăng kiểm xe 15C-180.99 | L33: 8249000 | O33: =H33+J33+K33+L33+M33+N33 -> 8249000
C34: Chi tiền ngoài đăng kiểm xe 15C-180.99 | L34: 300000 | O34: =H34+J34+K34+L34+M34+N34 -> 300000
C35: Lương lx (24/26) | K35: 7400000 | O35: =H35+J35+K35+L35+M35+N35 -> 7400000
C36: Phí gửi xe | L36: 1200000 | O36: =H36+J36+K36+L36+M36+N36 -> 1200000
A37: TỔNG CỘNG | G37: =SUM(G8:G36) -> 2105 | H37: =SUM(H7:H36) -> 54808630 | I37: =SUM(I7:I36) -> 0 | J37: =SUM(J7:J36) -> 23880000 | K37: =SUM(K7:K36) -> 7400000 | L37: =SUM(L7:L36) -> 10549000 | M37: =SUM(M7:M36) -> 0 | N37: =SUM(N7:N36) -> 0 | O37: =SUM(O8:O36) -> 96637630 | P37: =SUM(P8:P36) -> 108502223 | Q37: =P37-O37 -> 11864593
P39: LK = | Q39: ='04.2022'!Q39+'05.2022'!Q37 -> 32846754

Sheet 06.2022
A1: Bảng theo dõi doanh thu/ chi phí theo phương tiện vận chuyển
A2: Biển số xe: 15C - 180.99
A3: THÁNG 06.2022
A5: STT | B5: Ngày tháng | C5: Diễn giải | D5: Số cont | E5: Tuyến đường vận chuyển | F5: Khoảng cách (km) | G5: Chi phí | I5: Mức TTBQ | J5: Đi đường | K5: Lương lx | L5: Sửa chữa | M5: Lốp | N5: Dầu máy | O5: Tổng chi phí | P5: Cước vận chuyển | Q5: Lợi nhuận gộp
G6: Dầu (l) | H6: Dầu (đồng)
A8: 1 | B8: 44713 | C8: Trả hàng NK sáng 02/06 | D8: WHLU0350611 | E8: Yên Mỹ, Hưng Yên | G8: 85 | H8: =G8*26390 -> 2243150 | J8: 430000 | O8: =H8+J8+K8+L8+M8+N8 -> 2673150 | P8: 4400000 | Q8: =P8-O8 -> 1726850
A9: 2 | B9: 44714 | C9: Trả hàng NK sáng 03/06 | D9: HSLU5005764 | E9: KCN Quế Võ, Bắc Ninh | G9: 67 | H9: =G9*26390 -> 1768130 | J9: 790000 | O9: =H9+J9+K9+L9+M9+N9 -> 2558130 | P9: 4300000 | Q9: =P9-O9 -> 1741870
A10: 3 | B10: 44716 | C10: Trả hàng NK sáng 04/06 | D10: BMOU2152940 | E10: TT. Lai Cách, Cẩm Giàng, Hải Dương | G10: 60 | H10: =G10*26390 -> 1583400 | J10: 340000 | O10: =H10+J10+K10+L10+M10+N10 -> 1923400 | P10: 3700000 | Q10: =P10-O10 -> 1776600
A11: 4 | B11: 44720 | C11: Đóng hàng chè sáng 09/06 | D11: WHSU2813747 | E11: Thuận Châu, Sơn La | G11: 340 | H11: =G11*26390 -> 8972600 | J11: 3460000 | O11: =H11+J11+K11+L11+M11+N11 -> 12432600 | P11: 19768519 | Q11: =P11-O11 -> 7335919
A12: 5 | B12: 44722 | C12: Đóng hàng chè sáng 11/06 | D12: BEAU4577699 | E12: Bình Xuyên, Vĩnh Phúc | G12: 111 | H12: =G12*29020 -> 3221220 | J12: 790000 | O12: =H12+J12+K12+L12+M12+N12 -> 4011220 | P12: 5980000 | Q12: =P12-O12 -> 1968780
A13: 6 | B13: 44723 | C13: Đóng hàng chè sáng 13/06 | D13: TGBU6457978 | E13: Bình Xuyên, Vĩnh Phúc | G13: 111 | H13: =G13*29020 -> 3221220 | J13: 790000 | O13: =H13+J13+K13+L13+M13+N13 -> 4011220 | P13: 5980000 | Q13: =P13-O13 -> 1968780
A14: 7 | B14: 44725 | C14: Đóng hàng chè sáng 14/06 | D14: WHLU5820180 | E14: TT Trần Phú, Văn Chấn, Yên Bái | G14: 180 | H14: =G14*29020 -> 5223600 | J14: 1530000 | O14: =H14+J14+K14+L14+M14+N14 -> 6753600 | P14: 11666667 | Q14: =P14-O14 -> 4913067
A15: 8 | B15: 44726 | C15: Đóng hàng XK sáng 15/06 | D15: YMLU5717338 | E15: KCN Phố Nối A, Văn Lâm, Hưng Yên | G15: 77 | H15: =G15*29020 -> 2234540 | J15: 430000 | O15: =H15+J15+K15+L15+M15+N15 -> 2664540 | P15: 4000000 | Q15: =P15-O15 -> 1335460
A16: 9 | B16: 44727 | C16: Đóng hàng chè sáng 16/06 | D16: TEMU7628930 | E16: TT. Phong Hải, Bảo Thắng, Lào Cai | G16: 278 | H16: =G16*29020 -> 8067560 | J16: 3940000 | O16: =H16+J16+K16+L16+M16+N16 -> 12007560 | P16: 16342593 | Q16: =P16-O16 -> 4335033
A17: 10 | B17: 44729 | C17: Đóng hàng XK chiều 17/06 | D17: TRHU5979565 | E17: KCN Đồng Văn, Hà Nam | G17: 91 | H17: =G17*29020 -> 2640820 | J17: 430000 | O17: =H17+J17+K17+L17+M17+N17 -> 3070820 | P17: 4700000 | Q17: =P17-O17 -> 1629180
A18: 11 | B18: 44732 | C18: Đóng hàng chè sáng 20/06 | D18: YMLU8714121 | E18: Bình Xuyên, Vĩnh Phúc | G18: 111 | H18: =G18*29020 -> 3221220 | J18: 790000 | O18: =H18+J18+K18+L18+M18+N18 -> 4011220 | P18: 6200000 | Q18: =P18-O18 -> 2188780
A19: 12 | B19: 44733 | C19: Trả hàng NK sáng 21/06 | D19: WHSU2545182 | E19: KCN Tam Quang, Vũ Thư, Thái Bình | G19: 68 | H19: =G19*30010 -> 2040680 | J19: =790000-360000 -> 430000 | O19: =H19+J19+K19+L19+M19+N19 -> 2470680 | P19: 4000000 | Q19: =P19-O19 -> 1529320
A20: 13 | B20: 44733 | C20: Trả hàng NK sáng 22/06 | D20: SUDU1950326 | E20: Yên Mỹ, Hưng Yên | G20: 73 | H20: =G20*30010 -> 2190730 | J20: 430000 | O20: =H20+J20+K20+L20+M20+N20 -> 2620730 | P20: 4250000 | Q20: =P20-O20 -> 1629270
A21: 14 | B21: 44734 | C21: Đóng hàng chè sáng 23/06 | D21: BMOU6148342 | E21: TT. Phong Hải, Bảo Thắng, Lào Cai | G21: 278 | H21: =G21*30010 -> 8342780 | J21: 3940000 | O21: =H21+J21+K21+L21+M21+N21 -> 12282780 | P21: 16583333 | Q21: =P21-O21 -> 4300553
A22: 15 | B22: 44735 | C22: Trả hàng NK sáng 24/06 | D22: INKU6462055 | E22: Phổ Yên, Thái Nguyên | G22: 115 | H22: =G22*30010 -> 3451150 | J22: 830000 | O22: =H22+J22+K22+L22+M22+N22 -> 4281150 | P22: 6800000 | Q22: =P22-O22 -> 2518850
A23: 16 | B23: 44740 | C23: Trả hàng Vietsun sáng 28/06 | D23: DRYU9877694 | E23: Số 18, Trần Thái Tông, TP. Thái Bình | G23: 57 | H23: =G23*30010 -> 1710570 | J23: 430000 | O23: =H23+J23+K23+L23+M23+N23 -> 2140570 | P23: 3966296 | Q23: =P23-O23 -> 1825726
A24: 17 | B24: 44740 | C24: Đóng hàng chè sáng 29/06 | D24: YMMU6409164 | E24: Mộc Châu, Sơn La | G24: 240 | H24: =G24*30010 -> 7202400 | J24: 2020000 | O24: =H24+J24+K24+L24+M24+N24 -> 9222400 | P24: 15925926 | Q24: =P24-O24 -> 6703526
A25: 18 | B25: 44741 | C25: Trả hàng NK sáng 30/06 | D25: NLLU9009870 | E25: KCN Tam Quang, Vũ Thư, Thái Bình | G25: 68 | H25: =G25*29610 -> 2013480 | J25: 430000 | O25: =H25+J25+K25+L25+M25+N25 -> 2443480 | P25: 4000000 | Q25: =P25-O25 -> 1556520
O26: =H26+J26+K26+L26+M26+N26 -> 0
C27: Thanh toán tiền đấu lại cụm zắc đèn pha xe 15C-180.99 | L27: 150000 | O27: =H27+J27+K27+L27+M27+N27 -> 150000
C28: Thanh toán tiền thay RL xe 15C-180.99 | L28: 400000 | O28: =H28+J28+K28+L28+M28+N28 -> 400000
C29: Thanh toán tiền mua đinh công xe 15C-180.99 | L29: 280000 | O29: =H29+J29+K29+L29+M29+N29 -> 280000
C30: Thanh toán tiền sửa xe 15C-180.99 ( thông xúc két gió, phục hồi tăng áp ....) | L30: 24700000 | O30: =H30+J30+K30+L30+M30+N30 -> 24700000
C31: Chi tiền cứu hộ + thay 2 lốp cho xe 15C-180.99 | L31: 400000 | O31: =H31+J31+K31+L31+M31+N31 -> 400000
C32: Thanh toán tiền bơm mỡ xe15C-180.99 | L32: 200000 | O32: =H32+J32+K32+L32+M32+N32 -> 200000
C33: Thanh toán tiền mua bóng 906, tiền đảo lốp 2 cầu xe 15C-180.99 | L33: 180000 | O33: =H33+J33+K33+L33+M33+N33 -> 180000
C34: Thanh toán tiền mua tua vít xe 15C-180.99 ngày 19/6 | L34: 35000 | O34: =H34+J34+K34+L34+M34+N34 -> 35000
C35: Thanh toán tiền mua 1 bì tì, đóng bạc 3 ngang dọc, át actizo + công thợ xe 15C-180.99 ngày 26/6 | L35: 3280000 | O35: =H35+J35+K35+L35+M35+N35 -> 3280000
C36: Thanh toán công thay phớt, mua 2 vòng bi mayơ, phớt may ơ lái, dầu cầu xe 15C-180.99 ngày 15/6 | L36: 1400000 | O36: =H36+J36+K36+L36+M36+N36 -> 1400000
C37: Thanh toán tiền mua dầu total Rubia Tir 7400 cho xe 15C-136.31, 15C-139.82, 15C-070.63,15C180.99 ngày 13/6 | N37: 3250000 | O37: =H37+J37+K37+L37+M37+N37 -> 3250000
C38: Thanh toán tiền mua 4 lốp 295/75R22,5 ca su xe 15C-180.99 ngày 12-15/6 | M38: 19600000 | O38: =H38+J38+K38+L38+M38+N38 -> 19600000
C39: Thanh toán tiền lọc nhiên liệu, lọc nhớt, cốc lọc, lọc nhiên liệu tách nước xe 15C-180.99 ngày 13/6 | L39: 2311200 | O39: =H39+J39+K39+L39+M39+N39 -> 2311200
C40: Tiền vé trạm thu phí Epass | K40: 7394000 | O40: =H40+J40+K40+L40+M40+N40 -> 7394000
C41: Thanh toán tiền thay 1 ống tuy ô phanh bánh lái, 1 bát phanh lốc kè lái xe 15C-180.99 ngày 30/6 | L41: 350000 | O41: =H41+J41+K41+L41+M41+N41 -> 350000
C42: Lương lx (24/26) + tiền sinh nhật | K42: 7900000 | O42: =H42+J42+K42+L42+M42+N42 -> 7900000
...

Sheet 07.2022
A1: Bảng theo dõi doanh thu/ chi phí theo phương tiện vận chuyển
A2: Biển số xe: 15C - 180.99
A3: THÁNG 07.2022
A5: STT | B5: Ngày tháng | C5: Diễn giải | D5: Số cont | E5: Tuyến đường vận chuyển | F5: Khoảng cách (km) | G5: Chi phí | I5: Mức TTBQ | J5: Đi đường | K5: Lương lx | L5: Sửa chữa | M5: Lốp | N5: Dầu máy | O5: Tổng chi phí | P5: Cước vận chuyển | Q5: Lợi nhuận gộp
G6: Dầu (l) | H6: Dầu (đồng)
A8: 1 | B8: 44742 | C8: Trả hàng NK sáng 01/07 | D8: FSCU5340445 | E8: Km 12, đường Ngọc Hồi, Thanh Trì, Hà Nội | G8: 85 | H8: =G8*29610 -> 2516850 | J8: 890000 | O8: =H8+J8+K8+L8+M8+N8 -> 3406850 | P8: 5400000 | Q8: =P8-O8 -> 1993150
A9: 2 | B9: 44748 | C9: Trả hàng Vietsun sáng 02/07 | D9: DRYU9961634 | E9: KCN Phố Nối A, Văn Lâm, Hưng Yên | G9: 62 | H9: =G9*29610 -> 1835820 | J9: 430000 | O9: =H9+J9+K9+L9+M9+N9 -> 2265820 | P9: 3680000 | Q9: =P9-O9 -> 1414180
A10: 3 | B10: 44748 | C10: Đóng hàng chè sáng 07/07 | D10: TCNU1082354 | E10: Bình Xuyên, Vĩnh Phúc | G10: 111 | H10: =G10*29610 -> 3286710 | J10: 790000 | O10: =H10+J10+K10+L10+M10+N10 -> 4076710 | P10: 6250000 | Q10: =P10-O10 -> 2173290
A11: 4 | B11: 44749 | C11: Trả hàng NK sáng 08/07 | D11: SEGU4565576 | E11: Hưng Thịnh, Bình Giang, Hải Dương | G11: 59 | H11: =G11*29610 -> 1746990 | J11: 340000 | O11: =H11+J11+K11+L11+M11+N11 -> 2086990 | P11: 3400000 | Q11: =P11-O11 -> 1313010
A12: 5 | B12: 44750 | C12: Trả hàng Vietsun sáng 09/07 | D12: CAIU4667884 | E12: Cẩm Giàng, Hải Dương | G12: 52 | H12: =G12*29610 -> 1539720 | J12: 340000 | O12: =H12+J12+K12+L12+M12+N12 -> 1879720 | P12: 3349259 | Q12: =P12-O12 -> 1469539
A13: 6 | B13: 44751 | C13: Đóng hàng chè sáng 10/07 - 11/07 | D13: TCNU1854139 | E13: Bản Bo, TP. Tam Đường, Lai Châu | G13: 383 | H13: =G13*29610 -> 11340630 | J13: =4940000+400000 -> 5340000 | O13: =H13+J13+K13+L13+M13+N13 -> 16680630 | P13: 25000000 | Q13: =P13-O13 -> 8319370
A14: 7 | B14: 44754 | C14: Đóng hàng XK sáng 13/07 | D14: WHSU6607045 | E14: Phổ Yên, Thái Nguyên | G14: 113 | H14: =G14*26590 -> 3004670 | J14: 830000 | O14: =H14+J14+K14+L14+M14+N14 -> 3834670 | P14: 5400000 | Q14: =P14-O14 -> 1565330
A15: 8 | B15: 44755 | C15: Trả hàng NK sáng 14/07 | D15: TLLU8678080 | E15: KCN VSIP Bắc Ninh | G15: 84 | H15: =G15*26590 -> 2233560 | J15: 790000 | O15: =H15+J15+K15+L15+M15+N15 -> 3023560 | P15: 4600000 | Q15: =P15-O15 -> 1576440
A16: 9 | B16: 44756 | C16: Trả hàng NK sáng 15/07 | D16: TRHU4125957 | E16: KCN VSIP Bắc Ninh | G16: 84 | H16: =G16*26590 -> 2233560 | J16: 790000 | O16: =H16+J16+K16+L16+M16+N16 -> 3023560 | P16: 4600000 | Q16: =P16-O16 -> 1576440
A17: 10 | B17: 44757 | C17: Đóng hàng chè sáng 16/07 | D17: OCGU8051618 | E17: Bình Xuyên, Vĩnh Phúc | G17: 111 | H17: =G17*26590 -> 2951490 | J17: 790000 | O17: =H17+J17+K17+L17+M17+N17 -> 3741490 | P17: 5900000 | Q17: =P17-O17 -> 2158510
A18: 11 | B18: 44761 | C18: Đóng hàng chè sáng 19/07 | D18: SEGU6140652 | E18: Phù Ninh, Phú Thọ | G18: 147 | H18: =G18*26590 -> 3908730 | J18: 1240000 | O18: =H18+J18+K18+L18+M18+N18 -> 5148730 | P18: 7300000 | Q18: =P18-O18 -> 2151270
A19: 12 | B19: 44762 | C19: Đóng hàng chè sáng 20/07 | D19: TGBU5092978 | E19: Bình Xuyên, Vĩnh Phúc | G19: 111 | H19: =G19*26590 -> 2951490 | J19: 790000 | O19: =H19+J19+K19+L19+M19+N19 -> 3741490 | P19: 5900000 | Q19: =P19-O19 -> 2158510
A20: 13 | B20: 44762 | C20: Đóng hàng chè sáng 21/07 | D20: FBLU0064991 | E20: Mỹ Bằng, Yên Sơn, Tuyên Quang | G20: 193 | H20: =G20*24850 -> 4796050 | J20: 1530000 | O20: =H20+J20+K20+L20+M20+N20 -> 6326050 | P20: 10124074 | Q20: =P20-O20 -> 3798024
A21: 14 | B21: 44764 | C21: Đóng hàng XK sáng 22/07 | D21: FCIU7413979 | E21: KCN Phố Nối A, Văn Lâm, Hưng Yên | G21: 78 | H21: =G21*24850 -> 1938300 | J21: 430000 | O21: =H21+J21+K21+L21+M21+N21 -> 2368300 | P21: 4000000 | Q21: =P21-O21 -> 1631700
A22: 15 | B22: 44764 | C22: Đóng hàng chè sáng 23/07 | D22: OCGU8019025 | E22: Mộc Châu, Sơn La | G22: 240 | H22: =G22*24850 -> 5964000 | J22: 2020000 | O22: =H22+J22+K22+L22+M22+N22 -> 7984000 | P22: 14814815 | Q22: =P22-O22 -> 6830815
A23: 16 | B23: 44767 | C23: Đóng hàng chè chiều 26/07 | D23: GESU5292960 | E23: Mỹ Bằng, Yên Sơn, Tuyên Quang | G23: 193 | H23: =G23*24850 -> 4796050 | J23: 1530000 | O23: =H23+J23+K23+L23+M23+N23 -> 6326050 | P23: 9846296 | Q23: =P23-O23 -> 3520246
A24: 17 | B24: 44768 | C24: Trả hàng Vietsun sáng 27/07 | D24: GAOU6506614 | E24: Cargill Phố Nối, Hưng Yên | G24: 62 | H24: =G24*24850 -> 1540700 | J24: 430000 | O24: =H24+J24+K24+L24+M24+N24 -> 1970700 | P24: 3520000 | Q24: =P24-O24 -> 1549300
A25: 18 | B25: 44770 | C25: Trả hàng NK chiều 28/07 - 29/07 | D25: OOLU1540124 | E25: Mỹ Bằng, Yên Sơn, Tuyên Quang | G25: 193 | H25: =G25*24850 -> 4796050 | J25: 1530000 | O25: =H25+J25+K25+L25+M25+N25 -> 6326050 | P25: 9475926 | Q25: =P25-O25 -> 3149876
A26: 19 | B26: 44771 | C26: Trả hàng NK sáng 30/07 | D26: FSCU4745942 | E26: Kiêu Kỵ, Gia Lâm, Hà Nội | G26: 85 | H26: =G26*23900 -> 2031500 | J26: 790000 | O26: =H26+J26+K26+L26+M26+N26 -> 2821500 | P26: 4400000 | Q26: =P26-O26 -> 1578500
C27: Thanh toán tiền mua đèn hậu led, còi hơi xe 15C-180.99 | L27: 850000 | O27: =SUM(K27:N27) -> 850000
C28: Thanh toán tiền công thay lốp xe 15C-180.99 ngày 7/7 | M28: 100000 | O28: =SUM(K28:N28) -> 100000
C29: Thanh toán tiền đảo lốp xe 15C-180.99 ngày 8/7 | M29: 100000 | O29: =SUM(K29:N29) -> 100000
C30: Thanh toán tiền làm lốp, thay săm xe 15C-180.99 ngày 23/7 | M30: 500000 | O30: =SUM(K30:N30) -> 500000
C31: Mua phớt mayơ lái, bảo dưỡng 2 mayơ moóc, mỡ 4 cân, nắp mayơ, đường ống nước xe 15C-180.99 ngày 25/7 | M31: 1540000 | O31: =SUM(K31:N31) -> 1540000
C32: Tiền vé trạm thu phí Epass | K32: 6903000 | O32: =SUM(K32:N32) -> 6903000
C33: Lương lx (25/26) | K33: 7700000 | O33: =H33+J33+K33+L33+M33+N33 -> 7700000
C34: Phí gửi xe | L34: 1200000 | O34: =H34+J34+K34+L34+M34+N34 -> 1200000
A35: TỔNG CỘNG | G35: =SUM(G8:G34) -> 2446 | H35: =SUM(H7:H34) -> 65412870 | I35: =SUM(I7:I34) -> 0 | J35: =SUM(J7:J34) -> 21620000 | K35: =SUM(K7:K34) -> 14603000 | L35: =SUM(L7:L34) -> 2050000 | M35: =SUM(M7:M34) -> 2240000 | N35: =SUM(N7:N34) -> 0 | O35: =SUM(O8:O34) -> 105925870 | P35: =SUM(P8:P34) -> 136960370 | Q35: =P35-O35 -> 31034500
P37: LK = | Q37: ='06.2022'!Q46+'07.2022'!Q35 -> 41835138

Sheet 08.2022
A1: Bảng theo dõi doanh thu/ chi phí theo phương tiện vận chuyển
A2: Biển số xe: 15C - 180.99
A3: THÁNG 08.2022
A5: STT | B5: Ngày tháng | C5: Diễn giải | D5: Số cont | E5: Tuyến đường vận chuyển | F5: Khoảng cách (km) | G5: Chi phí | I5: Mức TTBQ | J5: Đi đường | K5: Lương lx | L5: Sửa chữa | M5: Lốp | N5: Dầu máy | O5: Tổng chi phí | P5: Cước vận chuyển | Q5: Lợi nhuận gộp
G6: Dầu (l) | H6: Dầu (đồng)
A8: 1 | B8: 44773 | C8: Đóng hàng chè sáng 01/08 | D8: FCIU9051550 | E8: Phù Ninh, Phú Thọ | G8: 147 | H8: =G8*23900 -> 3513300 | J8: 840000 | O8: =H8+J8+K8+L8+M8+N8 -> 4353300 | P8: 7050000 | Q8: =P8-O8 -> 2696700
A9: 2 | B9: 44775 | C9: Đóng hàng XK sáng 02/08 | D9: MIOU4960810 | E9: Thổ Tang, Vĩnh Tường, Vĩnh Phúc | G9: 121 | H9: =G9*23900 -> 2891900 | J9: 790000 | O9: =H9+J9+K9+L9+M9+N9 -> 3681900 | P9: 5800000 | Q9: =P9-O9 -> 2118100
A10: 3 | B10: 44775 | C10: Đóng hàng xỉ bọt sáng 03/08 | D10: DYLU5110265 | E10: Phả Lại, Hải Dương | G10: 57 | H10: =G10*23900 -> 1362300 | J10: 340000 | O10: =H10+J10+K10+L10+M10+N10 -> 1702300 | P10: 3700000 | Q10: =P10-O10 -> 1997700
A11: 4 | B11: 44776 | C11: Đóng hàng chè sáng 04/08 | D11: DFSU7821357 | E11: TT Trần Phú, Văn Chấn, Yên Bái | G11: 180 | H11: =G11*23900 -> 4302000 | J11: 1530000 | O11: =H11+J11+K11+L11+M11+N11 -> 5832000 | P11: 11203704 | Q11: =P11-O11 -> 5371704
A12: 5 | B12: 44779 | C12: Đóng hàng chè sáng 06/08 | D12: TGBU4597461 | E12: Mộc Châu, Sơn La | G12: 240 | H12: =G12*23900 -> 5736000 | J12: =2380000-360000 -> 2020000 | O12: =H12+J12+K12+L12+M12+N12 -> 7756000 | P12: 14629630 | Q12: =P12-O12 -> 6873630
A13: 6 | B13: 44780 | C13: Đóng hàng chè sáng 08/08 | D13: ONEU0072917 | E13: Phù Ninh, Phú Thọ | G13: 147 | H13: =G13*23900 -> 3513300 | J13: 1100000 | O13: =H13+J13+K13+L13+M13+N13 -> 4613300 | P13: 7000000 | Q13: =P13-O13 -> 2386700
A14: 7 | B14: 44781 | C14: Trả hàng Vietsun chiều 09/08 | D14: TGCU5262717 | E14: Thôn Ngọc Long, Yên Mỹ, Hưng Yên | G14: 67 | H14: =G14*23900 -> 1601300 | J14: 430000 | O14: =H14+J14+K14+L14+M14+N14 -> 2031300 | P14: 3290000 | Q14: =P14-O14 -> 1258700
A15: 8 | B15: 44782 | C15: Đóng hàng chè sáng 10/08 | D15: GAOU6554715 | E15: Bình Xuyên, Vĩnh Phúc | G15: 111 | H15: =G15*23900 -> 2652900 | J15: 790000 | O15: =H15+J15+K15+L15+M15+N15 -> 3442900 | P15: 5600000 | Q15: =P15-O15 -> 2157100
A16: 9 | B16: 44783 | C16: Đóng hàng chè sáng 11/08 | D16: WHLU4277150 | E16: Tân Lập, Mộc Châu, Sơn La | G16: 253 | H16: =G16*22900 -> 5793700 | J16: 2200000 | O16: =H16+J16+K16+L16+M16+N16 -> 7993700 | P16: 14814815 | Q16: =P16-O16 -> 6821115
A17: 10 | B17: 44784 | C17: Đóng hàng gỗ sáng 12/08 | D17: FFAU3524175 | E17: Quảng Chu, Chợ Mới, Bắc Cạn | G17: 154 | H17: =G17*22900 -> 3526600 | J17: 1140000 | O17: =H17+J17+K17+L17+M17+N17 -> 4666600 | P17: 7500000 | Q17: =P17-O17 -> 2833400
A18: 11 | B18: 44787 | C18: Đóng hàng chè chiều 15/08 | D18: OCGU8011030 | E18: Bình Xuyên, Vĩnh Phúc | G18: 111 | H18: =G18*22900 -> 2541900 | J18: 790000 | O18: =H18+J18+K18+L18+M18+N18 -> 3331900 | P18: 5500000 | Q18: =P18-O18 -> 2168100
A19: 12 | B19: 44789 | C19: Đóng hàng XK sáng 16/08 | D19: ONEU0152099 | E19: KCN Quang Châu, Bắc Giang | G19: 92 | H19: =G19*22900 -> 2106800 | J19: 790000 | O19: =H19+J19+K19+L19+M19+N19 -> 2896800 | P19: 4000000 | Q19: =P19-O19 -> 1103200
A20: 13 | B20: 44789 | C20: Trả hàng NK sáng 17/08 | D20: TGCU0199798 | E20: Nghiêm Xuyên, Phú Xuyên, Hà Nội | G20: 99 | H20: =G20*22900 -> 2267100 | J20: 790000 | O20: =H20+J20+K20+L20+M20+N20 -> 3057100 | P20: 4500000 | Q20: =P20-O20 -> 1442900
A21: 14 | B21: 44790 | C21: Trả hàng NK sáng 18/08 | D21: MSDU8950484 | E21: Phùng Xá, Thạch Thất, Hà Nội | G21: 117 | H21: =G21*22900 -> 2679300 | J21: 790000 | O21: =H21+J21+K21+L21+M21+N21 -> 3469300 | P21: 4900000 | Q21: =P21-O21 -> 1430700
A22: 15 | B22: 44791 | C22: Đóng hàng chè sáng 19/08 | D22: OOCU7369075 | E22: Mỹ Bằng, Yên Sơn, Tuyên Quang | G22: 183 | H22: =G22*22900 -> 4190700 | J22: 1350000 | O22: =H22+J22+K22+L22+M22+N22 -> 5540700 | P22: 9114815 | Q22: =P22-O22 -> 3574115
A23: 16 | B23: 44792 | C23: Trả hàng NK chiều 20/08 | D23: CMAU9438991 | E23: Bản Bo, TP. Tam Đường, Lai Châu | G23: 365 | H23: =G23*22900 -> 8358500 | J23: 2690000 | O23: =H23+J23+K23+L23+M23+N23 -> 11048500 | P23: 21550000 | Q23: =P23-O23 -> 10501500
A24: 17 | B24: 44797 | C24: Đóng hàng chè sáng 24/08 | D24: TGBU7778503 | E24: Bình Xuyên, Vĩnh Phúc | G24: 111 | H24: =G24*23750 -> 2636250 | J24: 790000 | O24: =H24+J24+K24+L24+M24+N24 -> 3426250 | P24: 5600000 | Q24: =P24-O24 -> 2173750
A25: 18 | B25: 44798 | C25: Trả hàng Vietsun sáng 25/08 | D25: GAOU6799929 | E25: KCN Yên Phong, Bắc Ninh | G25: 80 | H25: =G25*23750 -> 1900000 | J25: 790000 | O25: =H25+J25+K25+L25+M25+N25 -> 2690000 | P25: 4350000 | Q25: =P25-O25 -> 1660000
A26: 19 | B26: 44798 | C26: Đóng hàng chè sáng 26/08 | D26: OOLU9477917 | E26: TT Tân Uyên, Tân Uyên, Lai Châu | G26: 406 | H26: =G26*23750 -> 9642500 | J26: 2840000 | O26: =H26+J26+K26+L26+M26+N26 -> 12482500 | P26: 21950000 | Q26: =P26-O26 -> 9467500
A27: 20 | B27: 44803 | C27: Đóng hàng chè sáng 30/08 | D27: YMMU6276884 | E27: TT Tân Uyên, Tân Uyên, Lai Châu | G27: 376 | H27: =G27*23750 -> 8930000 | J27: 3020000 | O27: =H27+J27+K27+L27+M27+N27 -> 11950000 | P27: 21950000 | Q27: =P27-O27 -> 10000000
C29: Thanh toán tiền tay quay lốp, dây SPH, khẩu 14+17, tay L, đai ống xả, bóng 9005 xe 15C-180.99 | L29: 880000 | O29: =SUM(K29:N29) -> 880000
C30: Thanh toán tiền mua bóng 9006, RP7 bé xe 15C-180.99 | L30: 140000 | O30: =SUM(K30:N30) -> 140000
C31: Thanh toán tiền thay lốc lạnh, lọc ga, bơm ga + dầu lạnh xe 15C-180.99 | L31: 5000000 | O31: =SUM(K31:N31) -> 5000000
C32: Thanh toán tiền mua nhớt cầu xe 15C-180.99 ngày 8/8 | N32: 210000 | O32: =SUM(K32:N32) -> 210000
C33: Mua 2 lá còn, phanh Acơ, lán bánh đà, bàn ép, mâm trung gian công hạ côn xe 15C-180.99 | L33: 7100000 | O33: =SUM(K33:N33) -> 7100000
C34: Thanh toán tiền mua dây nối đồng, đan xiết, dây, lạt xe 15C-180.99 ngày 15/8 | L34: 95000 | O34: =SUM(K34:N34) -> 95000
C35: Thanh toán tiền đảo lốp xe 15C-180.99 ngày 17/8 | L35: 120000 | O35: =SUM(K35:N35) -> 120000
C36: Thanh toán tiền nước xanh làm mát động cơ xe 15C-180.99 | L36: 650000 | O36: =SUM(K36:N36) -> 650000
C37: Thanh toán tiền mua nối nhanh các loại, dây hơi, chổi gạt mưa, moóc kéo xe 15C-180.99 ngày 23/8 | L37: 480000 | O37: =SUM(K37:N37) -> 480000
C38: Thanh toán tiền mua đèn xin nhan sườn xe 15C-180.99 ngày 23/8 | L38: 350000 | O38: =SUM(K38:N38) -> 350000
C39: Thanh toán tiền mua đui đèn cốt xe 15C-180.99 ngày 18/8 | L39: 50000 | O39: =SUM(K39:N39) -> 50000
C40: Thanh toán tiền đảo cầu xe 15C-180.99 ngày 22/8 | L40: 80000 | O40: =SUM(K40:N40) -> 80000
C41: Thanh toán tiền mua rơ le + giá xe 15C-180.99 ngày 31/8 | L41: 100000 | O41: =SUM(K41:N41) -> 100000
C42: Thanh toán tiền mua 6 đèn sườn moóc, làm điện xe 15C-180.99 ngày 31/8 | L42: 460000 | O42: =SUM(K42:N42) -> 460000
C43: Tiền vé trạm thu phí Epass | K43: 15329000 | O43: =SUM(K43:N43) -> 15329000
...

Sheet 09.2022
A1: Bảng theo dõi doanh thu/ chi phí theo phương tiện vận chuyển
A2: Biển số xe: 15C - 180.99
A3: THÁNG 09.2022
A5: STT | B5: Ngày tháng | C5: Diễn giải | D5: Số cont | E5: Tuyến đường vận chuyển | F5: Khoảng cách (km) | G5: Chi phí | I5: Mức TTBQ | J5: Đi đường | K5: Lương lx | L5: Sửa chữa | M5: Lốp | N5: Dầu máy | O5: Tổng chi phí | P5: Cước vận chuyển | Q5: Lợi nhuận gộp
G6: Dầu (l) | H6: Dầu (đồng)
A8: 1 | B8: 44805 | C8: Trả hàng NK sáng 01/09 | D8: UACU4014078 | E8: Yên Phong, Bắc Ninh | G8: 88 | H8: =G8*25180 -> 2215840 | J8: 790000 | O8: =H8+J8+K8+L8+M8+N8 -> 3005840 | P8: 4400000 | Q8: =P8-O8 -> 1394160
A9: 2 | B9: 44808 | C9: Đóng hàng chè sáng 05/09 | D9: YMMU6105177 | E9: Mộc Châu, Sơn La | G9: 249 | H9: =G9*25180 -> 6269820 | J9: =2380000-180000 -> 2200000 | O9: =H9+J9+K9+L9+M9+N9 -> 8469820 | P9: 14629630 | Q9: =P9-O9 -> 6159810
A10: 3 | B10: 44810 | C10: Đóng hàng chè sáng 07/09 | D10: CBHU7046197 | E10: Mỹ Bằng, Yên Sơn, Tuyên Quang | G10: 184 | H10: =G10*25180 -> 4633120 | J10: 1530000 | O10: =H10+J10+K10+L10+M10+N10 -> 6163120 | P10: 9485185 | Q10: =P10-O10 -> 3322065
A11: 4 | B11: 44811 | C11: Đóng hàng chè sáng 08/09 | D11: TCKU6974425 | E11: TT. Phong Hải, Bảo Thắng, Lào Cai | G11: 269 | H11: =G11*25180 -> 6773420 | J11: 2170000 | O11: =H11+J11+K11+L11+M11+N11 -> 8943420 | P11: 15370370 | Q11: =P11-O11 -> 6426950
A12: 5 | B12: 44812 | C12: Đóng hàng chè chiều 09/09 | D12: EITU1842624 | E12: Mỹ Bằng, Yên Sơn, Tuyên Quang | G12: 182 | H12: =G12*25180 -> 4582760 | J12: 1530000 | O12: =H12+J12+K12+L12+M12+N12 -> 6112760 | P12: 9485185 | Q12: =P12-O12 -> 3372425
A13: 6 | B13: 44813 | C13: Đóng hàng XK chiều 10/09 | D13: AMFU3159068 | E13: Xuân Mai, Chương Mỹ, Hà Nội | G13: 120 | H13: =G13*25180 -> 3021600 | J13: 790000 | O13: =H13+J13+K13+L13+M13+N13 -> 3811600 | P13: 5787037 | Q13: =P13-O13 -> 1975437
A14: 7 | B14: 44816 | C14: Đóng hàng chè sáng 12/09 | D14: TCNU3099654 | E14: Mỹ Bằng, Yên Sơn, Tuyên Quang | G14: 183 | H14: =G14*24180 -> 4424940 | J14: 1530000 | O14: =H14+J14+K14+L14+M14+N14 -> 5954940 | P14: 9485185 | Q14: =P14-O14 -> 3530245
A15: 8 | B15: 44816 | C15: Trả hàng Vietsun sáng 13/09 | D15: DRYU9961260 | E15: KCN Tiên Sơn, Bắc Ninh | G15: 76 | H15: =G15*24180 -> 1837680 | J15: 790000 | O15: =H15+J15+K15+L15+M15+N15 -> 2627680 | P15: 4517778 | Q15: =P15-O15 -> 1890098
A16: 9 | B16: 44818 | C16: Đóng hàng chè sáng 15/09 | D16: TXGU5855250 | E16: Mỹ Bằng, Yên Sơn, Tuyên Quang | G16: 182 | H16: =G16*24180 -> 4400760 | J16: 1530000 | O16: =H16+J16+K16+L16+M16+N16 -> 5930760 | P16: 9300000 | Q16: =P16-O16 -> 3369240
A17: 10 | B17: 44820 | C17: Đóng hàng bình khí chiều 16/09 | D17: DRYU3053687 | E17: Ninh Hiệp, Gia Lâm, Hà Nội - Củ Chi, HCM | G17: 87 | H17: =G17*24180 -> 2103660 | J17: 790000 | O17: =H17+J17+K17+L17+M17+N17 -> 2893660 | P17: 4800000 | Q17: =P17-O17 -> 1906340
A18: 11 | B18: 44821 | C18: Đóng hàng chè sáng 17/09 | D18: YMLU9033483 | E18: Bình Xuyên, Vĩnh Phúc | G18: 111 | H18: =G18*24180 -> 2683980 | J18: 790000 | O18: =H18+J18+K18+L18+M18+N18 -> 3473980 | P18: 5650000 | Q18: =P18-O18 -> 2176020
A19: 12 | B19: 44823 | C19: Trả hàng Vietsun sáng 20/09 | D19: YMMU6398455 | E19: KCN Yên Phong mở rộng, Yên Phong, Bắc Ninh | G19: 86 | H19: =(G19-3)*24180+3*22530 -> 2074530 | J19: 790000 | O19: =H19+J19+K19+L19+M19+N19 -> 2864530 | P19: 4517778 | Q19: =P19-O19 -> 1653248
A20: 13 | B20: 44824 | C20: Đóng hàng chè sáng 21/09 | D20: OOLU9129737 | E20: Mộc Châu, Sơn La | G20: 244 | H20: =G20*22530 -> 5497320 | J20: 2380000 | O20: =H20+J20+K20+L20+M20+N20 -> 7877320 | P20: 14722222 | Q20: =P20-O20 -> 6844902
A21: 14 | B21: 44825 | C21: Đóng hàng chè chiều 22/09 | D21: FSCU7264370 | E21: Địch Quả, Thanh Sơn, Phú Thọ | G21: 151 | H21: =G21*22530 -> 3402030 | J21: 1060000 | O21: =H21+J21+K21+L21+M21+N21 -> 4462030 | P21: 7250000 | Q21: =P21-O21 -> 2787970
A22: 15 | B22: 44827 | C22: Đóng hàng chè chiều 24/09 | D22: YMMU6629913 | E22: Bản Giang, Tam Đường, Lai Châu | G22: 390 | H22: =G22*22530 -> 8786700 | J22: 3020000 | O22: =H22+J22+K22+L22+M22+N22 -> 11806700 | P22: 21850000 | Q22: =P22-O22 -> 10043300
A23: 16 | B23: 44829 | C23: Đóng hàng XK sáng 26/09 | D23: TEMU2074203 | E23: Xuân Mai, Chương Mỹ, Hà Nội | G23: 122 | H23: =G23*22530 -> 2748660 | J23: 790000 | O23: =H23+J23+K23+L23+M23+N23 -> 3538660 | P23: 5527778 | Q23: =P23-O23 -> 1989118
A24: 17 | B24: 44831 | C24: Trả hàng Vietsun sáng 28/09 | D24: TGBU5509070 | E24: KCN Quế Võ, Bắc Ninh | G24: 70 | H24: =G24*22530 -> 1577100 | J24: 790000 | O24: =H24+J24+K24+L24+M24+N24 -> 2367100 | P24: 4200000 | Q24: =P24-O24 -> 1832900
A25: 18 | B25: 44832 | C25: Đóng hàng chè sáng 29/09 | D25: SEGU4450920 | E25: Mộc Châu, Sơn La | G25: 240 | H25: =G25*22530 -> 5407200 | J25: 2380000 | O25: =H25+J25+K25+L25+M25+N25 -> 7787200 | P25: 14351852 | Q25: =P25-O25 -> 6564652
C27: Thanh toàn tiền bảo dưỡng đề máy phát xe 15C-180.99 ngày 6/9 | L27: 800000 | O27: =SUM(K27:N27) -> 800000
C28: Thanh toán tiền cân lốp + xịt lọc xe 15C-180.99 ngày 6/9 | L28: 90000 | O28: =SUM(K28:N28) -> 90000
C29: Thanh toán tiền bơm mỡ, thây dầu, lọc, nắp lọc nhỏ, cứ hộ thay gioăng nhớt xe 15C-180.99 ngày 11/9 | L29: 600000 | O29: =SUM(K29:N29) -> 600000
C30: Thanh toán tiền mua lọc nhiên liệu P550821; lọc nhiên liệu tách nước P550748; lọc dầu nhớt P551088 xe 15C-180.99 | L30: 1792800 | O30: =SUM(K30:N30) -> 1792800
C31: Thanh toán tiền tháo lắp thay đổi két gió mới , thay 02 đai gió mới xe 15C-180.99 ngày 6/9 | L31: 11300000 | O31: =SUM(K31:N31) -> 11300000
C32: Thanh toán tiền thay chân van xe 15C-180.99 ngày 11/9 | L32: 150000 | O32: =SUM(K32:N32) -> 150000
C33: Thanh toán tiền kiểm tra, tháo lắp, vệ sinh cánh quạt, sửa lưỡi gà mặt hút, thay dầu côn cánh quạt xe 15C-180.99 ngày 19/9 | L33: 2400000 | O33: =SUM(K33:N33) -> 2400000
C34: Thanh toán tiền mua 2 đèn hậu + công xe 15C-180.99 ngày 23/9 | L34: 150000 | O34: =SUM(K34:N34) -> 150000
C35: Tiền cứu hộ xe 15C-180.99 | L35: 2000000 | O35: =SUM(K35:N35) -> 2000000
C36: Thanh toán tiền bảo dưỡng 4 mayơ moóc, mỡ 8 cân xe 15C-180.99 ngày 23/8 | L36: 1120000 | O36: =SUM(K36:N36) -> 1120000
C37: Thanh toán tiền công làm 4 mỏ gạc, ắc + đóng bạc 4 mỏ gạc, 12 bạc , 12 ắc, 5 ốc tay giằng, công làm tay giằng xe 15C-180.99 ngày 29/8 | L37: 4160000 | O37: =SUM(K37:N37) -> 4160000
C38: Thanh toán tiền thùng dầu cho Việt Phát cho xe 15C-139.82; 15C-070.63; 15C-136.31, 15C-180.99 ngày 10/9 | N38: 3375000 | O38: =SUM(K38:N38) -> 3375000
C39: Thanh toán tiền mua phớt may ơ cầu, công thay phớt xe 15C-180.99 ngày 8/8 | L39: 700000 | O39: =SUM(K39:N39) -> 700000
C40: Tiền vé trạm thu phí Epass | K40: 10991000 | O40: =SUM(K40:N40) -> 10991000
C41: Lương lx ( ngày công 26/26) | K41: 8000000 | O41: =H41+J41+K41+L41+M41+N41 -> 8000000
C42: Phí gửi xe | L42: 1200000 | O42: =H42+J42+K42+L42+M42+N42 -> 1200000
A43: TỔNG CỘNG | G43: =SUM(G8:G42) -> 3034 | H43: =SUM(H7:H42) -> 72441120 | I43: =SUM(I7:I42) -> 0 | J43: =SUM(J7:J42) -> 25650000 | K43: =SUM(K7:K42) -> 18991000 | L43: =SUM(L7:L42) -> 26462800 | M43: =SUM(M7:M42) -> 0 | N43: =SUM(N7:N42) -> 3375000 | O43: =SUM(O8:O42) -> 146919920 | P43: =SUM(P8:P42) -> 165330000 | Q43: =P43-O43 -> 18410080
...

Sheet 10.2022
A1: Bảng theo dõi doanh thu/ chi phí theo phương tiện vận chuyển
A2: Biển số xe: 15C - 180.99
A3: THÁNG 10.2022
A5: STT | B5: Ngày tháng | C5: Diễn giải | D5: Số cont | E5: Tuyến đường vận chuyển | F5: Khoảng cách (km) | G5: Chi phí | I5: Mức TTBQ | J5: Đi đường | K5: Lương lx | L5: Sửa chữa | M5: Lốp | N5: Dầu máy | O5: Tổng chi phí | P5: Cước vận chuyển | Q5: Lợi nhuận gộp
G6: Dầu (l) | H6: Dầu (đồng)
A8: 1 | B8: 44838 | C8: Đóng hàng chè sáng 04/10 | D8: FFAU3542219 | E8: Bản Giang, Tam Đường, Lai Châu | G8: 393 | H8: =(G8-44)*22200+44*22530 -> 8739120 | J8: 3020000 | O8: =H8+J8+K8+L8+M8+N8 -> 11759120 | P8: 21850000 | Q8: =P8-O8 -> 10090880
A9: 2 | B9: 44839 | C9: Trả hàng Vietsun tối 05/10 | D9: NLLU4211548 | E9: KCN Đồng Văn, Duy Tiên, Hà Nam | G9: 83 | H9: =G9*22200 -> 1842600 | J9: 430000 | O9: =H9+J9+K9+L9+M9+N9 -> 2272600 | P9: 4627037 | Q9: =P9-O9 -> 2354437
A10: 3 | B10: 44840 | C10: Đóng hàng chè sáng 07/10 | D10: TLLU4946590 | E10: Mộc Châu, Sơn La | G10: 243 | H10: =G10*22200 -> 5394600 | J10: 2200000 | O10: =H10+J10+K10+L10+M10+N10 -> 7594600 | P10: 14259259 | Q10: =P10-O10 -> 6664659
A11: 4 | B11: 44841 | C11: Đóng hàng chè sáng 08/10 | D11: BMOU6188643 | E11: Bình Xuyên, Vĩnh Phúc | G11: 111 | H11: =G11*22200 -> 2464200 | J11: 790000 | O11: =H11+J11+K11+L11+M11+N11 -> 3254200 | P11: 5450000 | Q11: =P11-O11 -> 2195800
A12: 5 | B12: 44844 | C12: Đóng hàng chè sáng 10/10 | D12: YMMU6125208 | E12: Nghi Phú, TP. Vinh, Nghệ An | G12: 229 | H12: =G12*22200 -> 5083800 | J12: 1180000 | O12: =H12+J12+K12+L12+M12+N12 -> 6263800 | P12: 9900000 | Q12: =P12-O12 -> 3636200
A13: 6 | B13: 44844 | C13: Trả hàng Vietsun sáng 11/10 | D13: GAOU6798584 | E13: CJ Hà Nam, KCN Đồng Văn 2, Duy Tiên, Hà Nam | G13: 81 | H13: =G13*24180 -> 1958580 | J13: 430000 | O13: =H13+J13+K13+L13+M13+N13 -> 2388580 | P13: 4497037 | Q13: =P13-O13 -> 2108457
A14: 7 | B14: 44846 | C14: Trả hàng NK sáng 12/10 | D14: TGBU2424929 | E14: Lai Cách, Cẩm Giàng, Hải Dương | G14: 60 | H14: =G14*24180 -> 1450800 | J14: 340000 | O14: =H14+J14+K14+L14+M14+N14 -> 1790800 | P14: 3500000 | Q14: =P14-O14 -> 1709200
A15: 8 | B15: 44846 | C15: Đóng hàng chè sáng 13/10 | D15: SEGU6385418 | E15: Mộc Châu, Sơn La | G15: 240 | H15: =G15*24180 -> 5803200 | J15: 2380000 | O15: =H15+J15+K15+L15+M15+N15 -> 8183200 | P15: 14722222 | Q15: =P15-O15 -> 6539022
A16: 9 | B16: 44847 | C16: Trả hàng Vietsun sáng 14/10 | D16: DRYU9718347 | E16: KCN Quế Võ, Bắc Ninh | G16: 68 | H16: =G16*24180 -> 1644240 | J16: 790000 | O16: =H16+J16+K16+L16+M16+N16 -> 2434240 | P16: 4070000 | Q16: =P16-O16 -> 1635760
A17: 10 | B17: 44848 | C17: Trả hàng Vietsun sáng 15/10 | D17: TCNU4595495 | E17: KCN Phố Nối A, Văn Lâm, Hưng Yên | G17: 62 | H17: =G17*24180 -> 1499160 | J17: 430000 | O17: =H17+J17+K17+L17+M17+N17 -> 1929160 | P17: 3410000 | Q17: =P17-O17 -> 1480840
A18: 11 | B18: 44851 | C18: Đóng hàng chè sáng 18/10 | D18: SEKU4582855 | E18: Mộc Châu, Sơn La | G18: 243 | H18: =G18*24180 -> 5875740 | J18: 2380000 | O18: =H18+J18+K18+L18+M18+N18 -> 8255740 | P18: 14722222 | Q18: =P18-O18 -> 6466482
A19: 12 | B19: 44852 | C19: Đóng hàng chè sáng 19/10 | D19: DRYU9845887 | E19: Mỹ Bằng, Yên Sơn, Tuyên Quang | G19: 180 | H19: =G19*24180 -> 4352400 | J19: 1530000 | O19: =H19+J19+K19+L19+M19+N19 -> 5882400 | P19: 9300000 | Q19: =P19-O19 -> 3417600
A20: 13 | B20: 44853 | C20: Đóng hàng chè sáng 20/10 | D20: CMAU9258222 | E20: Mỹ Bằng, Yên Sơn, Tuyên Quang | G20: 196 | H20: =G20*24180 -> 4739280 | J20: 1530000 | O20: =H20+J20+K20+L20+M20+N20 -> 6269280 | P20: 9707407 | Q20: =P20-O20 -> 3438127
A21: 14 | B21: 44854 | C21: Đóng hàng chè sáng 21/10 | D21: BEAU6167353 | E21: Mỹ Bằng, Yên Sơn, Tuyên Quang | G21: 184 | H21: =G21*24780 -> 4559520 | J21: 1530000 | O21: =H21+J21+K21+L21+M21+N21 -> 6089520 | P21: 9300000 | Q21: =P21-O21 -> 3210480
A22: 15 | B22: 44858 | C22: Trả hàng Vietsun sáng 24/10 | D22: DRYU9718970 | E22: KCN Đồng Văn II, Duy Tiên, Hà Nam | G22: 81 | H22: =G22*24780 -> 2007180 | J22: 790000 | O22: =H22+J22+K22+L22+M22+N22 -> 2797180 | P22: 4497037 | Q22: =P22-O22 -> 1699857
A23: 16 | B23: 44860 | C23: Đóng hàng xỉ bọt sáng 26/10 | D23: SLSU8025773 | E23: Phả Lại, Hải Dương | G23: 59 | H23: =G23*24780 -> 1462020 | J23: 440000 | O23: =H23+J23+K23+L23+M23+N23 -> 1902020 | P23: 3700000 | Q23: =P23-O23 -> 1797980
A24: 17 | B24: 44860 | C24: Đóng hàng chè chiều 27/10 | D24: TGBU9840661 | E24: Bản Giang, Tam Đường, Lai Châu | G24: 390 | H24: =G24*24780 -> 9664200 | J24: =3232000+400000 -> 3632000 | O24: =H24+J24+K24+L24+M24+N24 -> 13296200 | P24: 24200000 | Q24: =P24-O24 -> 10903800
A25: 18 | B25: 44863 | C25: Đóng hàng XK sáng 29/10 | D25: CAIU6222959 | E25: Xuân Mai, Chương Mỹ, Hà Nội | G25: 122 | H25: =G25*24780 -> 3023160 | J25: 790000 | O25: =H25+J25+K25+L25+M25+N25 -> 3813160 | P25: 5879630 | Q25: =P25-O25 -> 2066470
A26: 19 | B26: 44864 | C26: Đóng hàng XK sáng 31/10 | D26: MEDU2699712 | E26: Xuân Mai, Chương Mỹ, Hà Nội | G26: =122 -> 122 | H26: =(G26-40)*24780+40*25070 -> 3034760 | J26: 790000 | O26: =H26+J26+K26+L26+M26+N26 -> 3824760 | P26: 5879630 | Q26: =P26-O26 -> 2054870
O27: =SUM(K27:N27) -> 0
C28: Cấp bổ sung dầu bị hao hụt do xe hỏng ngày 14/10 | L28: =50*24180 -> 1209000 | O28: =SUM(K28:N28) -> 1209000
C29: Thanh toán tiền mua đèn tròn hậu moóc, tay khóa ca bô MF xe 15C-180.99 ngày 6/10 | L29: 460000 | O29: =SUM(K29:N29) -> 460000
C30: Thanh toán tiền mua lọc gió ngoài xe 15C-180.99 ngày 6/10 | L30: 918000 | O30: =SUM(K30:N30) -> 918000
C31: Thanh toán tiền mua thân bơm cao áp , công tháo lắp xe 15C-180.99 ngày 1/10 | L31: 14000000 | O31: =SUM(K31:N31) -> 14000000
C32: Thanh toán tiền thay yếm, lót ghệt to bé, công xe 15C-180.99 | L32: 235000 | O32: =SUM(K32:N32) -> 235000
C33: Thanh toán tiền mua 3 hộp chì tạm cho xe | L33: 80000 | O33: =SUM(K33:N33) -> 80000
C34: Thanh toán tiền mua bạc cabin MF2FW, bóng hơi cabin MF, giảm sóc MF xe 15C-180.99 ngày 16/10 | L34: 2800000 | O34: =SUM(K34:N34) -> 2800000
C35: Thanh toán tiền mua bóng tải MF cho xe 15C-180.99 | L35: 2400000 | O35: =SUM(K35:N35) -> 2400000
C36: Thanh toán tiền ống gió tăng áp , quai nhê cho xe 15C-180.99 | L36: 550000 | O36: =SUM(K36:N36) -> 550000
C37: Thanh toán tiền bơm mỡ xe 15C-180.99 ngày 22/10 | L37: 200000 | O37: =SUM(K37:N37) -> 200000
C38: "Thanh toán tiền thay bóng hơi tải, tán 4 bộ phanh đầu ké, 4 tầng bua, thay 8 con lăn, đóng bạc giảm xóc, dây hơi + công xe 15C-180.99 ngày 23/10" | L38: 3700000 | O38: =SUM(K38:N38) -> 3700000
C39: Thanh toán công thay bóng hơi cabin, thay 1 giảm xóc, ép bạc giảm xóc xe 15C-180.99 ngày 16/10 | L39: 400000 | O39: =SUM(K39:N39) -> 400000
C40: Tiền vé trạm thu phí Epass | K40: 11654000 | O40: =SUM(K40:N40) -> 11654000
C41: Lương lx ( ngày công 26/26) | K41: 8000000 | O41: =H41+J41+K41+L41+M41+N41 -> 8000000
C42: Phí gửi xe | L42: 1200000 | O42: =H42+J42+K42+L42+M42+N42 -> 1200000
...

Sheet 11.2022
A1: Bảng theo dõi doanh thu/ chi phí theo phương tiện vận chuyển
A2: Biển số xe: 15C - 180.99
A3: THÁNG 11.2022
A5: STT | B5: Ngày tháng | C5: Diễn giải | D5: Số cont | E5: Tuyến đường vận chuyển | F5: Khoảng cách (km) | G5: Chi phí | I5: Mức TTBQ | J5: Đi đường | K5: Lương lx | L5: Sửa chữa | M5: Lốp | N5: Dầu máy | O5: Tổng chi phí | P5: Cước vận chuyển | Q5: Lợi nhuận gộp
G6: Dầu (l) | H6: Dầu (đồng)
A8: 1 | B8: 44866 | C8: Đóng hàng chè sáng 01/11 | D8: TRHU5578367 | E8: Mỹ Bằng, Yên Sơn, Tuyên Quang | G8: 180 | H8: =G8*25070 -> 4512600 | J8: 1530000 | O8: =H8+J8+K8+L8+M8+N8 -> 6042600 | P8: 9300000 | Q8: =P8-O8 -> 3257400
A9: 2 | B9: 44866 | C9: Đóng hàng chè sáng 02/11 | D9: TLLU4184258 | E9: Bản Bo, TP. Tam Đường, Lai Châu | G9: 368 | H9: =G9*25070 -> 9225760 | J9: 2927000 | O9: =H9+J9+K9+L9+M9+N9 -> 12152760 | P9: 21851852 | Q9: =P9-O9 -> 9699092
A10: 3 | B10: 44868 | C10: Trả hàng NK tối 03/11 | D10: BEAU5408292 | E10: Phạm Văn Đồng, Từ Liêm, Hà Nội | G10: 93 | H10: =G10*25070 -> 2331510 | J10: 790000 | O10: =H10+J10+K10+L10+M10+N10 -> 3121510 | P10: 4600000 | Q10: =P10-O10 -> 1478490
A11: 4 | B11: 44869 | C11: Đóng hàng chè sáng 06/11 | D11: TGBU5557186 | E11: TT. Phong Hải, Bảo Thắng, Lào Cai | G11: 271 | H11: =G11*25070 -> 6793970 | J11: 2600000 | O11: =H11+J11+K11+L11+M11+N11 -> 9393970 | P11: 15500000 | Q11: =P11-O11 -> 6106030
A12: 5 | B12: 44872 | C12: Trả hàng Vietsun sáng 07/11 | D12: TEMU8595641 | E12: KCN Quế Võ, Bắc Ninh | G12: 71 | H12: =G12*25070 -> 1779970 | J12: 790000 | O12: =H12+J12+K12+L12+M12+N12 -> 2569970 | P12: 4210000 | Q12: =P12-O12 -> 1640030
A13: 6 | B13: 44872 | C13: Trả hàng phế liệu sáng 08/11 | D13: BMOU6366370 | E13: Đồng Tâm, Lạc Thủy, Hòa Bình | G13: 103 | H13: =G13*25070 -> 2582210 | J13: 790000 | O13: =H13+J13+K13+L13+M13+N13 -> 3372210 | P13: 5250000 | Q13: =P13-O13 -> 1877790
A14: 7 | B14: 44875 | C14: Đóng hàng chè sáng 10/11 | D14: TLLU4078024 | E14: Mộc Châu, Sơn La | G14: 240 | H14: =G14*24980 -> 5995200 | J14: 2380000 | O14: =H14+J14+K14+L14+M14+N14 -> 8375200 | P14: 14861111 | Q14: =P14-O14 -> 6485911
A15: 8 | B15: 44875 | C15: Trả hàng NK sáng 11/11 | D15: SEGU1524629 | E15: Yên Mỹ, Hưng Yên | G15: 74 | H15: =G15*24980 -> 1848520 | J15: 430000 | O15: =H15+J15+K15+L15+M15+N15 -> 2278520 | P15: 4050000 | Q15: =P15-O15 -> 1771480
A16: 9 | B16: 44877 | C16: Trả hàng NK sáng 12/11 | D16: TGBU6932893 | E16: TP. Việt Trì, Phú Thọ | G16: 125 | H16: =G16*24980 -> 3122500 | J16: 880000 | O16: =H16+J16+K16+L16+M16+N16 -> 4002500 | P16: 6200000 | Q16: =P16-O16 -> 2197500
A17: 10 | B17: 44879 | C17: Đóng hàng chè sáng 14/11 | D17: YMMU6367264 | E17: Bản Bo, TP. Tam Đường, Lai Châu | G17: 367 | H17: =G17*24980 -> 9167660 | J17: 3450000 | O17: =H17+J17+K17+L17+M17+N17 -> 12617660 | P17: 22350000 | Q17: =P17-O17 -> 9732340
A18: 11 | B18: 44881 | C18: Đóng hàng chè sáng 16/11 | D18: TRHU8162434 | E18: Mỹ Bằng, Yên Sơn, Tuyên Quang | G18: 180 | H18: =G18*24980 -> 4496400 | J18: 1530000 | O18: =H18+J18+K18+L18+M18+N18 -> 6026400 | P18: 9300000 | Q18: =P18-O18 -> 3273600
A19: 12 | B19: 44881 | C19: Trả hàng NK sáng 17/11 | D19: MSKU0567767 | E19: CP Xuân Mai, Xuân Mai, Chương Mỹ, Hà Nội | G19: 118 | H19: =G19*24980 -> 2947640 | J19: 790000 | O19: =H19+J19+K19+L19+M19+N19 -> 3737640 | P19: 4900000 | Q19: =P19-O19 -> 1162360
A20: 13 | B20: 44883 | C20: Đóng hàng XK sáng 18/11 | D20: YMLU5147472 | E20: KCN Thăng Long 2, Yên Mỹ, Hưng Yên | G20: 64 | H20: =G20*24980 -> 1598720 | J20: 430000 | O20: =H20+J20+K20+L20+M20+N20 -> 2028720 | P20: 3400000 | Q20: =P20-O20 -> 1371280
A21: 14 | B21: 44883 | C21: Đóng hàng chè chiều 20/11 | D21: TCKU7559985 | E21: Bản Bo, TP. Tam Đường, Lai Châu | G21: 365 | H21: =G21*24800 -> 9052000 | J21: 3450000 | O21: =H21+J21+K21+L21+M21+N21 -> 12502000 | P21: 22350000 | Q21: =P21-O21 -> 9848000
A22: 15 | B22: 44886 | C22: Trả hàng phế liệu sáng 22/11 | D22: BMOU5783997 | E22: Đồng Tâm, Lạc Thủy, Hòa Bình | G22: 103 | H22: =G22*24800 -> 2554400 | J22: 790000 | O22: =H22+J22+K22+L22+M22+N22 -> 3344400 | P22: 5550000 | Q22: =P22-O22 -> 2205600
A23: 16 | B23: 44888 | C23: Trả hàng Vietsun sáng 24/11 | D23: GAOU6143606 | E23: Kho DHL - Samsung, KCN VSIP, Bắc Ninh | G23: 81 | H23: =G23*24800 -> 2008800 | J23: 610000 | O23: =H23+J23+K23+L23+M23+N23 -> 2618800 | P23: 4527778 | Q23: =P23-O23 -> 1908978
