Workbook

Sheet T12.2015
A1: Bảng theo dõi doanh thu/ chi phí theo phương tiện vận chuyển
A2: Biển số xe: 15C - 136.31
H3: THÁNG 12.2015
A5: STT | B5: Ngày tháng | C5: Diễn giải | D5: Số cont | E5: Tuyến đường vận chuyển | F5: Khoảng cách (km) | G5: Chi phí | O5: Tổng chi phí | P5: Cước vận chuyển | Q5: Lợi nhuận gộp
G6: Dầu (l) | H6: Dầu (đồng) | I6: Mức TTBQ | J6: Đi đường | K6: Lương lx | L6: Sửa chữa | M6: Lốp | N6: Dầu máy
O7: =H7+J7+K7+L7+M7+N7 -> 0 | Q7: =P7-O7 -> 0
A8: 1 | B8: 42705 | C8: Trả hàng + đóng hàng 1/12 | D8: TTNU3681945 | E8: Gia Lâm, Hà Nội - Hà Nam | H8: =G8*13510 -> 0 | J8: 1750000 | O8: =H8+J8+K8+L8+M8+N8 -> 1750000 | P8: =S8 -> 5760000 | Q8: =P8-O8 -> 4010000 | S8: 5760000
A9: 2 | B9: 42339 | C9: Trả hàng + đóng hàng 02/12 | D9: VSLU1041014 | E9: Bắc Ninh - Hà Nam | G9: 220 | H9: =G9*13510 -> 2972200 | J9: 1750000 | O9: =H9+J9+K9+L9+M9+N9 -> 4722200 | P9: =S9 -> 6060000 | Q9: =P9-O9 -> 1337800 | S9: 6060000
A10: 3 | B10: 42340 | C10: Trả hàng + đóng hàng 03/12 | D10: WFHU1352176 | E10: Như Quỳnh, Hưng Yên - Hà Nam | G10: 0 | H10: =G10*13510 -> 0 | J10: 1690000 | O10: =H10+J10+K10+L10+M10+N10 -> 1690000 | P10: =S10 -> 5660000 | Q10: =P10-O10 -> 3970000 | S10: 5660000
A11: 4 | B11: 42341 | C11: Trả hàng + đóng hàng 04/12 | D11: VSLU4025362 | E11: Long Biên, Hà Nội - Hà Nam | G11: 220 | H11: =G11*13230 -> 2910600 | J11: 1740000 | O11: =H11+J11+K11+L11+M11+N11 -> 4650600 | P11: =S11 -> 5960000 | Q11: =P11-O11 -> 1309400 | S11: 5960000
A12: 5 | B12: 42342 | C12: Trả hàng + đóng hàng 05/12 | D12: TRHU1344490 | E12: Mỹ Hào, Hưng Yên - Hà Nam | G12: 0 | H12: =G12*13230 -> 0 | J12: 1430000 | O12: =H12+J12+K12+L12+M12+N12 -> 1430000 | P12: =S12 -> 5580000 | Q12: =P12-O12 -> 4150000 | S12: 5580000
A13: 6 | B13: 42343 | C13: Trả hàng sáng 06/12 | D13: DRYU3092209 | E13: KCN Thạch Thất, Hà Nội | G13: 0 | H13: =G13*13230 -> 0 | J13: 1720000 | O13: =H13+J13+K13+L13+M13+N13 -> 1720000 | P13: =S13 -> 6460000 | Q13: =P13-O13 -> 4740000 | S13: 6460000
A14: 7 | B14: 42343 | C14: Đóng hàng KH 06/12 | D14: DRYU3015727 | E14: Phủ Lý, Hà Nam | G14: 238 | H14: =G14*13230 -> 3148740 | J14: 0 | O14: =H14+J14+K14+L14+M14+N14 -> 3148740 | P14: =S14 -> 0 | Q14: =P14-O14 -> -3148740 | S14: 0
A15: 8 | B15: 42343 | C15: Trả hàng sáng 07/12 | D15: DRYU2902096 | E15: KCN Đại Đồng, Bắc Ninh | G15: 0 | H15: =G15*13230 -> 0 | J15: 1750000 | O15: =H15+J15+K15+L15+M15+N15 -> 1750000 | P15: =S15 -> 3360000 | Q15: =P15-O15 -> 1610000 | S15: 3360000
A16: 9 | B16: 42343 | C16: Đóng hàng XK 07/12 | D16: DFSU1269940 | E16: Hoa Lư, Ninh Bình | G16: 0 | H16: =G16*13230 -> 0 | J16: 0 | O16: =H16+J16+K16+L16+M16+N16 -> 0 | P16: =S16 -> 4200000 | Q16: =P16-O16 -> 4200000 | S16: 4200000
A17: 10 | B17: 42345 | C17: Trả hàng + đóng hàng 08/12 | D17: DRYU2853941 | E17: Mỹ Hào, Hưng Yên - Hà Nam | G17: 210 | H17: =G17*13230 -> 2778300 | J17: 1430000 | O17: =H17+J17+K17+L17+M17+N17 -> 4208300 | P17: =S17 -> 5580000 | Q17: =P17-O17 -> 1371700 | S17: 5580000
A18: 11 | B18: 42346 | C18: Trả hàng sáng 09/12 | D18: WFHU1354374 | E18: Mỹ Hào, Hưng Yên | G18: 0 | H18: =G18*13230 -> 0 | J18: 1430000 | O18: =H18+J18+K18+L18+M18+N18 -> 1430000 | P18: =S18 -> 2890000 | Q18: =P18-O18 -> 1460000 | S18: 2890000
A19: 12 | B19: 42346 | C19: Đóng hàng XK 09/12 | D19: MSKU2662510 | E19: Hoa Lư, Ninh Bình | G19: 0 | H19: =G19*13230 -> 0 | J19: 0 | O19: =H19+J19+K19+L19+M19+N19 -> 0 | P19: =S19 -> 4200000 | Q19: =P19-O19 -> 4200000 | S19: 4200000
A20: 13 | B20: 42347 | C20: Đóng hàng chè sáng 11/12 | D20: TCNU5200310 | E20: Mỹ Bằng, Yên Sơn, Tuyên Quang | G20: 275 | H20: =G20*13230 -> 3638250 | J20: 2320000 | O20: =H20+J20+K20+L20+M20+N20 -> 5958250 | P20: =S20 -> 10000000 | Q20: =P20-O20 -> 4041750 | S20: 10000000
A21: 14 | B21: 42349 | C21: Trả hàng sáng 12/12 | D21: DRYU2924449 | E21: Mỹ Hào, Hưng Yên | G21: 0 | H21: =G21*13230 -> 0 | J21: 1450000 | O21: =H21+J21+K21+L21+M21+N21 -> 1450000 | P21: =S21 -> 5580000 | Q21: =P21-O21 -> 4130000 | S21: 5580000
A22: 15 | B22: 42349 | C22: Đóng hàng vôi XK 12/12 | D22: WHLU2890774 | E22: Tam Điệp, Ninh Bình | G22: 0 | H22: =G22*13230 -> 0 | J22: 0 | O22: =H22+J22+K22+L22+M22+N22 -> 0 | P22: =S22 -> 0 | Q22: =P22-O22 -> 0 | S22: 0
... A24: 17 | B24: 42351 | C24: Đóng hàng XK 14/12 | D24: MSKU4309708 | E24: Hoa Lư, Ninh Bình | G24: 238 | H24: =G24*13230 -> 3148740 | J24: 0 | O24: =H24+J24+K24+L24+M24+N24 -> 3148740 | P24: =S24 -> 4200000 | Q24: =P24-O24 -> 1051260 | S24: 4200000
A25: 18 | B25: 42352 | C25: Trả hàng sáng 15/12 | D25: DRYU3095656 | E25: Mỹ Hào, Hưng Yên | H25: =G25*13510 -> 0 | J25: 1520000 | O25: =H25+J25+K25+L25+M25+N25 -> 1520000 | P25: =S25 -> 5780000 | Q25: =P25-O25 -> 4260000 | S25: 5780000
A26: 19 | B26: 42352 | C26: Đóng hàng XK 15/12 | D26: AKLU6024071 | E26: Hoà Lạc, Hà Nội | H26: =G26*13510 -> 0 | J26: 0 | O26: =H26+J26+K26+L26+M26+N26 -> 0 | P26: =S26 -> 0 | Q26: =P26-O26 -> 0 | S26: 0
A27: 20 | B27: 42354 | C27: Trả hàng sáng 17/12 | D27: UETU2345338 | E27: Đức Giang, Hà Nội | H27: =G27*13510 -> 0 | J27: 1520000 | O27: =H27+J27+K27+L27+M27+N27 -> 1520000 | P27: =S27 -> 3000000 | Q27: =P27-O27 -> 1480000 | S27: 3000000
A28: 21 | B28: 42354 | C28: Đóng hàng XK sáng 18/12 | D28: DFSU1566803 | E28: Mỹ Hào, Hưng Yên | H28: =G28*13510 -> 0 | J28: 200000 | O28: =H28+J28+K28+L28+M28+N28 -> 200000 | P28: =S28 -> 3090909 | Q28: =P28-O28 -> 2890909 | S28: 3090909
A29: 22 | B29: 42356 | C29: Trả hàng 19/12 | D29: APZU3682140 | E29: Thạch Thất, Hà Nội | G29: 200 | H29: =G29*11980 -> 2396000 | J29: 1750000 | O29: =H29+J29+K29+L29+M29+N29 -> 4146000 | P29: =S29 -> 6460000 | Q29: =P29-O29 -> 2314000 | S29: 6460000
A30: 23 | B30: 42356 | C30: Đóng hàng XK 19/12 | D30: DRYU2902310 | E30: Phủ Lý, Hà Nam | H30: =G30*11980 -> 0 | J30: 0 | O30: =H30+J30+K30+L30+M30+N30 -> 0 | P30: =S30 -> 0 | Q30: =P30-O30 -> 0 | S30: 0
A31: 24 | B31: 42357 | C31: Trả hàng sáng 20/12 | D31: TCLU3239002 | E31: Thạch Thất, Hà Nội | H31: =G31*11980 -> 0 | J31: 1740000 | O31: =H31+J31+K31+L31+M31+N31 -> 1740000 | P31: =S31 -> 3000000 | Q31: =P31-O31 -> 1260000 | S31: 3000000
A32: 25 | B32: 42357 | C32: Đóng hàng XK 20/12 | D32: MRKU9690929 | E32: Hoa Lư, Ninh Bình | H32: =G32*11980 -> 0 | J32: 0 | O32: =H32+J32+K32+L32+M32+N32 -> 0 | P32: =S32 -> 4200000 | Q32: =P32-O32 -> 4200000 | S32: 4200000
A33: 26 | B33: 42358 | C33: Trả hàng sáng 21/12 | D33: WFHU1352303 | E33: KCN Đại Đồng, Bắc Ninh | G33: 263 | H33: =G33*11980 -> 3150740 | J33: 1740000 | O33: =H33+J33+K33+L33+M33+N33 -> 4890740 | P33: =S33 -> 3360000 | Q33: =P33-O33 -> -1530740 | S33: 3360000
A34: 27 | B34: 42358 | C34: Đóng hàng XK 21/12 | D34: PONU0910407 | E34: Hoa Lư, Ninh Bình | H34: =G34*11980 -> 0 | J34: 0 | O34: =H34+J34+K34+L34+M34+N34 -> 0 | P34: =S34 -> 4200000 | Q34: =P34-O34 -> 4200000 | S34: 4200000
A35: 28 | B35: 42359 | C35: Trả hàng + đóng hàng 22/12 | D35: DRYU2923329 | E35: Bắc Ninh - Hà Nam | G35: 260 | H35: =G35*11980 -> 3114800 | J35: 1750000 | O35: =H35+J35+K35+L35+M35+N35 -> 4864800 | P35: =S35 -> 6060000 | Q35: =P35-O35 -> 1195200 | S35: 6060000
A36: 29 | B36: 42361 | C36: Trả hàng NK sáng 24/12 | D36: WHLU5448977 | E36: Mộc Châu, Sơn La | H36: =G36*11980 -> 0 | J36: 3100000 | O36: =H36+J36+K36+L36+M36+N36 -> 3100000 | P36: =S36 -> 13636364 | Q36: =P36-O36 -> 10536364 | S36: 13636364
A37: 30 | B37: 42363 | C37: Trả hàng NK 27/12 | D37: TEMU9033741 | E37: Mường Chài, Điện Biên | G37: 593 | H37: =G37*11980 -> 7104140 | J37: =8000000+8000000 -> 16000000 | O37: =H37+J37+K37+L37+M37+N37 -> 23104140 | P37: =S37 -> 45000000 | Q37: =P37-O37 -> 21895860 | S37: 45000000
B38: 42353 | C38: Chữa máy phát | L38: 600000 | O38: =H38+J38+K38+L38+M38+N38 -> 600000 | Q38: =P38-O38 -> -600000
B39: 42357 | C39: Mua dây 8FK 2035 (xịn) | L39: 450000 | O39: =H39+J39+K39+L39+M39+N39 -> 450000 | Q39: =P39-O39 -> -450000
B40: 42364 | C40: Thay lọc nhớt + lọc dầu diezel | N40: 2200000 | O40: =H40+J40+K40+L40+M40+N40 -> 2200000 | Q40: =P40-O40 -> -2200000
C41: Tiền gửi xe | L41: 1200000 | O41: =H41+J41+K41+L41+M41+N41 -> 1200000 | Q41: =P41-O41 -> -1200000
O42: =H42+J42+K42+L42+M42+N42 -> 0 | Q42: =P42-O42 -> 0
...

Sheet T01.2016
A1: Bảng theo dõi doanh thu/ chi phí theo phương tiện vận chuyển
A2: Biển số xe: 15C - 136.31
B3: THÁNG 01.2016
A5: STT | B5: Ngày tháng | C5: Diễn giải | D5: Số cont | E5: Tuyến đường vận chuyển | F5: Khoảng cách (km) | G5: Chi phí | O5: Tổng chi phí | P5: Cước vận chuyển | Q5: Lợi nhuận gộp
G6: Dầu (l) | H6: Dầu (đồng) | I6: Mức TTBQ | J6: Đi đường | K6: Lương lx | L6: Sửa chữa | M6: Lốp | N6: Dầu máy
A8: 1 | C8: Lưu ca xe từ 29/12 đến 11/01 | D8: TEMU9033741 | J8: 5200000 | O8: =N8+M8+L8+K8+J8+H8 -> 5200000 | P8: =13*1800000 -> 23400000 | Q8: =P8-O8 -> 18200000
A9: 2 | B9: 42380 | C9: Đóng hàng chè sáng 14/01 | D9: BMOU6025986 | E9: Mỹ Bằng, Yên Sơn, Tuyên Quang | G9: 620 | H9: =G9*11110 -> 6888200 | J9: 2420000 | O9: =N9+M9+L9+K9+J9+H9 -> 9308200 | P9: 9545455 | Q9: =P9-O9 -> 237255
A10: 3 | B10: 42383 | C10: Đóng hàng than hoạt tính chiều 15/01 | D10: DRYU9590683 | E10: TP. Trà Vinh | J10: 960000 | O10: =N10+M10+L10+K10+J10+H10 -> 960000 | P10: 4000000 | Q10: =P10-O10 -> 3040000
A11: 4 | B11: 42385 | C11: Trả hàng sáng 17/01 | D11: DRYU9961948 | E11: Văn Lâm, Hưng Yên | J11: 970000 | O11: =N11+M11+L11+K11+J11+H11 -> 970000 | P11: 3190909 | Q11: =P11-O11 -> 2220909
A12: 5 | B12: 42387 | C12: Trả hàng Vietsun sáng 19/01 | D12: DRYU9969682 | E12: Mỹ Hào, Hưng Yên | J12: 800000 | O12: =N12+M12+L12+K12+J12+H12 -> 800000 | P12: 2918182 | Q12: =P12-O12 -> 2118182
A13: 6 | B13: 42388 | C13: Đóng hàng chè sáng 20/01 | D13: TCKU2077804 | E13: Mỹ Bằng, Yên Sơn, Tuyên Quang | J13: 2300000 | O13: =N13+M13+L13+K13+J13+H13 -> 2300000 | P13: 9090909 | Q13: =P13-O13 -> 6790909
A14: 7 | B14: 42388 | C14: Đóng hàng XK sáng 21/01 | D14: ZIMU1414597 | E14: Mỹ Hào, Hưng Yên | J14: 810000 | O14: =N14+M14+L14+K14+J14+H14 -> 810000 | P14: 3090909 | Q14: =P14-O14 -> 2280909
A15: 8 | B15: 42389 | C15: Đóng hàng chè sáng 22/01 | D15: TRHU2719899 | E15: Mỹ Bằng, Yên Sơn, Tuyên Quang | J15: 2320000 | O15: =N15+M15+L15+K15+J15+H15 -> 2320000 | P15: 9090909 | Q15: =P15-O15 -> 6770909
A16: 9 | B16: 42391 | C16: Trả hàng + đóng hàng KH sáng 23/01 | D16: SKLU1426219 | E16: KCN Hòa Xá, Nam Định | G16: 500 | H16: 5100000 | J16: 1200000 | O16: =N16+M16+L16+K16+J16+H16 -> 6300000 | P16: 5400000 | Q16: =P16-O16 -> -900000
A17: 10 | B17: 42391 | C17: Trả hàng + đóng hàng KH sáng 23/01 | D17: VSLU1048261 | E17: Phủ Lý, Hà Nam | P17: 0 | Q17: =P17-O17 -> 0
A18: 11 | B18: 42392 | C18: Trả hàng NK đêm 23/01 | D18: SITU2787335 | E18: Cảng Phà Đen, Hà Nội | J18: 1720000 | O18: =N18+M18+L18+K18+J18+H18 -> 1720000 | P18: 4300000 | Q18: =P18-O18 -> 2580000
A19: 12 | B19: 42392 | C19: Đóng hàng vôi XK sáng 24/01 | D19: EMCU3604017 | E19: Tam Điệp, Ninh Bình | O19: =N19+M19+L19+K19+J19+H19 -> 0 | P19: 3050000 | Q19: =P19-O19 -> 3050000
A20: 13 | B20: 42394 | C20: Trả hàng + đóng hàng KH sáng 26/01 | D20: VSLU9371400 | E20: KCN Đại Đồng, Bắc Ninh - Hà Nam | J20: 1740000 | O20: =N20+M20+L20+K20+J20+H20 -> 1740000 | P20: 5860000 | Q20: =P20-O20 -> 4120000
A21: 14 | B21: 42395 | C21: Trả hàng + đóng hàng KH sáng 27/01 | D21: DRYU3093972 | E21: KCN Đại Đồng, Bắc Ninh - Hà Nam | G21: 605 | H21: 6171000 | J21: 1750000 | O21: =N21+M21+L21+K21+J21+H21 -> 7921000 | P21: 5860000 | Q21: =P21-O21 -> -2061000
A22: 15 | B22: 42396 | C22: Đóng hàng sáng 28/01 | D22: YLMU8742545 | E22: KCN Quang Minh, Vĩnh Phúc | J22: 1100000 | O22: =N22+M22+L22+K22+J22+H22 -> 1100000 | P22: 4000000 | Q22: =P22-O22 -> 2900000
A23: 16 | B23: 42397 | C23: Trả hàng + đóng hàng KH sáng 29/01 | D23: GMDU2153911 | E23: KCN Tân Trường, Hải Dương - Hà Nam | J23: 1450000 | O23: =N23+M23+L23+K23+J23+H23 -> 1450000 | P23: 5180000 | Q23: =P23-O23 -> 3730000
A24: 17 | B24: 42399 | C24: Trả hàng + đóng hàng KH sáng 31/01 | D24: VSLU1041781 | E24: Hải Dương - Hà Nam | J24: 1400000 | O24: =N24+M24+L24+K24+J24+H24 -> 1400000 | P24: 5180000 | Q24: =P24-O24 -> 3780000
O25: =N25+M25+L25+K25+J25+H25 -> 0 | Q25: =P25-O25 -> 0
C26: Lương lái xe | K26: 9000000 | O26: =N26+M26+L26+K26+J26+H26 -> 9000000 | Q26: =P26-O26 -> -9000000
C27: Thay lọc nhớt | L27: 1100000 | O27: =N27+M27+L27+K27+J27+H27 -> 1100000 | Q27: =P27-O27 -> -1100000
C28: Thay lốp xe | L28: 5000000 | O28: =N28+M28+L28+K28+J28+H28 -> 5000000 | Q28: =P28-O28 -> -5000000
C29: Tiền gửi xe T1 | L29: 1200000 | O29: =N29+M29+L29+K29+J29+H29 -> 1200000 | Q29: =P29-O29 -> -1200000
C30: Thưởng Tết | K30: 7000000 | O30: =N30+M30+L30+K30+J30+H30 -> 7000000 | Q30: =P30-O30 -> -7000000
O31: =N31+M31+L31+K31+J31+H31 -> 0 | Q31: =P31-O31 -> 0
A32: TỔNG CỘNG | F32: =SUM(F9:F31) -> 0 | G32: =SUM(G9:G31) -> 1725 | H32: =SUM(H9:H31) -> 18159200 | I32: =SUM(I9:I31) -> 0 | J32: =SUM(J8:J31) -> 26140000 | K32: =SUM(K8:K31) -> 16000000 | L32: =SUM(L8:L31) -> 7300000 | M32: =SUM(M8:M31) -> 0 | N32: =SUM(N8:N31) -> 0 | O32: =SUM(O8:O31) -> 67599200 | P32: =SUM(P8:P31) -> 103157273 | Q32: =SUM(Q8:Q31) -> 35558073

Sheet T02.2016
A1: Bảng theo dõi doanh thu/ chi phí theo phương tiện vận chuyển
A2: Biển số xe: 15C - 136.31
A3: THÁNG 02.2016
A5: STT | B5: Ngày tháng | C5: Diễn giải | D5: Số cont | E5: Tuyến đường vận chuyển | F5: Khoảng cách (km) | G5: Chi phí | O5: Tổng chi phí | P5: Cước vận chuyển | Q5: Lợi nhuận gộp
G6: Dầu (l) | H6: Dầu (đồng) | I6: Mức TTBQ | J6: Đi đường | K6: Lương lx | L6: Sửa chữa | M6: Lốp | N6: Dầu máy
O7: =H7+J7+K7+L7+M7+N7 -> 0 | Q7: =P7-O7 -> 0
A8: 1 | B8: 42400 | C8: Trả hàng + đóng hàng KH sáng 01/02 | D8: VSLU3042719 | E8: Vũ Thư, Thái Bình - Hà Nam | J8: 1200000 | O8: =N8+M8+L8+K8+J8+H8 -> 1200000 | P8: 5500000 | Q8: =P8-O8 -> 4300000
A9: 2 | B9: 42401 | C9: Trả hàng + đóng hàng KH sáng 02/02 | D9: DRYU3093400 | E9: KCN Đại Đồng, Bắc Ninh - Hà Nam | J9: 1740000 | O9: =N9+M9+L9+K9+J9+H9 -> 1740000 | P9: 5860000 | Q9: =P9-O9 -> 4120000
A10: 3 | B10: 42402 | C10: Trả hàng + đóng hàng KH sáng 03/02 | D10: VSLU1046295 | E10: KCN Đại Đồng, Bắc Ninh - Hà Nam | J10: 1740000 | O10: =N10+M10+L10+K10+J10+H10 -> 1740000 | P10: 5860000 | Q10: =P10-O10 -> 4120000
A11: 4 | B11: 42402 | C11: Đóng hàng XK sáng 04/02 | D11: OOLU1801824 | E11: Mỹ Hào, Hưng Yên | G11: 530 | H11: 5406000 | J11: 810000 | O11: =N11+M11+L11+K11+J11+H11 -> 6216000 | P11: 3400000 | Q11: =P11-O11 -> -2816000
A12: 5 | B12: 42415 | C12: Đóng hàng tinh bột chiều 15/02 | D12: TCKU3471746 | E12: KCN Mỹ Phước 2, Bến Cát, BD | J12: 1900000 | O12: =N12+M12+L12+K12+J12+H12 -> 1900000 | P12: 5500000 | Q12: =P12-O12 -> 3600000
A13: 6 | B13: 42415 | C13: Trả hàng NK sáng 16/02 | D13: SEGU2563949 | E13: Cảng Phà Đen, Hà Nội | J13: 1740000 | O13: =N13+M13+L13+K13+J13+H13 -> 1740000 | P13: 4300000 | Q13: =P13-O13 -> 2560000
A14: 7 | B14: 42415 | C14: Đóng hàng KH chiều 16/02 | D14: NPLU2214334 | E14: Phủ Lý, Hà Nam | O14: =N14+M14+L14+K14+J14+H14 -> 0 | P14: 2850000 | Q14: =P14-O14 -> 2850000
A15: 8 | B15: 42416 | C15: Trả hàng Vietsun sáng 17/02 | D15: DRYU9170192 | E15: Mỹ Hào, Hưng Yên | J15: 1520000 | O15: =N15+M15+L15+K15+J15+H15 -> 1520000 | P15: 2918182 | Q15: =P15-O15 -> 1398182
A16: 9 | B16: 42416 | C16: Đóng hàng than hoạt tính chiều 17/02 | D16: DRYU9170192 | E16: TP. Trà Vinh | G16: 410 | H16: 3927800 | O16: =N16+M16+L16+K16+J16+H16 -> 3927800 | P16: 3000000 | Q16: =P16-O16 -> -927800
A17: 10 | B17: 42418 | C17: Trả hàng NK sáng 18/02 | D17: CMAU0854909 | E17: KCN Vân Trung, Việt Yên, Bắc Giang | J17: 1040000 | O17: =N17+M17+L17+K17+J17+H17 -> 1040000 | P17: 3500000 | Q17: =P17-O17 -> 2460000
A18: 11 | B18: 42418 | C18: Trả hàng NK sáng 19/02 | D18: SITU9030908 | E18: Mỹ Bằng, Yên Sơn, Tuyên Quang | J18: 2320000 | O18: =N18+M18+L18+K18+J18+H18 -> 2320000 | P18: 9545455 | Q18: =P18-O18 -> 7225455
A19: 12 | B19: 42418 | C19: Đóng hàng XK sáng 20/02 | D19: TGHU9610260 | E19: Phả Lại, Hải Dương | J19: 860000 | O19: =N19+M19+L19+K19+J19+H19 -> 860000 | P19: 3160000 | Q19: =P19-O19 -> 2300000
A20: 13 | B20: 42422 | C20: Trả hàng + đóng hàng KH 23/02 | D20: VSLU3041693 | E20: KCN Đại Đồng, Bắc Ninh - Hà Nam | J20: 1740000 | O20: =N20+M20+L20+K20+J20+H20 -> 1740000 | P20: 5720000 | Q20: =P20-O20 -> 3980000
A21: 14 | B21: 42424 | C21: Trả hàng NK sáng 25/02 | D21: WHLU5337232 | E21: TT Trần Phú, Văn Chấn, Yên Bái | G21: 575 | H21: 5508500 | J21: 2420000 | O21: =N21+M21+L21+K21+J21+H21 -> 7928500 | P21: 11818182 | Q21: =P21-O21 -> 3889682
A22: 15 | B22: 42425 | C22: Trả hàng + đóng hàng KH 26/02 | D22: VSLU2037111 | E22: Long Biên, Hà Nội - Hà Nam | J22: 1740000 | O22: =N22+M22+L22+K22+J22+H22 -> 1740000 | P22: 5640000 | Q22: =P22-O22 -> 3900000
A23: 16 | B23: 42426 | C23: Đóng hàng chè sáng 29/02 | D23: UETU2267549 | E23: Mỹ Bằng, Yên Sơn, Tuyên Quang | J23: 2320000 | O23: =N23+M23+L23+K23+J23+H23 -> 2320000 | P23: 8863636 | Q23: =P23-O23 -> 6543636
Q24: =P24-O24 -> 0
C25: Lương lái xe | K25: 9000000 | O25: =N25+M25+L25+K25+J25+H25 -> 9000000 | Q25: =P25-O25 -> -9000000
C26: Tiền gửi xe T2/2016 | L26: 1200000 | O26: =N26+M26+L26+K26+J26+H26 -> 1200000 | Q26: =P26-O26 -> -1200000
O29: =N29+M29+L29+K29+J29+H29 -> 0 | Q29: =P29-O29 -> 0
A30: TỔNG CỘNG | G30: =SUM(G7:G29) -> 1515 | H30: =SUM(H7:H29) -> 14842300 | I30: =SUM(I7:I29) -> 0 | J30: =SUM(J7:J29) -> 23090000 | K30: =SUM(K7:K29) -> 9000000 | L30: =SUM(L7:L29) -> 1200000 | M30: =SUM(M7:M29) -> 0 | N30: =SUM(N7:N29) -> 0 | ... Q30: =SUM(Q7:Q29) -> 39303155

Sheet 03-2016
A1: Bảng theo dõi doanh thu/ chi phí theo phương tiện vận chuyển
A2: Biển số xe: 15C - 136.31
A3: THÁNG 03.2016
A5: STT | B5: Ngày tháng | C5: Diễn giải | D5: Số cont | E5: Tuyến đường vận chuyển | F5: Khoảng cách (km) | G5: Chi phí | O5: Tổng chi phí | P5: Cước vận chuyển | Q5: Lợi nhuận gộp
G6: Dầu (l) | H6: Dầu (đồng) | I6: Mức TTBQ | J6: Đi đường | K6: Lương lx | L6: Sửa chữa | M6: Lốp | N6: Dầu máy
O7: =H7+J7+K7+L7+M7+N7 -> 0 | Q7: =P7-O7 -> 0
A8: 1 | B8: 42426 | C8: Đóng hàng XK sáng 03/03 | D8: WHLU0603005 | E8: Mỹ Hào, Hưng Yên | J8: 800000 | O8: =N8+M8+L8+K8+J8+H8 -> 800000 | P8: 3090909 | Q8: =P8-O8 -> 2290909
A9: 2 | B9: 42432 | C9: Đóng hàng XK đêm 03/03 | D9: CMAU1855751 | E9: Cầu Đá Bạc, Hải Phòng | J9: 300000 | O9: =N9+M9+L9+K9+J9+H9 -> 300000 | P9: 2000000 | Q9: =P9-O9 -> 1700000
A10: 3 | B10: 42433 | C10: Trả hàng NK sáng 05/03 | D10: SEGU1482204 | E10: ICD Mỹ Đình - Mỹ Hào, Hưng Yên | G10: 550 | H10: 5269000 | J10: 1120000 | O10: =N10+M10+L10+K10+J10+H10 -> 6389000 | P10: 4409091 | Q10: =P10-O10 -> -1979909
A11: 4 | B11: 42434 | C11: Trả hàng + đóng hàng KH 07/03 | D11: GMDU2151570 | E11: KCN Tân Trường, Hải Dương - Hà Nam | J11: 1670000 | O11: =N11+M11+L11+K11+J11+H11 -> 1670000 | P11: 5000000 | Q11: =P11-O11 -> 3330000
A12: 5 | B12: 42437 | C12: Trả hàng NK sáng 09/03 | D12: CAIU2046419 | E12: Phúc Xuyên, Hà Nội | J12: 1520000 | O12: =N12+M12+L12+K12+J12+H12 -> 1520000 | P12: 5200000 | Q12: =P12-O12 -> 3680000
A13: 6 | B13: 42437 | C13: Đóng hàng XK chiều 09/03 | D13: EITU0445561 | E13: Ngọc Hồi, Hà Nội | J13: 0 | O13: =N13+M13+L13+K13+J13+H13 -> 0 | P13: 0 | Q13: =P13-O13 -> 0
A14: 7 | B14: 42439 | C14: Trả hàng + đóng hàng KH 11/03 | D14: DRYU3095300 | E14: Ngọc Hồi, Thanh Trì, Hà Nội - Hà Nam | J14: =1120000+620000 -> 1740000 | O14: =N14+M14+L14+K14+J14+H14 -> 1740000 | P14: 5700000 | Q14: =P14-O14 -> 3960000
A15: 8 | B15: 42442 | C15: Trả hàng sáng 14/03 | D15: TCKU1525761 | E15: Kim Sơn, Ninh Bình | J15: 1200000 | O15: =N15+M15+L15+K15+J15+H15 -> 1200000 | P15: 5500000 | Q15: =P15-O15 -> 4300000
A16: 9 | B16: 42442 | C16: Đóng hàng vôi XK chiều 14/03 | D16: TCKU3059718 | E16: Tam Điệp, Ninh Bình | G16: 405 | H16: 3879900 | J16: 0 | O16: =N16+M16+L16+K16+J16+H16 -> 3879900 | P16: 0 | Q16: =P16-O16 -> -3879900
A17: 10 | B17: 42443 | C17: Đóng hàng XK sáng 16/03 | D17: KMTU9307742 | E17: Phả Lại, Hải Dương | J17: 660000 | O17: =N17+M17+L17+K17+J17+H17 -> 660000 | P17: 3160000 | Q17: =P17-O17 -> 2500000
A18: 11 | B18: 42443 | C18: Trả hàng NK 15/03 | D18: TGCU0188453 | E18: Cảng Phà Đen, Hà Nội | J18: 1740000 | O18: =N18+M18+L18+K18+J18+H18 -> 1740000 | P18: 4300000 | Q18: =P18-O18 -> 2560000
A19: 12 | B19: 42443 | C19: Đóng hàng vôi XK chiều 15/03 | D19: FCIU5845588 | E19: Tam Điệp, Ninh Bình | J19: 0 | O19: =N19+M19+L19+K19+J19+H19 -> 0 | P19: 2900000 | Q19: =P19-O19 -> 2900000
A20: 13 | B20: 42445 | C20: Trả hàng Vietsun sáng 17/03 | D20: DRYU9593403 | E20: Dị Sử, Mỹ Hào, Hưng Yên | J20: 1520000 | O20: =N20+M20+L20+K20+J20+H20 -> 1520000 | P20: 2790909 | Q20: =P20-O20 -> 1270909
A21: 14 | B21: 42447 | C21: Đóng than hoạt tính sáng 18/03 | D21: DRYU9593403 | E21: TP. Trà Vinh | J21: 0 | O21: =N21+M21+L21+K21+J21+H21 -> 0 | P21: 3000000 | Q21: =P21-O21 -> 3000000
A22: 15 | B22: 42450 | C22: Trả hàng sáng 19/03 | D22: EISU3907253 | E22: Thạch Bàn, Hà Nội | G22: 540 | H22: 5173200 | J22: 1740000 | O22: =N22+M22+L22+K22+J22+H22 -> 6913200 | P22: 3500000 | Q22: =P22-O22 -> -3413200
A23: 16 | B23: 42450 | C23: Đóng hàng vôi XK chiều 19/03 | D23: TEMU2325994 | E23: Tam Điệp, Ninh Bình | J23: 0 | O23: =N23+M23+L23+K23+J23+H23 -> 0 | P23: 2900000 | Q23: =P23-O23 -> 2900000
A24: 17 | B24: 42450 | C24: Trả hàng + đóng hàng KH 21/03 | D24: NSHU2700708 | E24: Trôi, Hà Nội | J24: 1740000 | O24: =N24+M24+L24+K24+J24+H24 -> 1740000 | P24: 5900000 | Q24: =P24-O24 -> 4160000
A25: 18 | B25: 42450 | C25: Trả hàng + đóng hàng KH 21/03 | D25: DRYU3094834 | E25: Tam Điệp, Ninh Bình | O25: =N25+M25+L25+K25+J25+H25 -> 0 | P25: 0 | Q25: =P25-O25 -> 0
A26: 19 | B26: 42450 | C26: Trả hàng Vietsun sáng 22/03 | D26: DRYU9592515 | E26: Mỹ Hào, Hưng Yên | J26: 800000 | O26: =N26+M26+L26+K26+J26+H26 -> 800000 | P26: 2790909 | Q26: =P26-O26 -> 1990909
A27: 20 | B27: 42452 | C27: Trả hàng sáng 23/03 | D27: DJLU5015945 | E27: Gia Lâm, Hà Nội | J27: 1120000 | O27: =N27+M27+L27+K27+J27+H27 -> 1120000 | P27: 3500000 | Q27: =P27-O27 -> 2380000
A28: 21 | B28: 42452 | C28: Trả hàng NK ngày 24/03 | D28: OOLU1382456 | E28: Sa Pa, Lào Cai | J28: 6500000 | O28: =N28+M28+L28+K28+J28+H28 -> 6500000 | P28: 25000000 | Q28: =P28-O28 -> 18500000
A29: 22 | B29: 42454 | C29: Trả hàng + đóng hàng KH 26/03 | D29: SITU2942832 | E29: Cầu Giấy, Hà Nội | G29: 505 | H29: 4984350 | J29: 1740000 | O29: =N29+M29+L29+K29+J29+H29 -> 6724350 | P29: 5900000 | Q29: =P29-O29 -> -824350
A30: 23 | B30: 42454 | C30: Trả hàng + đóng hàng KH 26/03 | D30: CBHU3802697 | E30: Tam Điệp, Ninh Bình | O30: =N30+M30+L30+K30+J30+H30 -> 0 | P30: 0 | Q30: =P30-O30 -> 0
A31: 24 | B31: 42457 | C31: Trả hàng + đóng hàng KH 29/03 | D31: DRYU2853303 | E31: KCN Đại Đồng, Bắc Ninh | J31: 1740000 | O31: =N31+M31+L31+K31+J31+H31 -> 1740000 | P31: 5500000 | Q31: =P31-O31 -> 3760000
A32: 25 | B32: 42457 | C32: Trả hàng + đóng hàng KH 29/03 | D32: DRYU2853303 | E32: Phủ Lý, Hà Nam | O32: =N32+M32+L32+K32+J32+H32 -> 0 | P32: 0 | Q32: =P32-O32 -> 0
A33: 26 | B33: 42458 | C33: Đóng hàng sáng 30/03 | D33: BMOU5445027 | E33: KCN VSIP, Thủy Nguyên, Hải Phòng | J33: 200000 | O33: =N33+M33+L33+K33+J33+H33 -> 200000 | P33: 1750000 | Q33: =P33-O33 -> 1550000
A34: 27 | B34: 42459 | C34: Trả hàng NK sáng 31/03 | D34: TGHU1534456 | E34: Cảng Phà Đen, Hà Nội | J34: 1120000 | O34: =N34+M34+L34+K34+J34+H34 -> 1120000 | P34: 4300000 | Q34: =P34-O34 -> 3180000
Q35: =P35-O35 -> 0
C36: Lương lái xe | K36: =25/27*9000000 -> 8333333.3 | O36: =N36+M36+L36+K36+J36+H36 -> 8333333.3 | Q36: =P36-O36 -> -8333333.3
C37: Sửa xe | L37: 400000 | O37: =N37+M37+L37+K37+J37+H37 -> 400000 | Q37: =P37-O37 -> -400000
C38: Rửa xe, bơm mỡ | L38: =330000+180000 -> 510000 | O38: =N38+M38+L38+K38+J38+H38 -> 510000 | Q38: =P38-O38 -> -510000
C39: Phí gửi xe | L39: =3960000/3 -> 1320000 | O39: =N39+M39+L39+K39+J39+H39 -> 1320000 | Q39: =P39-O39 -> -1320000
O40: =N40+M40+L40+K40+J40+H40 -> 0 | Q40: =P40-O40 -> 0 | R40: LK
A41: TỔNG CỘNG | G41: =SUM(G7:G40) -> 2000 | H41: =SUM(H7:H40) -> 19306450 | I41: =SUM(I7:I40) -> 0 | J41: =SUM(J7:J40) -> 28970000 | K41: =SUM(K7:K40) -> 8333333.3 | L41: =SUM(L7:L40) -> 2230000 | M41: =SUM(M7:M40) -> 0 | N41: =SUM(N7:N40) -> 0 | ... Q41: =SUM(Q7:Q40) -> 49252035 | R41: ='T01.2016'!Q32+'T02.2016'!Q30+'03-2016'!Q41 -> 1.2411326e+08 | S41: =R41/3 -> 41371088

Sheet 04-2016
A1: Bảng theo dõi doanh thu/ chi phí theo phương tiện vận chuyển
A2: Biển số xe: 15C - 136.31
A3: THÁNG 04.2016
A5: STT | B5: Ngày tháng | C5: Diễn giải | D5: Số cont | E5: Tuyến đường vận chuyển | F5: Khoảng cách (km) | G5: Chi phí | O5: Tổng chi phí | P5: Cước vận chuyển | Q5: Lợi nhuận gộp
G6: Dầu (l) | H6: Dầu (đồng) | I6: Mức TTBQ | J6: Đi đường | K6: Lương lx | L6: Sửa chữa | M6: Lốp | N6: Dầu máy
O7: =H7+J7+K7+L7+M7+N7 -> 0 | Q7: =P7-O7 -> 0
A8: 1 | B8: 42461 | C8: Trả hàng NK sáng 01/04 | D8: TRLU7311594 | E8: Quán Gỏi, Hải Dương | J8: 700000 | O8: =H8+J8+K8+L8+M8+N8 -> 700000 | P8: 3000000 | Q8: =P8-O8 -> 2300000
A9: 2 | B9: 42462 | C9: Trả hàng Vietsun sáng 04/04 | D9: DRYU9969830 | E9: Tân Quang, Văn Lâm, Hưng Yên | J9: 1640000 | O9: =H9+J9+K9+L9+M9+N9 -> 1640000 | P9: 2709091 | Q9: =P9-O9 -> 1069091
A10: 3 | B10: 42462 | C10: Đóng hàng than hoạt tính chiều 04/04 | D10: DRYU9969830 | E10: TP. Trà Vinh | J10: 0 | O10: =H10+J10+K10+L10+M10+N10 -> 0 | P10: 3000000 | Q10: =P10-O10 -> 3000000
A11: 4 | B11: 42465 | C11: Đóng hàng than hoạt tính chiều 05/04 | D11: TCNU9487045 | E11: TP. Trà Vinh | G11: 555 | H11: 5477850 | J11: 1040000 | O11: =H11+J11+K11+L11+M11+N11 -> 6517850 | P11: 3000000 | Q11: =P11-O11 -> -3517850
A12: 5 | B12: 42465 | C12: Trả hàng sáng 06/04 | D12: GMDU2151457 | E12: KCN Tân Trường, Hải Dương | J12: 1400000 | O12: =H12+J12+K12+L12+M12+N12 -> 1400000 | P12: 5100000 | Q12: =P12-O12 -> 3700000
A13: 6 | B13: 42465 | C13: Đóng hàng KH sáng 06/04 | D13: CBHU5844454 | E13: Tam Điệp, Ninh Bình | J13: 0 | O13: =H13+J13+K13+L13+M13+N13 -> 0 | P13: 0 | Q13: =P13-O13 -> 0
A14: 7 | B14: 42467 | C14: Trả hàng NK 08/04 | D14: CARU9972444 | E14: TX. Hồng Lĩnh, Hà Tĩnh | J14: 2500000 | O14: =H14+J14+K14+L14+M14+N14 -> 2500000 | P14: 9000000 | Q14: =P14-O14 -> 6500000
A15: 8 | B15: 42468 | C15: Trả hàng Vietsun sáng 09/04 | D15: DRYU9366457 | E15: KCN Quế Võ, Bắc Ninh | J15: 1040000 | O15: =H15+J15+K15+L15+M15+N15 -> 1040000 | P15: 3272727 | Q15: =P15-O15 -> 2232727
A16: 9 | B16: 42470 | C16: Trả hàng gạo tối 10/04 | D16: CAXU6311929 | E16: TP. Nam Định | J16: 1200000 | O16: =H16+J16+K16+L16+M16+N16 -> 1200000 | P16: 5200000 | Q16: =P16-O16 -> 4000000
A17: 10 | B17: 42470 | C17: Đóng hàng KH sáng 11/04 | D17: WHLU2899679 | E17: Tam Điệp, Ninh Bình | J17: 0 | O17: =H17+J17+K17+L17+M17+N17 -> 0 | P17: 0 | Q17: =P17-O17 -> 0
A18: 11 | B18: 42472 | C18: Trả hàng NK chiều 13/04 | D18: TRLU7025570 | E18: Quán Gỏi, Hải Dương | G18: 520 | H18: 5132400 | J18: 580000 | O18: =H18+J18+K18+L18+M18+N18 -> 5712400 | P18: 3000000 | Q18: =P18-O18 -> -2712400
A19: 12 | B19: 42473 | C19: Đóng hàng chè chiều 14/04 | D19: WHLU4307608 | E19: TT Trần Phú, Văn Chấn, Yên Bái | J19: 2480000 | O19: =H19+J19+K19+L19+M19+N19 -> 2480000 | P19: 10909091 | Q19: =P19-O19 -> 8429091
A20: 13 | B20: 42474 | C20: Trả hàng sáng 15/04 | D20: OOLU4370910 | E20: KCN Tây Nam, Phủ Lý, Hà Nam | J20: 1000000 | O20: =H20+J20+K20+L20+M20+N20 -> 1000000 | P20: 3600000 | Q20: =P20-O20 -> 2600000
A21: 14 | B21: 42479 | C21: Đóng hàng chè sáng 21/04 | D21: WHLU4249060 | E21: Thuận Châu, Sơn La | G21: 425 | H21: 4194750 | J21: 5340000 | O21: =H21+J21+K21+L21+M21+N21 -> 9534750 | P21: 22727273 | Q21: =P21-O21 -> 13192523
A22: 15 | B22: 42481 | C22: Trả hàng + đóng hàng 22/04 | D22: GMDU2151328 | E22: KCN Tân Trường, Hải Dương - Hà Nam | J22: 1470000 | O22: =H22+J22+K22+L22+M22+N22 -> 1470000 | P22: 5000000 | Q22: =P22-O22 -> 3530000
A23: 16 | B23: 42482 | C23: Trả hàng + đóng hàng KH 23/04 | D23: DRYU2923571 | E23: Mỹ Hào, Hưng Yên - Hà Nam | J23: 1400000 | O23: =H23+J23+K23+L23+M23+N23 -> 1400000 | P23: 5100000 | Q23: =P23-O23 -> 3700000
A24: 17 | B24: 42483 | C24: Trả hàng NK sáng 25/04 | D24: TWCU2047781 | E24: KCN VSIP, Thủy Nguyên, Hải Phòng | J24: 200000 | O24: =H24+J24+K24+L24+M24+N24 -> 200000 | P24: 1750000 | Q24: =P24-O24 -> 1550000
A25: 18 | B25: 42484 | C25: Trả hàng NK chiều 25/04 | D25: TWCU2041079 | E25: KCN VSIP, Thủy Nguyên, Hải Phòng | J25: 200000 | O25: =H25+J25+K25+L25+M25+N25 -> 200000 | P25: 1750000 | Q25: =P25-O25 -> 1550000
A26: 19 | B26: 42485 | C26: Đóng hàng XK sáng 26/04 | D26: TEMU6567764 | E26: Phả Lại, Hải Dương | J26: 740000 | O26: =H26+J26+K26+L26+M26+N26 -> 740000 | P26: 3240000 | Q26: =P26-O26 -> 2500000
A27: 20 | B27: 42485 | C27: Đóng hàng XK sáng 27/04 | D27: KMTU9281484 | E27: Phả Lại, Hải Dương | G27: 580 | H27: 6014600 | J27: 740000 | O27: =H27+J27+K27+L27+M27+N27 -> 6754600 | P27: 3240000 | Q27: =P27-O27 -> -3514600
A28: 21 | B28: 42487 | C28: Đóng hàng XK sáng 28/04 | D28: DFSU1101658 | E28: Mỹ Hào, Hưng Yên | J28: 890000 | O28: =H28+J28+K28+L28+M28+N28 -> 890000 | P28: 3090909 | Q28: =P28-O28 -> 2200909
A29: 22 | B29: 42488 | C29: Đóng hàng chè sáng 29/04 | D29: APZU3595025 | E29: Đại Từ, Thái Nguyên | J29: 1680000 | O29: =H29+J29+K29+L29+M29+N29 -> 1680000 | P29: 5400000 | Q29: =P29-O29 -> 3720000
A30: 23 | B30: 42494 | C30: Trả hàng NK sáng 30/04 | D30: SITU9097115 | E30: KCN VSIP, Thủy Nguyên, Hải Phòng | J30: 200000 | O30: =H30+J30+K30+L30+M30+N30 -> 200000 | P30: 1750000 | Q30: =P30-O30 -> 1550000
O31: =H31+J31+K31+L31+M31+N31 -> 0 | Q31: =P31-O31 -> 0
C32: Phí gửi xe T4/2016 | L32: 1320000 | O32: =H32+J32+K32+L32+M32+N32 -> 1320000 | Q32: =P32-O32 -> -1320000
C33: Lương + thưởng 30/4 | K33: 9500000 | O33: =H33+J33+K33+L33+M33+N33 -> 9500000 | Q33: =P33-O33 -> -9500000
C34: Mua chắn bùn xe | L34: 400000 | O34: =N34+M34+L34+K34+J34+H34 -> 400000 | Q34: =P34-O34 -> -400000
C35: Thay săm + yếm xe | L35: 520000 | O35: =N35+M35+L35+K35+J35+H35 -> 520000 | Q35: =P35-O35 -> -520000
C36: Nộp lệ phí sử dụng đường bộ | N36: 17303000 | O36: =N36+M36+L36+K36+J36+H36 -> 17303000 | Q36: =P36-O36 -> -17303000
C37: Lệ phí đăng kiểm đầu kéo | L37: 610000 | O37: =N37+M37+L37+K37+J37+H37 -> 610000 | Q37: =P37-O37 -> -610000
C38: Tiền dịch vụ đăng kiểm | L38: 200000 | O38: =N38+M38+L38+K38+J38+H38 -> 200000 | Q38: =P38-O38 -> -200000
C39: Phí bảo hiểm | N39: =26815000-3200000 -> 23615000 | O39: =N39+M39+L39+K39+J39+H39 -> 23615000 | Q39: =P39-O39 -> -23615000
C40: Mua 1/2 phuy nhớt máy | N40: 6000000 | O40: =N40+M40+L40+K40+J40+H40 -> 6000000 | Q40: =P40-O40 -> -6000000
O41: =N41+M41+L41+K41+J41+H41 -> 0 | Q41: =P41-O41 -> 0
...

Sheet 05-2016
A1: Bảng theo dõi doanh thu/ chi phí theo phương tiện vận chuyển
A2: Biển số xe: 15C - 136.31
A3: THÁNG 05.2016
A5: STT | B5: Ngày tháng | C5: Diễn giải | D5: Số cont | E5: Tuyến đường vận chuyển | F5: Khoảng cách (km) | G5: Chi phí | O5: Tổng chi phí | P5: Cước vận chuyển | Q5: Lợi nhuận gộp
G6: Dầu (l) | H6: Dầu (đồng) | I6: Mức TTBQ | J6: Đi đường | K6: Lương lx | L6: Sửa chữa | M6: Lốp | N6: Dầu máy
O7: =H7+J7+K7+L7+M7+N7 -> 0 | Q7: =P7-O7 -> 0
A8: 1 | B8: 42494 | C8: Trả hàng KH sáng 02/05 | D8: TRHU3321019 | E8: KCN Yên Phong, Bắc Ninh | G8: 455 | H8: 4718350 | J8: 1700000 | O8: =H8+J8+K8+L8+M8+N8 -> 6418350 | P8: 3100000 | Q8: =P8-O8 -> -3318350
A9: 2 | B9: 42494 | C9: Đóng hàng KH sáng 02/05 | D9: CAXU6725908 | E9: Tam Điệp, Ninh Bình | J9: 0 | O9: =H9+J9+K9+L9+M9+N9 -> 0 | P9: 2800000 | Q9: =P9-O9 -> 2800000
A10: 3 | B10: 42494 | C10: Đóng hàng chè sáng 05/05 | D10: DFSU4106838 | E10: TT Trần Phú, Văn Chấn, Yên Bái | J10: 2400000 | O10: =H10+J10+K10+L10+M10+N10 -> 2400000 | P10: 10909091 | Q10: =P10-O10 -> 8509091
A11: 4 | B11: 42495 | C11: Trả hàng 06/05 | D11: VSLU4495495 | E11: KCN Hà Bình Phương, Thường Tín, HN | J11: 1700000 | O11: =H11+J11+K11+L11+M11+N11 -> 1700000 | P11: 5700000 | Q11: =P11-O11 -> 4000000
A12: 5 | B12: 42495 | C12: Đóng hàng KH 06/05 | D12: KCSU3062908 | E12: Tam Điệp, Ninh Bình | J12: 0 | O12: =H12+J12+K12+L12+M12+N12 -> 0 | P12: 0 | Q12: =P12-O12 -> 0
A13: 6 | B13: 42496 | C13: Trả hàng NK sáng 07/05 | D13: SITU2938004 | E13: Cảng Phà Đen, Hà Nội | J13: 1700000 | O13: =H13+J13+K13+L13+M13+N13 -> 1700000 | P13: 4300000 | Q13: =P13-O13 -> 2600000
A14: 7 | B14: 42496 | C14: Đóng hàng KH chiều 07/05 | D14: WFHU1358322 | E14: Phủ Lý, Hà Nam | J14: 0 | O14: =H14+J14+K14+L14+M14+N14 -> 0 | P14: 2600000 | Q14: =P14-O14 -> 2600000
A15: 8 | B15: 42499 | C15: Trả hàng sáng 09/05 | D15: DRYU3093400 | E15: Gia Lâm, Hà Nội | J15: 1700000 | O15: =H15+J15+K15+L15+M15+N15 -> 1700000 | P15: 5600000 | Q15: =P15-O15 -> 3900000
A16: 9 | B16: 42499 | C16: Đóng hàng KH chiều 09/05 | D16: KCSU2104133 | E16: Tam Điệp, Ninh Bình | J16: 0 | O16: =H16+J16+K16+L16+M16+N16 -> 0 | P16: 0 | Q16: =P16-O16 -> 0
A17: 10 | B17: 42500 | C17: Trả hàng + đóng hàng KH 11/05 | D17: VSLU1045302 | E17: KCN Đại Đồng, Bắc Ninh - Hà Nam | G17: 600 | H17: 6612000 | J17: 1700000 | O17: =H17+J17+K17+L17+M17+N17 -> 8312000 | P17: 5500000 | Q17: =P17-O17 -> -2812000
A18: 11 | B18: 42501 | C18: Trả hàng NK sáng 12/05 | D18: TEMU4647372 | E18: KCN VSIP, Thủy Nguyên, Hải Phòng | J18: 200000 | O18: =H18+J18+K18+L18+M18+N18 -> 200000 | P18: 1400000 | Q18: =P18-O18 -> 1200000
A19: 12 | B19: 42502 | C19: Đóng hàng chè sáng 13/05 | D19: APHU7326470 | E19: Phủ Lỗ, Sóc Sơn, Hà Nội | J19: 1280000 | O19: =H19+J19+K19+L19+M19+N19 -> 1280000 | P19: 4400000 | Q19: =P19-O19 -> 3120000
A20: 13 | B20: 42503 | C20: Trả hàng + đóng hàng KH 14/05 | D20: DRYU3094773 | E20: KCN Quế Võ, Bắc Ninh - Hà Nam | J20: 1700000 | O20: =H20+J20+K20+L20+M20+N20 -> 1700000 | P20: 5500000 | Q20: =P20-O20 -> 3800000
A21: 14 | B21: 42507 | C21: Trả hàng NK sáng 18/05 | D21: SITU2850818 | E21: Cảng Phà Đen, Hà Nội | J21: 1280000 | O21: =H21+J21+K21+L21+M21+N21 -> 1280000 | P21: 4300000 | Q21: =P21-O21 -> 3020000
A22: 15 | B22: 42508 | C22: Trả hàng + đóng hàng KH 19/05 | D22: GMDU2415755 | E22: Văn Lâm, Hưng Yên - Hà Nam | J22: 1400000 | O22: =H22+J22+K22+L22+M22+N22 -> 1400000 | P22: 5100000 | Q22: =P22-O22 -> 3700000
A23: 16 | B23: 42511 | C23: Trả hàng chiều 21/05 | D23: TCNU9494759 | E23: Chương Mỹ, Hà Nội | G23: 590 | H23: 6667000 | J23: 1280000 | O23: =H23+J23+K23+L23+M23+N23 -> 7947000 | P23: 4600000 | Q23: =P23-O23 -> -3347000
A24: 17 | B24: 42513 | C24: Trả hàng + đóng hàng KH 24/05 | D24: DRYU3095574 | E24: KCN Hà Bình Phương, Hà Nội - Hà Nam | J24: 1700000 | O24: =H24+J24+K24+L24+M24+N24 -> 1700000 | P24: 5600000 | Q24: =P24-O24 -> 3900000
A25: 18 | B25: 42514 | C25: Trả hàng NK tối 24/05 | D25: EISU9126480 | E25: Ngọc Hồi, Hà Nội | J25: 1280000 | O25: =H25+J25+K25+L25+M25+N25 -> 1280000 | P25: 4300000 | Q25: =P25-O25 -> 3020000
A26: 19 | B26: 42515 | C26: Trả hàng NK chiều 26/05 | D26: WFHU1352495 | E26: Mỹ Bằng, Yên Sơn, Tuyên Quang | J26: 2600000 | O26: =H26+J26+K26+L26+M26+N26 -> 2600000 | P26: 6318182 | Q26: =P26-O26 -> 3718182
A27: 20 | B27: 42515 | C27: Đóng hàng bột đá 27/05 | D27: WFHU1352495 | E27: Phủ Lý, Hà Nam | J27: 0 | O27: =H27+J27+K27+L27+M27+N27 -> 0 | P27: 2600000 | Q27: =P27-O27 -> 2600000
A28: 21 | B28: 42518 | C28: Trả hàng NK chiều 30/05 | D28: DRYU3094984 | E28: Tân Sơn, Phú Thọ | J28: 2000000 | O28: =H28+J28+K28+L28+M28+N28 -> 2000000 | P28: 6000000 | Q28: =P28-O28 -> 4000000
A29: 22 | B29: 42520 | C29: Đóng hàng bột đá 31/05 | D29: DRYU3094984 | E29: Phủ Lý, Hà Nam | G29: 506 | H29: 5717800 | J29: 0 | O29: =H29+J29+K29+L29+M29+N29 -> 5717800 | P29: 2600000 | Q29: =P29-O29 -> -3117800
C30: Phí gửi xe T5/2016 | L30: 1320000 | O30: =H30+J30+K30+L30+M30+N30 -> 1320000 | Q30: =P30-O30 -> -1320000
C31: Lương 05.2016 | K31: 8653846 | O31: =H31+J31+K31+L31+M31+N31 -> 8653846 | Q31: =P31-O31 -> -8653846
C32: Thanh toán phí dịch vụ duy trì máy chủ + phí đường truyền | L32: 1254000 | O32: =H32+J32+K32+L32+M32+N32 -> 1254000 | Q32: =P32-O32 -> -1254000
C33: Lọc nhớt + lọc dầu xe 15C136.31 | N33: 2950000 | O33: =H33+J33+K33+L33+M33+N33 -> 2950000 | Q33: =P33-O33 -> -2950000
C34: Thanh toán tiền sửa xe 15C136.31 | L34: 5060000 | O34: =H34+J34+K34+L34+M34+N34 -> 5060000 | Q34: =P34-O34 -> -5060000
C35: Bơm mỡ xe 15C136.31 | L35: 180000 | O35: =H35+J35+K35+L35+M35+N35 -> 180000 | Q35: =P35-O35 -> -180000
C36: Trả tiền sửa xe 15C136.31 ( Xử lí ống dầu) | L36: 400000 | O36: =H36+J36+K36+L36+M36+N36 -> 400000 | Q36: =P36-O36 -> -400000
O37: =H37+J37+K37+L37+M37+N37 -> 0 | Q37: =P37-O37 -> 0
O38: =H38+J38+K38+L38+M38+N38 -> 0 | Q38: =P38-O38 -> 0
A39: TỔNG CỘNG | G39: =SUM(G7:G38) -> 2151 | H39: =SUM(H7:H38) -> 23715150 | I39: =SUM(I7:I38) -> 0 | J39: =SUM(J7:J38) -> 25620000 | K39: =SUM(K7:K38) -> 8653846 | L39: =SUM(L7:L38) -> 8214000 | M39: =SUM(M7:M38) -> 0 | N39: =SUM(N7:N38) -> 2950000 | ... Q39: =SUM(Q7:Q38) -> 24074277

Sheet 06-2016
A1: Bảng theo dõi doanh thu/ chi phí theo phương tiện vận chuyển
A2: Biển số xe: 15C - 136.31
A3: THÁNG 06.2016
A5: STT | B5: Ngày tháng | C5: Diễn giải | D5: Số cont | E5: Tuyến đường vận chuyển | F5: Khoảng cách (km) | G5: Chi phí | O5: Tổng chi phí | P5: Cước vận chuyển | Q5: Lợi nhuận gộp
G6: Dầu (l) | H6: Dầu (đồng) | I6: Mức TTBQ | J6: Đi đường | K6: Lương lx | L6: Sửa chữa | M6: Lốp | N6: Dầu máy
O7: =H7+J7+K7+L7+M7+N7 -> 0 | Q7: =P7-O7 -> 0
A8: 1 | B8: 42524 | C8: Trả hàng Vietsun sáng 03/06 | D8: DRYU9718964 | E8: Mỹ Hào, Hưng Yên | J8: 890000 | O8: =H8+J8+K8+L8+M8+N8 -> 890000 | P8: 2663636 | Q8: =P8-O8 -> 1773636 | R8: 2663636
A9: 2 | B9: 42525 | C9: Trả hàng NK tối 04/06 | D9: DFSU1146138 | E9: Long Biên, Hà Nội | J9: 1700000 | O9: =H9+J9+K9+L9+M9+N9 -> 1700000 | P9: 3200000 | Q9: =P9-O9 -> 1500000 | R9: 3200000
A10: 3 | B10: 42525 | C10: Đóng hàng KH 05/06 | D10: WFHU1356335 | E10: Phủ Lý, Hà Nam | O10: =H10+J10+K10+L10+M10+N10 -> 0 | P10: 2600000 | Q10: =P10-O10 -> 2600000 | R10: 2600000
A11: 4 | B11: 42527 | C11: Đóng hàng chè sáng 07/06 | D11: APZU3684307 | E11: Đồng Hỷ, Thái Nguyên | J11: 1680000 | O11: =H11+J11+K11+L11+M11+N11 -> 1680000 | P11: 5272727 | Q11: =P11-O11 -> 3592727 | R11: 5272727
A12: 5 | B12: 42528 | C12: Trả hàng + đóng hàng KH 08/06 | D12: CWFU3815507 | E12: Kim Động, Hưng Yên | G12: 450 | H12: 5355000 | J12: 1400000 | O12: =H12+J12+K12+L12+M12+N12 -> 6755000 | P12: 5200000 | Q12: =P12-O12 -> -1555000 | R12: 5200000
A13: 6 | B13: 42528 | C13: Trả hàng + đóng hàng KH 08/06 | D13: DRYU3094562 | E13: Phủ Lý, Hà Nam | O13: =H13+J13+K13+L13+M13+N13 -> 0 | P13: 0 | Q13: =P13-O13 -> 0 | R13: 0
A14: 7 | B14: 42528 | C14: Đóng hàng chè sáng 09/06 | D14: WHSU2022617 | E14: TT Trần Phú, Văn Chấn, Yên Bái | J14: 2200000 | O14: =H14+J14+K14+L14+M14+N14 -> 2200000 | P14: 10454545 | Q14: =P14-O14 -> 8254545 | R14: 10454545
A15: 8 | B15: 42530 | C15: Trả hàng + đóng hàng KH 10/06 | D15: CAIU2094058 | E15: Nam Định - Hà Nam | J15: 1200000 | O15: =H15+J15+K15+L15+M15+N15 -> 1200000 | P15: 5200000 | Q15: =P15-O15 -> 4000000 | R15: 5200000
A16: 9 | B16: 42532 | C16: Đóng hàng chè sáng 12/06 | D16: APHU6821226 | E16: Phủ Lỗ, Sóc Sơn, Hà Nội | J16: 1280000 | O16: =H16+J16+K16+L16+M16+N16 -> 1280000 | P16: 4400000 | Q16: =P16-O16 -> 3120000 | R16: 4400000
A17: 10 | B17: 42534 | C17: Trả hàng + đóng hàng KH 14/06 | D17: WFHU1352793 | E17: Như Quỳnh, Hưng Yên - Hà Nam | J17: 1700000 | O17: =H17+J17+K17+L17+M17+N17 -> 1700000 | P17: 5200000 | Q17: =P17-O17 -> 3500000 | R17: 5200000
A18: 11 | B18: 42535 | C18: Trả hàng sáng 15/06 | D18: DRYU9174644 | E18: Ngũ Hiệp, Thanh Trì, Hà Nội | G18: 480 | H18: 5712000 | J18: 1280000 | O18: =H18+J18+K18+L18+M18+N18 -> 6992000 | P18: 3327273 | Q18: =P18-O18 -> -3664727 | R18: 3327273
A19: 12 | B19: 42536 | C19: Trả hàng + đóng hàng KH 16/06 | D19: TRHU1344530 | E19: KCN Phố Nối, Hưng Yên - Hà Nam | J19: 1400000 | O19: =H19+J19+K19+L19+M19+N19 -> 1400000 | P19: 5000000 | Q19: =P19-O19 -> 3600000 | R19: 5000000
A20: 13 | B20: 42537 | C20: Trả hàng sáng 17/06 | D20: WFHU5141778 | E20: Phú Lãm, Hà Đông, Hà Nội | J20: 1280000 | O20: =H20+J20+K20+L20+M20+N20 -> 1280000 | P20: 3572727 | Q20: =P20-O20 -> 2292727 | R20: 3572727
A21: 14 | B21: 42538 | C21: Trả hàng + đóng hàng KH 18/06 | D21: SEGU1220251 | E21: Xuân Quang, Văn Giang, Hưng Yên | J21: 1700000 | O21: =H21+J21+K21+L21+M21+N21 -> 1700000 | P21: 5800000 | Q21: =P21-O21 -> 4100000 | R21: 5800000
A22: 15 | B22: 42538 | C22: Trả hàng + đóng hàng KH 18/06 | D22: MSCU2930384 | E22: Phủ Lý, Hà Nam | O22: =H22+J22+K22+L22+M22+N22 -> 0 | P22: 0 | Q22: =P22-O22 -> 0 | R22: 0
A23: 16 | B23: 42549 | C23: Trả hàng + đóng hàng KH 29/06 | D23: WHLU2311764 | E23: KCN Đại Đồng, Bắc Ninh - Hà Nam | G23: 146 | H23: 2057890 | J23: 1700000 | O23: =H23+J23+K23+L23+M23+N23 -> 3757890 | P23: 5500000 | Q23: =P23-O23 -> 1742110 | R23: 5500000
A24: 17 | B24: 42550 | C24: Trả hàng sáng 30/06 | D24: VSLU2000600 | E24: KCN Đại Đồng, Bắc Ninh | J24: 1700000 | O24: =H24+J24+K24+L24+M24+N24 -> 1700000 | P24: 5400000 | Q24: =P24-O24 -> 3700000 | R24: 5400000
A25: 18 | B25: 42550 | C25: Đóng hàng KH chiều 30/06 | D25: DRYU3093930 | E25: Phủ Lý, Hà Nam | O25: =H25+J25+K25+L25+M25+N25 -> 0 | P25: 0 | Q25: =P25-O25 -> 0 | R25: 0
A26: 19 | B26: 42551 | G26: 130 | H26: 1597700 | O26: =H26+J26+K26+L26+M26+N26 -> 1597700 | Q26: =P26-O26 -> -1597700
C27: Lương 06.2016 | G27: 130 | H27: =G27*12290 -> 1597700 | K27: =5538462+692308 -> 6230770 | O27: =H27+J27+K27+L27+M27+N27 -> 7828470 | Q27: =P27-O27 -> -7828470
C28: Nộp tiền biên bản phạt xe 15C136.31 lấy đăng kiểm đầu kéo về | L28: 350000 | O28: =H28+J28+K28+L28+M28+N28 -> 350000 | Q28: =P28-O28 -> -350000
C29: Sửa chữa xe 15C136.31 | L29: 200000 | O29: =H29+J29+K29+L29+M29+N29 -> 200000 | Q29: =P29-O29 -> -200000
C30: Nộp tiền biên bản lấy đăng kiểm Romooc xe 15C136.31 về | L30: 900000 | O30: =H30+J30+K30+L30+M30+N30 -> 900000 | Q30: =P30-O30 -> -900000
C31: Sử̉a xe 15C136.31 | L31: 350000 | O31: =H31+J31+K31+L31+M31+N31 -> 350000 | Q31: =P31-O31 -> -350000
C32: Chuyển bình dầu diesel xe 15C136.31 | L32: 100000 | O32: =H32+J32+K32+L32+M32+N32 -> 100000 | Q32: =P32-O32 -> -100000
C33: Căn chỉnh cầu trục xe 15C136.31 | L33: 490000 | O33: =H33+J33+K33+L33+M33+N33 -> 490000 | Q33: =P33-O33 -> -490000
C34: Mua 4 bình ắc quy 100A cho xe 15C136.31 | L34: 7800000 | O34: =H34+J34+K34+L34+M34+N34 -> 7800000 | Q34: =P34-O34 -> -7800000
C35: Thu lại tiền bán 3 bình ắc quy xe 15C136.31 | O35: =H35+J35+K35+L35+M35+N35 -> 0 | Q35: 900000
C36: Phí gửi xe T06.2016 | L36: 1320000 | O36: =H36+J36+K36+L36+M36+N36 -> 1320000 | Q36: =P36-O36 -> -1320000
A37: TỔNG CỘNG | G37: =SUM(G7:G36) -> 1336 | H37: =SUM(H7:H36) -> 16320290 | I37: =SUM(I7:I36) -> 0 | J37: =SUM(J7:J36) -> 21110000 | K37: =SUM(K7:K36) -> 6230770 | L37: =SUM(L7:L36) -> 11510000 | M37: =SUM(M7:M36) -> 0 | N37: =SUM(N7:N36) -> 0 | ... Q37: =SUM(Q7:Q36) -> 18519848

Sheet 07-2016
A1: Bảng theo dõi doanh thu/ chi phí theo phương tiện vận chuyển
A2: Biển số xe: 15C - 136.31
A3: THÁNG 07.2016
A5: STT | B5: Ngày tháng | C5: Diễn giải | D5: Số cont | E5: Tuyến đường vận chuyển | F5: Khoảng cách (km) | G5: Chi phí | O5: Tổng chi phí | P5: Cước vận chuyển | Q5: Lợi nhuận gộp
G6: Dầu (l) | H6: Dầu (đồng) | I6: Mức TTBQ | J6: Đi đường | K6: Lương lx | L6: Sửa chữa | M6: Lốp | N6: Dầu máy
O7: =H7+J7+K7+L7+M7+N7 -> 0 | Q7: =P7-O7 -> 0
A8: 1 | B8: 42551 | C8: Trả hàng sáng 01/07 | D8: VSLU4490472 | E8: KCN Đại Đồng, Bắc Ninh | J8: 1700000 | O8: =H8+J8+K8+L8+M8+N8 -> 1700000 | P8: 5600000 | Q8: =P8-O8 -> 3900000
A9: 2 | B9: 42551 | C9: Đóng hàng KH chiều 01/07 | D9: EGSU3027980 | E9: Tam Điệp, Ninh Bình | J9: 0 | O9: =H9+J9+K9+L9+M9+N9 -> 0 | P9: 0 | Q9: =P9-O9 -> 0
A10: 3 | B10: 42555 | C10: Trả hàng + đóng hàng KH 05/07 | D10: DRYU2924433 | E10: KCN Đại Đồng, Bắc Ninh - Hà Nam | G10: 150 | H10: 1843500 | J10: 1700000 | O10: =H10+J10+K10+L10+M10+N10 -> 3543500 | P10: 5500000 | Q10: =P10-O10 -> 1956500
A11: 4 | B11: 42556 | C11: Trả hàng + đóng hàng KH 06/07 | D11: TCKU3475248 | E11: KCN Đại Đồng, Bắc Ninh - Hà Nam | G11: 130 | H11: 1597700 | J11: 1700000 | O11: =H11+J11+K11+L11+M11+N11 -> 3297700 | P11: 5500000 | Q11: =P11-O11 -> 2202300
A12: 5 | B12: 42557 | C12: Trả hàng + đóng hàng KH 07/07 | D12: DRYU2902054 | E12: Như Quỳnh, Hưng Yên - Hà Nam | G12: 156 | H12: 1917240 | J12: 1700000 | O12: =H12+J12+K12+L12+M12+N12 -> 3617240 | P12: 5200000 | Q12: =P12-O12 -> 1582760
A13: 6 | B13: 42557 | C13: Đóng hàng xỉ bọt sáng 08/07 | D13: BMOU6364001 | E13: Phả Lại, Hải Dương | G13: 121 | H13: 1487090 | J13: 750000 | O13: =H13+J13+K13+L13+M13+N13 -> 2237090 | P13: 3240000 | Q13: =P13-O13 -> 1002910
A14: 7 | B14: 42559 | C14: Trả hàng NK sáng 09/07 | D14: SEGU1933674 | E14: Xuân Quang, Văn Giang, Hưng Yên | G14: 74 | H14: 909460 | J14: 1700000 | O14: =H14+J14+K14+L14+M14+N14 -> 2609460 | P14: 3200000 | Q14: =P14-O14 -> 590540
A15: 8 | B15: 42559 | C15: Trả hàng chiều 09/07 | D15: DRYU3095825 | E15: Phủ Lý, Hà Nam | G15: 131 | H15: 1609990 | J15: 0 | O15: =H15+J15+K15+L15+M15+N15 -> 1609990 | P15: 2600000 | Q15: =P15-O15 -> 990010
A16: 9 | B16: 42562 | C16: Trả hàng + đóng hàng KH 11/07 | D16: DRYU3093951 | E16: Cảng Phà Đen, Hà Nội - Hà Nam | J16: 1700000 | O16: =H16+J16+K16+L16+M16+N16 -> 1700000 | P16: 5500000 | Q16: =P16-O16 -> 3800000
A17: 10 | B17: 42562 | C17: Trả hàng + đóng hàng KH sáng 12/07 | D17: VSLU4493810 | E17: Mỹ Hào, Hưng Yên - Hà Nam | J17: 1400000 | O17: =H17+J17+K17+L17+M17+N17 -> 1400000 | P17: 5000000 | Q17: =P17-O17 -> 3600000
A18: 11 | B18: 42563 | C18: Trả hàng Vietsun sáng 13/07 | D18: DRYU9968726 | E18: KCN Tiên Sơn, Bắc Ninh - Hà Nam | G18: 266 | H18: 3269140 | J18: 1280000 | O18: =H18+J18+K18+L18+M18+N18 -> 4549140 | P18: 3754545 | Q18: =P18-O18 -> -794595
A19: 12 | B19: 42564 | C19: Đóng hàng KH Vietsun chiều 13/07 | D19: DRYU9968726 | E19: KCN Tiên Sơn, Bắc Ninh - Hà Nam | J19: 0 | O19: =H19+J19+K19+L19+M19+N19 -> 0 | P19: 1636364 | Q19: =P19-O19 -> 1636364
A20: 13 | B20: 42564 | C20: Đóng hàng chè sáng 14/07 | D20: DFSU3077735 | E20: Mộc Châu, Sơn La - Phủ Lỗ, Sóc Sơn | J20: 3000000 | O20: =H20+J20+K20+L20+M20+N20 -> 3000000 | P20: 14090909 | Q20: =P20-O20 -> 11090909
A21: 14 | B21: 42568 | C21: Trả hàng + đóng hàng KH 18/07 | D21: DRYU2923099 | E21: KCN Ngọc Hồi, Thanh Trì, HN - Hà Nam | G21: 326 | H21: 4006540 | J21: 1700000 | O21: =H21+J21+K21+L21+M21+N21 -> 5706540 | P21: 5500000 | Q21: =P21-O21 -> -206540
A22: 15 | B22: 42569 | C22: Trả hàng Vietsun sáng 19/07 | D22: DRYU9168488 | E22: KCN Đồng Văn, Duy Tiên, Hà Nam | J22: 1280000 | O22: =H22+J22+K22+L22+M22+N22 -> 1280000 | P22: 3545455 | Q22: =P22-O22 -> 2265455
A23: 16 | B23: 42570 | C23: Trả hàng + đóng hàng KH 20/07 | D23: DRYU3094840 | E23: Xuân Mai, Hà Nội - Hà Nam | J23: 1600000 | O23: =H23+J23+K23+L23+M23+N23 -> 1600000 | P23: 5800000 | Q23: =P23-O23 -> 4200000
A24: 17 | B24: 42571 | C24: Đóng hàng chè sáng 21/07 | D24: SEGU4243728 | E24: Mỹ Bằng, Yên Sơn, Tuyên Quang | G24: 190 | H24: 2335100 | J24: 1950000 | O24: =H24+J24+K24+L24+M24+N24 -> 4285100 | P24: 8181818 | Q24: =P24-O24 -> 3896718
A25: 18 | B25: 42572 | C25: Trả hàng + đóng hàng KH 22/07 | D25: DRYU2853242 | E25: KCN Ngọc Hồi, Hà Nội - Hà Nam | J25: 1600000 | O25: =H25+J25+K25+L25+M25+N25 -> 1600000 | P25: 5200000 | Q25: =P25-O25 -> 3600000
A26: 19 | B26: 42573 | C26: Trả hàng + đóng hàng KH 23/07 | D26: GMDU2141124 | E26: Hà Đông, Hà Nội - Hà Nam | G26: 320 | H26: 3932800 | J26: 1600000 | O26: =H26+J26+K26+L26+M26+N26 -> 5532800 | P26: 5300000 | Q26: =P26-O26 -> -232800
A27: 20 | B27: 42575 | C27: Trả hàng NK sáng 24/07 | D27: DYLU2130057 | E27: Bát Tràng, Hà Nội | G27: 232 | H27: 2851280 | J27: 1600000 | O27: =H27+J27+K27+L27+M27+N27 -> 4451280 | P27: 5600000 | Q27: =P27-O27 -> 1148720
A28: 21 | B28: 42575 | C28: Đóng hàng KH chiều 24/07 | D28: TRHU1344490 | E28: Phủ Lý, Hà Nam | J28: 0 | O28: =H28+J28+K28+L28+M28+N28 -> 0 | P28: 0 | Q28: =P28-O28 -> 0
A29: 22 | B29: 42576 | C29: Đóng hàng chè sáng 26/07 | D29: PONU7558788 | E29: Mỹ Bằng, Yên Sơn, Tuyên Quang | J29: 1950000 | O29: =H29+J29+K29+L29+M29+N29 -> 1950000 | P29: 8181818 | Q29: =P29-O29 -> 6231818
A30: 23 | B30: 42577 | C30: Trả hàng + đóng hàng KH 27/07 | D30: VSLU1046572 | E30: KCN Đại Đồng, Bắc Ninh - Hà Nam | J30: 1600000 | O30: =H30+J30+K30+L30+M30+N30 -> 1600000 | P30: 5200000 | Q30: =P30-O30 -> 3600000
A31: 24 | B31: 42578 | C31: Trả hàng sáng 28/07 | D31: UETU2229045 | E31: cảng Phà Đen, Hà Nội | G31: 295 | H31: 3625550 | J31: 1600000 | O31: =H31+J31+K31+L31+M31+N31 -> 5225550 | P31: 4000000 | Q31: =P31-O31 -> -1225550
A32: 25 | B32: 42578 | C32: Đóng hàng vôi KH chiều 28/07 | D32: WHLU2934846 | E32: Phủ Lý, Hà Nam | G32: 270 | H32: 3318300 | J32: 0 | O32: =H32+J32+K32+L32+M32+N32 -> 3318300 | P32: 2400000 | Q32: =P32-O32 -> -918300
A33: 26 | B33: 42581 | C33: Trả hàng sáng 30/07 | D33: WHLU5381385 | E33: KCN Tiên Sơn, Bắc Ninh | J33: 830000 | O33: =H33+J33+K33+L33+M33+N33 -> 830000 | P33: 3500000 | Q33: =P33-O33 -> 2670000
A34: 27 | B34: 42581 | C34: Trả hàng NK sáng 31/07 | D34: TSLU0534134 | E34: cảng Phà Đen, Hà Nội | G34: 162 | H34: =G34*12290 -> 1990980 | J34: 1230000 | O34: =H34+J34+K34+L34+M34+N34 -> 3220980 | P34: 4000000 | Q34: =P34-O34 -> 779020
C35: Lương 06.2016 | K35: =346154+2711000+5884615 -> 8941769 | O35: =H35+J35+K35+L35+M35+N35 -> 8941769 | Q35: =P35-O35 -> -8941769
C36: 2 texamatic (dầu bót lái) | N36: 240000 | O36: =H36+J36+K36+L36+M36+N36 -> 240000 | Q36: =P36-O36 -> -240000
C37: Đóng số lốp xe thành 295/75R22.5 | L37: 1500000 | O37: =H37+J37+K37+L37+M37+N37 -> 1500000 | Q37: =P37-O37 -> -1500000
C38: Làm lốp, cứu hộ xe | L38: 450000 | O38: =H38+J38+K38+L38+M38+N38 -> 450000 | Q38: =P38-O38 -> -450000
C39: Thay motor gió | L39: 700000 | O39: =H39+J39+K39+L39+M39+N39 -> 700000 | Q39: =P39-O39 -> -700000
C40: Sửa bình gạt mưa | L40: 100000 | O40: =H40+J40+K40+L40+M40+N40 -> 100000 | Q40: =P40-O40 -> -100000
C41: Lắp đèn, phiếu, hàn cửa, thay đảo lốp, rửa xe | L41: 980000 | O41: =H41+J41+K41+L41+M41+N41 -> 980000 | Q41: =P41-O41 -> -980000
...

Sheet 08-2016
A1: Bảng theo dõi doanh thu/ chi phí theo phương tiện vận chuyển
A2: Biển số xe: 15C - 136.31
A3: THÁNG 08.2016
A5: STT | B5: Ngày tháng | C5: Diễn giải | D5: Số cont | E5: Tuyến đường vận chuyển | F5: Khoảng cách (km) | G5: Chi phí | O5: Tổng chi phí | P5: Cước vận chuyển | Q5: Lợi nhuận gộp
G6: Dầu (l) | H6: Dầu (đồng) | I6: Mức TTBQ | J6: Đi đường | K6: Lương lx | L6: Sửa chữa | M6: Lốp | N6: Dầu máy
O7: =H7+J7+K7+L7+M7+N7 -> 0 | Q7: =P7-O7 -> 0
A8: 1 | B8: 42583 | C8: Đóng hàng XK sáng 02/08 | D8: OOLU8596845 | E8: KCN Châu Sơn, Phủ Lý, Hà Nam | J8: 950000 | O8: =H8+J8+K8+L8+M8+N8 -> 950000 | P8: 3600000 | Q8: =P8-O8 -> 2650000
A9: 2 | B9: 42585 | C9: Đóng hàng sáng 03/08 | D9: TCNU7387221 | E9: Phủ Lỗ, Sóc Sơn, Hà Nội | G9: 180 | H9: 2212200 | J9: 850000 | O9: =H9+J9+K9+L9+M9+N9 -> 3062200 | P9: 4200000 | Q9: =P9-O9 -> 1137800
A10: 3 | B10: 42585 | C10: Trả hàng sáng 04/08 | D10: UACU3600367 | E10: Thường Tín, Hà Nội | J10: 1600000 | O10: =H10+J10+K10+L10+M10+N10 -> 1600000 | P10: 3100000 | Q10: =P10-O10 -> 1500000
A11: 4 | B11: 42585 | C11: Đóng hàng KH chiều 04/08 | D11: DRYU3093632 | E11: Phủ Lý, Hà Nam | J11: 0 | O11: =H11+J11+K11+L11+M11+N11 -> 0 | P11: 2500000 | Q11: =P11-O11 -> 2500000
A12: 5 | B12: 42587 | C12: Trả hàng + đóng hàng KH 06/08 | D12: DRYU2853290 | E12: Văn Lâm, Hưng Yên - Hà Nam | J12: 1600000 | O12: =H12+J12+K12+L12+M12+N12 -> 1600000 | P12: 5000000
A13: 6 | B13: 42589 | C13: Trả hàng + đóng hàng KH 08/08 | D13: DRYU2923360 | E13: KCN Tiên Sơn, Bắc Ninh - Hà Nam | G13: 241 | H13: 2810060 | J13: 1600000 | O13: =H13+J13+K13+L13+M13+N13 -> 4410060 | P13: 5200000 | Q13: =P13-O13 -> 789940
A14: 7 | B14: 42590 | C14: Trả hàng + đóng hàng KH 09/08 | D14: VSLU3037712 | E14: KCN Đại Đồng Bắc Ninh - Hà Nam | J14: 1600000 | O14: =H14+J14+K14+L14+M14+N14 -> 1600000 | P14: 5200000 | Q14: =P14-O14 -> 3600000
A15: 8 | B15: 42591 | C15: Trả hàng + đóng hàng KH 10/08 | D15: WFHU1352725 | E15: KCN Đại Đồng, Bắc Ninh - Hà Nam | J15: 1600000 | O15: =H15+J15+K15+L15+M15+N15 -> 1600000 | P15: 5200000 | Q15: =P15-O15 -> 3600000
A16: 9 | B16: 42592 | C16: Đóng hàng chè chiều 11/08 | D16: FSCU8715530 | E16: Mỹ Bằng, Yên Sơn, Tuyên Quang | G16: 250 | H16: 2915000 | J16: 1950000 | O16: =H16+J16+K16+L16+M16+N16 -> 4865000 | P16: 8181818 | Q16: =P16-O16 -> 3316818
A17: 10 | B17: 42595 | C17: Trả hàng sáng 13/08 | D17: DYLU2111709 | E17: Bát Tràng, Hà Nội | G17: 309 | H17: 3602940 | J17: 1600000 | O17: =H17+J17+K17+L17+M17+N17 -> 5202940 | P17: 5600000 | Q17: =P17-O17 -> 397060
A18: 11 | B18: 42595 | C18: Đóng hàng bột đá chiều 13/08 | D18: DRYU2852225 | E18: Phủ Lý, Hà Nam | J18: 0 | O18: =H18+J18+K18+L18+M18+N18 -> 0 | P18: 0 | Q18: =P18-O18 -> 0
A19: 12 | B19: 42595 | C19: Trả hàng sáng 14/08 | D19: TEMU4705592 | E19: Bát Tràng, Hà Nội | J19: 1600000 | O19: =H19+J19+K19+L19+M19+N19 -> 1600000 | P19: 5600000 | Q19: =P19-O19 -> 4000000
A20: 13 | B20: 42595 | C20: Đóng hàng bột đá chiều 14/08 | D20: GMDU2403585 | E20: Phủ Lý, Hà Nam | J20: 0 | O20: =H20+J20+K20+L20+M20+N20 -> 0 | P20: 0 | Q20: =P20-O20 -> 0
A21: 14 | B21: 42597 | C21: Trả hàng + đóng hàng chè 16/08 | D21: TGHU7743514 | E21: Mỹ Bằng, Yên Sơn, Tuyên Quang | G21: 243 | H21: 2833380 | J21: 1950000 | O21: =H21+J21+K21+L21+M21+N21 -> 4783380 | P21: 8181818 | Q21: =P21-O21 -> 3398438
A22: 15 | B22: 42598 | C22: Trả hàng sáng 17/08 | D22: DRYU9590683 | E22: KCN Quế Võ, Bắc Ninh | J22: 830000 | O22: =H22+J22+K22+L22+M22+N22 -> 830000 | P22: 3381818 | Q22: =P22-O22 -> 2551818
A23: 16 | B23: 42599 | C23: Trả hàng + đóng hàng KH 18/08 | D23: DRYU2853200 | E23: Dị Sử, Mỹ Hào, Hưng Yên - Hà Nam | G23: 262 | H23: 3054920 | J23: 1370000 | O23: =H23+J23+K23+L23+M23+N23 -> 4424920 | P23: 4800000 | Q23: =P23-O23 -> 375080
A24: 17 | B24: 42600 | C24: Đóng hàng chè sáng 20/08 | D24: APHU7016540 | E24: Vân Hồ, Sơn La | J24: 3000000 | O24: =H24+J24+K24+L24+M24+N24 -> 3000000 | P24: 14090909 | Q24: =P24-O24 -> 11090909
A25: 18 | B25: 42604 | C25: Trả hàng sáng 22/08 | D25: DRYU9169910 | E25: Chương Mỹ, Hà Nội | G25: 134 | H25: 1595940 | J25: 2030000 | O25: =H25+J25+K25+L25+M25+N25 -> 3625940 | P25: 3854545 | Q25: =P25-O25 -> 228605
A26: 19 | B26: 42604 | C26: Đóng hàng KH chiều 22/08 | D26: DRYU9169910 | E26: KCN Tân Quang, Văn Lâm, Hưng Yên | J26: 0 | O26: =H26+J26+K26+L26+M26+N26 -> 0 | P26: 1953636 | Q26: =P26-O26 -> 1953636
A27: 20 | B27: 42604 | C27: Trả hàng + đóng hàng KH 23/08 | D27: DRYU3026070 | E27: Thanh Trì, Hà Nội - Hà Nam | G27: 221 | H27: 2632110 | J27: 1600000 | O27: =H27+J27+K27+L27+M27+N27 -> 4232110 | P27: 5200000 | Q27: =P27-O27 -> 967890
A28: 21 | B28: 42605 | C28: Trả hàng + đóng hàng KH 24/08 | D28: WFHU1356211 | E28: Dị Sử, Mỹ Hào, Hưng Yên - Hà Nam | J28: 1300000 | O28: =H28+J28+K28+L28+M28+N28 -> 1300000 | P28: 4800000 | Q28: =P28-O28 -> 3500000
A29: 22 | B29: 42607 | C29: Đóng hàng 25/08 | D29: KMTU7374206 | E29: KCN VSIP Hải Phòng | G29: 219.48 | H29: 2614007 | J29: 200000 | O29: =H29+J29+K29+L29+M29+N29 -> 2814007 | P29: 1400000 | Q29: =P29-O29 -> -1414007
A30: 23 | B30: 42607 | C30: Trả hàng Vietsun sáng 26/08 | D30: DRYU9718157 | E30: KCN Đồng Văn, Hà Nam | J30: 1020000 | O30: =H30+J30+K30+L30+M30+N30 -> 1020000 | P30: 3545455 | Q30: =P30-O30 -> 2525455
A31: 24 | B31: 42608 | C31: Trả hàng + đóng hàng KH 27/08 | D31: WFHU1352710 | E31: KCN Đại Đồng, Bắc Ninh - Hà Nam | G31: 229 | H31: 2727390 | J31: 1600000 | O31: =H31+J31+K31+L31+M31+N31 -> 4327390 | P31: 5200000 | Q31: =P31-O31 -> 872610
A32: 25 | B32: 42611 | C32: Trả hàng sáng 30/08 | D32: WFHU5142265 | E32: KCN Đồng Văn, Hà Nam | J32: 950000 | O32: =H32+J32+K32+L32+M32+N32 -> 950000 | P32: 3545455 | Q32: =P32-O32 -> 2595455
A33: 26 | B33: 42611 | C33: Đóng hàng xỉ bọt 31/08 | D33: SKHU9202599 | E33: Phả Lại, Hải Dương | J33: 690000 | O33: =H33+J33+K33+L33+M33+N33 -> 690000 | P33: 3181818 | Q33: =P33-O33 -> 2491818
O34: =H34+J34+K34+L34+M34+N34 -> 0 | Q34: =P34-O34 -> 0
C35: Thay cao su tay giằng móc, DV căn chỉnh móc xe | L35: 2170000 | O35: =H35+J35+K35+L35+M35+N35 -> 2170000 | Q35: =P35-O35 -> -2170000
C36: Lọc dầu nhớt | L36: 2780000 | O36: =H36+J36+K36+L36+M36+N36 -> 2780000 | Q36: =P36-O36 -> -2780000
C37: Phí gửi xe tháng 08.2016 | L37: 1320000 | O37: =H37+J37+K37+L37+M37+N37 -> 1320000 | Q37: =P37-O37 -> -1320000
C38: Thanh toán tiền sửa xe 15C-136.31 (đôi chắn bùn lò xo, ống chắn bùn) | L38: 1600000 | O38: =H38+J38+K38+L38+M38+N38 -> 1600000 | Q38: =P38-O38 -> -1600000
C39: Đưa anh Hà thay đèn led, thay motor bơm nước, công thợ xe | L39: 800000 | O39: =H39+J39+K39+L39+M39+N39 -> 800000 | Q39: =P39-O39 -> -800000
C40: Thanh toán tiền sửa xe 15C-136.31 ngày 1/8 (bi vai cầu, bi quả dứa, bi đỡ đầu quả dứa, phớt đầu cầu, công thợ hạ cầu, dầu rửa, giẻ lau, keo, dầu cầu) | L40: 5700000 | O40: =H40+J40+K40+L40+M40+N40 -> 5700000 | Q40: =P40-O40 -> -5700000
C41: Thanh toán tiền sửa xe 15C-136.31 (phớt may ơ, công thợ thay phớt, dầu mồi may ơ) | L41: 700000 | O41: =H41+J41+K41+L41+M41+N41 -> 700000 | Q41: =P41-O41 -> -700000
...

Sheet 09-2016
A1: Bảng theo dõi doanh thu/ chi phí theo phương tiện vận chuyển
A2: Biển số xe: 15C - 136.31
A3: THÁNG 09.2016
A5: STT | B5: Ngày tháng | C5: Diễn giải | D5: Số cont | E5: Tuyến đường vận chuyển | F5: Khoảng cách (km) | G5: Chi phí | O5: Tổng chi phí | P5: Cước vận chuyển | Q5: Lợi nhuận gộp
G6: Dầu (l) | H6: Dầu (đồng) | I6: Mức TTBQ | J6: Đi đường | K6: Lương lx | L6: Sửa chữa | M6: Lốp | N6: Dầu máy
O7: =H7+J7+K7+L7+M7+N7 -> 0 | Q7: =P7-O7 -> 0
A8: 1 | B8: 42613 | C8: Trả hàng sáng 01/09 | D8: UACU3216460 | E8: Thường Tín, Hà Nội | J8: 1600000 | O8: =H8+J8+K8+L8+M8+N8 -> 1600000 | P8: 3300000 | Q8: =P8-O8 -> 1700000
A9: 2 | B9: 42613 | C9: Đóng hàng sáng 01/09 | D9: GMDU2418266 | E9: Hoa Lư, Ninh Bình | J9: 0 | O9: =H9+J9+K9+L9+M9+N9 -> 0 | P9: 2700000 | Q9: =P9-O9 -> 2700000
A10: 3 | B10: 42614 | C10: Trả hàng + đóng hàng KH 03/09 | D10: WFHU1356612 | E10: KCN Phố Nối A, HY - Hà Nam | G10: 301 | H10: 3584910 | J10: 1300000 | O10: =H10+J10+K10+L10+M10+N10 -> 4884910 | P10: 4800000 | Q10: =P10-O10 -> -84910
A11: 4 | B11: 42614 | C11: Trả hàng sáng 05/09 | D11: MSKU6528881 | E11: Văn Lâm, Hưng Yên | J11: 1250000 | O11: =H11+J11+K11+L11+M11+N11 -> 1250000 | P11: 3400000 | Q11: =P11-O11 -> 2150000
A12: 5 | B12: 42618 | C12: Trả hàng + đóng hàng KH 06/09 | D12: WFHU1358261 | E12: KCN Đại Đồng, Bắc Ninh - Hà Nam | J12: 1600000 | O12: =H12+J12+K12+L12+M12+N12 -> 1600000 | P12: 5200000
A13: 6 | B13: 42619 | C13: Đóng hàng chè chiều 07/09 | D13: TCNU4840714 | E13: Mỹ Bằng, Yên Sơn, Tuyên Quang | G13: 330 | H13: 4085400 | J13: 1950000 | O13: =H13+J13+K13+L13+M13+N13 -> 6035400 | P13: 8181818 | Q13: =P13-O13 -> 2146418
A14: 7 | B14: 42620 | C14: Trả hàng Vietsun sáng 08/09 | D14: DRYU9718120 | E14: KCN Quế Võ, Bắc Ninh | J14: 830000 | O14: =H14+J14+K14+L14+M14+N14 -> 830000 | P14: 3381818 | Q14: =P14-O14 -> 2551818
A15: 8 | B15: 42621 | C15: Trả hàng + đóng hàng KH 09/09 | D15: GMDU2152598 | E15: Mỹ Hào, Hưng Yên - Hà Nam | G15: 285 | H15: 3528300 | J15: 1300000 | O15: =H15+J15+K15+L15+M15+N15 -> 4828300 | P15: 4700000 | Q15: =P15-O15 -> -128300
A16: 9 | B16: 42622 | C16: Đóng hàng sáng 10/09 | D16: TCNU6063927 | E16: Ngã tư Ắc Quy, Hải Phòng | J16: 200000 | O16: =H16+J16+K16+L16+M16+N16 -> 200000 | P16: 1100000 | Q16: =P16-O16 -> 900000
A17: 10 | B17: 42623 | C17: Trả hàng NK 10/09 | D17: MSKU2261441 | E17: Thanh Trì, Hà Nội | G17: 195 | H17: 2414100 | J17: 1600000 | O17: =H17+J17+K17+L17+M17+N17 -> 4014100 | P17: 5200000 | Q17: =P17-O17 -> 1185900
A18: 11 | B18: 42623 | C18: Đóng hàng bột đá 11/09 | D18: DRYU3094449 | E18: Phủ Lý, Hà Nam | J18: 0 | O18: =H18+J18+K18+L18+M18+N18 -> 0 | P18: 0 | Q18: =P18-O18 -> 0
A19: 12 | B19: 42625 | C19: Trả hàng + đóng hàng KH 13/09 | D19: VSLU1015910 | E19: Quốc Oai, Hà Nội - Hà Nam | J19: 1600000 | O19: =H19+J19+K19+L19+M19+N19 -> 1600000 | P19: 5300000 | Q19: =P19-O19 -> 3700000
A20: 13 | B20: 42626 | C20: Đóng hàng chè sáng 14/09 | D20: DFSU7760415 | E20: Mộc Châu, Sơn La | J20: 3000000 | O20: =H20+J20+K20+L20+M20+N20 -> 3000000 | P20: 14318182 | Q20: =P20-O20 -> 11318182
A21: 14 | B21: 42628 | C21: Trả hàng NK chiều 15/09 | D21: SKLU1114252 | E21: Mỹ Hào, Hưng Yên | G21: 256 | H21: 3169280 | J21: 840000 | O21: =H21+J21+K21+L21+M21+N21 -> 4009280 | P21: 2800000 | Q21: =P21-O21 -> -1209280
