Workbook

Sheet T12.2015
A1: Bảng theo dõi doanh thu/ chi phí theo phương tiện vận chuyển
A2: Biển số xe: 15C - 139.82
H3: THÁNG 12/2015
A5: STT | B5: Ngày tháng | C5: Diễn giải | D5: Số cont | E5: Tuyến đường vận chuyển | F5: Khoảng cách (km) | G5: Chi phí | O5: Tổng chi phí | P5: Cước vận chuyển | Q5: Lợi nhuận gộp
G6: Dầu (l) | H6: Dầu (đồng) | I6: Mức TTBQ | J6: Đi đường | K6: Lương lx | L6: Sửa chữa | M6: Lốp | N6: Dầu máy
O7: =H7+J7+K7+L7+M7+N7 -> 0 | Q7: =P7-O7 -> 0
A8: 1 | B8: 42705 | C8: Đóng hàng chè sáng 01/12 | D8: WHLU0542640 | E8: Mỹ Bằng, Yên Sơn, Tuyên Quang | G8: 0 | H8: =G8*13510 -> 0 | J8: 2320000 | O8: =H8+J8+K8+L8+M8+N8 -> 2320000 | P8: =S8 -> 9545455 | Q8: =P8-O8 -> 7225455 | S8: 9545455
A9: 2 | B9: 42339 | C9: Trả hàng + đóng hàng 02/12 | D9: VSLU4026224 | E9: Long Biên, Hà Nội - Hà Nam | G9: 260 | H9: =G9*13510 -> 3512600 | J9: 1750000 | O9: =H9+J9+K9+L9+M9+N9 -> 5262600 | P9: =S9 -> 5960000 | Q9: =P9-O9 -> 697400 | S9: 5960000
A10: 3 | B10: 42340 | C10: Trả hàng NK sáng 03/12 | D10: KKTU7978160 | E10: Kim Bảng, Hà Nam | H10: =G10*13510 -> 0 | J10: 1430000 | O10: =H10+J10+K10+L10+M10+N10 -> 1430000 | P10: =S10 -> 3800000 | Q10: =P10-O10 -> 2370000 | S10: 3800000
A11: 4 | B11: 42340 | C11: Đóng hàng bột đá chiều 03/12 | D11: DRYU3022433 | E11: Phủ Lý, Hà Nam | H11: =G11*13510 -> 0 | J11: 0 | O11: =H11+J11+K11+L11+M11+N11 -> 0 | P11: =S11 -> 3000000 | Q11: =P11-O11 -> 3000000 | S11: 3000000
A12: 5 | B12: 42341 | C12: Trả hàng + đóng hàng 04/12 | D12: CAXU6113950 | E12: Văn Lâm, Hưng Yên - Hà Nam | H12: =G12*13510 -> 0 | J12: 1510000 | O12: =H12+J12+K12+L12+M12+N12 -> 1510000 | P12: =S12 -> 5580000 | Q12: =P12-O12 -> 4070000 | S12: 5580000
A13: 6 | B13: 42342 | C13: Trả hàng + đóng hàng 05/12 | D13: GMDU2409583 | E13: Bắc Ninh - Hà Nam | G13: 340 | H13: =G13*13230 -> 4498200 | J13: 1740000 | O13: =H13+J13+K13+L13+M13+N13 -> 6238200 | P13: =S13 -> 6060000 | Q13: =P13-O13 -> -178200 | S13: 6060000
A14: 7 | B14: 42343 | C14: Trả hàng sáng 07/12 | D14: TCKU2640820 | E14: KCN Đại Đồng, Bắc Ninh | G14: 0 | H14: =G14*13230 -> 0 | J14: 1750000 | O14: =H14+J14+K14+L14+M14+N14 -> 1750000 | P14: =S14 -> 3360000 | Q14: =P14-O14 -> 1610000 | S14: 3360000
A15: 8 | B15: 42343 | C15: Đóng hàng XK 07/12 | D15: RFCU2241173 | E15: Hoa Lư, Ninh Bình | G15: 0 | H15: =G15*13230 -> 0 | J15: 0 | O15: =H15+J15+K15+L15+M15+N15 -> 0 | P15: =S15 -> 4200000 | Q15: =P15-O15 -> 4200000 | S15: 4200000
A16: 9 | B16: 42345 | C16: Trả hàng sáng 08/12 | D16: VSLU3031904 | E16: Phú Thị, Gia Lâm, Hà Nội | G16: 0 | H16: =G16*13230 -> 0 | J16: 1740000 | O16: =H16+J16+K16+L16+M16+N16 -> 1740000 | P16: =S16 -> 3240000 | Q16: =P16-O16 -> 1500000 | S16: 3240000
A17: 10 | B17: 42345 | C17: Đóng hàng XK 08/12 | D17: TCKU3592563 | E17: Hoa Lư, Ninh Bình | G17: 248 | H17: =G17*13230 -> 3281040 | J17: 0 | O17: =H17+J17+K17+L17+M17+N17 -> 3281040 | P17: =S17 -> 4200000 | Q17: =P17-O17 -> 918960 | S17: 4200000
A18: 11 | B18: 42347 | C18: Đóng hàng chè sáng 11/12 | D18: TCLU9112550 | E18: TX Nghĩa Lộ, Yên Bái | G18: 0 | H18: =G18*13230 -> 0 | J18: 2320000 | O18: =H18+J18+K18+L18+M18+N18 -> 2320000 | P18: =S18 -> 11363636 | Q18: =P18-O18 -> 9043636 | S18: 11363636
A19: 12 | B19: 42349 | C19: Đóng hàng chè sáng 14/12 | D19: TCNU8139960 | E19: Mỹ Bằng, Yên Sơn, Tuyên Quang | G19: 371 | H19: =G19*13230 -> 4908330 | J19: 2320000 | O19: =H19+J19+K19+L19+M19+N19 -> 7228330 | P19: =S19 -> 10000000 | Q19: =P19-O19 -> 2771670 | S19: 10000000
A20: 13 | B20: 42352 | C20: Trả hàng sáng 15/12 | D20: DRYU2924032 | E20: KCN Đại Đồng, Bắc Ninh | H20: =G20*13230 -> 0 | J20: 1520000 | O20: =H20+J20+K20+L20+M20+N20 -> 1520000 | P20: =S20 -> 6100000 | Q20: =P20-O20 -> 4580000 | S20: 6100000
A21: 14 | B21: 42352 | C21: Đóng hàng XK 15/12 | D21: AKLU6029108 | E21: Hoà Lạc, Hà Nội | H21: =G21*13230 -> 0 | J21: 0 | O21: =H21+J21+K21+L21+M21+N21 -> 0 | P21: =S21 -> 0 | Q21: =P21-O21 -> 0 | S21: 0
A22: 15 | B22: 42353 | C22: Trả hàng sáng 16/12 | D22: DRYU2923273 | E22: KCN Đại Đồng, Bắc Ninh | H22: =G22*13230 -> 0 | J22: 1520000 | O22: =H22+J22+K22+L22+M22+N22 -> 1520000 | P22: =S22 -> 3360000 | Q22: =P22-O22 -> 1840000 | S22: 3360000
A23: 16 | B23: 42353 | C23: Đóng hàng bình khí 16/12 | D23: PCIU3151530 | E23: Từ Liêm, Hà Nội | H23: =G23*13230 -> 0 | J23: 0 | O23: =H23+J23+K23+L23+M23+N23 -> 0 | P23: =S23 -> 4500000 | Q23: =P23-O23 -> 4500000 | S23: 4500000
A24: 17 | B24: 42354 | C24: Trả hàng sáng 17/12 | D24: VNLU3016277 | E24: Văn Điển, Hà Nội | H24: =G24*13230 -> 0 | J24: 1520000 | O24: =H24+J24+K24+L24+M24+N24 -> 1520000 | P24: =S24 -> 3000000 | Q24: =P24-O24 -> 1480000 | S24: 3000000
A25: 18 | B25: 42354 | C25: Đóng hàng XK sáng 18/12 | D25: WHLU0499246 | E25: Mỹ Hào, Hưng Yên | G25: 285 | H25: =G25*13230 -> 3770550 | J25: 200000 | O25: =H25+J25+K25+L25+M25+N25 -> 3970550 | P25: =S25 -> 3090909 | Q25: =P25-O25 -> -879641 | S25: 3090909
A26: 19 | B26: 42355 | C26: Trả hàng 18/12 | D26: WFHU1362683 | E26: Mỹ Hào, Hưng Yên | H26: =G26*13510 -> 0 | J26: 1110000 | O26: =H26+J26+K26+L26+M26+N26 -> 1110000 | P26: =S26 -> 2890000 | Q26: =P26-O26 -> 1780000 | S26: 2890000
A27: 20 | B27: 42357 | C27: Trả hàng NK sáng 20/12 | D27: DRYU3094515 | E27: Mỹ Hào, Hưng Yên | H27: =G27*13510 -> 0 | J27: 1480000 | O27: =H27+J27+K27+L27+M27+N27 -> 1480000 | P27: =S27 -> 5780000 | Q27: =P27-O27 -> 4300000 | S27: 5780000
A28: 21 | B28: 42357 | C28: Đóng hàng XK 20/12 | D28: MAGU2327532 | E28: Tam Điệp, Ninh Bình | H28: =G28*13510 -> 0 | J28: 0 | O28: =H28+J28+K28+L28+M28+N28 -> 0 | P28: =S28 -> 0 | Q28: =P28-O28 -> 0 | S28: 0
A29: 22 | B29: 42358 | C29: Trả hàng sáng 21/12 | D29: DRYU3095804 | E29: KCN Đại Đồng, Bắc Ninh | H29: =G29*13510 -> 0 | J29: 1740000 | O29: =H29+J29+K29+L29+M29+N29 -> 1740000 | P29: =S29 -> 3360000 | Q29: =P29-O29 -> 1620000 | S29: 3360000
A30: 23 | B30: 42358 | C30: Đóng hàng XK 21/12 | D30: MRKU8758048 | E30: Hoa Lư, Ninh Bình | G30: 176 | H30: =G30*11980 -> 2108480 | J30: 0 | O30: =H30+J30+K30+L30+M30+N30 -> 2108480 | P30: =S30 -> 4200000 | Q30: =P30-O30 -> 2091520 | S30: 4200000
A31: 24 | B31: 42359 | C31: Trả hàng + đóng hàng 22/12 | D31: DRYU2852729 | E31: Bắc Ninh - Hà Nam | H31: =G31*11980 -> 0 | J31: 1750000 | O31: =H31+J31+K31+L31+M31+N31 -> 1750000 | P31: =S31 -> 6060000 | Q31: =P31-O31 -> 4310000 | S31: 6060000
A32: 25 | B32: 42360 | C32: Đóng hàng chè sáng 23/12 | D32: BMOU5260477 | E32: Mỹ Bằng, Yên Sơn, Tuyên Quang | G32: 420 | H32: =G32*11980 -> 5031600 | J32: 2320000 | O32: =H32+J32+K32+L32+M32+N32 -> 7351600 | P32: =S32 -> 10000000 | Q32: =P32-O32 -> 2648400 | S32: 10000000
A33: 26 | B33: 42361 | C33: Trả hàng NK sáng 24/12 | D33: WHLU5451100 | E33: Mộc Châu, Sơn La | H33: =G33*11980 -> 0 | J33: 3100000 | O33: =H33+J33+K33+L33+M33+N33 -> 3100000 | P33: =S33 -> 13636364 | Q33: =P33-O33 -> 10536364 | S33: 13636364
A34: 27 | B34: 42363 | C34: Trả hàng NK 27/12 | D34: TEMU9037789 | E34: Mường Chài, Điện Biên | G34: 567 | H34: =G34*11980 -> 6792660 | J34: =8000000+8000000 -> 16000000 | O34: =H34+J34+K34+L34+M34+N34 -> 22792660 | P34: =S34 -> 45000000 | Q34: =P34-O34 -> 22207340 | S34: 45000000
A35: 28 | B35: 42735 | C35: Thu tiền bồi thường tai nạn xe 08/12 | O35: =H35+J35+K35+L35+M35+N35 -> 0 | P35: 19000000 | Q35: =P35-O35 -> 19000000
B36: 42714 | C36: gửi xe: 150.000, cắt hàn đinh mooc: 300.000, mỡ bò: 40.000, sửa hơi: 50.000 | L36: 540000 | O36: =H36+J36+K36+L36+M36+N36 -> 540000 | P36: =S36 -> 0 | Q36: =P36-O36 -> -540000
B37: 42714 | C37: Anh Phụng thanh toán tiền sửa xe 15C-139.82 | L37: 5000000 | O37: =H37+J37+K37+L37+M37+N37 -> 5000000 | P37: =S37 -> 0 | Q37: =P37-O37 -> -5000000
B38: 42716 | C38: A. Huấn bơm mỡ xe 15C-139.82 | L38: 170000 | O38: =H38+J38+K38+L38+M38+N38 -> 170000 | P38: =S38 -> 0 | Q38: =P38-O38 -> -170000
B39: 42719 | C39: Anh Phụng thanh toán sửa xe 15C-139.382 | L39: 3900000 | O39: =H39+J39+K39+L39+M39+N39 -> 3900000 | P39: =S39 -> 0 | Q39: =P39-O39 -> -3900000
B40: 42729 | C40: A. Huấn sửa giằng gương xe 15C-139.82 | L40: 300000 | O40: =H40+J40+K40+L40+M40+N40 -> 300000 | P40: =S40 -> 0 | Q40: =P40-O40 -> -300000
B41: 42730 | C41: Thanh toán tiền lốp xe 15C-139.82 (4 quả) | M41: 23200000 | O41: =H41+J41+K41+L41+M41+N41 -> 23200000 | P41: =S41 -> 0 | Q41: =P41-O41 -> -23200000 | R41: T5 | T41: 42389340
...

Sheet T01-2016
A1: Bảng theo dõi doanh thu/ chi phí theo phương tiện vận chuyển
A2: Biển số xe: 15C - 139.82
B3: THÁNG 01.2016
A5: STT | B5: Ngày tháng | C5: Diễn giải | D5: Số cont | E5: Tuyến đường vận chuyển | F5: Khoảng cách (km) | G5: Chi phí | O5: Tổng chi phí | P5: Cước vận chuyển | Q5: Lợi nhuận gộp
G6: Dầu (l) | H6: Dầu (đồng) | I6: Mức TTBQ | J6: Đi đường | K6: Lương lx | L6: Sửa chữa | M6: Lốp | N6: Dầu máy
A8: 1 | C8: Lưu ca xe từ 29/12 đến 11/01 | D8: TEMU9037789 | J8: =13*400000 -> 5200000 | O8: =N8+M8+L8+K8+J8+H8 -> 5200000 | P8: =13*1800000 -> 23400000 | Q8: =P8-O8 -> 18200000
C9: Luật phát sinh thêm 500k | D9: TEMU9037789 | J9: 500000 | O9: =N9+M9+L9+K9+J9+H9 -> 500000 | P9: 0 | Q9: =P9-O9 -> -500000
A10: 2 | B10: 42380 | C10: Đóng hàng chè sáng 14/01 | D10: TCLU9522302 | E10: Mỹ Bằng, Yên Sơn, Tuyên Quang | J10: 2420000 | O10: =N10+M10+L10+K10+J10+H10 -> 2420000 | P10: 9545455 | Q10: =P10-O10 -> 7125455
A11: 3 | B11: 42383 | C11: Trả hàng NK sáng 15/01 | D11: HLXU6420609 | E11: KCN Nam Sách, Hải Dương | G11: 610 | H11: 6777100 | J11: 660000 | O11: =N11+M11+L11+K11+J11+H11 -> 7437100 | P11: 2800000 | Q11: =P11-O11 -> -4637100
A12: 4 | B12: 42384 | C12: Trả hàng NK sáng 16/01 | D12: TEMU2888067 | E12: KCN Song Khê, Bắc Giang | J12: 2280000 | O12: =N12+M12+L12+K12+J12+H12 -> 2280000 | P12: 4000000 | Q12: =P12-O12 -> 1720000
A13: 5 | B13: 42384 | C13: Đóng hàng tinh bột sáng 18/01 | D13: TRHU1347141 | E13: KCN Mỹ Phước 2, Bến Cát, BD | J13: 0 | O13: =N13+M13+L13+K13+J13+H13 -> 0 | P13: 5200000 | Q13: =P13-O13 -> 5200000
A14: 6 | B14: 42387 | C14: Đóng hàng XK chiều 19/01 | D14: TCLU8556817 | E14: KCN VSIP, Thủy Nguyên, Hải Phòng | J14: 300000 | O14: =N14+M14+L14+K14+J14+H14 -> 300000 | P14: 1750000 | Q14: =P14-O14 -> 1450000
A15: 7 | B15: 42388 | C15: Trả hàng Vietsun sáng 20/01 | D15: WFHU5152854 | E15: KCN Quất Động, Thường Tín, Hà Nội | J15: 1450000 | O15: =N15+M15+L15+K15+J15+H15 -> 1450000 | P15: 3481818 | Q15: =P15-O15 -> 2031818
A16: 8 | B16: 42388 | C16: Đóng hàng than hoạt tính chiều 20/01 | D16: WFHU5152854 | E16: TP. Trà Vinh | G16: 405 | H16: 4499550 | J16: 0 | O16: =N16+M16+L16+K16+J16+H16 -> 4499550 | P16: 3000000 | Q16: =P16-O16 -> -1499550
A17: 9 | B17: 42389 | C17: Trả hàng Vietsun sáng 21/01 | D17: VSLU9371400 | E17: Văn Lâm, Hưng Yên | J17: 970000 | O17: =N17+M17+L17+K17+J17+H17 -> 970000 | P17: 3190909 | Q17: =P17-O17 -> 2220909
A18: 10 | B18: 42389 | C18: Đóng hàng chè sáng 22/01 | D18: MAGU5185658 | E18: Mỹ Bằng, Yên Sơn, Tuyên Quang | J18: 2320000 | O18: =N18+M18+L18+K18+J18+H18 -> 2320000 | P18: 9545455 | Q18: =P18-O18 -> 7225455
A19: 11 | B19: 42391 | C19: Trả hàng + đóng hàng KH sáng 23/01 | D19: EITU0420938 | E19: Văn Điển, Hà Nội | J19: 1800000 | O19: =N19+M19+L19+K19+J19+H19 -> 1800000 | P19: 6500000 | Q19: =P19-O19 -> 4700000
A20: 12 | B20: 42391 | C20: Trả hàng + đóng hàng KH sáng 23/01 | D20: OOLU1665435 | E20: Bình Xuyên, Vĩnh Phúc | G20: 510 | H20: 5202000 | J20: 0 | O20: =N20+M20+L20+K20+J20+H20 -> 5202000 | P20: 0 | Q20: =P20-O20 -> -5202000
A21: 13 | B21: 42393 | C21: Trả hàng + đóng hàng KH 25/01 | D21: TRHU1343723 | E21: KCN Đại Đồng, Bắc Ninh - Hà Nam | G21: 120 | H21: 1224000 | J21: 1750000 | O21: =N21+M21+L21+K21+J21+H21 -> 2974000 | P21: 5860000 | Q21: =P21-O21 -> 2886000
A22: 14 | B22: 42394 | C22: Trả hàng NK 26/01 | D22: SZLU9073612 | E22: CK Ma Lù Thàng, Lai Châu | G22: 580 | H22: =G22*10200 -> 5916000 | J22: 8500000 | O22: =N22+M22+L22+K22+J22+H22 -> 14416000 | P22: 34000000 | Q22: =P22-O22 -> 19584000
O23: =N23+M23+L23+K23+J23+H23 -> 0
C24: Tiền gửi xe T01/2016 | L24: 1200000 | O24: =N24+M24+L24+K24+J24+H24 -> 1200000 | Q24: =P24-O24 -> -1200000
C25: Lương lái xe | K25: 9000000 | O25: =N25+M25+L25+K25+J25+H25 -> 9000000 | Q25: =P25-O25 -> -9000000
C26: Lắp đặt thiết bị định vị | L26: 2740000 | O26: =N26+M26+L26+K26+J26+H26 -> 2740000 | Q26: =P26-O26 -> -2740000
C27: Sửa điều hóa | L27: 1300000 | O27: =N27+M27+L27+K27+J27+H27 -> 1300000 | Q27: =P27-O27 -> -1300000
C28: Bơm mỡ xe | L28: 180000 | O28: =N28+M28+L28+K28+J28+H28 -> 180000 | Q28: =P28-O28 -> -180000
C29: Tiền ăn lưu ca xe 1 ngày 21.01 | L29: 200000 | O29: =N29+M29+L29+K29+J29+H29 -> 200000 | Q29: =P29-O29 -> -200000
C30: Thưởng Tết AL | K30: 7000000 | O30: =N30+M30+L30+K30+J30+H30 -> 7000000 | Q30: =P30-O30 -> -7000000
O31: =N31+M31+L31+K31+J31+H31 -> 0 | Q31: =P31-O31 -> 0
O32: =N32+M32+L32+K32+J32+H32 -> 0 | Q32: =P32-O32 -> 0
A33: TỔNG CỘNG | G33: =SUM(G7:G32) -> 2225 | H33: =SUM(H7:H32) -> 23618650 | I33: =SUM(I7:I32) -> 0 | J33: =SUM(J8:J32) -> 28150000 | K33: =SUM(K8:K32) -> 16000000 | L33: =SUM(L8:L32) -> 5620000 | M33: =SUM(M8:M32) -> 0 | N33: =SUM(N8:N32) -> 0 | O33: =SUM(O8:O32) -> 73388650 | P33: =SUM(P8:P32) -> 112273637 | Q33: =SUM(Q8:Q32) -> 38884987
P35: LK | Q35: =Q33 -> 38884987

Sheet T02-2016
A1: Bảng theo dõi doanh thu/ chi phí theo phương tiện vận chuyển
A2: Biển số xe: 15C - 139.82
B3: THÁNG 02.2016
A5: STT | B5: Ngày tháng | C5: Diễn giải | D5: Số cont | E5: Tuyến đường vận chuyển | F5: Khoảng cách (km) | G5: Chi phí | O5: Tổng chi phí | P5: Cước vận chuyển | Q5: Lợi nhuận gộp
G6: Dầu (l) | H6: Dầu (đồng) | I6: Mức TTBQ | J6: Đi đường | K6: Lương lx | L6: Sửa chữa | M6: Lốp | N6: Dầu máy
C8: Lưu ca xe từ 30/01 đến 16/02 (21 ngày) | D8: SZLU9073612 | J8: =21*400000 -> 8400000 | O8: =N8+M8+L8+K8+J8+H8 -> 8400000 | P8: =21*1800000 -> 37800000 | Q8: =P8-O8 -> 29400000
A9: 1 | B9: 42422 | C9: Trả hàng + đóng hàng KH 23/02 | D9: VSLU1046000 | E9: KCN Đại Đồng, Bắc Ninh - Hà Nam | J9: 1740000 | O9: =N9+M9+L9+K9+J9+H9 -> 1740000 | P9: 5720000 | Q9: =P9-O9 -> 3980000
A10: 2 | B10: 42425 | C10: Trả hàng NK sáng 25/02 | D10: TEMU0282131 | E10: KCN VSIP, Thủy Nguyên, Hải Phòng | J10: 200000 | O10: =N10+M10+L10+K10+J10+H10 -> 200000 | P10: 1750000 | Q10: =P10-O10 -> 1550000
A11: 3 | B11: 42426 | C11: Đóng hàng chè sáng 29/02 | D11: BMOU4555040 | E11: Mỹ Bằng, Yên Sơn, Tuyên Quang | J11: 2320000 | O11: =N11+M11+L11+K11+J11+H11 -> 2320000 | P11: 9090909 | Q11: =P11-O11 -> 6770909
O12: =N12+M12+L12+K12+J12+H12 -> 0 | Q12: =P12-O12 -> 0
C13: Lương lái xe | K13: 8280000 | O13: =N13+M13+L13+K13+J13+H13 -> 8280000 | Q13: =P13-O13 -> -8280000
C14: Tiền gửi xe T2 | L14: 1200000 | O14: =N14+M14+L14+K14+J14+H14 -> 1200000 | Q14: =P14-O14 -> -1200000
O15: =N15+M15+L15+K15+J15+H15 -> 0 | Q15: =P15-O15 -> 0
O16: =N16+M16+L16+K16+J16+H16 -> 0 | Q16: =P16-O16 -> 0
A17: TỔNG CỘNG | G17: =SUM(G7:G16) -> 0 | H17: =SUM(H7:H16) -> 0 | I17: =SUM(I7:I16) -> 0 | J17: =SUM(J7:J16) -> 12660000 | K17: =SUM(K7:K16) -> 8280000 | L17: =SUM(L7:L16) -> 1200000 | M17: =SUM(M7:M16) -> 0 | N17: =SUM(N7:N16) -> 0 | ... Q17: =SUM(Q7:Q16) -> 32220909
P19: LK | Q19: ='T01-2016'!Q35+'T02-2016'!Q17 -> 71105896

Sheet 03-2016
A1: Bảng theo dõi doanh thu/ chi phí theo phương tiện vận chuyển
A2: Biển số xe: 15C - 139.82
B3: THÁNG 03.2016
A5: STT | B5: Ngày tháng | C5: Diễn giải | D5: Số cont | E5: Tuyến đường vận chuyển | F5: Khoảng cách (km) | G5: Chi phí | O5: Tổng chi phí | P5: Cước vận chuyển | Q5: Lợi nhuận gộp
G6: Dầu (l) | H6: Dầu (đồng) | I6: Mức TTBQ | J6: Đi đường | K6: Lương lx | L6: Sửa chữa | M6: Lốp | N6: Dầu máy
A8: 1 | B8: 42429 | C8: Trả hàng + đóng hàng KH 01/03 | D8: TCKU3311500 | E8: KCN Đại Đồng, Bắc Ninh - Hà Nam | J8: 1700000 | O8: =SUM(H8:N8) -> 1700000 | P8: 5720000 | Q8: =P8-O8 -> 4020000
A9: 2 | B9: 42431 | C9: Đóng hàng than hoạt tính sáng 03/03 | D9: YMLU8172144 | E9: TP. Trà Vinh | J9: 960000 | O9: =N9+M9+L9+K9+J9+H9 -> 960000 | P9: 3000000 | Q9: =P9-O9 -> 2040000
A10: 3 | B10: 42432 | C10: Trả hàng NK sáng 04/03 | D10: TGHU2733093 | E10: Phú Thị, Gia Lâm, Hà Nội | G10: 438 | H10: 4196040 | J10: 1740000 | O10: =N10+M10+L10+K10+J10+H10 -> 5936040 | P10: 3600000 | Q10: =P10-O10 -> -2336040
B11: 42432 | C11: Đóng hàng bột đá chiều 04/03 | D11: GMTU4486575 | E11: Phủ Lý, Hà Nam | J11: 0 | O11: =N11+M11+L11+K11+J11+H11 -> 0 | P11: 2800000 | Q11: =P11-O11 -> 2800000
B12: 42433 | C12: Đóng hàng XK sáng 05/03 | D12: EGSU9100671 | E12: KCN Vân Trung, Việt Yên, Bắc Giang | J12: 1120000 | O12: =N12+M12+L12+K12+J12+H12 -> 1120000 | P12: 3800000 | Q12: =P12-O12 -> 2680000
B13: 42434 | C13: Trả hàng + đóng hàng KH 07/03 | D13: DRYU3094032 | E13: KCN Đại Đồng, Bắc Ninh - Hà Nam | J13: =780000+960000 -> 1740000 | O13: =N13+M13+L13+K13+J13+H13 -> 1740000 | P13: 5720000 | Q13: =P13-O13 -> 3980000
B14: 42436 | C14: Đóng hàng XK 08/03 | D14: TCKU2310937 | E14: Từ Liêm, Hà Nội | J14: 1120000 | O14: =N14+M14+L14+K14+J14+H14 -> 1120000 | P14: 4318182 | Q14: =P14-O14 -> 3198182
B15: 42438 | C15: Đóng hàng XK sáng 09/03 | D15: TTNU3744431 | E15: Cầu Đá Bạc, Hải Phòng | J15: 400000 | O15: =N15+M15+L15+K15+J15+H15 -> 400000 | P15: 2000000 | Q15: =P15-O15 -> 1600000
B16: 42438 | C16: Đóng hàng XK chiều 09/03 | D16: UESU2439304 | E16: Cầu Đá Bạc, Hải Phòng | G16: 485 | H16: 4646300 | J16: 400000 | O16: =N16+M16+L16+K16+J16+H16 -> 5046300 | P16: 2000000 | Q16: =P16-O16 -> -3046300
B17: 42438 | C17: Trả hàng NK sáng 10/03 | D17: UETU2239130 | E17: Cảng Phà Đen, Hà Nội | J17: 1120000 | O17: =N17+M17+L17+K17+J17+H17 -> 1120000 | P17: 4300000 | Q17: =P17-O17 -> 3180000
B18: 42440 | C18: Đóng hàng chiều 11/03 | D18: EITU1509845 | E18: KCN VSIP, Thủy Nguyên, Hải Phòng | J18: 300000 | O18: =N18+M18+L18+K18+J18+H18 -> 300000 | P18: 1750000 | Q18: =P18-O18 -> 1450000
B19: 42441 | C19: Trả hàng NK sáng 12/03 | D19: TWCU2069203 | E19: KCN Vân Trung, Việt Yên, Bắc Giang | J19: 1120000 | O19: =N19+M19+L19+K19+J19+H19 -> 1120000 | P19: 3500000 | Q19: =P19-O19 -> 2380000
B20: 42442 | C20: Trả hàng sáng 14/03 | D20: TCKU3061968 | E20: Kim Sơn, Ninh Bình | J20: 1200000 | O20: =N20+M20+L20+K20+J20+H20 -> 1200000 | P20: 5500000 | Q20: =P20-O20 -> 4300000
B21: 42442 | C21: Đóng hàng vôi XK chiều 14/03 | D21: DFSU1104451 | E21: Tam Điệp, Ninh Bình | J21: 0 | O21: =N21+M21+L21+K21+J21+H21 -> 0 | P21: 0 | Q21: =P21-O21 -> 0
B22: 42443 | C22: Đóng hàng XK sáng 15/03 | D22: TEMU6644027 | E22: Phả Lại, Hải Dương | J22: 660000 | O22: =N22+M22+L22+K22+J22+H22 -> 660000 | P22: 3160000 | Q22: =P22-O22 -> 2500000
B23: 42443 | C23: Đóng hàng XK sáng 16/03 | D23: FCIU8864600 | E23: Phả Lại, Hải Dương | G23: 420 | H23: 4023600 | J23: 660000 | O23: =N23+M23+L23+K23+J23+H23 -> 4683600 | P23: 3160000 | Q23: =P23-O23 -> -1523600
B24: 42445 | C24: Trả hàng + đóng hàng KH 17/03 | D24: NPLU2212795 | E24: Hoài Đức, Hà Nội | J24: 1740000 | O24: =N24+M24+L24+K24+J24+H24 -> 1740000 | P24: 5900000 | Q24: =P24-O24 -> 4160000
B25: 42445 | C25: Trả hàng + đóng hàng KH 17/03 | D25: GMTU4021834 | E25: Phủ Lý, Hà Nam | J25: 0 | O25: =N25+M25+L25+K25+J25+H25 -> 0 | P25: 0 | Q25: =P25-O25 -> 0
B26: 42446 | C26: Trả hàng + đóng hàng KH 18/03 | D26: EMCU3680697 | E26: Trôi, Hà Nội | J26: 1740000 | O26: =N26+M26+L26+K26+J26+H26 -> 1740000 | P26: 5900000 | Q26: =P26-O26 -> 4160000
B27: 42446 | C27: Trả hàng + đóng hàng KH 18/03 | D27: TCLU2357443 | E27: Phủ Lý, Hà Nam | J27: 0 | O27: =N27+M27+L27+K27+J27+H27 -> 0 | P27: 0 | Q27: =P27-O27 -> 0
B28: 42448 | C28: Trả hàng NK 20/03 | D28: TEMU4650355 | E28: Cảng Phà Đen, Hà Nội | G28: 373 | H28: 3573340 | J28: 1740000 | O28: =N28+M28+L28+K28+J28+H28 -> 5313340 | P28: 4300000 | Q28: =P28-O28 -> -1013340
B29: 42450 | C29: Đóng hàng vôi XK chiều 20/03 | D29: TCKU3739470 | E29: Tam Điệp, Ninh Bình | J29: 0 | O29: =N29+M29+L29+K29+J29+H29 -> 0 | P29: 2900000 | Q29: =P29-O29 -> 2900000
B30: 42451 | C30: Trả hàng sáng 23/03 | D30: TRIU6800507 | E30: KCN Tiên Sơn, Bắc Ninh | J30: 1320000 | O30: =N30+M30+L30+K30+J30+H30 -> 1320000 | P30: 5000000 | Q30: =P30-O30 -> 3680000
B31: 42452 | C31: Trả hàng sáng 23/03 | D31: TEXU9017929 | E31: KCN Tiên Sơn, Bắc Ninh | J31: 0 | O31: =N31+M31+L31+K31+J31+H31 -> 0 | P31: 0 | Q31: =P31-O31 -> 0
B32: 42452 | C32: Trả hàng NK sáng 24/03 | D32: HAHU2058597 | E32: Cảng Phà Đen, Hà Nội | J32: =1740000-620000 -> 1120000 | O32: =N32+M32+L32+K32+J32+H32 -> 1120000 | P32: 4300000 | Q32: =P32-O32 -> 3180000
B33: 42453 | C33: Trả hàng NK ngày 25/03 | D33: TCNU5846445 | E33: Mộc Châu, Sơn La | J33: 3180000 | O33: =N33+M33+L33+K33+J33+H33 -> 3180000 | P33: 15454545 | Q33: =P33-O33 -> 12274545
B34: 42457 | C34: Trả hàng + đóng hàng KH 28/03 | D34: FCIU5416201 | E34: Từ Liêm, Hà Nội | G34: 540 | H34: 5329800 | J34: 1740000 | O34: =N34+M34+L34+K34+J34+H34 -> 7069800 | P34: 5740000 | Q34: =P34-O34 -> -1329800
B35: 42457 | C35: Trả hàng + đóng hàng KH 28/03 | D35: EMCU3670092 | E35: Tam Điệp, Ninh Bình | J35: 0 | O35: =N35+M35+L35+K35+J35+H35 -> 0 | P35: 0 | Q35: =P35-O35 -> 0
B36: 42457 | C36: Đóng hàng KH sáng 29/03 | D36: TCNU7470716 | E36: Giáp Bát, Hà Nội | J36: 1120000 | O36: =N36+M36+L36+K36+J36+H36 -> 1120000 | P36: 3536364 | Q36: =P36-O36 -> 2416364
B37: 42458 | C37: Đóng hàng sáng 30/03 | D37: FCIU9458041 | E37: KCN VSIP, Thủy Nguyên, Hải Phòng | J37: 200000 | O37: =N37+M37+L37+K37+J37+H37 -> 200000 | P37: 1750000 | Q37: =P37-O37 -> 1550000
O38: =N38+M38+L38+K38+J38+H38 -> 0 | Q38: =P38-O38 -> 0
O39: =N39+M39+L39+K39+J39+H39 -> 0 | Q39: =P39-O39 -> 0
C40: Lương lái xe | K40: 9000000 | O40: =N40+M40+L40+K40+J40+H40 -> 9000000 | Q40: =P40-O40 -> -9000000
C41: Rửa xe + bơm mỡ xe | L41: 290000 | O41: =N41+M41+L41+K41+J41+H41 -> 290000 | Q41: =P41-O41 -> -290000
C42: Vé đường bộ | L42: 475000 | O42: =N42+M42+L42+K42+J42+H42 -> 475000 | Q42: =P42-O42 -> -475000
...

Sheet 04-2016
A1: Bảng theo dõi doanh thu/ chi phí theo phương tiện vận chuyển
A2: Biển số xe: 15C - 139.82
B3: THÁNG 04.2016
A5: STT | B5: Ngày tháng | C5: Diễn giải | D5: Số cont | E5: Tuyến đường vận chuyển | F5: Khoảng cách (km) | G5: Chi phí | O5: Tổng chi phí | P5: Cước vận chuyển | Q5: Lợi nhuận gộp
G6: Dầu (l) | H6: Dầu (đồng) | I6: Mức TTBQ | J6: Đi đường | K6: Lương lx | L6: Sửa chữa | M6: Lốp | N6: Dầu máy
A8: 1 | B8: 42460 | C8: Trả hàng NK sáng 01/04 | D8: BSIU2616883 | E8: Cảng Phà Đen, Hà Nội | J8: 1120000 | O8: =N8+M8+L8+K8+J8+H8 -> 1120000 | P8: 4300000 | Q8: =P8-O8 -> 3180000
A9: 2 | B9: 42464 | C9: Trả hàng sáng 05/04 | D9: GMDU2150830 | E9: KCN Tân Trường, Hải Dương | J9: 1400000 | O9: =N9+M9+L9+K9+J9+H9 -> 1400000 | P9: 5100000 | Q9: =P9-O9 -> 3700000
A10: 3 | B10: 42464 | C10: Đóng hàng KH sáng 05/04 | D10: CBHU5588500 | E10: Tam Điệp, Ninh Bình | J10: 0 | O10: =N10+M10+L10+K10+J10+H10 -> 0 | P10: 0 | Q10: =P10-O10 -> 0
A11: 4 | B11: 42465 | C11: Đóng hàng chè sáng 06/04 | D11: TCNU9076131 | E11: Phủ Lỗ, Sóc Sơn, Hà Nội | J11: 1380000 | O11: =N11+M11+L11+K11+J11+H11 -> 1380000 | P11: 4400000 | Q11: =P11-O11 -> 3020000
A12: 5 | B12: 42466 | C12: Trả hàng + đóng hàng KH 07/04 | D12: GMTU4494185 | E12: Bắc Giang - Ninh Bình | J12: 1820000 | O12: =N12+M12+L12+K12+J12+H12 -> 1820000 | P12: 5500000 | Q12: =P12-O12 -> 3680000
A13: 6 | B13: 42467 | C13: Đóng hàng chiều 08/04 | D13: DFSU3014085 | E13: Mỹ Hào, Hưng Yên | J13: 890000 | O13: =N13+M13+L13+K13+J13+H13 -> 890000 | P13: 3090909 | Q13: =P13-O13 -> 2200909
A14: 7 | B14: 42468 | C14: Trả hàng + đóng hàng KH 09/04 | D14: DRYU3094990 | E14: Đồng Văn, Hà Nam - Hà Nam | G14: 680 | H14: 6711600 | J14: 1400000 | O14: =N14+M14+L14+K14+J14+H14 -> 8111600 | P14: 5300000 | Q14: =P14-O14 -> -2811600
A15: 8 | B15: 42471 | C15: Trả hàng KH sáng 12/04 | D15: WFHU1352411 | E15: Thạch Thất, Hà Nội | J15: 1820000 | O15: =N15+M15+L15+K15+J15+H15 -> 1820000 | P15: 6000000 | Q15: =P15-O15 -> 4180000
A16: 9 | B16: 42471 | C16: Đóng hàng KH sáng 12/04 | D16: TEMU0161248 | E16: Tam Điệp, Ninh Bình | J16: 0 | O16: =N16+M16+L16+K16+J16+H16 -> 0 | P16: 0 | Q16: =P16-O16 -> 0
A17: 10 | B17: 42472 | C17: Trả hàng + đóng hàng KH 13/04 | D17: DRYU2853129 | E17: KCN Đại Đồng, Bắc Ninh - Hà Nam | J17: 1820000 | O17: =N17+M17+L17+K17+J17+H17 -> 1820000 | P17: 5500000 | Q17: =P17-O17 -> 3680000
A18: 11 | B18: 42473 | C18: Trả hàng NK chiều 19/04 | D18: YMLU3246938 | E18: Mỹ Hào, Hưng Yên | J18: 1470000 | O18: =N18+M18+L18+K18+J18+H18 -> 1470000 | P18: 3090909 | Q18: =P18-O18 -> 1620909
A19: 12 | B19: 42473 | C19: Trả hàng + đóng hàng KH 14/04 | D19: WFHU1358512 | E19: KCN Đại Đồng, Bắc Ninh - Hà Nam | J19: 1820000 | O19: =N19+M19+L19+K19+J19+H19 -> 1820000 | P19: 5500000 | Q19: =P19-O19 -> 3680000
A20: 13 | B20: 42474 | C20: Trả hàng KH sáng 15/04 | D20: VSLU4492027 | E20: KCN Đại Đồng, Bắc Ninh | G20: 437 | H20: 4313190 | J20: 1820000 | O20: =N20+M20+L20+K20+J20+H20 -> 6133190 | P20: 5500000 | Q20: =P20-O20 -> -633190
A21: 14 | B21: 42474 | C21: Đóng hàng chiều 15/04 | D21: WHLU2602560 | E21: Tam Điệp, Ninh Bình | J21: 0 | O21: =N21+M21+L21+K21+J21+H21 -> 0 | P21: 0 | Q21: =P21-O21 -> 0
A22: 15 | B22: 42478 | C22: Đóng hàng KH bột đá chiều 19/04 | D22: WFHU1351673 | E22: Phủ Lý, Hà Nam | J22: 0 | O22: =N22+M22+L22+K22+J22+H22 -> 0 | P22: 2700000 | Q22: =P22-O22 -> 2700000
A23: 16 | B23: 42479 | C23: Trả hàng + đóng hàng KH sáng 20/04 | D23: VSLU4497163 | E23: KCN Hà Bình Phương, Hà Nội - Hà Nam | J23: 1820000 | O23: =N23+M23+L23+K23+J23+H23 -> 1820000 | P23: 5600000 | Q23: =P23-O23 -> 3780000
A24: 17 | B24: 42479 | C24: Đóng hàng chè sáng 21/04 | D24: DFSU3066900 | E24: TT Trần Phú, Văn Chấn, Yên Bái | G24: 560 | H24: 5807200 | J24: 2480000 | O24: =N24+M24+L24+K24+J24+H24 -> 8287200 | P24: 10454545 | Q24: =P24-O24 -> 2167345
A25: 18 | B25: 42481 | C25: Trả hàng + đóng hàng 22/04 | D25: DRYU3095229 | E25: KCN Đồng Văn, Hà Nam - Hà Nam | J25: 1470000 | O25: =N25+M25+L25+K25+J25+H25 -> 1470000 | P25: 5300000 | Q25: =P25-O25 -> 3830000
A26: 19 | B26: 42483 | C26: Trả hàng chiều 23/04 | D26: TGHU3953493 | E26: Cảng Phà Đen, Hà Nội | J26: 1280000 | O26: =N26+M26+L26+K26+J26+H26 -> 1280000 | P26: 4300000 | Q26: =P26-O26 -> 3020000
A27: 20 | B27: 42485 | C27: Trả hàng NK chiều 25/04 | D27: TWCU2052983 | E27: KCN VSIP, Thủy Nguyên, Hải Phòng | J27: 200000 | O27: =N27+M27+L27+K27+J27+H27 -> 200000 | P27: 1750000 | Q27: =P27-O27 -> 1550000
A28: 21 | B28: 42485 | C28: Đóng hàng XK sáng 26/04 | D28: TCNU8581231 | E28: Phả Lại, Hải Dương | G28: 391 | H28: 4054670 | J28: 740000 | O28: =N28+M28+L28+K28+J28+H28 -> 4794670 | P28: 3240000 | Q28: =P28-O28 -> -1554670
A29: 22 | B29: 42486 | C29: Đóng hàng than hoạt tính sáng 27/04 | D29: FSCU9408800 | E29: KCN Quế Võ, Bắc Ninh | J29: 1040000 | O29: =N29+M29+L29+K29+J29+H29 -> 1040000 | P29: 3800000 | Q29: =P29-O29 -> 2760000
A30: 23 | B30: 42487 | C30: Trả hàng NK sáng 28/04 | D30: SITU2930683 | E30: Cảng Phà Đen, Hà Nội | J30: 1820000 | O30: =N30+M30+L30+K30+J30+H30 -> 1820000 | P30: 4300000 | Q30: =P30-O30 -> 2480000
A31: 24 | B31: 42487 | C31: Đóng hàng KH chiều 28/04 | D31: MSKU7323654 | E31: Tam Điệp, Ninh Bình | J31: 0 | O31: =N31+M31+L31+K31+J31+H31 -> 0 | P31: 2800000 | Q31: =P31-O31 -> 2800000
A32: 25 | B32: 42488 | C32: Trả hàng NK sáng 29/04 | D32: EGSU9157770 | E32: Ngọc Hồi, Hà Nội | J32: 1280000 | O32: =N32+M32+L32+K32+J32+H32 -> 1280000 | P32: 4300000 | Q32: =P32-O32 -> 3020000
A33: 26 | B33: 42494 | C33: Trả hàng NK sáng 30/04 | D33: TGHU6829547 | E33: KCN VSIP, Thủy Nguyên, Hải Phòng | G33: 444 | H33: =G33*(10370+650) -> 4892880 | J33: 200000 | O33: =N33+M33+L33+K33+J33+H33 -> 5092880 | P33: 1750000 | Q33: =P33-O33 -> -3342880
C35: Lương lái xe + thưởng 30/4 | K35: 9500000 | O35: =N35+M35+L35+K35+J35+H35 -> 9500000 | Q35: =P35-O35 -> -9500000
C36: Nộp lệ phí sử dụng đường bộ 12 tháng | N36: 17160000 | O36: =N36+M36+L36+K36+J36+H36 -> 17160000 | Q36: =P36-O36 -> -17160000
C37: Lệ phí đăng kiểm đầu kéo | L37: 610000 | O37: =N37+M37+L37+K37+J37+H37 -> 610000 | Q37: =P37-O37 -> -610000
C38: Tiền dịch vụ đăng kiểm xe | L38: 200000 | O38: =N38+M38+L38+K38+J38+H38 -> 200000 | Q38: =P38-O38 -> -200000
C39: Phí gửi xe T4/2016 | L39: =3960000/3 -> 1320000 | O39: =N39+M39+L39+K39+J39+H39 -> 1320000 | Q39: =P39-O39 -> -1320000
C40: Mua 1/2 phuy nhớt máy | N40: 6000000 | O40: =N40+M40+L40+K40+J40+H40 -> 6000000 | Q40: =P40-O40 -> -6000000
C41: Bổ sung phí thay lọc nhớt + lọc dầu xe từ 26/12/2015 | N41: 2200000 | O41: =N41+M41+L41+K41+J41+H41 -> 2200000 | Q41: =P41-O41 -> -2200000
O42: =N42+M42+L42+K42+J42+H42 -> 0 | Q42: =P42-O42 -> 0
A43: TỔNG CỘNG | G43: =SUM(G7:G42) -> 2512 | H43: =SUM(H7:H42) -> 25779540 | I43: =SUM(I7:I42) -> 0 | J43: =SUM(J7:J42) -> 29090000 | K43: =SUM(K7:K42) -> 9500000 | L43: =SUM(L7:L42) -> 2130000 | M43: =SUM(M7:M42) -> 0 | N43: =SUM(N7:N42) -> 25360000 | ... Q43: =SUM(Q7:Q42) -> 11716823
...

Sheet 05-2016
A1: Bảng theo dõi doanh thu/ chi phí theo phương tiện vận chuyển
A2: Biển số xe: 15C - 139.82
B3: THÁNG 05.2016
A5: STT | B5: Ngày tháng | C5: Diễn giải | D5: Số cont | E5: Tuyến đường vận chuyển | F5: Khoảng cách (km) | G5: Chi phí | O5: Tổng chi phí | P5: Cước vận chuyển | Q5: Lợi nhuận gộp
G6: Dầu (l) | H6: Dầu (đồng) | I6: Mức TTBQ | J6: Đi đường | K6: Lương lx | L6: Sửa chữa | M6: Lốp | N6: Dầu máy
A8: 1 | B8: 42494 | C8: Trả hàng sáng 01/05 | D8: SITU2821086 | E8: Ninh Phúc, Ninh Bình | J8: 1200000 | O8: =N8+M8+L8+K8+J8+H8 -> 1200000 | P8: 5500000 | Q8: =P8-O8 -> 4300000
A9: 2 | B9: 42494 | C9: Đóng hàng KH sáng 01/05 | D9: MSKU3757077 | E9: Tam Điệp, Ninh Bình | J9: 0 | O9: =N9+M9+L9+K9+J9+H9 -> 0 | P9: 0 | Q9: =P9-O9 -> 0
A10: 3 | B10: 42500 | C10: Đóng hàng thép sáng 11/05 | D10: BISU2841729 | E10: Kinh Môn, Hải Dương | J10: 980000 | O10: =N10+M10+L10+K10+J10+H10 -> 980000 | P10: 2500000 | Q10: =P10-O10 -> 1520000
A11: 4 | B11: 42502 | C11: Đóng hàng XK chiều 12/05 | D11: TCKU3292904 | E11: Từ Liêm, Hà Nội | J11: 1700000 | O11: =N11+M11+L11+K11+J11+H11 -> 1700000 | P11: 4318182 | Q11: =P11-O11 -> 2618182
A12: 5 | B12: 42502 | C12: Đóng hàng bột đá chiều 12/05 | D12: DRYU2852740 | E12: Phủ Lý, Hà Nam | J12: 0 | O12: =N12+M12+L12+K12+J12+H12 -> 0 | P12: 2600000 | Q12: =P12-O12 -> 2600000
A13: 6 | B13: 42502 | C13: Trả hàng NK chiều 13/05 | D13: TCLU3872406 | E13: ICD Mỹ Đình - Mỹ Hào, Hưng Yên | J13: 1280000 | O13: =N13+M13+L13+K13+J13+H13 -> 1280000 | P13: 4409091 | Q13: =P13-O13 -> 3129091
A14: 7 | B14: 42504 | C14: Trả hàng + đóng hàng KH 16/05 | D14: WFHU1356309 | E14: KCN Đại Đồng, Bắc Ninh - Hà Nam | G14: 480 | H14: 5289600 | J14: 1700000 | O14: =N14+M14+L14+K14+J14+H14 -> 6989600 | P14: 5500000 | Q14: =P14-O14 -> -1489600
A15: 8 | B15: 42506 | C15: Trả hàng NK chiều 17/05 | D15: BSIU2868340 | E15: Mỹ Bằng, Yên Sơn, Tuyên Quang | J15: 2480000 | O15: =N15+M15+L15+K15+J15+H15 -> 2480000 | P15: 8181818 | Q15: =P15-O15 -> 5701818
A16: 9 | B16: 42510 | C16: Trả hàng NK sáng 20/05 | D16: MRKU5622192 | E16: KCN Châu Sơn, Phủ Lý, Hà Nam | J16: 1000000 | O16: =N16+M16+L16+K16+J16+H16 -> 1000000 | P16: 3600000 | Q16: =P16-O16 -> 2600000
A17: 10 | B17: 42511 | C17: Trả hàng + đóng hàng KH 23/05 | D17: VSLU1042089 | E17: Yên Mỹ, Hưng Yên - Hà Nam | J17: 1400000 | O17: =N17+M17+L17+K17+J17+H17 -> 1400000 | P17: 5000000 | Q17: =P17-O17 -> 3600000
A18: 11 | B18: 42513 | C18: Đóng hàng tinh bột chiều 24/05 | D18: TCKU3441799 | E18: KCN Thụy Vân, Việt Trì | G18: 430 | H18: 4859000 | J18: 2040000 | O18: =N18+M18+L18+K18+J18+H18 -> 6899000 | P18: 5500000 | Q18: =P18-O18 -> -1399000
A19: 12 | B19: 42514 | C19: Trả hàng + đóng hàng KH 25/05 | D19: NLLU9008889 | E19: Long Biên, Hà Nội | G19: 123 | H19: 1389900 | J19: 1700000 | O19: =N19+M19+L19+K19+J19+H19 -> 3089900 | P19: 5500000 | Q19: =P19-O19 -> 2410100
A20: 13 | B20: 42514 | C20: Trả hàng + đóng hàng KH 25/05 | D20: TCKU3320138 | E20: Phủ Lý, Hà Nam | J20: 0 | O20: =N20+M20+L20+K20+J20+H20 -> 0 | P20: 0 | Q20: =P20-O20 -> 0
A21: 14 | B21: 42515 | C21: Trả hàng + đóng hàng KH 26/05 | D21: DRYU2901778 | E21: Hai Bà Trưng, Hà Nội - Hà Nam | J21: 1700000 | O21: =N21+M21+L21+K21+J21+H21 -> 1700000 | P21: 5500000 | Q21: =P21-O21 -> 3800000
A22: 15 | B22: 42516 | C22: Trả hàng + đóng hàng KH 27/05 | D22: DRYU2851450 | E22: KCN Sông Trà, Thái Bình - Hà Nam | J22: 1200000 | O22: =N22+M22+L22+K22+J22+H22 -> 1200000 | P22: 4800000 | Q22: =P22-O22 -> 3600000
A23: 16 | B23: 42518 | C23: Đóng hàng chè sáng 30/05 | D23: TCNU6793099 | E23: Mỹ Bằng, Yên Sơn, Tuyên Quang | J23: 1800000 | O23: =N23+M23+L23+K23+J23+H23 -> 1800000 | P23: 8545455 | Q23: =P23-O23 -> 6745455
A24: 17 | B24: 42520 | C24: Trả hàng + đóng hàng KH 31/05 | D24: WHLU2322492 | E24: KCN Đại Đồng, Bắc Ninh - Hà Nam | G24: 500 | H24: 5650000 | J24: 1700000 | O24: =N24+M24+L24+K24+J24+H24 -> 7350000 | P24: 5500000 | Q24: =P24-O24 -> -1850000
O25: =N25+M25+L25+K25+J25+H25 -> 0 | Q25: =P25-O25 -> 0
O26: =N26+M26+L26+K26+J26+H26 -> 0 | Q26: =P26-O26 -> 0
C27: Lương lái xe | K27: 7418000 | O27: =N27+M27+L27+K27+J27+H27 -> 7418000 | Q27: =P27-O27 -> -7418000
C28: Sửa + rửa xe 15C139.82 | L28: 535000 | O28: =N28+M28+L28+K28+J28+H28 -> 535000 | Q28: =P28-O28 -> -535000
C29: Tiền cứu hộ kéo xe 15C139.82 | L29: 1500000 | O29: =N29+M29+L29+K29+J29+H29 -> 1500000 | Q29: =P29-O29 -> -1500000
C30: Lọc nhớt xe 15C139.82 | N30: 1200000 | O30: =N30+M30+L30+K30+J30+H30 -> 1200000 | Q30: =P30-O30 -> -1200000
C31: Mua kim phun dầu 4c * 8tr | L31: 32000000 | O31: =N31+M31+L31+K31+J31+H31 -> 32000000 | Q31: =P31-O31 -> -32000000
C32: Sửa chữa | L32: 420000 | O32: =N32+M32+L32+K32+J32+H32 -> 420000 | Q32: =P32-O32 -> -420000
C33: Phí bảo hiểm 2016 | L33: =26815000-3500000 -> 23315000 | O33: =N33+M33+L33+K33+J33+H33 -> 23315000 | Q33: =P33-O33 -> -23315000
C34: Phí gửi xe T5/2016 | L34: 1320000 | O34: =N34+M34+L34+K34+J34+H34 -> 1320000 | Q34: =P34-O34 -> -1320000
C35: "Trả tiền sửa xe 15C139.82: Thay tăng áp: 23.000.000đ Thay 2 kim phun : 8.000.000đ*2 Công thợ : 3.000.000đ" | L35: 42000000 | O35: =N35+M35+L35+K35+J35+H35 -> 42000000 | Q35: =P35-O35 -> -42000000
C36: Thuê xe ngoài cứu hộ hàng | L36: 1100000 | O36: =N36+M36+L36+K36+J36+H36 -> 1100000 | Q36: =P36-O36 -> -1100000
A37: TỔNG CỘNG | G37: =SUM(G7:G36) -> 1533 | H37: =SUM(H7:H36) -> 17188500 | I37: =SUM(I7:I36) -> 0 | J37: =SUM(J7:J36) -> 21880000 | K37: =SUM(K7:K36) -> 7418000 | L37: =SUM(L7:L36) -> 102190000 | M37: =SUM(M7:M36) -> 0 | N37: =SUM(N7:N36) -> 1200000 | ... Q37: =SUM(Q7:Q36) -> -72921954
Q38: =P37-O37 -> -72921954
P39: LK | Q39: =Q37+'04-2016'!Q45 -> 57685776

Sheet 06-2016
A1: Bảng theo dõi doanh thu/ chi phí theo phương tiện vận chuyển
A2: Biển số xe: 15C - 139.82
B3: THÁNG 06.2016
A5: STT | B5: Ngày tháng | C5: Diễn giải | D5: Số cont | E5: Tuyến đường vận chuyển | F5: Khoảng cách (km) | G5: Chi phí | O5: Tổng chi phí | P5: Cước vận chuyển | Q5: Lợi nhuận gộp
G6: Dầu (l) | H6: Dầu (đồng) | I6: Mức TTBQ | J6: Đi đường | K6: Lương lx | L6: Sửa chữa | M6: Lốp | N6: Dầu máy
A8: 1 | B8: 42520 | C8: Đóng hàng sáng 01/06 | D8: HJLU1370821 | E8: Mỹ Hào, Hưng Yên | J8: 890000 | O8: =N8+M8+L8+K8+J8+H8 -> 890000 | P8: 3090909 | Q8: =P8-O8 -> 2200909
A9: 2 | B9: 42522 | C9: Trả hàng NK sáng 02/06 | D9: SEGU5359374 | E9: KCN Thạch Thất, Hà Nội | J9: 1280000 | O9: =N9+M9+L9+K9+J9+H9 -> 1280000 | P9: 4100000 | Q9: =P9-O9 -> 2820000
A10: 3 | B10: 42523 | C10: Trả hàng NK tối 02/06 | D10: TEMU4077246 | E10: Cảng Phà Đen, Hà Nội | J10: 1700000 | O10: =N10+M10+L10+K10+J10+H10 -> 1700000 | P10: 4000000 | Q10: =P10-O10 -> 2300000
A11: 4 | B11: 42523 | C11: Đóng hàng kết hợp 03/06 | D11: TTNU1617090 | E11: Phủ Lý, Hà Nam | O11: =N11+M11+L11+K11+J11+H11 -> 0 | P11: 2600000 | Q11: =P11-O11 -> 2600000
A12: 5 | B12: 42524 | G12: 442 | H12: 4994600
A13: 6 | B13: 42525 | C13: Trả hàng NK tối 04/06 | D13: BSIU2620820 | E13: Long Biên, Hà Nội | J13: 1700000 | O13: =N13+M13+L13+K13+J13+H13 -> 1700000 | P13: 3200000 | Q13: =P13-O13 -> 1500000
A14: 7 | B14: 42525 | C14: Đóng hàng KH 05/06 | D14: DRYU3093041 | E14: Phủ Lý, Hà Nam | O14: =N14+M14+L14+K14+J14+H14 -> 0 | P14: 2600000 | Q14: =P14-O14 -> 2600000
A15: 8 | B15: 42527 | C15: Trả hàng + đóng hàng KH 06/06 | D15: DRYU3094752 | E15: Như Quỳnh, Hưng Yên - Hà Nam | J15: 1700000 | O15: =N15+M15+L15+K15+J15+H15 -> 1700000 | P15: 5200000 | Q15: =P15-O15 -> 3500000
A16: 9 | B16: 42527 | C16: Trả hàng + đóng hàng KH 07/06 | D16: TTNU2348606 | E16: KCN Đại Đồng, Bắc Ninh - Hà Nam | J16: 1700000 | O16: =N16+M16+L16+K16+J16+H16 -> 1700000 | P16: 5500000 | Q16: =P16-O16 -> 3800000
A17: 10 | B17: 42528 | C17: Trả hàng + đóng hàng KH 08/06 | D17: WFHU1362467 | E17: Phố Nối , Hưng Yên- Hà Nam | G17: 384 | H17: 4569600 | J17: 1400000 | O17: =N17+M17+L17+K17+J17+H17 -> 5969600 | P17: 5200000 | Q17: =P17-O17 -> -769600
A18: 11 | B18: 42529 | C18: Trả hàng + đóng hàng KH 09/06 | D18: WFHU1364834 | E18: Như Quỳnh, Hưng Yên - Hà Nam | J18: 1700000 | O18: =N18+M18+L18+K18+J18+H18 -> 1700000 | P18: 5200000 | Q18: =P18-O18 -> 3500000
A19: 12 | B19: 42530 | C19: Trả hàng + đóng hàng KH 10/06 | D19: DRYU2853772 | E19: KCN Đại Đồng, Bắc Ninh - Hà Nam | J19: 1700000 | O19: =N19+M19+L19+K19+J19+H19 -> 1700000 | P19: 5500000 | Q19: =P19-O19 -> 3800000
A20: 13 | B20: 42533 | C20: Trả hàng + đóng hàng KH 13/06 | D20: VSLU1048770 | E20: Hà Nam- Hà Nam | J20: 1200000 | O20: =N20+M20+L20+K20+J20+H20 -> 1200000 | P20: 5100000 | Q20: =P20-O20 -> 3900000
A21: 14 | B21: 42534 | C21: Trả hàng sáng 14/06 | D21: DRYU9367617 | E21: Kiện Khê, Hà Nam | G21: 448 | H21: 5331200 | J21: 1000000 | O21: =N21+M21+L21+K21+J21+H21 -> 6331200 | P21: 3727273 | Q21: =P21-O21 -> -2603927
A22: 15 | B22: 42535 | C22: Trả hàng + đóng hàng KH 15/06 | D22: WFHU1351966 | E22: KCN Ngọc Hồi, Hà Nội - Hà Nam | J22: 1700000 | O22: =N22+M22+L22+K22+J22+H22 -> 1700000 | P22: 5500000 | Q22: =P22-O22 -> 3800000
A23: 16 | B23: 42536 | C23: Đóng hàng chiều 16/06 | D23: MRKU6511640 | E23: Chí Linh, Hải Dương | J23: 740000 | O23: =N23+M23+L23+K23+J23+H23 -> 740000 | P23: 2400000 | Q23: =P23-O23 -> 1660000
A24: 17 | B24: 42537 | C24: Trả hàng + đóng hàng KH 17/06 | D24: WFHU1361500 | E24: Dương Xá, Gia Lâm, Hà Nội - Hà Nam | J24: 1700000 | O24: =N24+M24+L24+K24+J24+H24 -> 1700000 | P24: 5500000 | Q24: =P24-O24 -> 3800000
A25: 18 | B25: 42538 | C25: Trả hàng + đóng hàng KH 18/06 | D25: TEMU3523886 | E25: Xuân Quang, Văn Giang, Hưng Yên | J25: 1700000 | O25: =N25+M25+L25+K25+J25+H25 -> 1700000 | P25: 5800000 | Q25: =P25-O25 -> 4100000
A26: 19 | B26: 42538 | C26: Trả hàng + đóng hàng KH 18/06 | D26: CAXU6968153 | E26: Phủ Lý, Hà Nam | O26: =N26+M26+L26+K26+J26+H26 -> 0 | P26: 0 | Q26: =P26-O26 -> 0
A27: 20 | B27: 42539 | C27: Trả hàng NK sáng 19/06 | D27: MRKU8883646 | E27: KCN Đồng Văn, Hà Nam | J27: 1200000 | O27: =N27+M27+L27+K27+J27+H27 -> 1200000 | P27: 5100000 | Q27: =P27-O27 -> 3900000
A28: 21 | B28: 42539 | C28: Đóng hàng KH chiều 19/06 | D28: DRYU2851851 | E28: Phủ Lý, Hà Nam | O28: =N28+M28+L28+K28+J28+H28 -> 0 | P28: 0 | Q28: =P28-O28 -> 0
A29: 22 | B29: 42540 | G29: 590 | H29: 7021000 | O29: =N29+M29+L29+K29+J29+H29 -> 7021000 | Q29: =P29-O29 -> -7021000
A30: 23 | B30: 42541 | C30: Trả hàng + đóng hàng KH 20/06 | D30: DRYU3093988 | E30: Yên Mỹ, Hưng Yên - Hà Nam | J30: 1400000 | O30: =N30+M30+L30+K30+J30+H30 -> 1400000 | P30: 5000000 | Q30: =P30-O30 -> 3600000
A31: 24 | B31: 42541 | C31: Trả hàng + đóng hàng KH 21/06 | D31: DRYU2923519 | E31: KCN Đại Đồng, Bắc Ninh - Hà Nam | J31: 1700000 | O31: =N31+M31+L31+K31+J31+H31 -> 1700000 | P31: 5500000 | Q31: =P31-O31 -> 3800000
A32: 25 | B32: 42543 | C32: Trả hàng NK chiều 22/06 | D32: BMOU5398861 | E32: KCN Ngọc Hồi, Thanh Trì, Hà Nội | J32: 1280000 | O32: =N32+M32+L32+K32+J32+H32 -> 1280000 | P32: 4000000 | Q32: =P32-O32 -> 2720000
A33: 26 | B33: 42543 | C33: Trả hàng sáng 23/06 | D33: VSLU4486976 | E33: Dương Xá, Gia Lâm, Hà Nội | J33: 1700000 | O33: =N33+M33+L33+K33+J33+H33 -> 1700000 | P33: 5600000 | Q33: =P33-O33 -> 3900000
A34: 27 | B34: 42543 | C34: Đóng hàng KH chiều 23/06 | D34: IMTU3085230 | E34: Tam Điệp, Ninh Bình | O34: =N34+M34+L34+K34+J34+H34 -> 0 | P34: 0 | Q34: =P34-O34 -> 0
A35: 28 | B35: 42544 | C35: Trả hàng 24/06 | D35: MRKU9570332 | E35: KCN Phố Nối A, Hưng Yên | J35: 1400000 | O35: =N35+M35+L35+K35+J35+H35 -> 1400000 | P35: 5000000 | Q35: =P35-O35 -> 3600000
A36: 29 | B36: 42544 | C36: Đóng hàng bột đá KH chiều 24/06 | D36: GATU0129975 | E36: Phủ Lý, Hà Nam | O36: =N36+M36+L36+K36+J36+H36 -> 0 | P36: 0 | Q36: =P36-O36 -> 0
A37: 30 | B37: 42545 | C37: Trả hàng + đóng hàng KH 25/05 | D37: TCKU3587886 | E37: Như Quỳnh, Hưng Yên - Hà Nam | J37: 1700000 | O37: =N37+M37+L37+K37+J37+H37 -> 1700000 | P37: 5200000 | Q37: =P37-O37 -> 3500000
A38: 31 | B38: 42546 | C38: Trả hàng + đóng hàng KH 27/06 | D38: DRYU3095337 | E38: KCN Đại Đồng, Bắc Ninh - Hà Nam | G38: 688 | H38: 8455520 | J38: 1700000 | O38: =N38+M38+L38+K38+J38+H38 -> 10155520 | P38: 5500000 | Q38: =P38-O38 -> -4655520
A39: 32 | B39: 42548 | C39: Trả hàng + đóng hàng KH 28/06 | D39: WFHU1352807 | E39: Kho D, cảng Hà Nội - Hà Nam | J39: 1700000 | O39: =N39+M39+L39+K39+J39+H39 -> 1700000 | P39: 5500000 | Q39: =P39-O39 -> 3800000
A40: 33 | B40: 42549 | C40: Trả hàng Vietsun sáng 29/06 | D40: DRYU9878495 | E40: KCN Quế Võ, Bắc Ninh | J40: 1280000 | O40: =N40+M40+L40+K40+J40+H40 -> 1280000 | P40: 3463636 | Q40: =P40-O40 -> 2183636
A41: 34 | B41: 42550 | C41: Trả hàng NK sáng 30/06 | D41: TGHU3665310 | E41: Mỹ Hào, Hưng Yên | J41: 1400000 | O41: =N41+M41+L41+K41+J41+H41 -> 1400000 | P41: 3090909 | Q41: =P41-O41 -> 1690909
A42: 35 | B42: 42550 | C42: Đóng hàng KH chiều 30/06 | D42: PCIU3944771 | E42: Phủ Lý, Hà Nam | G42: 580 | H42: =G42*12290 -> 7128200 | O42: =N42+M42+L42+K42+J42+H42 -> 7128200 | P42: 2600000 | Q42: =P42-O42 -> -4528200
...

Sheet 07-2016
A1: Bảng theo dõi doanh thu/ chi phí theo phương tiện vận chuyển
A2: Biển số xe: 15C - 139.82
B3: THÁNG 07.2016
A5: STT | B5: Ngày tháng | C5: Diễn giải | D5: Số cont | E5: Tuyến đường vận chuyển | F5: Khoảng cách (km) | G5: Chi phí | O5: Tổng chi phí | P5: Cước vận chuyển | Q5: Lợi nhuận gộp
G6: Dầu (l) | H6: Dầu (đồng) | I6: Mức TTBQ | J6: Đi đường | K6: Lương lx | L6: Sửa chữa | M6: Lốp | N6: Dầu máy
A8: 1 | B8: 42551 | C8: Đóng hàng chè sáng 01/07 | D8: MRKU3989804 | E8: Mỹ Bằng, Yên Sơn, Tuyên Quang | J8: 2000000 | O8: =H8+I8+J8+K8+L8+M8+N8 -> 2000000 | P8: 8181818 | Q8: =P8-O8 -> 6181818
A9: 2 | B9: 42552 | C9: Trả hàng sáng 02/07 | D9: SEGU1763454 | E9: Xuân Quang, Văn Giang, Hưng Yên | J9: 1700000 | O9: =H9+I9+J9+K9+L9+M9+N9 -> 1700000 | P9: 5800000 | Q9: =P9-O9 -> 4100000
A10: 3 | B10: 42552 | C10: Đóng hàng chiều 02/07 | D10: TCLU3237632 | E10: Phủ Lý, Hà Nam | J10: 0 | O10: =H10+I10+J10+K10+L10+M10+N10 -> 0 | P10: 0 | Q10: =P10-O10 -> 0
A11: 4 | B11: 42553 | C11: Trả hàng + đóng hàng KH 04/07 | D11: DRYU2853900 | E11: KCN Đại Đồng, Bắc Ninh - Hà Nam | J11: 1700000 | O11: =H11+I11+J11+K11+L11+M11+N11 -> 1700000 | P11: 5500000 | Q11: =P11-O11 -> 3800000
A12: 5 | B12: 42555 | C12: Trả hàng sáng 05/07 | D12: DRYU9878140 | E12: Ngũ Hiệp, Thanh Trì, Hà Nội | J12: 1280000 | O12: =H12+I12+J12+K12+L12+M12+N12 -> 1280000 | P12: 3327273 | Q12: =P12-O12 -> 2047273
A13: 6 | B13: 42556 | C13: Đóng hàng kết hợp sáng 06/07 | D13: DRYU9878140 | E13: KCN Hà Bình Phương, Hà Nội | J13: 900000 | O13: =H13+I13+J13+K13+L13+M13+N13 -> 900000 | P13: 2973636 | Q13: =P13-O13 -> 2073636
A14: 7 | B14: 42557 | C14: Đóng hàng chè sáng 07/07 | D14: YMLU8774286 | E14: Phủ Lỗ, Sóc Sơn, Hà Nội | J14: 900000 | O14: =H14+I14+J14+K14+L14+M14+N14 -> 900000 | P14: 4400000 | Q14: =P14-O14 -> 3500000
A15: 8 | B15: 42558 | C15: Trả hàng + đóng hàng KH 08/07 | D15: DRYU3093606 | E15: Dương Xá, Gia Lâm, Hà Nội - Hà Nam | G15: 670 | H15: 8234300 | J15: 1700000 | O15: =H15+I15+J15+K15+L15+M15+N15 -> 9934300 | P15: 5500000 | Q15: =P15-O15 -> -4434300
A16: 9 | B16: 42559 | C16: Đóng hàng chè sáng 09/07 | D16: TCNU6285610 | E16: Phủ Lỗ, Sóc Sơn, Hà Nội | J16: 900000 | O16: =H16+I16+J16+K16+L16+M16+N16 -> 900000 | P16: 4400000 | Q16: =P16-O16 -> 3500000
A17: 10 | B17: 42560 | C17: Đóng hàng sáng 11/07 | D17: DRYU4293527 | E17: Mỹ Bằng, Yên Sơn, Tuyên Quang | J17: 2000000 | O17: =H17+I17+J17+K17+L17+M17+N17 -> 2000000 | P17: 6500000 | Q17: =P17-O17 -> 4500000
A18: 11 | B18: 42562 | C18: Đóng hàng chè chiều 11/07 | D18: TCLU9642904 | E18: Mỹ Bằng, Yên Sơn, Tuyên Quang | J18: 2000000 | O18: =H18+I18+J18+K18+L18+M18+N18 -> 2000000 | P18: 8181818 | Q18: =P18-O18 -> 6181818
A19: 12 | B19: 42563 | C19: Trả hàng + đóng hàng KH sáng 13/07 | D19: DRYU3094963 | E19: Thanh Hóa - Hà Nam | G19: 541 | H19: 6648890 | J19: 1700000 | O19: =H19+I19+J19+K19+L19+M19+N19 -> 8348890 | P19: 6900000 | Q19: =P19-O19 -> -1448890
A20: 13 | B20: 42564 | C20: Trả hàng + đóng hàng KH sáng 14/07 | D20: WFHU1352047 | E20: KCN Đại Đồng, Bắc Ninh - Hà Nam | J20: 1700000 | O20: =H20+I20+J20+K20+L20+M20+N20 -> 1700000 | P20: 5500000 | Q20: =P20-O20 -> 3800000
A21: 14 | B21: 42565 | C21: Trả hàng + đóng hàng KH sáng 15/07 | D21: WFHU1352880 | E21: KCN Đại Đồng, Bắc Ninh - Hà Nam | J21: 1700000 | O21: =H21+I21+J21+K21+L21+M21+N21 -> 1700000 | P21: 5500000 | Q21: =P21-O21 -> 3800000
A22: 15 | B22: 42567 | C22: Trả hàng NK sáng 16/07 | D22: OOLU1865201 | E22: Thạch Thất, Hà Nội | J22: 1700000 | O22: =H22+I22+J22+K22+L22+M22+N22 -> 1700000 | P22: 5700000 | Q22: =P22-O22 -> 4000000
A23: 16 | B23: 42567 | C23: Đóng hàng chiều 16/07 | D23: DRYU2923062 | E23: Phủ Lý, Hà Nam | J23: 0 | O23: =H23+I23+J23+K23+L23+M23+N23 -> 0 | P23: 0 | Q23: =P23-O23 -> 0
A24: 17 | B24: 42568 | C24: Trả hàng sáng 18/07 | D24: GMDU2151159 | E24: KCN Tân Trường, Hải Dương | J24: 1400000 | O24: =H24+I24+J24+K24+L24+M24+N24 -> 1400000 | P24: 5000000 | Q24: =P24-O24 -> 3600000
A25: 18 | B25: 42568 | C25: Đóng hàng KH chiều 18/07 | D25: DRYU3023506 | E25: Phủ Lý, Hà Nam | J25: 0 | O25: =H25+I25+J25+K25+L25+M25+N25 -> 0 | P25: 0 | Q25: =P25-O25 -> 0
A26: 19 | B26: 42569 | C26: Trả hàng sáng 19/07 | D26: MSKU5108122 | E26: Lai Cách, Cẩm Giàng, Hải Dương | G26: 520 | H26: 6390800 | J26: 1400000 | O26: =H26+I26+J26+K26+L26+M26+N26 -> 7790800 | P26: 5000000 | Q26: =P26-O26 -> -2790800
A27: 20 | B27: 42569 | C27: Đóng hàng KH 19/07 | D27: GMDU2151159 | E27: Phủ Lý, Hà Nam | J27: 0 | O27: =H27+I27+J27+K27+L27+M27+N27 -> 0 | P27: 0 | Q27: =P27-O27 -> 0
A28: 21 | B28: 42570 | C28: Đóng hàng chè sáng 20/07 | D28: MIEU0012896 | E28: Mỹ Bằng, Yên Sơn, Tuyên Quang | J28: 1950000 | O28: =H28+I28+J28+K28+L28+M28+N28 -> 1950000 | P28: 8181818 | Q28: =P28-O28 -> 6231818
A29: 22 | B29: 42571 | C29: Trả hàng + đóng hàng KH 21/07 | D29: DRYU3095425 | E29: Thanh Trì, Hà Nội - Hà Nam | J29: 1600000 | O29: =H29+I29+J29+K29+L29+M29+N29 -> 1600000 | P29: 5200000 | Q29: =P29-O29 -> 3600000
A30: 23 | B30: 42572 | C30: Đóng hàng chè sáng 22/07 | D30: BMOU5731252 | E30: Phủ Lỗ, Sóc Sơn, Hà Nội | J30: 850000 | O30: =H30+I30+J30+K30+L30+M30+N30 -> 850000 | P30: 4200000 | Q30: =P30-O30 -> 3350000
A31: 24 | B31: 42573 | C31: Trả hàng NK sáng 23/07 | D31: MSKU5219548 | E31: Thường Tín, Hà Nội | J31: 1600000 | O31: =H31+I31+J31+K31+L31+M31+N31 -> 1600000 | P31: 3100000 | Q31: =P31-O31 -> 1500000
A32: 25 | B32: 42574 | C32: Đóng hàng chiều 23/07 | D32: WHLU0222436 | E32: Phủ Lý, Hà Nam | J32: 0 | O32: =H32+I32+J32+K32+L32+M32+N32 -> 0 | P32: 2400000 | Q32: =P32-O32 -> 2400000
A33: 26 | B33: 42576 | C33: Trả hàng NK sáng 25/07 | D33: PONU0555637 | E33: Sóc Sơn, Hà Nội | G33: 795 | H33: 9770550 | J33: 1600000 | O33: =H33+I33+J33+K33+L33+M33+N33 -> 11370550 | P33: 3100000 | Q33: =P33-O33 -> -8270550
A34: 27 | B34: 42576 | C34: Đóng hàng vôi KH chiều 25/07 | D34: WHLU2698139 | E34: Phủ Lý, Hà Nam | J34: 0 | O34: =H34+I34+J34+K34+L34+M34+N34 -> 0 | P34: 2400000 | Q34: =P34-O34 -> 2400000
A35: 28 | B35: 42576 | C35: Trả hàng + đóng hàng KH 26/07 | D35: GMDU2142898 | E35: KCN Tân Trường, Hải Dương - Hà Nam | J35: 1300000 | O35: =H35+I35+J35+K35+L35+M35+N35 -> 1300000 | P35: 4800000 | Q35: =P35-O35 -> 3500000
A36: 29 | B36: 42577 | C36: Đóng hàng chè sáng 27/07 | D36: MRKU4051988 | E36: Mỹ Bằng, Yên Sơn, Tuyên Quang | J36: 1950000 | O36: =H36+I36+J36+K36+L36+M36+N36 -> 1950000 | P36: 8181818 | Q36: =P36-O36 -> 6231818
A37: 30 | B37: 42578 | C37: Trả hàng sáng 28/07 | D37: DFSU3054426 | E37: Chu Đậu, Nam Sách, Hải Dương | J37: 1300000 | O37: =H37+I37+J37+K37+L37+M37+N37 -> 1300000 | P37: 2400000 | Q37: =P37-O37 -> 1100000
A38: 31 | B38: 42578 | C38: Đóng hàng KH chiều 28/07 | D38: DFSU2942021 | E38: Tam Điệp, Ninh Bình | J38: 0 | O38: =H38+I38+J38+K38+L38+M38+N38 -> 0 | P38: 2800000 | Q38: =P38-O38 -> 2800000
A39: 32 | B39: 42580 | C39: Trả hàng sáng 30/07 | D39: WHLU2931657 | E39: Bát Tràng, Hà Nội | J39: 1600000 | O39: =H39+I39+J39+K39+L39+M39+N39 -> 1600000 | P39: 3300000 | Q39: =P39-O39 -> 1700000
A40: 33 | B40: 42580 | C40: Đóng hàng KH gạch 30/07 | D40: BSIU2821743 | E40: KCN Bình Xuyên, Vĩnh Phúc | J40: 0 | O40: =H40+I40+J40+K40+L40+M40+N40 -> 0 | P40: 2500000 | Q40: =P40-O40 -> 2500000
A41: 34 | B41: 42581 | G41: 610 | H41: 7496900 | O41: =N41+M41+L41+K41+J41+H41 -> 7496900 | Q41: =P41-O41 -> -7496900
C42: Lương lái xe T07/2016 | K42: 9000000 | O42: =N42+M42+L42+K42+J42+H42 -> 9000000 | Q42: =P42-O42 -> -9000000
...

Sheet 08.2016
A1: Bảng theo dõi doanh thu/ chi phí theo phương tiện vận chuyển
A2: Biển số xe: 15C - 139.82
B3: THÁNG 08.2016
A5: STT | B5: Ngày tháng | C5: Diễn giải | D5: Số cont | E5: Tuyến đường vận chuyển | F5: Khoảng cách (km) | G5: Chi phí | O5: Tổng chi phí | P5: Cước vận chuyển | Q5: Lợi nhuận gộp
G6: Dầu (l) | H6: Dầu (đồng) | I6: Mức TTBQ | J6: Đi đường | K6: Lương lx | L6: Sửa chữa | M6: Lốp | N6: Dầu máy
A8: 1 | B8: 42583 | C8: Trả hàng sáng 01/08 | D8: YMLU3199409 | E8: Đức Giang, Hà Nội | J8: 1600000 | O8: =H8+J8+K8+L8+M8+N8 -> 1600000 | P8: 3400000 | Q8: =P8-O8 -> 1800000
A9: 2 | B9: 42583 | C9: Đóng hàng vôi chiều 01/08 | D9: OOLU0526409 | E9: Phủ Lý, Hà Nam | J9: 0 | O9: =H9+J9+K9+L9+M9+N9 -> 0 | P9: 2400000 | Q9: =P9-O9 -> 2400000
A10: 3 | B10: 42585 | C10: Trả hàng sáng 03/08 | D10: WHLU0447290 | E10: Bát Tràng, Hà Nội | G10: 300 | H10: 3687000 | J10: 1600000 | O10: =H10+J10+K10+L10+M10+N10 -> 5287000 | P10: 3300000 | Q10: =P10-O10 -> -1987000
A11: 4 | B11: 42585 | C11: Đóng hàng KH chiều 03/08 | D11: DRYU2852884 | E11: Phủ Lý, Hà Nam | J11: 0 | O11: =H11+J11+K11+L11+M11+N11 -> 0 | P11: 2500000 | Q11: =P11-O11 -> 2500000
A12: 5 | B12: 42585 | C12: Trả hàng + đóng hàng KH 04/08 | D12: DRYU3025469 | E12: KCN Đại Đồng, Bắc Ninh - Hà Nam | J12: 1600000 | O12: =H12+J12+K12+L12+M12+N12 -> 1600000 | P12: 5200000 | Q12: =P12-O12 -> 3600000
A13: 6 | B13: 42586 | C13: Đóng hàng chè chiều 05/08 | D13: MRKU3402516 | E13: Mỹ Bằng, Yên Sơn, Tuyên Quang | J13: 1950000 | O13: =H13+J13+K13+L13+M13+N13 -> 1950000 | P13: 8181818 | Q13: =P13-O13 -> 6231818
A14: 7 | B14: 42587 | C14: Đóng hàng XK sáng 06/08 | D14: DFSU3136904 | E14: Mỹ Hào, Hưng Yên | J14: 840000 | O14: =H14+J14+K14+L14+M14+N14 -> 840000 | P14: 3000000 | Q14: =P14-O14 -> 2160000
A15: 8 | B15: 42588 | C15: Trả hàng NK sáng 07/08 | D15: SKLU1526286 | E15: Mỹ Hào, Hưng Yên | G15: 440 | H15: 5130400 | J15: 1300000 | O15: =H15+J15+K15+L15+M15+N15 -> 6430400 | P15: 3000000 | Q15: =P15-O15 -> -3430400
A16: 9 | B16: 42588 | C16: Đóng hàng KH chiều 07/08 | D16: DRYU3023300 | E16: Phủ Lý, Hà Nam | J16: 0 | O16: =H16+J16+K16+L16+M16+N16 -> 0 | P16: 2500000 | Q16: =P16-O16 -> 2500000
A17: 10 | B17: 42589 | C17: Đóng hàng XK sáng 08/08 | D17: DRYU9926314 | E17: KCN Châu Sơn, Phủ Lý, Hà Nam | J17: 950000 | O17: =H17+J17+K17+L17+M17+N17 -> 950000 | P17: 3600000 | Q17: =P17-O17 -> 2650000
A18: 11 | B18: 42590 | C18: Trả hàng NK sáng 09/08 | D18: NYKU2975144 | E18: Văn Lâm, Hưng Yên | J18: 1600000 | O18: =H18+J18+K18+L18+M18+N18 -> 1600000 | P18: 2600000 | Q18: =P18-O18 -> 1000000
A19: 12 | B19: 42590 | C19: Đóng hàng bột đá chiều 09/08 | D19: DRYU3095661 | E19: Phủ Lý, Hà Nam | J19: 0 | O19: =H19+J19+K19+L19+M19+N19 -> 0 | P19: 2500000 | Q19: =P19-O19 -> 2500000
A20: 13 | B20: 42592 | C20: Đóng hàng chè chiều 10/08 | D20: BMOU6267697 | E20: Mỹ Bằng, Yên Sơn, Tuyên Quang | G20: 388 | H20: 4524080 | J20: 1950000 | O20: =H20+J20+K20+L20+M20+N20 -> 6474080 | P20: 8181818 | Q20: =P20-O20 -> 1707738
A21: 14 | B21: 42592 | C21: Đóng hàng chè chiều 11/08 | D21: TGHU7743514 | E21: Mỹ Bằng, Yên Sơn, Tuyên Quang | J21: 1950000 | O21: =H21+J21+K21+L21+M21+N21 -> 1950000 | P21: 8181818 | Q21: =P21-O21 -> 6231818
A22: 15 | B22: 42593 | C22: Trả hàng + đóng hàng KH 12/08 | D22: WFHU1355961 | E22: KCN Phố Nối A, Hưng Yên - Hà Nam | J22: 1300000 | O22: =H22+J22+K22+L22+M22+N22 -> 1300000 | P22: 4800000 | Q22: =P22-O22 -> 3500000
A23: 16 | B23: 42594 | C23: Trả hàng sáng 13/08 | D23: DYLU2101357 | E23: Bát Tràng, Hà Nội | J23: 1600000 | O23: =H23+J23+K23+L23+M23+N23 -> 1600000 | P23: 5600000 | Q23: =P23-O23 -> 4000000
A24: 17 | B24: 42594 | C24: Đóng hàng bột đá chiều 13/08 | D24: DRYU3095790 | E24: Phủ Lý, Hà Nam | J24: 0 | O24: =H24+J24+K24+L24+M24+N24 -> 0 | P24: 0 | Q24: =P24-O24 -> 0
A25: 18 | B25: 42596 | C25: Trả hàng + đóng hàng kết hợp 15/08 | D25: DRYU2853303 | E25: Nga Sơn, Thanh Hóa - Hà Nam | G25: 620 | H25: 7229200 | J25: 1600000 | O25: =H25+J25+K25+L25+M25+N25 -> 8829200 | P25: 6000000 | Q25: =P25-O25 -> -2829200
A26: 19 | B26: 42597 | C26: Trả hàng + đóng hàng KH 16/08 | D26: DRYU2852591 | E26: Xuân Mai, Hà Nội - Hà Nam | J26: 1600000 | O26: =H26+J26+K26+L26+M26+N26 -> 1600000 | P26: 5400000 | Q26: =P26-O26 -> 3800000
A27: 20 | B27: 42599 | C27: Đóng hàng chè sáng 18/08 | D27: WHLU5683430 | E27: Mộc Châu, Sơn La | J27: 2620000 | O27: =H27+J27+K27+L27+M27+N27 -> 2620000 | P27: 14318182 | Q27: =P27-O27 -> 11698182
A28: 21 | B28: 42600 | C28: Đóng hàng chè sáng 19/08 | D28: MAGU5761706 | E28: Mỹ Bằng, Yên Sơn, Tuyên Quang | J28: 1950000 | O28: =H28+J28+K28+L28+M28+N28 -> 1950000 | P28: 8181818 | Q28: =P28-O28 -> 6231818
A29: 22 | B29: 42604 | C29: Trả hàng NK sáng 22/09 | D29: WHLU0210707 | E29: Bát Tràng, Hà Nội | G29: 550 | H29: 6413000 | J29: 1600000 | O29: =H29+J29+K29+L29+M29+N29 -> 8013000 | P29: 3300000 | Q29: =P29-O29 -> -4713000
A30: 23 | B30: 42604 | C30: Đóng hàng bột đá chiều 22/08 | D30: DRYU2849582 | E30: Phủ Lý, Hà Nam | J30: 0 | O30: =H30+J30+K30+L30+M30+N30 -> 0 | P30: 2500000 | Q30: =P30-O30 -> 2500000
A31: 24 | B31: 42604 | C31: Trả hàng Vietsun sáng 23/08 | D31: TCNU8134104 | E31: KCN Quế Võ, Bắc Ninh | J31: 900000 | O31: =H31+J31+K31+L31+M31+N31 -> 900000 | P31: 3381818 | Q31: =P31-O31 -> 2481818
A32: 25 | B32: 42605 | C32: Trả hàng Vietsun sáng 24/08 | D32: DRYU9718645 | E32: KCN Đồng Văn, Hà Nam | J32: 1020000 | O32: =H32+J32+K32+L32+M32+N32 -> 1020000 | P32: 3545455 | Q32: =P32-O32 -> 2525455
A33: 26 | B33: 42606 | C33: Trả hàng Vietsun tối 24/08 | D33: TCNU4595670 | E33: Tam Trinh, Hoàng Mai, Hà Nội | G33: 500 | H33: 5955000 | J33: 1630000 | O33: =H33+J33+K33+L33+M33+N33 -> 7585000 | P33: 3427273 | Q33: =P33-O33 -> -4157727
A34: 27 | B34: 42606 | C34: Đóng hàng kết hợp sáng 25/08 | D34: TCNU4595670 | E34: Thạch Thất, Hà Nội | J34: 0 | O34: =H34+J34+K34+L34+M34+N34 -> 0 | P34: 3432455 | Q34: =P34-O34 -> 3432455
A35: 28 | B35: 42607 | C35: Trả hàng + đóng hàng KH 26/08 | D35: WFHU1358019 | E35: KCN Đại Đồng, Bắc Ninh - Hà Nam | J35: 1600000 | O35: =H35+J35+K35+L35+M35+N35 -> 1600000 | P35: 5200000 | Q35: =P35-O35 -> 3600000
A36: 29 | B36: 42608 | C36: Đóng hàng sáng 27/08 | D36: YMLU8809335 | E36: Kiện Khê, Hà Nam | J36: 1020000 | O36: =H36+J36+K36+L36+M36+N36 -> 1020000 | P36: 3945455 | Q36: =P36-O36 -> 2925455
A37: 30 | B37: 42610 | C37: Trả hàng sáng 29/08 | D37: DRYU9171115 | E37: KCN Phố Nối A, Hưng Yên | J37: 850000 | O37: =H37+J37+K37+L37+M37+N37 -> 850000 | P37: 2745455 | Q37: =P37-O37 -> 1895455
A38: 31 | B38: 42611 | C38: Đóng hàng sáng 30/08 | D38: TCNU8538976 | E38: KCN Châu Sơn, Hà Nam | G38: 383 | H38: 4561530 | J38: 950000 | O38: =H38+J38+K38+L38+M38+N38 -> 5511530 | P38: 3600000 | Q38: =P38-O38 -> -1911530
A39: 32 | B39: 42611 | C39: Đóng hàng xỉ bọt 31/08 | D39: SKHU4546502 | E39: Phả Lại, Hải Dương | J39: 690000 | O39: =H39+J39+K39+L39+M39+N39 -> 690000 | P39: 3500000 | Q39: =P39-O39 -> 2810000
O40: =H40+J40+K40+L40+M40+N40 -> 0 | Q40: =P40-O40 -> 0
C41: Lương lái xe T08/2016 | K41: 9500000 | O41: =H41+J41+K41+L41+M41+N41 -> 9500000 | Q41: =P41-O41 -> -9500000
C42: Thanh toán tiền sửa chữa, hàn đắp bướm, mâm xe 15C-139.82 | L42: 600000 | O42: =H42+J42+K42+L42+M42+N42 -> 600000 | Q42: =P42-O42 -> -600000
...

Sheet 09.2016
A1: Bảng theo dõi doanh thu/ chi phí theo phương tiện vận chuyển
A2: Biển số xe: 15C - 139.82
B3: THÁNG 09.2016
A5: STT | B5: Ngày tháng | C5: Diễn giải | D5: Số cont | E5: Tuyến đường vận chuyển | F5: Khoảng cách (km) | G5: Chi phí | O5: Tổng chi phí | P5: Cước vận chuyển | Q5: Lợi nhuận gộp
G6: Dầu (l) | H6: Dầu (đồng) | I6: Mức TTBQ | J6: Đi đường | K6: Lương lx | L6: Sửa chữa | M6: Lốp | N6: Dầu máy
A8: 1 | B8: 42613 | C8: Trả hàng + đóng hàng KH 01/09 | D8: DRYU3092976 | E8: KCN Tây Bắc, Thanh Hóa - Hà Nam | J8: 1600000 | O8: =H8+J8+K8+L8+M8+N8 -> 1600000 | P8: 6500000 | Q8: =P8-O8 -> 4900000
A9: 2 | B9: 42614 | C9: Trả hàng Vietsun sáng 02/09 | D9: DRYU9592388 | E9: KCN Phố Nối A, Hưng Yên | J9: 1230000 | O9: =H9+J9+K9+L9+M9+N9 -> 1230000 | P9: 3472727 | Q9: =P9-O9 -> 2242727
A10: 3 | B10: 42617 | C10: Trả hàng + đóng hàng KH 05/09 | D10: DRYU3094618 | E10: KCN Đại Đồng, BN - Hà Nam | G10: 420 | H10: 5002200 | J10: =1600000+70000 -> 1670000 | O10: =H10+J10+K10+L10+M10+N10 -> 6672200 | P10: 5200000 | Q10: =P10-O10 -> -1472200
A11: 4 | B11: 42619 | C11: Đóng hàng chè sáng 07/09 | D11: TCLU8283287 | E11: Mỹ Bằng, Yên Sơn, Tuyên Quang | J11: 1950000 | O11: =H11+J11+K11+L11+M11+N11 -> 1950000 | P11: 8181818 | Q11: =P11-O11 -> 6231818
A12: 5 | B12: 42620 | C12: Trả hàng + đóng hàng KH 08/09 | D12: DRYU2924407 | E12: KCN Phố Nối A, Hưng Yên Hà Nam | J12: 1300000 | O12: =H12+J12+K12+L12+M12+N12 -> 1300000 | P12: 4800000 | Q12: =P12-O12 -> 3500000
A13: 6 | B13: 42621 | C13: Trả hàng + đóng hàng KH 09/09 | D13: WFHU1365044 | E13: Mỹ Hào, Hưng Yên - Hà Nam | J13: 1300000 | O13: =H13+J13+K13+L13+M13+N13 -> 1300000 | P13: 4700000 | Q13: =P13-O13 -> 3400000
A14: 7 | B14: 42623 | C14: Trả hàng NK 10/09 | D14: BMOU2443400 | E14: Thanh Trì, Hà Nội | G14: 550 | H14: 6809000 | J14: =1600000+230000 -> 1830000 | O14: =H14+J14+K14+L14+M14+N14 -> 8639000 | P14: 5200000 | Q14: =P14-O14 -> -3439000
A15: 8 | B15: 42623 | C15: Đóng hàng bột đá 11/09 | D15: VSLU4480527 | E15: Phủ Lý, Hà Nam | J15: 0 | O15: =H15+J15+K15+L15+M15+N15 -> 0 | P15: 0 | Q15: =P15-O15 -> 0
A16: 9 | B16: 42625 | C16: Trả hàng + đóng hàng KH 12/09 | D16: GMDU2412822 | E16: Phù Ninh, Phú Thọ - Hà Nam | J16: 2300000 | O16: =H16+J16+K16+L16+M16+N16 -> 2300000 | P16: 7500000 | Q16: =P16-O16 -> 5200000
A17: 10 | B17: 42625 | C17: Trả hàng + đóng hàng KH 13/09 | D17: GMDU2152999 | E17: Mỹ Hào, Hưng Yên - Hà Nam | J17: 1300000 | O17: =H17+J17+K17+L17+M17+N17 -> 1300000 | P17: 4700000 | Q17: =P17-O17 -> 3400000
A18: 11 | B18: 42626 | C18: Đóng hàng chè chiều 14/09 | D18: BHCU4973660 | E18: Mỹ Bằng, Yên Sơn, Tuyên Quang | J18: 1950000 | O18: =H18+J18+K18+L18+M18+N18 -> 1950000 | P18: 8181818 | Q18: =P18-O18 -> 6231818
A19: 12 | B19: 42627 | C19: Trả hàng + đóng hàng KH 15/09 | D19: GMDU2153341 | E19: Từ Sơn, Bắc Ninh - Hà Nam | G19: 450 | H19: 5571000 | J19: 1600000 | O19: =H19+J19+K19+L19+M19+N19 -> 7171000 | P19: 5300000 | Q19: =P19-O19 -> -1871000
A20: 13 | B20: 42628 | C20: Trả hàng + đóng hàng KH 16/09 | D20: TRHU1344355 | E20: Thanh Trì, Hà Nội - Hà Nam | J20: 1600000 | O20: =H20+J20+K20+L20+M20+N20 -> 1600000 | P20: 5200000 | Q20: =P20-O20 -> 3600000
A21: 14 | B21: 42631 | C21: Trả hàng + đóng hàng KH 19/09 | D21: DRYU2851358 | E21: KCN Phố Nối, Hưng Yên - Hà Nam | G21: 450 | H21: 5571000 | J21: 1300000 | O21: =H21+J21+K21+L21+M21+N21 -> 6871000 | P21: 4800000 | Q21: =P21-O21 -> -2071000
A22: 15 | B22: 42632 | C22: Trả hàng + đóng hàng KH 20/09 | D22: DRYU3023785 | E22: Ngọc Hồi, Hà Nội - Hà Nam | J22: 1600000 | O22: =H22+J22+K22+L22+M22+N22 -> 1600000 | P22: 5200000 | Q22: =P22-O22 -> 3600000
A23: 16 | B23: 42633 | C23: Trả hàng Vietsun sáng 21/09 | D23: DRYU9592520 | E23: Chương Mỹ, Hà Nội | J23: =1230000+400000+180000 -> 1810000 | O23: =H23+J23+K23+L23+M23+N23 -> 1810000 | P23: 3854545 | Q23: =P23-O23 -> 2044545
